Workbook

Sheet 데이터
A1: DATE | B1: 코스피 | C1: =Sheet2!C9 -> KODEX 200 | D1: =Sheet2!D9 -> KODEX 코스닥150 | E1: =Sheet2!E9 -> ACE 테슬라밸류체인액티브 | F1: =Sheet2!F9 -> SOL 조선TOP3플러스 | G1: =Sheet2!G9 -> TIGER 미국나스닥100 | H1: =Sheet2!H9 -> TIGER 미국테크TOP10 INDXX | I1: =Sheet2!I9 -> KODEX 미국나스닥100 | J1: =Sheet2!J9 -> ACE KRX금현물 | ... AR1: =Sheet2!AR9 -> TIGER AI반도체핵심공정
A2: 45426 | B2: 17810 | C2: 36383 | D2: 13917 | E2: 9875 | F2: 11141 | G2: 110225 | H2: 18420 | I2: 16553 | J2: 14760 | K2: 19538 | L2: 6130 | M2: 17336 | N2: 40609 | O2: 3090 | P2: 12751 | T2: 12096 | U2: 41835 | V2: 11159 | X2: 12849 | AA2: 13235 | AB2: 16542 | AC2: 8010 | AD2: 7781 | AE2: 23158 | AF2: 13430 | AH2: 6961 | AI2: 12487 | AJ2: 36855 | AK2: 13626 | AL2: 11330 | AM2: 6446 | AP2: 10045 | AQ2: 18508 | AR2: 12711
A3: 45428 | B3: 17815 | C3: 36730 | D3: 13992 | E3: 9890 | F3: 11141 | G3: 110950 | H3: 18545 | I3: 16653 | J3: 14820 | K3: 19746 | L3: 6085 | M3: 17788 | N3: 41319 | O3: 3095 | P3: 12865 | T3: 12101 | U3: 43285 | V3: 11102 | X3: 13048 | AA3: 13477 | AB3: 16953 | AC3: 7790 | AD3: 7891 | AE3: 23338 | AF3: 13580 | AH3: 7050 | AI3: 12780 | AJ3: 37620 | AK3: 14045 | AL3: 11440 | AM3: 6531 | AP3: 9977 | AQ3: 19160 | AR3: 13066
A4: 45429 | B4: 17910 | C4: 36300 | D4: 13344 | E4: 9955 | F4: 10806 | G4: 111417 | H4: 18590 | I4: 16738 | J4: 14880 | K4: 19453 | L4: 6125 | M4: 17847 | N4: 40777 | O4: 3090 | P4: 12632 | T4: 11806 | U4: 43095 | V4: 11102 | X4: 12884 | AA4: 13367 | AB4: 16919 | AC4: 7825 | AD4: 7986 | AE4: 23048 | AF4: 13615 | AH4: 6975 | AI4: 12648 | AJ4: 37610 | AK4: 13803 | AL4: 11504 | AM4: 6201 | AP4: 10014 | AQ4: 18933 | AR4: 12849
A5: 45432 | B5: 17955 | C5: 36602 | D5: 13374 | E5: 10090 | F5: 10672 | G5: 111571 | H5: 18620 | I5: 16753 | J5: 15300 | K5: 19299 | L5: 6220 | M5: 17828 | N5: 40945 | O5: 3110 | P5: 12502 | T5: 11911 | U5: 42685 | V5: 11159 | X5: 13048 | AA5: 13500 | AB5: 17513 | AC5: 7890 | AD5: 7816 | AE5: 22938 | AF5: 13650 | AH5: 6931 | AI5: 12879 | AJ5: 37650 | AK5: 13912 | AL5: 11514 | AM5: 6201 | AP5: 10072 | AQ5: 19911 | AR5: 13046
A6: 45433 | B6: 18045 | C6: 36412 | D6: 13389 | E6: 9975 | F6: 10657 | G6: 112614 | H6: 18760 | I6: 16913 | J6: 15225 | K6: 18843 | L6: 5990 | M6: 18205 | N6: 41196 | O6: 3210 | P6: 12134 | T6: 11861 | U6: 42415 | V6: 11140 | X6: 13077 | AA6: 13434 | AB6: 17255 | AC6: 7815 | AD6: 7726 | AE6: 22384 | AF6: 13775 | AH6: 6746 | AI6: 12836 | AJ6: 37950 | AK6: 14026 | AL6: 11644 | AM6: 6181 | AP6: 10072 | AQ6: 19521 | AR6: 13159
A7: 45434 | B7: 18080 | C7: 36412 | D7: 13424 | E7: 10375 | F7: 10337 | G7: 112972 | H7: 18900 | I7: 16958 | J7: 15150 | K7: 18788 | L7: 6060 | M7: 18239 | N7: 41492 | O7: 3170 | P7: 12124 | T7: 11756 | U7: 42515 | V7: 11102 | X7: 13246 | AA7: 13306 | AB7: 17241 | AC7: 7920 | AD7: 7666 | AE7: 22389 | AF7: 13800 | AH7: 6741 | AI7: 12586 | AJ7: 38210 | AK7: 14159 | AL7: 11828 | AM7: 6117 | AP7: 10072 | AQ7: 19551 | AR7: 13253
A8: 45435 | B8: 18130 | C8: 36412 | D8: 13384 | E8: 10250 | F8: 10477 | G8: 113777 | H8: 19105 | I8: 17082 | J8: 14860 | K8: 18758 | L8: 5895 | M8: 18701 | N8: 41739 | O8: 3190 | P8: 12085 | T8: 11741 | U8: 42820 | V8: 11078 | X8: 13266 | AA8: 13282 | AB8: 17414 | AC8: 7770 | AD8: 8171 | AE8: 22359 | AF8: 13960 | AH8: 6771 | AI8: 12421 | AJ8: 38405 | AK8: 14050 | AL8: 11833 | AM8: 6047 | AP8: 10045 | AQ8: 19990 | AR8: 13184
A9: 45436 | B9: 18000 | C9: 35845 | D9: 13260 | E9: 9945 | F9: 10732 | G9: 112962 | H9: 19040 | I9: 16958 | J9: 14725 | K9: 18411 | L9: 5746 | M9: 18458 | N9: 40787 | O9: 3210 | P9: 11856 | T9: 11656 | U9: 42475 | V9: 10967 | X9: 13008 | AA9: 13116 | AB9: 18172 | AC9: 7690 | AD9: 8156 | AE9: 22004 | AF9: 13890 | AH9: 6636 | AI9: 12337 | AJ9: 37895 | AK9: 13685 | AL9: 11774 | AM9: 5967 | AP9: 9995 | AQ9: 20301 | AR9: 12820
A10: 45439 | B10: 18040 | C10: 36344 | D10: 13469 | E10: 10205 | F10: 10637 | G10: 113613 | H10: 19190 | I10: 17053 | J10: 14715 | K10: 19175 | L10: 5826 | M10: 18691 | N10: 41556 | O10: 3155 | P10: 12303 | T10: 11851 | U10: 42635 | V10: 10928 | X10: 13251 | AA10: 13149 | AB10: 18841 | AC10: 7625 | AD10: 8381 | AE10: 22763 | AF10: 14030 | AH10: 6941 | AI10: 12337 | AJ10: 38280 | AK10: 14070 | AL10: 11933 | AM10: 6012 | AP10: 9968 | AQ10: 20835 | AR10: 13204
A11: 45440 | B11: 17995 | C11: 36383 | D11: 13454 | E11: 10160 | F11: 10647 | G11: 113389 | H11: 19205 | I11: 17023 | J11: 14690 | K11: 18793 | L11: 5781 | M11: 18780 | N11: 42246 | O11: 3155 | P11: 11960 | T11: 12201 | U11: 42630 | V11: 10885 | X11: 13534 | AA11: 13144 | AB11: 19316 | AC11: 7535 | AD11: 8141 | AE11: 22424 | AF11: 14045 | AH11: 6796 | AI11: 12308 | AJ11: 38375 | AK11: 14351 | AL11: 11963 | AM11: 6042 | AP11: 9937 | AQ11: 21102 | AR11: 13583
A12: 45441 | B12: 17985 | C12: 35850 | D12: 13210 | E12: 10145 | F12: 10487 | G12: 113593 | H12: 19310 | I12: 17058 | J12: 14765 | K12: 18143 | L12: 5681 | M12: 18969 | N12: 41916 | O12: 3255 | P12: 11383 | T12: 11731 | U12: 41545 | V12: 10803 | X12: 13465 | AA12: 13144 | AB12: 18900 | AC12: 7620 | AD12: 7966 | AE12: 21639 | AF12: 14185 | AH12: 6581 | AI12: 12332 | AJ12: 38215 | AK12: 14356 | AL12: 12137 | AM12: 5947 | AP12: 9900 | AQ12: 20603 | AR12: 13469
A13: 45442 | B13: 18020 | C13: 35200 | D13: 13115 | E13: 10130 | F13: 10352 | G13: 113692 | H13: 19445 | I13: 17063 | J13: 14765 | K13: 17905 | L13: 5701 | M13: 18711 | N13: 41191 | O13: 3319 | P13: 11110 | T13: 11452 | U13: 41075 | V13: 10784 | X13: 13167 | AA13: 13059 | AB13: 18449 | AC13: 7775 | AD13: 8101 | AE13: 21274 | AF13: 14325 | AH13: 6491 | AI13: 12256 | AJ13: 37935 | AK13: 14065 | AL13: 12152 | AM13: 5947 | AP13: 9864 | AQ13: 20306 | AR13: 13228
... A19: 45453 | B19: 18340 | C19: 36070 | D19: 13853 | E19: 10265 | F19: 10427 | G19: 115689 | H19: 19865 | I19: 17362 | J19: 14560 | K19: 19409 | L19: 5661 | M19: 19078 | N19: 41955 | O19: 3220 | P19: 12100 | T19: 11582 | U19: 42755 | V19: 10987 | X19: 13375 | AA19: 13306 | AB19: 17890 | AC19: 7620 | AD19: 7901 | AE19: 23083 | AF19: 14545 | AH19: 7155 | AI19: 12214 | AJ19: 38290 | AK19: 13951 | AL19: 12442 | AM19: 6201 | AP19: 10005 | AQ19: 19442 | AR19: 13327
A20: 45454 | B20: 18445 | C20: 36104 | D20: 14037 | E20: 10105 | F20: 10382 | G20: 116498 | H20: 20020 | I20: 17482 | J20: 14580 | K20: 19821 | L20: 5731 | M20: 19386 | N20: 41916 | O20: 3235 | P20: 12119 | T20: 11577 | U20: 42630 | V20: 10968 | X20: 13336 | Z20: 10080 | AA20: 13311 | AB20: 17602 | AC20: 7680 | AD20: 7861 | AE20: 23403 | AF20: 14695 | AH20: 7270 | AI20: 12166 | AJ20: 38390 | AK20: 13700 | AL20: 12447 | AM20: 6246 | AP20: 10042 | AQ20: 19343 | AR20: 13080
A21: 45455 | B21: 18485 | C21: 36422 | D21: 14052 | E21: 9965 | F21: 10497 | G21: 117318 | H21: 20380 | I21: 17612 | J21: 14650 | K21: 19741 | L21: 5646 | M21: 19500 | N21: 42764 | O21: 3424 | P21: 12000 | T21: 11826 | U21: 43000 | V21: 10948 | X21: 13663 | Z21: 10150 | AA21: 13364 | AB21: 17300 | AC21: 7645 | AD21: 7786 | AE21: 23278 | AF21: 14920 | AH21: 7225 | AI21: 12285 | AJ21: 38835 | AK21: 14129 | AL21: 12491 | AM21: 6201 | AP21: 10046 | AQ21: 19081 | AR21: 13430
A22: 45456 | B22: 18625 | C22: 36671 | D22: 14017 | E22: 10450 | F22: 10477 | G22: 119305 | H22: 20915 | I22: 17911 | J22: 14575 | K22: 19776 | L22: 5646 | M22: 20224 | N22: 43588 | O22: 3529 | P22: 12085 | T22: 11831 | U22: 43445 | V22: 10910 | X22: 14020 | Z22: 10745 | AA22: 13449 | AB22: 17434 | AC22: 7660 | AD22: 7791 | AE22: 23393 | AF22: 15365 | AH22: 7255 | AI22: 12233 | AJ22: 40135 | AK22: 14490 | AL22: 12865 | AM22: 6146 | AP22: 9992 | AQ22: 19180 | AR22: 13696
A23: 45457 | B23: 18710 | C23: 36793 | D23: 13773 | E23: 10485 | F23: 10777 | G23: 119931 | H23: 21090 | I23: 18001 | J23: 14505 | K23: 19324 | L23: 5676 | M23: 20378 | N23: 43405 | O23: 3514 | P23: 11736 | T23: 11911 | U23: 44325 | V23: 10910 | X23: 13991 | Z23: 10840 | AA23: 13478 | AB23: 17919 | AC23: 7650 | AD23: 7716 | AE23: 22933 | AF23: 15475 | AH23: 7065 | AI23: 12233 | AJ23: 40115 | AK23: 14262 | AL23: 13035 | AM23: 6107 | AP23: 10055 | AQ23: 19249 | AR23: 13514
A24: 45460 | B24: 18710 | C24: 36593 | D24: 13758 | E24: 10300 | F24: 10717 | G24: 120258 | H24: 21160 | I24: 18051 | J24: 14680 | K24: 18882 | L24: 5661 | M24: 20408 | N24: 43371 | O24: 3489 | P24: 11483 | T24: 12196 | U24: 44765 | V24: 10857 | X24: 13936 | Z24: 10835 | AA24: 13464 | AB24: 17934 | AC24: 7790 | AD24: 7706 | AE24: 22459 | AF24: 15545 | AH24: 6891 | AI24: 12081 | AJ24: 40480 | AK24: 14317 | AL24: 13060 | AM24: 6057 | AP24: 10055 | AQ24: 19081 | AR24: 13607
A25: 45461 | B25: 18870 | C25: 36979 | D25: 13768 | E25: 10530 | F25: 10647 | G25: 121763 | H25: 21405 | I25: 18281 | J25: 14700 | K25: 18585 | L25: 5631 | M25: 20765 | N25: 44268 | O25: 3539 | P25: 11239 | T25: 12226 | U25: 44600 | V25: 10958 | X25: 14214 | Z25: 11095 | AA25: 13549 | AB25: 17900 | AC25: 7785 | AD25: 7696 | AE25: 22044 | AF25: 15745 | AH25: 6786 | AI25: 12081 | AJ25: 41245 | AK25: 14425 | AL25: 13254 | AM25: 6067 | AP25: 10101 | AQ25: 18869 | AR25: 13784
A26: 45462 | B26: 18930 | C26: 37531 | D26: 13788 | E26: 10570 | F26: 10996 | G26: 122022 | H26: 21540 | I26: 18325 | J26: 14770 | K26: 18833 | L26: 5821 | M26: 21117 | N26: 44337 | O26: 3469 | P26: 11577 | T26: 12241 | U26: 45155 | V26: 10992 | X26: 14269 | Z26: 11615 | AA26: 13659 | AB26: 18083 | AC26: 7700 | AD26: 7656 | AE26: 22424 | AF26: 15780 | AH26: 6861 | AI26: 12237 | AJ26: 40995 | AK26: 14317 | AL26: 13234 | AM26: 6102 | AP26: 10133 | AQ26: 18963 | AR26: 13858
A27: 45463 | B27: 19025 | C27: 37677 | D27: 13718 | E27: 10600 | F27: 11001 | G27: 122861 | H27: 21580 | I27: 18445 | J27: 14875 | K27: 18813 | L27: 5766 | M27: 21326 | N27: 44702 | O27: 3389 | P27: 11577 | T27: 12186 | U27: 44825 | V27: 11006 | X27: 14432 | Z27: 11735 | AA27: 13859 | AB27: 17934 | AC27: 7560 | AD27: 7646 | AE27: 22364 | AF27: 15860 | AH27: 6771 | AI27: 12464 | AJ27: 41315 | AK27: 14119 | AL27: 13384 | AM27: 6072 | AP27: 10156 | AQ27: 18800 | AR27: 13725
A28: 45464 | B28: 18985 | C28: 37355 | D28: 13693 | E28: 10250 | F28: 11036 | G28: 121724 | H28: 21265 | I28: 18276 | J28: 15000 | K28: 18565 | L28: 5696 | M28: 20636 | N28: 43928 | O28: 3459 | P28: 11368 | T28: 11901 | U28: 44670 | V28: 11103 | X28: 14234 | Z28: 11175 | AA28: 13926 | AB28: 18479 | AC28: 7490 | AD28: 7596 | AE28: 22044 | AF28: 15625 | AH28: 6701 | AI28: 12436 | AJ28: 40650 | AK28: 13951 | AL28: 13119 | AM28: 6072 | AP28: 10238 | AQ28: 19427 | AR28: 13499
A29: 45467 | B29: 18955 | C29: 37071 | D29: 13504 | E29: 10295 | F29: 11276 | G29: 121406 | H29: 21135 | I29: 18226 | J29: 14845 | K29: 18202 | L29: 5591 | M29: 20303 | N29: 43094 | O29: 3454 | P29: 11145 | T29: 11926 | U29: 44570 | V29: 11127 | X29: 14006 | Z29: 10925 | AA29: 13907 | AB29: 18048 | AC29: 7435 | AD29: 7461 | AE29: 21524 | AF29: 15495 | AH29: 6581 | AI29: 12488 | AJ29: 40400 | AK29: 13769 | AL29: 13090 | AM29: 6092 | AP29: 10220 | AQ29: 18780 | AR29: 13371
A30: 45468 | B30: 18880 | C30: 37179 | D30: 13569 | E30: 10185 | F30: 11306 | G30: 119940 | H30: 20740 | I30: 18006 | J30: 14870 | K30: 17994 | L30: 5596 | M30: 19718 | N30: 43060 | O30: 3404 | P30: 10971 | T30: 11876 | U30: 44915 | V30: 11252 | X30: 13901 | Z30: 10405 | AA30: 13974 | AB30: 17924 | AC30: 7370 | AD30: 7446 | AE30: 21259 | AF30: 15160 | AH30: 6496 | AI30: 12535 | AJ30: 39670 | AK30: 13685 | AL30: 12840 | AM30: 6181 | AP30: 10302 | AQ30: 18696 | AR30: 13292
A31: 45469 | B31: 18990 | C31: 37487 | D31: 13509 | E31: 10455 | F31: 11221 | G31: 121515 | H31: 21295 | I31: 18241 | J31: 14800 | K31: 17979 | L31: 5686 | M31: 20229 | N31: 44130 | O31: 3504 | P31: 10995 | T31: 11836 | U31: 44650 | V31: 11185 | X31: 14214 | Z31: 10965 | AA31: 13978 | AB31: 17959 | AC31: 7445 | AD31: 7466 | AE31: 21244 | AF31: 15565 | AH31: 6461 | AI31: 12493 | AJ31: 40360 | AK31: 13843 | AL31: 13154 | AM31: 6062 | AP31: 10242 | AQ31: 18642 | AR31: 13504
... A39: 45481 | B39: 19195 | C39: 38703 | D39: 14316 | E39: 12950 | F39: 11405 | G39: 124838 | H39: 22190 | I39: 18740 | J39: 15100 | K39: 18739 | L39: 5431 | M39: 20542 | N39: 44160 | O39: 3255 | P39: 11756 | T39: 11587 | U39: 43290 | V39: 11015 | X39: 14149 | Z39: 11170 | AA39: 14337 | AB39: 18301 | AC39: 6915 | AD39: 7506 | AE39: 22339 | AF39: 16170 | AH39: 6846 | AI39: 13244 | AJ39: 43725 | AK39: 13517 | AL39: 14271 | AM39: 6481 | AP39: 10252 | AQ39: 18637 | AR39: 13464
A40: 45482 | B40: 19255 | C40: 38840 | D40: 14311 | E40: 13130 | F40: 11361 | G40: 125459 | H40: 22355 | I40: 18840 | J40: 15050 | K40: 18689 | L40: 5521 | M40: 21013 | N40: 44628 | O40: 3195 | P40: 11727 | R40: 10060 | S40: 10271 | T40: 11651 | U40: 43555 | V40: 11049 | X40: 14343 | Z40: 11410 | AA40: 14189 | AB40: 19059 | AC40: 7040 | AD40: 7446 | AE40: 22169 | AF40: 16295 | AH40: 6781 | AI40: 13054 | AJ40: 43835 | AK40: 13833 | AL40: 14425 | AM40: 6521 | AP40: 10279 | AQ40: 18741 | AR40: 13716
A41: 45483 | B41: 19280 | C41: 38825 | D41: 14241 | E41: 13490 | F41: 11560 | G41: 125598 | H41: 22460 | I41: 18870 | J41: 15005 | K41: 18391 | L41: 5521 | M41: 21028 | N41: 44376 | O41: 3230 | P41: 11488 | R41: 10115 | S41: 10968 | T41: 11671 | U41: 43415 | V41: 11054 | X41: 14303 | Z41: 11400 | AA41: 14304 | AB41: 19361 | AC41: 7050 | AD41: 7431 | AE41: 21894 | AF41: 16370 | AH41: 6671 | AI41: 13016 | AJ41: 43880 | AK41: 13813 | AL41: 14675 | AM41: 6551 | AP41: 10270 | AQ41: 18741 | AR41: 13583
A42: 45484 | B42: 19395 | C42: 39065 | D42: 14122 | E42: 13555 | F42: 11600 | G42: 126243 | H42: 22635 | I42: 18949 | J42: 15070 | K42: 18619 | L42: 5631 | M42: 21335 | N42: 44574 | O42: 3165 | P42: 11826 | R42: 10245 | S42: 10958 | T42: 11786 | U42: 43465 | V42: 11112 | X42: 14323 | Z42: 11595 | AA42: 14462 | AB42: 19331 | AC42: 7185 | AD42: 7321 | AE42: 22139 | AF42: 16515 | AH42: 6736 | AI42: 13182 | AJ42: 44090 | AK42: 14006 | AL42: 14759 | AM42: 6541 | AP42: 10321 | AQ42: 18829 | AR42: 13706
A43: 45485 | B43: 19255 | C43: 38527 | D43: 14092 | E43: 12355 | F43: 11615 | G43: 123527 | H43: 21940 | I43: 18540 | J43: 15200 | K43: 18590 | L43: 5766 | M43: 20661 | N43: 43568 | O43: 3120 | P43: 11776 | R43: 10160 | S43: 10721 | T43: 11921 | U43: 44205 | V43: 11233 | X43: 14110 | Z43: 11015 | AA43: 14376 | AB43: 19118 | AC43: 7270 | AD43: 7431 | AE43: 22164 | AF43: 15960 | AH43: 6756 | AI43: 13192 | AJ43: 42670 | AK43: 13690 | AL43: 14171 | AM43: 6621 | AP43: 10330 | AQ43: 18760 | AR43: 13376
A44: 45488 | B44: 19425 | C44: 38772 | D44: 14117 | E44: 13495 | F44: 11710 | G44: 125037 | H44: 22135 | I44: 18775 | J44: 15310 | K44: 18327 | L44: 5641 | M44: 21122 | N44: 43701 | O44: 3115 | P44: 11612 | R44: 10324 | S44: 10879 | T44: 12176 | U44: 43740 | V44: 11403 | X44: 14125 | Z44: 11235 | AA44: 14318 | AB44: 19698 | AC44: 7170 | AD44: 7326 | AE44: 21734 | AF44: 16100 | AH44: 6681 | AI44: 13097 | AJ44: 42950 | AK44: 13576 | AL44: 14490 | AM44: 6631 | AP44: 10431 | AQ44: 18736 | AR44: 13243
A45: 45489 | B45: 19505 | C45: 38796 | D45: 13868 | E45: 13200 | F45: 12119 | G45: 125379 | H45: 22185 | I45: 18820 | J45: 15530 | K45: 17716 | L45: 5571 | M45: 21132 | N45: 44278 | O45: 3020 | P45: 11095 | R45: 10205 | S45: 10800 | T45: 12176 | U45: 43960 | V45: 11446 | X45: 14333 | Z45: 11205 | AA45: 14395 | AB45: 19411 | AC45: 7215 | AD45: 7277 | AE45: 20900 | AF45: 16140 | AH45: 6401 | AI45: 13092 | AJ45: 42925 | AK45: 13823 | AL45: 14565 | AM45: 6606 | AP45: 10472 | AQ45: 18444 | AR45: 13474
A46: 45490 | B46: 19470 | C46: 38474 | D46: 13643 | E46: 13170 | F46: 12464 | G46: 123889 | H46: 21690 | I46: 18595 | J46: 15705 | K46: 17458 | L46: 5591 | M46: 20874 | N46: 42384 | O46: 3150 | P46: 10906 | R46: 10120 | S46: 10311 | T46: 12091 | U46: 44550 | V46: 11596 | X46: 13787 | Z46: 11000 | AA46: 14395 | AB46: 19084 | AC46: 7240 | AD46: 7112 | AE46: 20500 | AF46: 15765 | AH46: 6232 | AI46: 13149 | AJ46: 42280 | AK46: 12954 | AL46: 14386 | AM46: 6761 | AP46: 10523 | AQ46: 18306 | AR46: 12564
A47: 45491 | B47: 19345 | C47: 38190 | D47: 13579 | E47: 12840 | F47: 12339 | G47: 121878 | H47: 21255 | I47: 18306 | J47: 15715 | K47: 17428 | L47: 5551 | M47: 20060 | N47: 41635 | O47: 3115 | P47: 10911 | R47: 9501 | S47: 9940 | T47: 11846 | U47: 44530 | V47: 11824 | X47: 13524 | Z47: 10385 | AA47: 14510 | AB47: 18776 | AC47: 7290 | AD47: 7152 | AE47: 20455 | AF47: 15430 | AH47: 6281 | AI47: 13197 | AJ47: 41490 | AK47: 12796 | AL47: 13992 | AM47: 6716 | AP47: 10573 | AQ47: 17990 | AR47: 12372
A48: 45492 | B48: 19255 | C48: 37741 | D48: 13683 | E48: 12950 | F48: 11979 | G48: 121575 | H48: 21220 | I48: 18256 | J48: 15445 | K48: 17746 | L48: 5461 | M48: 19956 | N48: 41186 | O48: 3090 | P48: 11219 | R48: 9521 | S48: 9995 | T48: 11886 | U48: 44075 | V48: 11747 | X48: 13380 | Z48: 10215 | AA48: 14447 | AB48: 18509 | AC48: 7340 | AD48: 7187 | AE48: 20860 | AF48: 15420 | AH48: 6481 | AI48: 13154 | AJ48: 41255 | AK48: 12737 | AL48: 14017 | AM48: 6676 | AP48: 10491 | AQ48: 18177 | AR48: 12229
A49: 45495 | B49: 19125 | C49: 37365 | D49: 13344 | E49: 12440 | F49: 12369 | G49: 120581 | H49: 21035 | I49: 18106 | J49: 15380 | K49: 16947 | L49: 5531 | M49: 19366 | N49: 39909 | O49: 3145 | P49: 10637 | R49: 9616 | S49: 9654 | T49: 11646 | U49: 44060 | V49: 11664 | X49: 12983 | Z49: 10010 | AA49: 14452 | AB49: 18316 | AC49: 7285 | AD49: 7047 | AE49: 19965 | AF49: 15250 | AH49: 6182 | AI49: 13349 | AJ49: 40775 | AK49: 12209 | AL49: 13663 | AM49: 6721 | AP49: 10445 | AQ49: 17703 | AR49: 11781
A50: 45496 | B50: 19210 | C50: 37472 | D50: 13394 | E50: 12830 | F50: 12778 | G50: 121172 | H50: 21295 | I50: 18191 | J50: 15275 | K50: 16654 | L50: 5446 | M50: 19777 | N50: 39781 | O50: 3195 | P50: 10513 | R50: 9826 | S50: 10676 | T50: 11851 | U50: 43485 | V50: 11630 | X50: 12934 | Z50: 10290 | AA50: 14476 | AB50: 19306 | AC50: 7135 | AD50: 7072 | AE50: 19601 | AF50: 15440 | AH50: 6022 | AI50: 13354 | AJ50: 41350 | AK50: 12100 | AL50: 14052 | AM50: 6726 | AP50: 10431 | AQ50: 17925 | AR50: 11677
A51: 45497 | B51: 19080 | C51: 37252 | D51: 13439 | E51: 11745 | F51: 12728 | G51: 119995 | H51: 21025 | I51: 18021 | J51: 15420 | K51: 16460 | L51: 5357 | M51: 19425 | N51: 39816 | O51: 3225 | P51: 10409 | R51: 9851 | S51: 10765 | T51: 12096 | U51: 43435 | V51: 11519 | X51: 12899 | Z51: 10245 | AA51: 14419 | AB51: 19430 | AC51: 6955 | AD51: 6947 | AE51: 19331 | AF51: 15330 | AH51: 5952 | AI51: 13173 | AJ51: 40580 | AK51: 12095 | AL51: 13713 | AM51: 6875 | AP51: 10357 | AQ51: 17861 | AR51: 11702
... A107: 45586 | B107: 20105 | C107: 34256 | D107: 12826 | E107: 11135 | F107: 12578 | G107: 123706 | H107: 21595 | I107: 18585 | J107: 17570 | K107: 16520 | L107: 6903 | M107: 18775 | N107: 32119 | O107: 2906 | P107: 10762 | R107: 12040 | S107: 8957 | T107: 11851 | U107: 44260 | V107: 12412 | X107: 10328 | Z107: 9645 | AA107: 14686 | AB107: 17776 | AC107: 8910 | AD107: 6972 | AE107: 19970 | AF107: 15550 | AH107: 5732 | AI107: 14149 | AJ107: 42190 | AK107: 10293 | AL107: 14256 | AM107: 8199 | AP107: 10989 | AQ107: 17219 | AR107: 9403
...

Sheet Sheet2
A1: Refresh | B1: Last Update : 2025-05-30 15:34:56
A2: 0
A3: Time Series (Company)
A4: Frequency | B4: D | C4: Ascending | D4: 0
A5: Period(From) | B5: 20240514 | C5: Korean | D5: 0
A6: Period(To) | B6: 20250530 | D6: 0
A8: Code | B8: A360750 | C8: A069500 | D8: A229200 | E8: A457480 | F8: A466920 | G8: A133690 | H8: A381170 | I8: A379810 | J8: A411060 | K8: A305720 | L8: A371160 | M8: A381180 | N8: A091160 | O8: A228790 | P8: A364980 | Q8: A494670 | R8: A487230 | S8: A487240 | T8: A463250 | U8: A458250 | V8: A458730 | W8: A498400 | X8: A396500 | Y8: A0047A0 | Z8: A483320 | AA8: A161510 | AB8: A434730 | AC8: A371460 | AD8: A475050 | AE8: A305540 | AF8: A465580 | AG8: A0000J0 | AH8: A462010 | AI8: A466940 | AJ8: A314250 | AK8: A471990 | AL8: A473460 | AM8: A364970 | AN8: A0008E0 | AO8: A0048K0 | AP8: A441640 | AQ8: A385510 | AR8: A471760
A9: Name | B9: TIGER 미국S&P500 | C9: KODEX 200 | D9: KODEX 코스닥150 | E9: ACE 테슬라밸류체인액티브 | F9: SOL 조선TOP3플러스 | G9: TIGER 미국나스닥100 | H9: TIGER 미국테크TOP10 INDXX | I9: KODEX 미국나스닥100 | J9: ACE KRX금현물 | K9: KODEX 2차전지산업 | L9: TIGER 차이나항셍테크 | M9: TIGER 미국필라델피아반도체나스닥 | N9: KODEX 반도체 | O9: TIGER 화장품 | P9: TIGER 2차전지TOP10 | Q9: TIGER 조선TOP10 | R9: KODEX 미국AI전력핵심인프라 | S9: KODEX AI전력핵심설비 | T9: TIGER K방산&우주 | U9: TIGER 미국30년국채스트립액티브(합성 H) | V9: TIGER 미국배당다우존스 | W9: KODEX 200타겟위클리커버드콜 | X9: TIGER Fn반도체TOP10 | Y9: TIGER 차이나테크TOP10 | Z9: ACE 엔비디아밸류체인액티브 | AA9: PLUS 고배당주 | AB9: HANARO 원자력iSelect | AC9: TIGER 차이나전기차SOLACTIVE | AD9: ACE KPOP포커스 | AE9: TIGER 2차전지테마 | AF9: ACE 미국빅테크TOP7 Plus | AG9: PLUS 한화그룹주 | AH9: TIGER 2차전지소재Fn | AI9: TIGER 은행고배당플러스TOP10 | AJ9: KODEX 미국빅테크10(H) | AK9: KODEX AI반도체핵심장비 | AL9: KODEX 미국서학개미 | AM9: TIGER 바이오TOP10 | AN9: ACE 미국중심중소형제조업 | AO9: KODEX 차이나휴머노이드로봇 | AP9: KODEX 미국배당커버드콜액티브 | AQ9: KODEX 신재생에너지액티브 | AR9: TIGER AI반도체핵심공정
A10: Item Code | B10: S100100 | C10: S100300 | D10: S100300 | E10: S100300 | F10: S100300 | G10: S100300 | H10: S100300 | I10: S100300 | J10: S100300 | K10: S100300 | L10: S100300 | M10: S100300 | N10: S100300 | O10: S100300 | P10: S100300 | Q10: S100300 | R10: S100300 | S10: S100300 | T10: S100300 | U10: S100300 | V10: S100300 | W10: S100300 | X10: S100300 | Y10: S100300 | Z10: S100300 | AA10: S100300 | AB10: S100300 | AC10: S100300 | AD10: S100300 | AE10: S100300 | AF10: S100300 | AG10: S100300 | AH10: S100300 | AI10: S100300 | AJ10: S100300 | AK10: S100300 | AL10: S100300 | AM10: S100300 | AN10: S100300 | AO10: S100300 | AP10: S100300 | AQ10: S100300 | AR10: S100300
A11: Unit | B11: Local/Shares | C11: Local/Shares | D11: Local/Shares | E11: Local/Shares | F11: Local/Shares | G11: Local/Shares | H11: Local/Shares | I11: Local/Shares | J11: Local/Shares | K11: Local/Shares | L11: Local/Shares | M11: Local/Shares | N11: Local/Shares | O11: Local/Shares | P11: Local/Shares | Q11: Local/Shares | R11: Local/Shares | S11: Local/Shares | T11: Local/Shares | U11: Local/Shares | V11: Local/Shares | W11: Local/Shares | X11: Local/Shares | Y11: Local/Shares | Z11: Local/Shares | AA11: Local/Shares | AB11: Local/Shares | AC11: Local/Shares | AD11: Local/Shares | AE11: Local/Shares | AF11: Local/Shares | AG11: Local/Shares | AH11: Local/Shares | AI11: Local/Shares | AJ11: Local/Shares | AK11: Local/Shares | AL11: Local/Shares | AM11: Local/Shares | AN11: Local/Shares | AO11: Local/Shares | AP11: Local/Shares | AQ11: Local/Shares | AR11: Local/Shares
A12: Base Date
A14: D A T E | B14: 종가 | C14: 수정주가 | D14: 수정주가 | E14: 수정주가 | F14: 수정주가 | G14: 수정주가 | H14: 수정주가 | I14: 수정주가 | J14: 수정주가 | K14: 수정주가 | L14: 수정주가 | M14: 수정주가 | N14: 수정주가 | O14: 수정주가 | P14: 수정주가 | Q14: 수정주가 | R14: 수정주가 | S14: 수정주가 | T14: 수정주가 | U14: 수정주가 | V14: 수정주가 | W14: 수정주가 | X14: 수정주가 | Y14: 수정주가 | Z14: 수정주가 | AA14: 수정주가 | AB14: 수정주가 | AC14: 수정주가 | AD14: 수정주가 | AE14: 수정주가 | AF14: 수정주가 | AG14: 수정주가 | AH14: 수정주가 | AI14: 수정주가 | AJ14: 수정주가 | AK14: 수정주가 | AL14: 수정주가 | AM14: 수정주가 | AN14: 수정주가 | AO14: 수정주가 | AP14: 수정주가 | AQ14: 수정주가 | AR14: 수정주가
A15: 45425 | B15: 17835 | C15: 36309 | D15: 13793 | E15: 9695 | F15: 11211 | G15: 110245 | H15: 18415 | I15: 16553 | J15: 14830 | K15: 19359 | L15: 6050 | M15: 17326 | N15: 40363 | O15: 3085 | P15: 12612 | T15: 12036 | U15: 41825 | V15: 11130 | X15: 12795 | AA15: 13249 | AB15: 16636 | AC15: 8015 | AD15: 7646 | AE15: 22903 | AF15: 13435 | AH15: 6871 | AI15: 12685 | AJ15: 36770 | AK15: 13468 | AL15: 11255 | AM15: 6446 | AP15: 10050 | AQ15: 18706 | AR15: 12583
A16: 45426 | B16: 17810 | C16: 36383 | D16: 13917 | E16: 9875 | F16: 11141 | G16: 110225 | H16: 18420 | I16: 16553 | J16: 14760 | K16: 19538 | L16: 6130 | M16: 17336 | N16: 40609 | O16: 3090 | P16: 12751 | T16: 12096 | U16: 41835 | V16: 11159 | X16: 12849 | AA16: 13235 | AB16: 16542 | AC16: 8010 | AD16: 7781 | AE16: 23158 | AF16: 13430 | AH16: 6961 | AI16: 12487 | AJ16: 36855 | AK16: 13626 | AL16: 11330 | AM16: 6446 | AP16: 10045 | AQ16: 18508 | AR16: 12711
A17: 45428 | B17: 17815 | C17: 36730 | D17: 13992 | E17: 9890 | F17: 11141 | G17: 110950 | H17: 18545 | I17: 16653 | J17: 14820 | K17: 19746 | L17: 6085 | M17: 17788 | N17: 41319 | O17: 3095 | P17: 12865 | T17: 12101 | U17: 43285 | V17: 11102 | X17: 13048 | AA17: 13477 | AB17: 16953 | AC17: 7790 | AD17: 7891 | AE17: 23338 | AF17: 13580 | AH17: 7050 | AI17: 12780 | AJ17: 37620 | AK17: 14045 | AL17: 11440 | AM17: 6531 | AP17: 9977 | AQ17: 19160 | AR17: 13066
A18: 45429 | B18: 17910 | C18: 36300 | D18: 13344 | E18: 9955 | F18: 10806 | G18: 111417 | H18: 18590 | I18: 16738 | J18: 14880 | K18: 19453 | L18: 6125 | M18: 17847 | N18: 40777 | O18: 3090 | P18: 12632 | T18: 11806 | U18: 43095 | V18: 11102 | X18: 12884 | AA18: 13367 | AB18: 16919 | AC18: 7825 | AD18: 7986 | AE18: 23048 | AF18: 13615 | AH18: 6975 | AI18: 12648 | AJ18: 37610 | AK18: 13803 | AL18: 11504 | AM18: 6201 | AP18: 10014 | AQ18: 18933 | AR18: 12849
A19: 45432 | B19: 17955 | C19: 36602 | D19: 13374 | E19: 10090 | F19: 10672 | G19: 111571 | H19: 18620 | I19: 16753 | J19: 15300 | K19: 19299 | L19: 6220 | M19: 17828 | N19: 40945 | O19: 3110 | P19: 12502 | T19: 11911 | U19: 42685 | V19: 11159 | X19: 13048 | AA19: 13500 | AB19: 17513 | AC19: 7890 | AD19: 7816 | AE19: 22938 | AF19: 13650 | AH19: 6931 | AI19: 12879 | AJ19: 37650 | AK19: 13912 | AL19: 11514 | AM19: 6201 | AP19: 10072 | AQ19: 19911 | AR19: 13046
A20: 45433 | B20: 18045 | C20: 36412 | D20: 13389 | E20: 9975 | F20: 10657 | G20: 112614 | H20: 18760 | I20: 16913 | J20: 15225 | K20: 18843 | L20: 5990 | M20: 18205 | N20: 41196 | O20: 3210 | P20: 12134 | T20: 11861 | U20: 42415 | V20: 11140 | X20: 13077 | AA20: 13434 | AB20: 17255 | AC20: 7815 | AD20: 7726 | AE20: 22384 | AF20: 13775 | AH20: 6746 | AI20: 12836 | AJ20: 37950 | AK20: 14026 | AL20: 11644 | AM20: 6181 | AP20: 10072 | AQ20: 19521 | AR20: 13159
A21: 45434 | B21: 18080 | C21: 36412 | D21: 13424 | E21: 10375 | F21: 10337 | G21: 112972 | H21: 18900 | I21: 16958 | J21: 15150 | K21: 18788 | L21: 6060 | M21: 18239 | N21: 41492 | O21: 3170 | P21: 12124 | T21: 11756 | U21: 42515 | V21: 11102 | X21: 13246 | AA21: 13306 | AB21: 17241 | AC21: 7920 | AD21: 7666 | AE21: 22389 | AF21: 13800 | AH21: 6741 | AI21: 12586 | AJ21: 38210 | AK21: 14159 | AL21: 11828 | AM21: 6117 | AP21: 10072 | AQ21: 19551 | AR21: 13253
A22: 45435 | B22: 18130 | C22: 36412 | D22: 13384 | E22: 10250 | F22: 10477 | G22: 113777 | H22: 19105 | I22: 17082 | J22: 14860 | K22: 18758 | L22: 5895 | M22: 18701 | N22: 41739 | O22: 3190 | P22: 12085 | T22: 11741 | U22: 42820 | V22: 11078 | X22: 13266 | AA22: 13282 | AB22: 17414 | AC22: 7770 | AD22: 8171 | AE22: 22359 | AF22: 13960 | AH22: 6771 | AI22: 12421 | AJ22: 38405 | AK22: 14050 | AL22: 11833 | AM22: 6047 | AP22: 10045 | AQ22: 19990 | AR22: 13184
A23: 45436 | B23: 18000 | C23: 35845 | D23: 13260 | E23: 9945 | F23: 10732 | G23: 112962 | H23: 19040 | I23: 16958 | J23: 14725 | K23: 18411 | L23: 5746 | M23: 18458 | N23: 40787 | O23: 3210 | P23: 11856 | T23: 11656 | U23: 42475 | V23: 10967 | X23: 13008 | AA23: 13116 | AB23: 18172 | AC23: 7690 | AD23: 8156 | AE23: 22004 | AF23: 13890 | AH23: 6636 | AI23: 12337 | AJ23: 37895 | AK23: 13685 | AL23: 11774 | AM23: 5967 | AP23: 9995 | AQ23: 20301 | AR23: 12820
A24: 45439 | B24: 18040 | C24: 36344 | D24: 13469 | E24: 10205 | F24: 10637 | G24: 113613 | H24: 19190 | I24: 17053 | J24: 14715 | K24: 19175 | L24: 5826 | M24: 18691 | N24: 41556 | O24: 3155 | P24: 12303 | T24: 11851 | U24: 42635 | V24: 10928 | X24: 13251 | AA24: 13149 | AB24: 18841 | AC24: 7625 | AD24: 8381 | AE24: 22763 | AF24: 14030 | AH24: 6941 | AI24: 12337 | AJ24: 38280 | AK24: 14070 | AL24: 11933 | AM24: 6012 | AP24: 9968 | AQ24: 20835 | AR24: 13204
A25: 45440 | B25: 17995 | C25: 36383 | D25: 13454 | E25: 10160 | F25: 10647 | G25: 113389 | H25: 19205 | I25: 17023 | J25: 14690 | K25: 18793 | L25: 5781 | M25: 18780 | N25: 42246 | O25: 3155 | P25: 11960 | T25: 12201 | U25: 42630 | V25: 10885 | X25: 13534 | AA25: 13144 | AB25: 19316 | AC25: 7535 | AD25: 8141 | AE25: 22424 | AF25: 14045 | AH25: 6796 | AI25: 12308 | AJ25: 38375 | AK25: 14351 | AL25: 11963 | AM25: 6042 | AP25: 9937 | AQ25: 21102 | AR25: 13583
A26: 45441 | B26: 17985 | C26: 35850 | D26: 13210 | E26: 10145 | F26: 10487 | G26: 113593 | H26: 19310 | I26: 17058 | J26: 14765 | K26: 18143 | L26: 5681 | M26: 18969 | N26: 41916 | O26: 3255 | P26: 11383 | T26: 11731 | U26: 41545 | V26: 10803 | X26: 13465 | AA26: 13144 | AB26: 18900 | AC26: 7620 | AD26: 7966 | AE26: 21639 | AF26: 14185 | AH26: 6581 | AI26: 12332 | AJ26: 38215 | AK26: 14356 | AL26: 12137 | AM26: 5947 | AP26: 9900 | AQ26: 20603 | AR26: 13469
... A33: 45453 | B33: 18340 | C33: 36070 | D33: 13853 | E33: 10265 | F33: 10427 | G33: 115689 | H33: 19865 | I33: 17362 | J33: 14560 | K33: 19409 | L33: 5661 | M33: 19078 | N33: 41955 | O33: 3220 | P33: 12100 | T33: 11582 | U33: 42755 | V33: 10987 | X33: 13375 | AA33: 13306 | AB33: 17890 | AC33: 7620 | AD33: 7901 | AE33: 23083 | AF33: 14545 | AH33: 7155 | AI33: 12214 | AJ33: 38290 | AK33: 13951 | AL33: 12442 | AM33: 6201 | AP33: 10005 | AQ33: 19442 | AR33: 13327
A34: 45454 | B34: 18445 | C34: 36104 | D34: 14037 | E34: 10105 | F34: 10382 | G34: 116498 | H34: 20020 | I34: 17482 | J34: 14580 | K34: 19821 | L34: 5731 | M34: 19386 | N34: 41916 | O34: 3235 | P34: 12119 | T34: 11577 | U34: 42630 | V34: 10968 | X34: 13336 | Z34: 10080 | AA34: 13311 | AB34: 17602 | AC34: 7680 | AD34: 7861 | AE34: 23403 | AF34: 14695 | AH34: 7270 | AI34: 12166 | AJ34: 38390 | AK34: 13700 | AL34: 12447 | AM34: 6246 | AP34: 10042 | AQ34: 19343 | AR34: 13080
A35: 45455 | B35: 18485 | C35: 36422 | D35: 14052 | E35: 9965 | F35: 10497 | G35: 117318 | H35: 20380 | I35: 17612 | J35: 14650 | K35: 19741 | L35: 5646 | M35: 19500 | N35: 42764 | O35: 3424 | P35: 12000 | T35: 11826 | U35: 43000 | V35: 10948 | X35: 13663 | Z35: 10150 | AA35: 13364 | AB35: 17300 | AC35: 7645 | AD35: 7786 | AE35: 23278 | AF35: 14920 | AH35: 7225 | AI35: 12285 | AJ35: 38835 | AK35: 14129 | AL35: 12491 | AM35: 6201 | AP35: 10046 | AQ35: 19081 | AR35: 13430
A36: 45456 | B36: 18625 | C36: 36671 | D36: 14017 | E36: 10450 | F36: 10477 | G36: 119305 | H36: 20915 | I36: 17911 | J36: 14575 | K36: 19776 | L36: 5646 | M36: 20224 | N36: 43588 | O36: 3529 | P36: 12085 | T36: 11831 | U36: 43445 | V36: 10910 | X36: 14020 | Z36: 10745 | AA36: 13449 | AB36: 17434 | AC36: 7660 | AD36: 7791 | AE36: 23393 | AF36: 15365 | AH36: 7255 | AI36: 12233 | AJ36: 40135 | AK36: 14490 | AL36: 12865 | AM36: 6146 | AP36: 9992 | AQ36: 19180 | AR36: 13696
A37: 45457 | B37: 18710 | C37: 36793 | D37: 13773 | E37: 10485 | F37: 10777 | G37: 119931 | H37: 21090 | I37: 18001 | J37: 14505 | K37: 19324 | L37: 5676 | M37: 20378 | N37: 43405 | O37: 3514 | P37: 11736 | T37: 11911 | U37: 44325 | V37: 10910 | X37: 13991 | Z37: 10840 | AA37: 13478 | AB37: 17919 | AC37: 7650 | AD37: 7716 | AE37: 22933 | AF37: 15475 | AH37: 7065 | AI37: 12233 | AJ37: 40115 | AK37: 14262 | AL37: 13035 | AM37: 6107 | AP37: 10055 | AQ37: 19249 | AR37: 13514
A38: 45460 | B38: 18710 | C38: 36593 | D38: 13758 | E38: 10300 | F38: 10717 | G38: 120258 | H38: 21160 | I38: 18051 | J38: 14680 | K38: 18882 | L38: 5661 | M38: 20408 | N38: 43371 | O38: 3489 | P38: 11483 | T38: 12196 | U38: 44765 | V38: 10857 | X38: 13936 | Z38: 10835 | AA38: 13464 | AB38: 17934 | AC38: 7790 | AD38: 7706 | AE38: 22459 | AF38: 15545 | AH38: 6891 | AI38: 12081 | AJ38: 40480 | AK38: 14317 | AL38: 13060 | AM38: 6057 | AP38: 10055 | AQ38: 19081 | AR38: 13607
A39: 45461 | B39: 18870 | C39: 36979 | D39: 13768 | E39: 10530 | F39: 10647 | G39: 121763 | H39: 21405 | I39: 18281 | J39: 14700 | K39: 18585 | L39: 5631 | M39: 20765 | N39: 44268 | O39: 3539 | P39: 11239 | T39: 12226 | U39: 44600 | V39: 10958 | X39: 14214 | Z39: 11095 | AA39: 13549 | AB39: 17900 | AC39: 7785 | AD39: 7696 | AE39: 22044 | AF39: 15745 | AH39: 6786 | AI39: 12081 | AJ39: 41245 | AK39: 14425 | AL39: 13254 | AM39: 6067 | AP39: 10101 | AQ39: 18869 | AR39: 13784
A40: 45462 | B40: 18930 | C40: 37531 | D40: 13788 | E40: 10570 | F40: 10996 | G40: 122022 | H40: 21540 | I40: 18325 | J40: 14770 | K40: 18833 | L40: 5821 | M40: 21117 | N40: 44337 | O40: 3469 | P40: 11577 | T40: 12241 | U40: 45155 | V40: 10992 | X40: 14269 | Z40: 11615 | AA40: 13659 | AB40: 18083 | AC40: 7700 | AD40: 7656 | AE40: 22424 | AF40: 15780 | AH40: 6861 | AI40: 12237 | AJ40: 40995 | AK40: 14317 | AL40: 13234 | AM40: 6102 | AP40: 10133 | AQ40: 18963 | AR40: 13858
A41: 45463 | B41: 19025 | C41: 37677 | D41: 13718 | E41: 10600 | F41: 11001 | G41: 122861 | H41: 21580 | I41: 18445 | J41: 14875 | K41: 18813 | L41: 5766 | M41: 21326 | N41: 44702 | O41: 3389 | P41: 11577 | T41: 12186 | U41: 44825 | V41: 11006 | X41: 14432 | Z41: 11735 | AA41: 13859 | AB41: 17934 | AC41: 7560 | AD41: 7646 | AE41: 22364 | AF41: 15860 | AH41: 6771 | AI41: 12464 | AJ41: 41315 | AK41: 14119 | AL41: 13384 | AM41: 6072 | AP41: 10156 | AQ41: 18800 | AR41: 13725
A42: 45464 | B42: 18985 | C42: 37355 | D42: 13693 | E42: 10250 | F42: 11036 | G42: 121724 | H42: 21265 | I42: 18276 | J42: 15000 | K42: 18565 | L42: 5696 | M42: 20636 | N42: 43928 | O42: 3459 | P42: 11368 | T42: 11901 | U42: 44670 | V42: 11103 | X42: 14234 | Z42: 11175 | AA42: 13926 | AB42: 18479 | AC42: 7490 | AD42: 7596 | AE42: 22044 | AF42: 15625 | AH42: 6701 | AI42: 12436 | AJ42: 40650 | AK42: 13951 | AL42: 13119 | AM42: 6072 | AP42: 10238 | AQ42: 19427 | AR42: 13499
A43: 45467 | B43: 18955 | C43: 37071 | D43: 13504 | E43: 10295 | F43: 11276 | G43: 121406 | H43: 21135 | I43: 18226 | J43: 14845 | K43: 18202 | L43: 5591 | M43: 20303 | N43: 43094 | O43: 3454 | P43: 11145 | T43: 11926 | U43: 44570 | V43: 11127 | X43: 14006 | Z43: 10925 | AA43: 13907 | AB43: 18048 | AC43: 7435 | AD43: 7461 | AE43: 21524 | AF43: 15495 | AH43: 6581 | AI43: 12488 | AJ43: 40400 | AK43: 13769 | AL43: 13090 | AM43: 6092 | AP43: 10220 | AQ43: 18780 | AR43: 13371
A44: 45468 | B44: 18880 | C44: 37179 | D44: 13569 | E44: 10185 | F44: 11306 | G44: 119940 | H44: 20740 | I44: 18006 | J44: 14870 | K44: 17994 | L44: 5596 | M44: 19718 | N44: 43060 | O44: 3404 | P44: 10971 | T44: 11876 | U44: 44915 | V44: 11252 | X44: 13901 | Z44: 10405 | AA44: 13974 | AB44: 17924 | AC44: 7370 | AD44: 7446 | AE44: 21259 | AF44: 15160 | AH44: 6496 | AI44: 12535 | AJ44: 39670 | AK44: 13685 | AL44: 12840 | AM44: 6181 | AP44: 10302 | AQ44: 18696 | AR44: 13292
A45: 45469 | B45: 18990 | C45: 37487 | D45: 13509 | E45: 10455 | F45: 11221 | G45: 121515 | H45: 21295 | I45: 18241 | J45: 14800 | K45: 17979 | L45: 5686 | M45: 20229 | N45: 44130 | O45: 3504 | P45: 10995 | T45: 11836 | U45: 44650 | V45: 11185 | X45: 14214 | Z45: 10965 | AA45: 13978 | AB45: 17959 | AC45: 7445 | AD45: 7466 | AE45: 21244 | AF45: 15565 | AH45: 6461 | AI45: 12493 | AJ45: 40360 | AK45: 13843 | AL45: 13154 | AM45: 6062 | AP45: 10242 | AQ45: 18642 | AR45: 13504
... A53: 45481 | B53: 19195 | C53: 38703 | D53: 14316 | E53: 12950 | F53: 11405 | G53: 124838 | H53: 22190 | I53: 18740 | J53: 15100 | K53: 18739 | L53: 5431 | M53: 20542 | N53: 44160 | O53: 3255 | P53: 11756 | T53: 11587 | U53: 43290 | V53: 11015 | X53: 14149 | Z53: 11170 | AA53: 14337 | AB53: 18301 | AC53: 6915 | AD53: 7506 | AE53: 22339 | AF53: 16170 | AH53: 6846 | AI53: 13244 | AJ53: 43725 | AK53: 13517 | AL53: 14271 | AM53: 6481 | AP53: 10252 | AQ53: 18637 | AR53: 13464
A54: 45482 | B54: 19255 | C54: 38840 | D54: 14311 | E54: 13130 | F54: 11361 | G54: 125459 | H54: 22355 | I54: 18840 | J54: 15050 | K54: 18689 | L54: 5521 | M54: 21013 | N54: 44628 | O54: 3195 | P54: 11727 | R54: 10060 | S54: 10271 | T54: 11651 | U54: 43555 | V54: 11049 | X54: 14343 | Z54: 11410 | AA54: 14189 | AB54: 19059 | AC54: 7040 | AD54: 7446 | AE54: 22169 | AF54: 16295 | AH54: 6781 | AI54: 13054 | AJ54: 43835 | AK54: 13833 | AL54: 14425 | AM54: 6521 | AP54: 10279 | AQ54: 18741 | AR54: 13716
A55: 45483 | B55: 19280 | C55: 38825 | D55: 14241 | E55: 13490 | F55: 11560 | G55: 125598 | H55: 22460 | I55: 18870 | J55: 15005 | K55: 18391 | L55: 5521 | M55: 21028 | N55: 44376 | O55: 3230 | P55: 11488 | R55: 10115 | S55: 10968 | T55: 11671 | U55: 43415 | V55: 11054 | X55: 14303 | Z55: 11400 | AA55: 14304 | AB55: 19361 | AC55: 7050 | AD55: 7431 | AE55: 21894 | AF55: 16370 | AH55: 6671 | AI55: 13016 | AJ55: 43880 | AK55: 13813 | AL55: 14675 | AM55: 6551 | AP55: 10270 | AQ55: 18741 | AR55: 13583
...

Sheet Sheet3
A1: Refresh | B1: Last Update : 2025-05-23 15:53:42
A3: Peer Analysis (To Select)
A4: Account Type | B4: All Listed | C4: Korean
B9: Account | C9: R100200 | D9: S301540
B10: Period | D10: CPD-1TD
B11: Unit | C11: Txt | D11: Local
B12: Base Date
A13: Code | B13: Name | C13: 결산월 | D13: 월간누계거래대금
A14: A069500 | B14: KODEX 200 | C14: 10 | D14: 3032437929074
A15: A229200 | B15: KODEX 코스닥150 | D15: 1344590981680
A16: A360750 | B16: TIGER 미국S&P500 | D16: 905456580635
A17: A457480 | B17: ACE 테슬라밸류체인액티브 | D17: 793606578894
A18: A466920 | B18: SOL 조선TOP3플러스 | D18: 581437860957
A19: A133690 | B19: TIGER 미국나스닥100 | C19: 10 | D19: 513364648385
A20: A381170 | B20: TIGER 미국테크TOP10 INDXX | D20: 511819416758
A21: A379810 | B21: KODEX 미국나스닥100 | D21: 346026773897
A22: A411060 | B22: ACE KRX금현물 | D22: 328957510338
A23: A305720 | B23: KODEX 2차전지산업 | D23: 325252664602
A24: A371160 | B24: TIGER 차이나항셍테크 | D24: 314497116026
A25: A381180 | B25: TIGER 미국필라델피아반도체나스닥 | D25: 284227543938
A26: A091160 | B26: KODEX 반도체 | C26: 10 | D26: 264563503311
A27: A228790 | B27: TIGER 화장품 | D27: 254462527056
A28: A364980 | B28: TIGER 2차전지TOP10 | D28: 234768359431
A29: A494670 | B29: TIGER 조선TOP10 | D29: 224565602821
A30: A487230 | B30: KODEX 미국AI전력핵심인프라 | D30: 224560324830
A31: A487240 | B31: KODEX AI전력핵심설비 | D31: 212749420719
A32: A463250 | B32: TIGER K방산&우주 | D32: 198463846588
A33: A458250 | B33: TIGER 미국30년국채스트립액티브(합성 H) | D33: 188047066127
A34: A458730 | B34: TIGER 미국배당다우존스 | D34: 180668921933
A35: A498400 | B35: KODEX 200타겟위클리커버드콜 | D35: 177536650862
A36: A396500 | B36: TIGER Fn반도체TOP10 | D36: 157668867501
A37: A0047A0 | B37: TIGER 차이나테크TOP10 | D37: 154501788748
A38: A483320 | B38: ACE 엔비디아밸류체인액티브 | D38: 149327959551
... A41: A371460 | B41: TIGER 차이나전기차SOLACTIVE | D41: 115181736944
A42: A475050 | B42: ACE KPOP포커스 | C42: 12 | D42: 104023650793
A43: A305540 | B43: TIGER 2차전지테마 | D43: 102816118356
A44: A465580 | B44: ACE 미국빅테크TOP7 Plus | D44: 98848208608
A45: A0000J0 | B45: PLUS 한화그룹주 | D45: 97230943619
A46: A462010 | B46: TIGER 2차전지소재Fn | D46: 92712260763
A47: A466940 | B47: TIGER 은행고배당플러스TOP10 | D47: 91873380370
...
