Workbook

Sheet db
A1: 종목명 | B1: 유동시가총액 | C1: EPS(Fwd.12M)(1개월, 지배) | D1: EPS(Fwd.12M)(3개월, 지배) | E1: 20일누적 외국인총합계순매수대금(일간) | F1: 120일누적 외국인총합계순매수대금(일간) | G1: 20일누적 기관 순매수대금(일간) | H1: 120일누적 기관 순매수대금(일간)
A2: =Sheet1!B14 -> 삼성전자 | B2: =Sheet1!D14 -> 4345911.7 | C2: =Sheet1!E14 -> 9536 | D2: =Sheet1!F14 -> 9229 | E2: =Sheet1!G14 -> 9526.12 | F2: =Sheet1!H14 -> 122385.38 | G2: =Sheet1!I14 -> -11178.47 | H2: =Sheet1!J14 -> 502
A3: =Sheet1!B15 -> SK하이닉스 | B3: =Sheet1!D15 -> 3024180.1 | C3: =Sheet1!E15 -> 77374 | D3: =Sheet1!F15 -> 75630 | E3: =Sheet1!G15 -> -97239.8 | F3: =Sheet1!H15 -> -74498.47 | G3: =Sheet1!I15 -> 21155.75 | H3: =Sheet1!J15 -> 15662.58
A4: =Sheet1!B16 -> KB금융 | B4: =Sheet1!D16 -> 386648.65 | C4: =Sheet1!E16 -> 15642 | D4: =Sheet1!F16 -> 15527 | E4: =Sheet1!G16 -> -4330.48 | F4: =Sheet1!H16 -> -5729.06 | G4: =Sheet1!I16 -> 5311.04 | H4: =Sheet1!J16 -> 8171
A5: =Sheet1!B17 -> 한화에어로스페이스 | B5: =Sheet1!D17 -> 308507.7 | C5: =Sheet1!E17 -> 47286 | D5: =Sheet1!F17 -> 47574 | E5: =Sheet1!G17 -> -594.47 | F5: =Sheet1!H17 -> 3329.39 | G5: =Sheet1!I17 -> 742.68 | H5: =Sheet1!J17 -> 1597.07
A6: =Sheet1!B18 -> NAVER | B6: =Sheet1!D18 -> 341477.29 | C6: =Sheet1!E18 -> 14533 | D6: =Sheet1!F18 -> 14299 | E6: =Sheet1!G18 -> -4516.07 | F6: =Sheet1!H18 -> -35486.37 | G6: =Sheet1!I18 -> -1383.47 | H6: =Sheet1!J18 -> 5973.79
A7: =Sheet1!B19 -> 현대차 | B7: =Sheet1!D19 -> 364630.07 | C7: =Sheet1!E19 -> 42764 | D7: =Sheet1!F19 -> 42764 | E7: =Sheet1!G19 -> -3766.21 | F7: =Sheet1!H19 -> -2409.16 | G7: =Sheet1!I19 -> 778.54 | H7: =Sheet1!J19 -> -502.09
A8: =Sheet1!B20 -> 신한지주 | B8: =Sheet1!D20 -> 308892.66 | C8: =Sheet1!E20 -> 10745 | D8: =Sheet1!F20 -> 10713 | E8: =Sheet1!G20 -> -1300.52 | F8: =Sheet1!H20 -> -507.8 | G8: =Sheet1!I20 -> 2437.16 | H8: =Sheet1!J20 -> 6344.09
A9: =Sheet1!B21 -> 두산에너빌리티 | B9: =Sheet1!D21 -> 347020.16 | C9: =Sheet1!E21 -> 639 | D9: =Sheet1!F21 -> 639 | E9: =Sheet1!G21 -> -8435.35 | F9: =Sheet1!H21 -> -9488.95 | G9: =Sheet1!I21 -> -2341.2 | H9: =Sheet1!J21 -> -2740.24
A10: =Sheet1!B22 -> 셀트리온 | B10: =Sheet1!D22 -> 288234.76 | C10: =Sheet1!E22 -> 5251 | D10: =Sheet1!F22 -> 5274 | E10: =Sheet1!G22 -> 2692.02 | F10: =Sheet1!H22 -> 1422.88 | G10: =Sheet1!I22 -> 1182.31 | H10: =Sheet1!J22 -> -283.45
A11: =Sheet1!B23 -> 기아 | B11: =Sheet1!D23 -> 273399.23 | C11: =Sheet1!E23 -> 21310 | D11: =Sheet1!F23 -> 21326 | E11: =Sheet1!G23 -> -1434.77 | F11: =Sheet1!H23 -> 2580.38 | G11: =Sheet1!I23 -> 1049.55 | H11: =Sheet1!J23 -> -447.57
A12: =Sheet1!B24 -> 하나금융지주 | B12: =Sheet1!D24 -> 228924.99 | C12: =Sheet1!E24 -> 14908 | D12: =Sheet1!F24 -> 14840 | E12: =Sheet1!G24 -> -1061.14 | F12: =Sheet1!H24 -> -2225.86 | G12: =Sheet1!I24 -> 1178.55 | H12: =Sheet1!J24 -> 1901.61
A13: =Sheet1!B25 -> 카카오 | B13: =Sheet1!D25 -> 204641.43 | C13: =Sheet1!E25 -> 1461 | D13: =Sheet1!F25 -> 1459 | E13: =Sheet1!G25 -> 1568.75 | F13: =Sheet1!H25 -> 5614.13 | G13: =Sheet1!I25 -> 672.47 | H13: =Sheet1!J25 -> 2365.63
... A301: =Sheet1!B313 -> 대한광통신 | B301: =Sheet1!D313 -> 2244.82 | C301: =Sheet1!E313 -> 64 | D301: =Sheet1!F313 -> 30 | E301: =Sheet1!G313 -> -84.37 | F301: =Sheet1!H313 -> -102.39 | G301: =Sheet1!I313 -> 30.67 | H301: =Sheet1!J313 -> -79.37

Sheet Sheet1
A1: Refresh | B1: Last Update : 2025-11-14 19:57:52
A3: Peer Analysis (To Select)
A4: Account Type | B4: All Listed | C4: Korean
B9: Account | C9: R100200 | D9: S102306 | E9: E312060.M1 | F9: E312060.M | G9: U630320 | H9: U930320 | I9: U610320 | J9: U910320
B10: Period | D10: CPD | G10: CPD | H10: CPD | I10: CPD | J10: CPD
B11: Unit | C11: Txt | D11: Local 100mn | E11: Local/Shares | F11: Local/Shares | G11: Local 100mn | H11: Local 100mn | I11: Local 100mn | J11: Local 100mn
B12: Base Date | E12: CPD | F12: CPD
A13: Code | B13: Name | C13: 결산월 | D13: 유동시가총액 | E13: EPS(Fwd.12M, 지배) | F13: EPS(Fwd.12M, 지배) | G13: 20일누적 외국인총합계 순매수대금(일간) | H13: 120일누적 외국인총합계 순매수대금(일간) | I13: 20일누적 기관 순매수대금(일간) | J13: 120일누적 기관 순매수대금(일간)
A14: A005930 | B14: 삼성전자 | C14: 12 | D14: 4345911.7 | E14: 9536 | F14: 9229 | G14: 9526.12 | H14: 122385.38 | I14: -11178.47 | J14: 502
A15: A000660 | B15: SK하이닉스 | C15: 12 | D15: 3024180.1 | E15: 77374 | F15: 75630 | G15: -97239.8 | H15: -74498.47 | I15: 21155.75 | J15: 15662.58
A16: A105560 | B16: KB금융 | C16: 12 | D16: 386648.65 | E16: 15642 | F16: 15527 | G16: -4330.48 | H16: -5729.06 | I16: 5311.04 | J16: 8171
A17: A012450 | B17: 한화에어로스페이스 | C17: 12 | D17: 308507.7 | E17: 47286 | F17: 47574 | G17: -594.47 | H17: 3329.39 | I17: 742.68 | J17: 1597.07
A18: A035420 | B18: NAVER | C18: 12 | D18: 341477.29 | E18: 14533 | F18: 14299 | G18: -4516.07 | H18: -35486.37 | I18: -1383.47 | J18: 5973.79
A19: A005380 | B19: 현대차 | C19: 12 | D19: 364630.07 | E19: 42764 | F19: 42764 | G19: -3766.21 | H19: -2409.16 | I19: 778.54 | J19: -502.09
A20: A055550 | B20: 신한지주 | C20: 12 | D20: 308892.66 | E20: 10745 | F20: 10713 | G20: -1300.52 | H20: -507.8 | I20: 2437.16 | J20: 6344.09
A21: A034020 | B21: 두산에너빌리티 | C21: 12 | D21: 347020.16 | E21: 639 | F21: 639 | G21: -8435.35 | H21: -9488.95 | I21: -2341.2 | J21: -2740.24
A22: A068270 | B22: 셀트리온 | C22: 12 | D22: 288234.76 | E22: 5251 | F22: 5274 | G22: 2692.02 | H22: 1422.88 | I22: 1182.31 | J22: -283.45
A23: A000270 | B23: 기아 | C23: 12 | D23: 273399.23 | E23: 21310 | F23: 21326 | G23: -1434.77 | H23: 2580.38 | I23: 1049.55 | J23: -447.57
A24: A086790 | B24: 하나금융지주 | C24: 12 | D24: 228924.99 | E24: 14908 | F24: 14840 | G24: -1061.14 | H24: -2225.86 | I24: 1178.55 | J24: 1901.61
A25: A035720 | B25: 카카오 | C25: 12 | D25: 204641.43 | E25: 1461 | F25: 1459 | G25: 1568.75 | H25: 5614.13 | I25: 672.47 | J25: 2365.63
... A133: A062040 | B133: 산일전기 | C133: 12 | D133: 18545.05 | E133: 6494 | F133: 6370 | G133: -220.8 | H133: 687.88 | I133: 122.91 | J133: 449.74
A134: A039200 | B134: 오스코텍 | C134: 12 | D134: 17505.29 | F134: 560 | G134: -33.78 | H134: 80.55 | I134: 589.73 | J134: 1423.45
A135: A336260 | B135: 두산퓨얼셀 | C135: 12 | D135: 13730.49 | E135: -122 | F135: -105 | G135: 994.49 | H135: 1901.23 | I135: -126.28 | J135: 302.35
A136: A122870 | B136: 와이지엔터테인먼트 | C136: 12 | D136: 8354.82 | E136: 3664 | F136: 3664 | G136: 301.88 | H136: 704.02 | I136: -1316.62 | J136: -722.26
A137: A081660 | B137: 미스토홀딩스 | C137: 12 | D137: 12723.97 | E137: 4328 | F137: 4072 | G137: -20.33 | H137: -687.46 | I137: -47.08 | J137: -68.33
A138: A010060 | B138: OCI홀딩스 | C138: 12 | D138: 15225.45 | E138: 12162 | F138: 11780 | G138: 487.82 | H138: 687.01 | I138: 9.04 | J138: 823.24
A139: A263750 | B139: 펄어비스 | C139: 12 | D139: 14620.37 | E139: 2273 | F139: 2112 | G139: 68.69 | H139: -151.59 | I139: 81.79 | J139: -209.81
A140: A011170 | B140: 롯데케미칼 | C140: 12 | D140: 16035.65 | E140: -7871 | F140: -7312 | G140: 85.24 | H140: 757.59 | I140: 203.01 | J140: -108.8
A141: A454910 | B141: 두산로보틱스 | C141: 12 | D141: 15875.09 | F141: -508 | G141: -33.35 | H141: 328.67 | I141: 182.85 | J141: 302.42
A142: A950160 | B142: 코오롱티슈진 | C142: 12 | D142: 15084.04 | E142: -497 | F142: -497 | G142: 245.42 | H142: 340.02 | I142: 82.04 | J142: -95.32
A143: A140860 | B143: 파크시스템스 | C143: 12 | D143: 11701.7 | E143: 8552 | F143: 8805 | G143: -55.95 | H143: -590.54 | I143: 48.62 | J143: 235.8
A144: A375500 | B144: DL이앤씨 | C144: 12 | D144: 11635.01 | E144: 8121 | F144: 8279 | G144: -160.8 | H144: -424.97 | I144: 7.63 | J144: -601.91
A145: A483650 | B145: 달바글로벌 | C145: 12 | D145: 9643.23 | E145: 9703 | F145: 9703 | G145: -141.25 | H145: 2007.04 | I145: -276.92 | J145: 1.09
A146: A006360 | B146: GS건설 | C146: 12 | D146: 11968.98 | E146: 3498 | F146: 3534 | G146: 67.37 | H146: 405.88 | I146: -97.3 | J146: -800.53
A147: A088350 | B147: 한화생명 | C147: 12 | D147: 11243.71 | E147: 660 | F147: 723 | G147: -42.16 | H147: -46.67 | I147: 23.42 | J147: 92.75
A148: A357780 | B148: 솔브레인 | C148: 12 | D148: 11159.16 | E148: 20580 | F148: 20510 | G148: 237.13 | H148: -608.43 | I148: -195.18 | J148: 912.24
A149: A004170 | B149: 신세계 | C149: 12 | D149: 12828.73 | E149: 22841 | F149: 23002 | G149: 123.79 | H149: 546.06 | I149: 352.74 | J149: 190.33
A150: A307950 | B150: 현대오토에버 | C150: 12 | D150: 12176.06 | E150: 8501 | F150: 8501 | G150: 403.81 | H150: 988.1 | I150: -147.1 | J150: -212.2
A151: A204320 | B151: HL만도 | C151: 12 | D151: 11834.46 | E151: 4943 | F151: 4896 | G151: 202.01 | H151: -145.28 | I151: -5.19 | J151: -365
A152: A214150 | B152: 클래시스 | C152: 12 | D152: 11653 | E152: 2710 | F152: 2709 | G152: 81.88 | H152: -1303.82 | I152: 240.51 | J152: -77.89
...

Sheet Sheet2
A1: Refresh | B1: Last Update : 2025-11-14 19:57:54
A3: Peer Analysis (To Select)
A4: Account Type | B4: All Listed | C4: Korean
B9: Account | C9: R100200 | D9: S102306 | E9: E312060.M1
B10: Period | D10: CPD
B11: Unit | C11: Txt | D11: Local 100mn | E11: Local/Shares
B12: Base Date | E12: CPD
A13: Code | B13: Name | C13: 결산월 | D13: 유동시가총액 | E13: EPS(Fwd.12M, 지배)
A14: A005930 | B14: 삼성전자 | C14: 12 | D14: 4345911.7 | E14: 9536
A15: A000660 | B15: SK하이닉스 | C15: 12 | D15: 3024180.1 | E15: 77374
A16: A105560 | B16: KB금융 | C16: 12 | D16: 386648.65 | E16: 15642
A17: A012450 | B17: 한화에어로스페이스 | C17: 12 | D17: 308507.7 | E17: 47286
A18: A035420 | B18: NAVER | C18: 12 | D18: 341477.29 | E18: 14533
A19: A005380 | B19: 현대차 | C19: 12 | D19: 364630.07 | E19: 42764
A20: A055550 | B20: 신한지주 | C20: 12 | D20: 308892.66 | E20: 10745
A21: A034020 | B21: 두산에너빌리티 | C21: 12 | D21: 347020.16 | E21: 639
A22: A068270 | B22: 셀트리온 | C22: 12 | D22: 288234.76 | E22: 5251
A23: A000270 | B23: 기아 | C23: 12 | D23: 273399.23 | E23: 21310
A24: A086790 | B24: 하나금융지주 | C24: 12 | D24: 228924.99 | E24: 14908
A25: A035720 | B25: 카카오 | C25: 12 | D25: 204641.43 | E25: 1461
... A133: A062040 | B133: 산일전기 | C133: 12 | D133: 18545.05 | E133: 6494
A134: A039200 | B134: 오스코텍 | C134: 12 | D134: 17505.29
A135: A336260 | B135: 두산퓨얼셀 | C135: 12 | D135: 13730.49 | E135: -122
A136: A122870 | B136: 와이지엔터테인먼트 | C136: 12 | D136: 8354.82 | E136: 3664
A137: A081660 | B137: 미스토홀딩스 | C137: 12 | D137: 12723.97 | E137: 4328
A138: A010060 | B138: OCI홀딩스 | C138: 12 | D138: 15225.45 | E138: 12162
A139: A263750 | B139: 펄어비스 | C139: 12 | D139: 14620.37 | E139: 2273
A140: A011170 | B140: 롯데케미칼 | C140: 12 | D140: 16035.65 | E140: -7871
A141: A454910 | B141: 두산로보틱스 | C141: 12 | D141: 15875.09
A142: A950160 | B142: 코오롱티슈진 | C142: 12 | D142: 15084.04 | E142: -497
A143: A140860 | B143: 파크시스템스 | C143: 12 | D143: 11701.7 | E143: 8552
A144: A375500 | B144: DL이앤씨 | C144: 12 | D144: 11635.01 | E144: 8121
A145: A483650 | B145: 달바글로벌 | C145: 12 | D145: 9643.23 | E145: 9703
A146: A006360 | B146: GS건설 | C146: 12 | D146: 11968.98 | E146: 3498
A147: A088350 | B147: 한화생명 | C147: 12 | D147: 11243.71 | E147: 660
A148: A357780 | B148: 솔브레인 | C148: 12 | D148: 11159.16 | E148: 20580
A149: A004170 | B149: 신세계 | C149: 12 | D149: 12828.73 | E149: 22841
A150: A307950 | B150: 현대오토에버 | C150: 12 | D150: 12176.06 | E150: 8501
A151: A204320 | B151: HL만도 | C151: 12 | D151: 11834.46 | E151: 4943
A152: A214150 | B152: 클래시스 | C152: 12 | D152: 11653 | E152: 2710
...
