Workbook

Sheet 최종정리
A1: DATE | B1: S&P500 | C1: NASDAQ | D1: VIX | E1: 미국 10년금리 | F1: 미국 5년금릭 | G1: HYG | H1: IEF
A2: 45293 | B2: ='S&P500'!B3 -> 4704.81 | C2: =나스닥!B3 -> 14592.21 | D2: =VLOOKUP(A2,VIX!$A$2:B5000,2,0) -> 13.2 | E2: =VLOOKUP(A2,'10년'!$A$2:$B$5000,2,0) -> 3.941 | F2: =VLOOKUP(A2,'5년'!$A$2:$B$5000,2,0) -> 3.922 | G2: 77.13 | H2: 96.03
A3: 45294 | B3: ='S&P500'!B4 -> 4688.68 | C3: =나스닥!B4 -> 14510.3 | D3: =VLOOKUP(A3,VIX!$A$2:B5001,2,0) -> 14.04 | E3: =VLOOKUP(A3,'10년'!$A$2:$B$5000,2,0) -> 3.92 | F3: =VLOOKUP(A3,'5년'!$A$2:$B$5000,2,0) -> 3.905 | G3: 76.92 | H3: 96.26
A4: 45295 | B4: ='S&P500'!B5 -> 4697.24 | C4: =나스닥!B5 -> 14524.07 | D4: =VLOOKUP(A4,VIX!$A$2:B5002,2,0) -> 14.13 | E4: =VLOOKUP(A4,'10년'!$A$2:$B$5000,2,0) -> 4.003 | F4: =VLOOKUP(A4,'5년'!$A$2:$B$5000,2,0) -> 3.98 | G4: 76.62 | H4: 95.68
A5: 45296 | B5: ='S&P500'!B6 -> 4763.54 | C5: =나스닥!B6 -> 14843.77 | D5: =VLOOKUP(A5,VIX!$A$2:B5003,2,0) -> 13.35 | E5: =VLOOKUP(A5,'10년'!$A$2:$B$5000,2,0) -> 4.051 | F5: =VLOOKUP(A5,'5년'!$A$2:$B$5000,2,0) -> 4.015 | G5: 76.68 | H5: 95.33
A6: 45299 | B6: ='S&P500'!B7 -> 4756.5 | C6: =나스닥!B7 -> 14857.71 | D6: =VLOOKUP(A6,VIX!$A$2:B5004,2,0) -> 13.08 | E6: =VLOOKUP(A6,'10년'!$A$2:$B$5000,2,0) -> 4.027 | F6: =VLOOKUP(A6,'5년'!$A$2:$B$5000,2,0) -> 3.986 | G6: 77.11 | H6: 95.65
A7: 45300 | B7: ='S&P500'!B8 -> 4783.45 | C7: =나스닥!B8 -> 14969.65 | D7: =VLOOKUP(A7,VIX!$A$2:B5005,2,0) -> 12.76 | E7: =VLOOKUP(A7,'10년'!$A$2:$B$5000,2,0) -> 4.015 | F7: =VLOOKUP(A7,'5년'!$A$2:$B$5000,2,0) -> 3.972 | G7: 77.23 | H7: 95.61
A8: 45301 | B8: ='S&P500'!B9 -> 4780.24 | C8: =나스닥!B9 -> 14970.18 | D8: =VLOOKUP(A8,VIX!$A$2:B5006,2,0) -> 12.69 | E8: =VLOOKUP(A8,'10년'!$A$2:$B$5000,2,0) -> 4.03 | F8: =VLOOKUP(A8,'5년'!$A$2:$B$5000,2,0) -> 3.974 | G8: 77.37 | H8: 95.46
A9: 45302 | B9: ='S&P500'!B10 -> 4783.83 | C9: =나스닥!B10 -> 14972.76 | D9: =VLOOKUP(A9,VIX!$A$2:B5007,2,0) -> 12.44 | E9: =VLOOKUP(A9,'10년'!$A$2:$B$5000,2,0) -> 3.975 | F9: =VLOOKUP(A9,'5년'!$A$2:$B$5000,2,0) -> 3.888 | G9: 77.62 | H9: 95.97
A10: 45303 | B10: ='S&P500'!B11 -> 4765.98 | C10: =나스닥!B11 -> 14944.35 | D10: =VLOOKUP(A10,VIX!$A$2:B5008,2,0) -> 12.7 | E10: =VLOOKUP(A10,'10년'!$A$2:$B$5000,2,0) -> 3.939 | F10: =VLOOKUP(A10,'5년'!$A$2:$B$5000,2,0) -> 3.832 | G10: 77.7 | H10: 96.23
A11: 45307 | B11: ='S&P500'!B12 -> 4739.21 | C11: =나스닥!B12 -> 14855.62 | D11: =VLOOKUP(A11,VIX!$A$2:B5009,2,0) -> 13.84 | E11: =VLOOKUP(A11,'10년'!$A$2:$B$5000,2,0) -> 4.054 | F11: =VLOOKUP(A11,'5년'!$A$2:$B$5000,2,0) -> 3.934 | G11: 77.21 | H11: 95.45
A12: 45308 | B12: ='S&P500'!B13 -> 4780.94 | C12: =나스닥!B13 -> 15055.65 | D12: =VLOOKUP(A12,VIX!$A$2:B5010,2,0) -> 14.79 | E12: =VLOOKUP(A12,'10년'!$A$2:$B$5000,2,0) -> 4.106 | F12: =VLOOKUP(A12,'5년'!$A$2:$B$5000,2,0) -> 4.031 | G12: 76.88 | H12: 95.14
A13: 45309 | B13: ='S&P500'!B14 -> 4839.81 | C13: =나스닥!B14 -> 15310.97 | D13: =VLOOKUP(A13,VIX!$A$2:B5011,2,0) -> 14.13 | E13: =VLOOKUP(A13,'10년'!$A$2:$B$5000,2,0) -> 4.142 | F13: =VLOOKUP(A13,'5년'!$A$2:$B$5000,2,0) -> 4.045 | G13: 77.04 | H13: 94.93
... A338: 45783 | B338: ='S&P500'!B339 -> 5629.67 | C338: =나스닥!B339 -> 17738.16 | D338: =VLOOKUP(A338,VIX!$A$2:B5336,2,0) -> 24.76 | E338: =VLOOKUP(A338,'10년'!$A$2:$B$5000,2,0) -> 4.298 | F338: =VLOOKUP(A338,'5년'!$A$2:$B$5000,2,0) -> 3.894 | G338: 78.44 | H338: 94.77
A339: 45784 | B339: ='S&P500'!B340 -> 5663.95 | C339: =나스닥!B340 -> 17928.14 | D339: =VLOOKUP(A339,VIX!$A$2:B5337,2,0) -> 23.55 | E339: =VLOOKUP(A339,'10년'!$A$2:$B$5000,2,0) -> 4.268 | F339: =VLOOKUP(A339,'5년'!$A$2:$B$5000,2,0) -> 3.864 | G339: =VLOOKUP(A339,HYG!$A$2:$B$5000,2,0) -> 78.52 | H339: =VLOOKUP(A339,IEF!$A$2:$B$5000,2,0) -> 95.02
A340: 45785 | B340: ='S&P500'!B341 -> 5659.91 | C340: =나스닥!B341 -> 17928.92 | D340: =VLOOKUP(A340,VIX!$A$2:B5338,2,0) -> 22.45 | E340: =VLOOKUP(A340,'10년'!$A$2:$B$5000,2,0) -> 4.382 | F340: =VLOOKUP(A340,'5년'!$A$2:$B$5000,2,0) -> 3.988 | G340: =VLOOKUP(A340,HYG!$A$2:$B$5000,2,0) -> 78.5 | H340: =VLOOKUP(A340,IEF!$A$2:$B$5000,2,0) -> 94.27
A341: 45786 | B341: ='S&P500'!B342 -> 5834.11 | C341: =나스닥!B342 -> 18705.84 | D341: =VLOOKUP(A341,VIX!$A$2:B5339,2,0) -> 21.9 | E341: =VLOOKUP(A341,'10년'!$A$2:$B$5000,2,0) -> 4.381 | F341: =VLOOKUP(A341,'5년'!$A$2:$B$5000,2,0) -> 4 | G341: =VLOOKUP(A341,HYG!$A$2:$B$5000,2,0) -> 78.55 | H341: =VLOOKUP(A341,IEF!$A$2:$B$5000,2,0) -> 94.35
A342: 45789 | B342: ='S&P500'!B343 -> 5901.18 | C342: =나스닥!B343 -> 19010.09 | D342: =VLOOKUP(A342,VIX!$A$2:B5340,2,0) -> 18.35 | E342: =VLOOKUP(A342,'10년'!$A$2:$B$5000,2,0) -> 4.46 | F342: =VLOOKUP(A342,'5년'!$A$2:$B$5000,2,0) -> 4.106 | G342: =VLOOKUP(A342,HYG!$A$2:$B$5000,2,0) -> 79.36 | H342: =VLOOKUP(A342,IEF!$A$2:$B$5000,2,0) -> 93.75
A343: 45790 | B343: ='S&P500'!B344 -> 5892.58 | C343: =나스닥!B344 -> 19146.81 | D343: =VLOOKUP(A343,VIX!$A$2:B5341,2,0) -> 18.22 | E343: =VLOOKUP(A343,'10년'!$A$2:$B$5000,2,0) -> 4.48 | F343: =VLOOKUP(A343,'5년'!$A$2:$B$5000,2,0) -> 4.101 | G343: =VLOOKUP(A343,HYG!$A$2:$B$5000,2,0) -> 79.44 | H343: =VLOOKUP(A343,IEF!$A$2:$B$5000,2,0) -> 93.68
A344: 45791 | B344: ='S&P500'!B345 -> 5916.93 | C344: =나스닥!B345 -> 19112.32 | D344: =VLOOKUP(A344,VIX!$A$2:B5342,2,0) -> 18.62 | E344: =VLOOKUP(A344,'10년'!$A$2:$B$5000,2,0) -> 4.542 | F344: =VLOOKUP(A344,'5년'!$A$2:$B$5000,2,0) -> 4.172 | G344: =VLOOKUP(A344,HYG!$A$2:$B$5000,2,0) -> 79.18 | H344: =VLOOKUP(A344,IEF!$A$2:$B$5000,2,0) -> 93.33
A345: 45792 | B345: ='S&P500'!B346 -> 5958.38 | C345: =나스닥!B346 -> 19211.1 | D345: =VLOOKUP(A345,VIX!$A$2:B5343,2,0) -> 17.82 | E345: =VLOOKUP(A345,'10년'!$A$2:$B$5000,2,0) -> 4.438 | F345: =VLOOKUP(A345,'5년'!$A$2:$B$5000,2,0) -> 4.057 | G345: =VLOOKUP(A345,HYG!$A$2:$B$5000,2,0) -> 79.33 | H345: =VLOOKUP(A345,IEF!$A$2:$B$5000,2,0) -> 93.94
A346: 45793 | B346: ='S&P500'!B347 -> 5963.59 | C346: =나스닥!B347 -> 19191.06 | D346: =VLOOKUP(A346,VIX!$A$2:B5344,2,0) -> 17.24 | E346: =VLOOKUP(A346,'10년'!$A$2:$B$5000,2,0) -> 4.443 | F346: =VLOOKUP(A346,'5년'!$A$2:$B$5000,2,0) -> 4.069 | G346: =VLOOKUP(A346,HYG!$A$2:$B$5000,2,0) -> 79.42 | H346: =VLOOKUP(A346,IEF!$A$2:$B$5000,2,0) -> 93.97
A347: 45796 | B347: ='S&P500'!B348 -> 5940.46 | C347: =나스닥!B348 -> 19142.71 | D347: =VLOOKUP(A347,VIX!$A$2:B5345,2,0) -> 18.15 | E347: =VLOOKUP(A347,'10년'!$A$2:$B$5000,2,0) -> 4.451 | F347: =VLOOKUP(A347,'5년'!$A$2:$B$5000,2,0) -> 4.061 | G347: =VLOOKUP(A347,HYG!$A$2:$B$5000,2,0) -> 79.38 | H347: =VLOOKUP(A347,IEF!$A$2:$B$5000,2,0) -> 93.91
A348: 45797 | B348: ='S&P500'!B349 -> 5849.47 | C348: =나스닥!B349 -> 18872.64 | D348: =VLOOKUP(A348,VIX!$A$2:B5346,2,0) -> 18.1 | E348: =VLOOKUP(A348,'10년'!$A$2:$B$5000,2,0) -> 4.482 | F348: =VLOOKUP(A348,'5년'!$A$2:$B$5000,2,0) -> 4.068 | G348: =VLOOKUP(A348,HYG!$A$2:$B$5000,2,0) -> 79.34 | H348: =VLOOKUP(A348,IEF!$A$2:$B$5000,2,0) -> 93.8
A349: 45798 | B349: ='S&P500'!B350 -> 5842.88 | C349: =나스닥!B350 -> 19026.41 | D349: =VLOOKUP(A349,VIX!$A$2:B5347,2,0) -> 20.88 | E349: =VLOOKUP(A349,'10년'!$A$2:$B$5000,2,0) -> 4.594 | F349: =VLOOKUP(A349,'5년'!$A$2:$B$5000,2,0) -> 4.158 | G349: =VLOOKUP(A349,HYG!$A$2:$B$5000,2,0) -> 78.81 | H349: =VLOOKUP(A349,IEF!$A$2:$B$5000,2,0) -> 93.15
A350: 45799 | B350: ='S&P500'!B351 -> 5802.83 | C350: =나스닥!B351 -> 18737.21 | D350: =VLOOKUP(A350,VIX!$A$2:B5348,2,0) -> 19.73 | E350: =VLOOKUP(A350,'10년'!$A$2:$B$5000,2,0) -> 4.541 | F350: =VLOOKUP(A350,'5년'!$A$2:$B$5000,2,0) -> 4.09 | G350: =VLOOKUP(A350,HYG!$A$2:$B$5000,2,0) -> 78.96 | H350: =VLOOKUP(A350,IEF!$A$2:$B$5000,2,0) -> 93.5
... A492: 46008 | B492: ='S&P500'!B493 -> 6721.51 | C492: =나스닥!B493 -> 22693.32 | D492: =VLOOKUP(A492,VIX!$A$2:B5490,2,0) -> 17.62 | E492: =VLOOKUP(A492,'10년'!$A$2:$B$5000,2,0) -> 4.154 | F492: =VLOOKUP(A492,'5년'!$A$2:$B$5000,2,0) -> 3.7 | G492: =VLOOKUP(A492,HYG!$A$2:$B$5000,2,0) -> 80.56 | H492: =VLOOKUP(A492,IEF!$A$2:$B$5000,2,0) -> 96.52

Sheet S&P500
A1: 날짜 | B1: 종가 | C1: 시가 | D1: 고가 | E1: 저가 | F1: 거래량 | G1: 변동 %
A2: 45293 | B2: 4742.83 | C2: 4745.2 | D2: 4754.33 | E2: 4722.67 | G2: -0.0057
A3: 45294 | B3: 4704.81 | C3: 4725.07 | D3: 4729.29 | E3: 4699.71 | G3: -0.008
A4: 45295 | B4: 4688.68 | C4: 4697.42 | D4: 4726.78 | E4: 4687.53 | G4: -0.0034
A5: 45296 | B5: 4697.24 | C5: 4690.57 | D5: 4721.49 | E5: 4682.11 | G5: 0.0018
A6: 45299 | B6: 4763.54 | C6: 4703.7 | D6: 4764.54 | E6: 4699.82 | G6: 0.0141
A7: 45300 | B7: 4756.5 | C7: 4741.93 | D7: 4765.47 | E7: 4730.35 | G7: -0.0015
A8: 45301 | B8: 4783.45 | C8: 4759.94 | D8: 4790.8 | E8: 4756.2 | G8: 0.0057
A9: 45302 | B9: 4780.24 | C9: 4792.13 | D9: 4798.5 | E9: 4739.58 | G9: -0.0007
A10: 45303 | B10: 4783.83 | C10: 4791.18 | D10: 4802.4 | E10: 4768.98 | G10: 0.0008
A11: 45307 | B11: 4765.98 | C11: 4772.35 | D11: 4782.34 | E11: 4747.12 | G11: -0.0037
A12: 45308 | B12: 4739.21 | C12: 4739.13 | D12: 4744.23 | E12: 4714.82 | G12: -0.0056
A13: 45309 | B13: 4780.94 | C13: 4760.1 | D13: 4785.79 | E13: 4740.57 | G13: 0.0088
... A344: 45791 | B344: 5892.58 | C344: 5896.74 | D344: 5906.55 | E344: 5872.11 | G344: 0.001
A345: 45792 | B345: 5916.93 | C345: 5869.82 | D345: 5924.21 | E345: 5865.16
A346: 45793 | B346: 5958.38 | C346: 5929.09 | D346: 5958.47 | E346: 5907.36
A347: 45796 | B347: 5963.59 | C347: 5902.88 | D347: 5968.61 | E347: 5895.69
A348: 45797 | B348: 5940.46 | C348: 5944.66 | D348: 5953.06 | E348: 5909.26
A349: 45798 | B349: 5849.47 | C349: 5896.83 | D349: 5938.72 | E349: 5830.67
A350: 45799 | B350: 5842.88 | C350: 5838.83 | D350: 5878.41 | E350: 5826.19 | G350: -0.0003
A351: 45800 | B351: 5802.83 | C351: 5781.89 | D351: 5829.51 | E351: 5767.41
A352: 45804 | B352: 5921.54 | C352: 5854.07 | D352: 5924.33 | E352: 5854.07
A353: 45805 | B353: 5888.56 | C353: 5925.54 | D353: 5939.92 | E353: 5881.88
A354: 45806 | B354: 5912.17 | C354: 5939.96 | D354: 5943.13 | E354: 5873.8
A355: 45807 | B355: 5911.69 | C355: 5903.67 | D355: 5922.14 | E355: 5843.66
A356: 45810 | B356: 5935.94 | C356: 5896.68 | D356: 5937.19 | E356: 5861.43
A357: 45811 | B357: 5970.38 | C357: 5938.56 | D357: 5981.35 | E357: 5929
A358: 45812 | B358: 5970.81 | C358: 5978.94 | D358: 5990.48 | E358: 5966.11
A359: 45813 | B359: 5939.3 | C359: 5985.67 | D359: 5999.7 | E359: 5921.2
A360: 45814 | B360: 6000.36 | C360: 5987.06 | D360: 6016.87 | E360: 5978.63
A361: 45817 | B361: 6005.88 | C361: 6004.63 | D361: 6021.31 | E361: 5994.18
A362: 45818 | B362: 6040.16 | C362: 6009.94 | D362: 6043.42 | E362: 6000.58
... A492: 46007 | B492: 6800.21 | C492: 6800.12 | D492: 6819.27 | E492: 6759.74
A493: 46008 | B493: 6721.51

Sheet 나스닥
A1: 날짜 | B1: 종가 | C1: 시가 | D1: 고가 | E1: 저가 | F1: 거래량 | G1: 변동 %
A2: 45293 | B2: 14765.94 | C2: 14873.7 | D2: 14887.8 | E2: 14682.38 | F2: 1.08B | G2: -0.0163
A3: 45294 | B3: 14592.21 | C3: 14641.47 | D3: 14694.58 | E3: 14577.44 | F3: 1.06B | G3: -0.0118
A4: 45295 | B4: 14510.3 | C4: 14532.23 | D4: 14632.77 | E4: 14504.78 | F4: 1.04B | G4: -0.0056
A5: 45296 | B5: 14524.07 | C5: 14500.11 | D5: 14625.19 | E5: 14477.57 | F5: 1.01B | G5: 0.0009
A6: 45299 | B6: 14843.77 | C6: 14564.47 | D6: 14846.9 | E6: 14560.2 | F6: 1.14B | G6: 0.022
A7: 45300 | B7: 14857.71 | C7: 14744.13 | D7: 14894.32 | E7: 14716.71 | F7: 959.65M | G7: 0.0009
A8: 45301 | B8: 14969.65 | C8: 14877.7 | D8: 14998.2 | E8: 14842.7 | F8: 904.43M | G8: 0.0075
A9: 45302 | B9: 14970.18 | C9: 15020.95 | D9: 15063.61 | E9: 14800.38 | F9: 1.00B | G9: 0
A10: 45303 | B10: 14972.76 | C10: 15001.01 | D10: 15047.25 | E10: 14931.88 | F10: 865.51M | G10: 0.0002
A11: 45307 | B11: 14944.35 | C11: 14908.26 | D11: 15004.35 | E11: 14863.81 | F11: 1.10B | G11: -0.0019
A12: 45308 | B12: 14855.62 | C12: 14814.77 | D12: 14865.76 | E12: 14706.23 | F12: 944.50M | G12: -0.0059
A13: 45309 | B13: 15055.65 | C13: 14994.52 | D13: 15066.81 | E13: 14911.11 | F13: 1.04B | G13: 0.0135
... A344: 45791 | B344: 19146.81 | C344: 19074.72 | D344: 19174.27 | E344: 19023.63 | F344: 1.61B | G344: 0.0072
A345: 45792 | B345: 19112.32 | C345: 19031.24 | D345: 19206.88 | E345: 18968.34 | F345: 1.45B
A346: 45793 | B346: 19211.1 | C346: 19151.54 | D346: 19213.42 | E346: 19038.48 | G346: 0.0052
A347: 45796 | B347: 19191.06 | C347: 18937.42 | D347: 19227.22 | E347: 18937.42
A348: 45797 | B348: 19142.71 | C348: 19132.06 | D348: 19186.69 | E348: 19015.63 | F348: 1.28B
A349: 45798 | B349: 18872.64 | C349: 19002.94 | D349: 19241.37 | E349: 18799.22
A350: 45799 | B350: 19026.41 | C350: 18888.05 | D350: 19060.93 | E350: 18840.81 | F350: 821.54M
A351: 45800 | B351: 18737.21 | C351: 18622.38 | D351: 18841.52 | E351: 18602.62 | F351: 1.21B
A352: 45804 | B352: 19199.16 | C352: 19014.44 | D352: 19209.82 | E352: 18961.78
A353: 45805 | B353: 19100.94 | C353: 19232.62 | D353: 19276.83 | E353: 19084.38
A354: 45806 | B354: 19175.87 | C354: 19389.39 | D354: 19389.39 | E354: 19092.67
A355: 45807 | B355: 19113.77 | C355: 19131.22 | D355: 19157.78 | E355: 18847.74
A356: 45810 | B356: 19242.61 | C356: 19063.06 | D356: 19252.03 | E356: 18987.03
A357: 45811 | B357: 19378.33 | C357: 19288.66 | D357: 19459.28 | E357: 19224.97
A358: 45812 | B358: 19460.49 | C358: 19434.94 | D358: 19493.16 | E358: 19359.09
A359: 45813 | B359: 19298.45 | C359: 19518.2 | D359: 19610.51 | E359: 19226.21
A360: 45814 | B360: 19529.95 | C360: 19526.99 | D360: 19593.18 | E360: 19464.84
A361: 45817 | B361: 19591.24 | C361: 19573.14 | D361: 19637.56 | E361: 19531.77
A362: 45818 | B362: 19714.99 | C362: 19620.11 | D362: 19730.26 | E362: 19540.07
A363: 45819 | B363: 19578.37 | C363: 19779.36 | D363: 19800.34 | E363: 19551.43
... A477: 45985 | B477: 22868.28 | C477: 22482.16 | D477: 22879.73 | E477: 22480.25
A478: 45986 | B478: 23025.59 | C478: 22802.85 | D478: 23069.86 | E478: 22587.11 | F478: 1.48
A479: 45987 | B479: 23214.69 | C479: 23163.19 | D479: 23280.58 | E479: 23076.2
A480: 45989 | B480: 23365.69 | C480: 23291.59 | D480: 23365.69 | E480: 23250.92
A481: 45992 | B481: 23275.92 | C481: 23172.34 | D481: 23363.85 | E481: 23110.21
A482: 45993 | B482: 23413.67 | C482: 23379.75 | D482: 23526.23 | E482: 23286.46
A483: 45994 | B483: 23454.09 | C483: 23315.58 | D483: 23499.93 | E483: 23271.83
...

Sheet VIX
A1: 날짜 | B1: 종가 | C1: 시가 | D1: 고가 | E1: 저가 | F1: 거래량 | G1: 변동 %
A2: 45293 | B2: 13.2 | C2: 13.22 | D2: 14.23 | E2: 13.1 | G2: 0.0602
A3: 45294 | B3: 14.04 | C3: 13.35 | D3: 14.22 | E3: 13.33 | G3: 0.0636
A4: 45295 | B4: 14.13 | C4: 13.93 | D4: 14.2 | E4: 13.64 | G4: 0.0064
A5: 45296 | B5: 13.35 | C5: 14.24 | D5: 14.58 | E5: 13.29 | G5: -0.0552
A6: 45299 | B6: 13.08 | C6: 14 | D6: 14.18 | E6: 13.02 | G6: -0.0202
A7: 45300 | B7: 12.76 | C7: 13.2 | D7: 13.45 | E7: 12.74 | G7: -0.0245
A8: 45301 | B8: 12.69 | C8: 12.86 | D8: 12.95 | E8: 12.67 | G8: -0.0055
A9: 45302 | B9: 12.44 | C9: 12.64 | D9: 13.31 | E9: 12.35 | G9: -0.0197
A10: 45303 | B10: 12.7 | C10: 12.66 | D10: 13.08 | E10: 12.47 | G10: 0.0209
A11: 45306 | B11: 13.25 | C11: 13.23 | D11: 13.34 | E11: 13.2 | G11: 0.0433
A12: 45307 | B12: 13.84 | C12: 14.12 | D12: 14.35 | E12: 13.52 | G12: 0.0445
A13: 45308 | B13: 14.79 | C13: 14.59 | D13: 15.4 | E13: 14.38 | G13: 0.0686
... A355: 45791 | B355: 18.62 | C355: 18.1 | D355: 18.82 | E355: 18.06 | G355: 0.022
A356: 45792 | B356: 17.82 | C356: 19.19 | D356: 19.38 | E356: 17.77
A357: 45793 | B357: 17.24 | C357: 17.96 | D357: 17.96 | E357: 17.15
A358: 45796 | B358: 18.15 | C358: 19.84 | D358: 19.92 | E358: 17.92
A359: 45797 | B359: 18.1 | C359: 18.46 | D359: 18.68 | E359: 17.7
A360: 45798 | B360: 20.88 | C360: 18.77 | D360: 21.05 | E360: 17.77
A361: 45799 | B361: 19.73 | C361: 20.62 | D361: 22.07 | E361: 19.71 | G361: -0.0546
A362: 45800 | B362: 22.29 | C362: 20.14 | D362: 25.53 | E362: 19.83
A363: 45804 | B363: 18.98 | C363: 20.63 | D363: 21.01 | E363: 18.97
A364: 45805 | B364: 19.3 | C364: 19.21 | D364: 19.43 | E364: 18.68
A365: 45806 | B365: 19.18 | C365: 18.25 | D365: 20.2 | E365: 18.11
A366: 45807 | B366: 18.57 | C366: 19.61 | D366: 20.55 | E366: 18.57
A367: 45810 | B367: 18.36 | C367: 19.81 | D367: 20.45 | E367: 18.36
A368: 45811 | B368: 17.69 | C368: 18.83 | D368: 19.21 | E368: 17.64
A369: 45812 | B369: 17.6 | C369: 17.68 | D369: 18.07 | E369: 17.41
A370: 45813 | B370: 18.48 | C370: 17.68 | D370: 18.8 | E370: 17.08
A371: 45814 | B371: 16.77 | C371: 18.16 | D371: 18.35 | E371: 16.65
A372: 45817 | B372: 17.17 | C372: 17.69 | D372: 17.72 | E372: 16.82
A373: 45818 | B373: 16.87 | C373: 17.5 | D373: 17.99 | E373: 16.68
... A503: 46007 | B503: 16.5 | C503: 17.28 | D503: 17.61 | E503: 16.19
A504: 46008 | B504: 17.62

Sheet 10년
A1: 날짜 | B1: 종가 | C1: 시가 | D1: 고가 | E1: 저가 | F1: 변동 %
A2: 45292 | B2: 3.898 | C2: 3.879 | D2: 3.898 | E2: 3.866 | F2: 0.0083
A3: 45293 | B3: 3.941 | C3: 3.899 | D3: 4.023 | E3: 3.881 | F3: 0.0109
A4: 45294 | B4: 3.92 | C4: 3.95 | D4: 4.01 | E4: 3.894 | F4: -0.0053
A5: 45295 | B5: 4.003 | C5: 3.914 | D5: 4.006 | E5: 3.901 | F5: 0.0211
A6: 45296 | B6: 4.051 | C6: 4.003 | D6: 4.103 | E6: 3.953 | F6: 0.0122
A7: 45299 | B7: 4.027 | C7: 4.061 | D7: 4.068 | E7: 3.966 | F7: -0.0061
A8: 45300 | B8: 4.015 | C8: 4.023 | D8: 4.053 | E8: 3.996 | F8: -0.0029
A9: 45301 | B9: 4.03 | C9: 4.006 | D9: 4.043 | E9: 3.979 | F9: 0.0037
A10: 45302 | B10: 3.975 | C10: 4.028 | D10: 4.068 | E10: 3.968 | F10: -0.0136
A11: 45303 | B11: 3.939 | C11: 3.962 | D11: 4.007 | E11: 3.916 | F11: -0.0091
A12: 45305 | B12: 3.968 | C12: 3.956 | D12: 3.968 | E12: 3.956 | F12: 0.0074
A13: 45306 | B13: 3.986 | C13: 3.966 | D13: 4.002 | E13: 3.949 | F13: 0.0045
... A354: 45791 | B354: 4.542 | C354: 4.473 | D354: 4.55 | E354: 4.448 | F354: 0.0162
A355: 45792 | B355: 4.438 | C355: 4.535 | D355: 4.542 | E355: 4.436
A356: 45793 | B356: 4.443 | C356: 4.443 | D356: 4.499 | E356: 4.388
A357: 45796 | B357: 4.451 | C357: 4.511 | D357: 4.566 | E357: 4.449
A358: 45797 | B358: 4.482 | C358: 4.46 | D358: 4.524 | E358: 4.427 | F358: 0.0078
A359: 45798 | B359: 4.594 | C359: 4.507 | D359: 4.607 | E359: 4.473
A360: 45799 | B360: 4.541 | C360: 4.585 | D360: 4.629 | E360: 4.535 | F360: -0.0119
A361: 45800 | B361: 4.521 | C361: 4.53 | D361: 4.544 | E361: 4.445
A362: 45804 | B362: 4.445 | C362: 4.507 | D362: 4.509 | E362: 4.428
A363: 45805 | B363: 4.474 | C363: 4.444 | D363: 4.501 | E363: 4.438
A364: 45806 | B364: 4.424 | C364: 4.506 | D364: 4.541 | E364: 4.413
A365: 45807 | B365: 4.397 | C365: 4.426 | D365: 4.442 | E365: 4.387
A366: 45810 | B366: 4.439 | C366: 4.41 | D366: 4.469 | E366: 4.408
A367: 45811 | B367: 4.45 | C367: 4.434 | D367: 4.474 | E367: 4.404
A368: 45812 | B368: 4.356 | C368: 4.449 | D368: 4.471 | E368: 4.345
A369: 45813 | B369: 4.389 | C369: 4.359 | D369: 4.402 | E369: 4.318
A370: 45814 | B370: 4.505 | C370: 4.394 | D370: 4.514 | E370: 4.375
A371: 45817 | B371: 4.483 | C371: 4.496 | D371: 4.521 | E371: 4.471
A372: 45818 | B372: 4.47 | C372: 4.483 | D372: 4.492 | E372: 4.436
... A502: 46007 | B502: 4.147 | C502: 4.168 | D502: 4.197 | E502: 4.133
A503: 46008 | B503: 4.154

Sheet 5년
A1: 날짜 | B1: 종가 | C1: 시가 | D1: 고가 | E1: 저가 | F1: 변동 %
A2: 45292 | B2: 3.84 | C2: 3.84 | D2: 3.84 | E2: 3.84 | F2: 0
A3: 45293 | B3: 3.922 | C3: 3.889 | D3: 3.98 | E3: 3.849 | F3: 0.0213
A4: 45294 | B4: 3.905 | C4: 3.931 | D4: 3.989 | E4: 3.882 | F4: -0.0044
A5: 45295 | B5: 3.98 | C5: 3.898 | D5: 3.987 | E5: 3.877 | F5: 0.0193
A6: 45296 | B6: 4.015 | C6: 3.976 | D6: 4.098 | E6: 3.919 | F6: 0.0089
A7: 45299 | B7: 3.986 | C7: 4.009 | D7: 4.033 | E7: 3.917 | F7: -0.0074
A8: 45300 | B8: 3.972 | C8: 3.979 | D8: 4.007 | E8: 3.954 | F8: -0.0035
A9: 45301 | B9: 3.974 | C9: 3.959 | D9: 3.991 | E9: 3.933 | F9: 0.0005
A10: 45302 | B10: 3.888 | C10: 3.972 | D10: 4.012 | E10: 3.881 | F10: -0.0216
A11: 45303 | B11: 3.832 | C11: 3.875 | D11: 3.925 | E11: 3.8 | F11: -0.0144
A12: 45306 | B12: 3.875 | C12: 3.875 | D12: 3.875 | E12: 3.875 | F12: 0.0114
A13: 45307 | B13: 3.934 | C13: 3.875 | D13: 3.967 | E13: 3.867 | F13: 0.015
... A357: 45791 | B357: 4.172 | C357: 4.096 | D357: 4.174 | E357: 4.077 | F357: 1.82
A358: 45792 | B358: 4.057 | C358: 4.165 | D358: 4.17 | E358: 4.05
A359: 45793 | B359: 4.069 | C359: 4.064 | D359: 4.109 | E359: 4.012
A360: 45796 | B360: 4.061 | C360: 4.104 | D360: 4.152 | E360: 4.058
A361: 45797 | B361: 4.068 | C361: 4.066 | D361: 4.105 | E361: 4.036 | F361: 0.002
A362: 45798 | B362: 4.158 | C362: 4.063 | D362: 4.169 | E362: 4.058
A363: 45799 | B363: 4.09 | C363: 4.162 | D363: 4.168 | E363: 4.088 | F363: -0.0139
A364: 45800 | B364: 4.077 | C364: 4.097 | D364: 4.104 | E364: 4
A365: 45804 | B365: 4.032 | C365: 4.079 | D365: 4.081 | E365: 4.017
A366: 45805 | B366: 4.061 | C366: 4.035 | D366: 4.085 | E366: 4.026
A367: 45806 | B367: 4.002 | C367: 4.091 | D367: 4.124 | E367: 3.997
A368: 45807 | B368: 3.959 | C368: 4.003 | D368: 4.014 | E368: 3.953
A369: 45810 | B369: 4.003 | C369: 3.965 | D369: 4.024 | E369: 3.963
A370: 45811 | B370: 4.024 | C370: 3.998 | D370: 4.04 | E370: 3.974
A371: 45812 | B371: 3.923 | C371: 4.017 | D371: 4.04 | E371: 3.922
A372: 45813 | B372: 3.989 | C372: 3.928 | D372: 4.003 | E372: 3.892
A373: 45814 | B373: 4.118 | C373: 3.989 | D373: 4.128 | E373: 3.972
A374: 45817 | B374: 4.082 | C374: 4.096 | D374: 4.122 | E374: 4.077
A375: 45818 | B375: 4.086 | C375: 4.091 | D375: 4.098 | E375: 4.05
... A386: 45834 | B386: 3.799 | C386: 3.84 | D386: 3.849 | E386: 3.794
A387: 45835 | B387: 3.826 | C387: 3.82 | D387: 3.844 | E387: 3.801 | F387: +
A388: 45838 | B388: 3.795 | C388: 3.835 | D388: 3.839 | E388: 3.787
A389: 45839 | B389: 3.835 | C389: 3.785 | D389: 3.858 | E389: 3.759
A390: 45840 | B390: 3.866 | C390: 3.842 | D390: 3.878 | E390: 3.832
A391: 45841 | B391: 3.939 | C391: 3.849 | D391: 3.946 | E391: 3.838
A392: 45845 | B392: 3.96 | C392: 3.915 | D392: 3.966 | E392: 3.903
A393: 45846 | B393: 3.976 | C393: 3.953 | D393: 3.997 | E393: 3.952
...

Sheet HYG
A1: 날짜 | B1: 종가 | C1: 시가 | D1: 고가 | E1: 저가 | F1: 거래량 | G1: 변동 %
A2: 45293 | B2: 77.13 | C2: 77.13 | D2: 77.24 | E2: 77.04 | F2: 41.55M | G2: -0.0034
A3: 45294 | B3: 76.92 | C3: 76.72 | D3: 77.08 | E3: 76.55 | F3: 39.50M | G3: -0.0027
A4: 45295 | B4: 76.62 | C4: 76.81 | D4: 76.9 | E4: 76.6 | F4: 32.86M | G4: -0.0039
A5: 45296 | B5: 76.68 | C5: 76.6 | D5: 77 | E5: 76.55 | F5: 31.16M | G5: 0.0008
A6: 45299 | B6: 77.11 | C6: 76.7 | D6: 77.17 | E6: 76.7 | F6: 33.48M | G6: 0.0056
A7: 45300 | B7: 77.23 | C7: 77.01 | D7: 77.32 | E7: 76.96 | F7: 25.59M | G7: 0.0016
A8: 45301 | B8: 77.37 | C8: 77.41 | D8: 77.49 | E8: 77.28 | F8: 35.70M | G8: 0.0018
A9: 45302 | B9: 77.62 | C9: 77.35 | D9: 77.63 | E9: 77.17 | F9: 35.95M | G9: 0.0032
A10: 45303 | B10: 77.7 | C10: 77.68 | D10: 77.92 | E10: 77.63 | F10: 31.16M | G10: 0.001
A11: 45307 | B11: 77.21 | C11: 77.55 | D11: 77.55 | E11: 77.13 | F11: 43.67M | G11: -0.0063
A12: 45308 | B12: 76.88 | C12: 77.08 | D12: 77.08 | E12: 76.73 | F12: 54.16M | G12: -0.0043
A13: 45309 | B13: 77.04 | C13: 76.99 | D13: 77.05 | E13: 76.85 | F13: 34.84M | G13: 0.0021
... A344: 45791 | B344: 79.18 | C344: 79.4 | D344: 79.4 | E344: 79.14 | F344: 43.09M | G344: -0.36
A345: 45792 | B345: 79.33 | C345: 79.06 | D345: 79.32 | E345: 79.06 | F345: 47.51M
A346: 45793 | B346: 79.42 | C346: 79.38 | D346: 79.43 | E346: 79.27 | F346: 30.66M
A347: 45796 | B347: 79.38 | C347: 79.06 | D347: 79.39 | E347: 79.05
A348: 45797 | B348: 79.34 | C348: 79.27 | D348: 79.38 | E348: 79.21 | F348: 24.75M | G348: -0.0005
A349: 45798 | B349: 78.81 | C349: 79.08 | D349: 79.22 | E349: 78.8 | F349: 53.07M
A350: 45799 | B350: 78.96 | C350: 78.79 | D350: 79.04 | E350: 78.75 | F350: 42.04M
A351: 45800 | B351: 78.95 | C351: 78.76 | D351: 78.98 | E351: 78.75 | F351: 29.35M
A352: 45804 | B352: 79.43 | C352: 79.28 | D352: 79.44 | E352: 79.17 | F352: 31.89M
A353: 45805 | B353: 79.38 | C353: 79.41 | D353: 79.43 | E353: 79.26
A354: 45806 | B354: 79.5 | C354: 79.56 | D354: 79.54 | E354: 79.41
A355: 45807 | B355: 79.57 | C355: 79.45 | D355: 79.58 | E355: 79.4
A356: 45810 | B356: 79.18 | C356: 79.13 | D356: 79.18 | E356: 78.99
A357: 45811 | B357: 79.33 | C357: 79.24 | D357: 79.34 | E357: 79.17
A358: 45812 | B358: 79.48 | C358: 79.34 | D358: 79.5 | E358: 79.39
A359: 45813 | B359: 79.31 | C359: 79.47 | D359: 79.49 | E359: 79.26 | F359: 4
A360: 45814 | B360: 79.3 | C360: 79.38 | D360: 79.39 | E360: 79.25
A361: 45817 | B361: 79.34 | C361: 79.28 | D361: 79.43 | E361: 79.28
A362: 45818 | B362: 79.53 | C362: 79.41 | D362: 79.55 | E362: 79.33
A363: 45819 | B363: 79.51 | C363: 79.59 | D363: 79.64 | E363: 79.49
A364: 45820 | B364: 79.58 | C364: 79.53 | D364: 79.59 | E364: 79.47
A365: 45821 | B365: 79.36 | C365: 79.42 | D365: 79.5 | E365: 79.3
A366: 45824 | B366: 79.52 | C366: 79.52 | D366: 79.6 | E366: 79.5
A367: 45825 | B367: 79.43 | C367: 79.52 | D367: 79.64 | E367: 79.37
A368: 45826 | B368: 79.55 | C368: 79.49 | D368: 79.71 | E368: 79.43
A369: 45828 | B369: 79.8 | C369: 79.62 | D369: 79.81 | E369: 79.59
A370: 45831 | B370: 79.95 | C370: 79.77 | D370: 79.95 | E370: 79.73
...

Sheet IEF
A1: 날짜 | B1: 종가 | C1: 시가 | D1: 고가 | E1: 저가 | F1: 거래량 | G1: 변동 %
A2: 45293 | B2: 96.03 | C2: 95.93 | D2: 96.14 | E2: 95.92 | F2: 9.44M | G2: -0.0037
A3: 45294 | B3: 96.26 | C3: 95.61 | D3: 96.33 | E3: 95.53 | F3: 11.04M | G3: 0.0024
A4: 45295 | B4: 95.68 | C4: 95.69 | D4: 95.83 | E4: 95.58 | F4: 7.35M | G4: -0.006
A5: 45296 | B5: 95.33 | C5: 95.33 | D5: 96.02 | E5: 95.26 | F5: 10.00M | G5: -0.0037
A6: 45299 | B6: 95.65 | C6: 95.39 | D6: 95.96 | E6: 95.36 | F6: 7.04M | G6: 0.0034
A7: 45300 | B7: 95.61 | C7: 95.52 | D7: 95.75 | E7: 95.52 | F7: 7.36M | G7: -0.0004
A8: 45301 | B8: 95.46 | C8: 95.79 | D8: 95.86 | E8: 95.44 | F8: 9.21M | G8: -0.0016
A9: 45302 | B9: 95.97 | C9: 95.6 | D9: 96.04 | E9: 95.47 | F9: 10.31M | G9: 0.0053
A10: 45303 | B10: 96.23 | C10: 96.23 | D10: 96.48 | E10: 96.02 | F10: 8.47M | G10: 0.0027
A11: 45307 | B11: 95.45 | C11: 95.84 | D11: 95.96 | E11: 95.32 | F11: 9.85M | G11: -0.0081
A12: 45308 | B12: 95.14 | C12: 95.17 | D12: 95.23 | E12: 94.95 | F12: 9.17M | G12: -0.0032
A13: 45309 | B13: 94.93 | C13: 95.1 | D13: 95.17 | E13: 94.83 | F13: 8.91M | G13: -0.0022
... A343: 45790 | B343: 93.68 | C343: 93.87 | D343: 93.92 | E343: 93.53 | F343: 12.47M | G343: -0.0007
A344: 45791 | B344: 93.33 | C344: 93.64 | D344: 93.71 | E344: 93.27 | F344: 6.74M | G344: -
A345: 45792 | B345: 93.94 | C345: 93.72 | D345: 93.99 | E345: 93.6 | F345: 8.99M
A346: 45793 | B346: 93.97 | C346: 94.31 | D346: 94.33 | E346: 93.96 | F346: 6.82M
A347: 45796 | B347: 93.91 | C347: 93.42 | D347: 93.93 | E347: 93.4
A348: 45797 | B348: 93.8 | C348: 93.67 | D348: 93.86 | E348: 93.53 | F348: 8.88M | G348: -0.1
A349: 45798 | B349: 93.15 | C349: 93.43 | D349: 93.56 | E349: 93.04 | F349: 10.95M
A350: 45799 | B350: 93.5 | C350: 93.19 | D350: 93.54 | E350: 93.06 | F350: 10.43M
A351: 45800 | B351: 93.77 | C351: 93.91 | D351: 93.92 | E351: 93.64 | F351: 9.73M
A352: 45804 | B352: 94.16 | C352: 93.97 | D352: 94.25 | E352: 93.87 | F352: 9.68M
A353: 45805 | B353: 93.9 | C353: 93.96 | D353: 94.04 | E353: 93.8
A354: 45806 | B354: 94.29 | C354: 94.14 | D354: 94.38 | E354: 94.1
A355: 45807 | B355: 94.57 | C355: 94.36 | D355: 94.62 | E355: 94.3
A356: 45810 | B356: 93.95 | C356: 94 | D356: 94.14 | E356: 93.78 | F356: 1
A357: 45811 | B357: 93.85 | C357: 94.07 | D357: 94.2 | E357: 93.77
A358: 45812 | B358: 94.53 | C358: 94.21 | D358: 94.62 | E358: 94.14
A359: 45813 | B359: 94.26 | C359: 94.54 | D359: 94.66 | E359: 94.23
A360: 45814 | B360: 93.51 | C360: 93.78 | D360: 93.86 | E360: 93.47 | F360: 7.62
A361: 45817 | B361: 93.68 | C361: 93.51 | D361: 93.8 | E361: 93.51
A362: 45818 | B362: 93.83 | C362: 93.98 | D362: 94.01 | E362: 93.74
A363: 45819 | B363: 94.23 | C363: 94.02 | D363: 94.27 | E363: 93.94
A364: 45820 | B364: 94.64 | C364: 94.59 | D364: 94.64 | E364: 94.42
A365: 45821 | B365: 94.29 | C365: 94.43 | D365: 94.5 | E365: 94.04
A366: 45824 | B366: 94.02 | C366: 94.18 | D366: 94.36 | E366: 94
A367: 45825 | B367: 94.47 | C367: 94.26 | D367: 94.51 | E367: 94.11
A368: 45826 | B368: 94.54 | C368: 94.64 | D368: 94.82 | E368: 94.38
A369: 45828 | B369: 94.6 | C369: 94.35 | D369: 94.74 | E369: 94.29
...
