Workbook
Name bench2_list: [1]combo_lists!$C$1:$C$5
Name bench3_list: [1]combo_lists!$D$1:$D$2
Name benchmark_list: [1]combo_lists!$A$1:$A$2
Name Bm_Cushion: OFFSET([2]Work!$S$12,0,0,COUNT([2]Work!$S$12:$S$65536),1)
Name Bm_Floor: OFFSET([2]Work!$R$13,0,0,COUNT([2]Work!$R$13:$R$65536),1)
Name Bm_NAV: OFFSET([2]Work!$O$12,0,0,COUNT([2]Work!$O$12:$O$65536),1)
Name BM_Return: OFFSET([2]Work!$P$13,0,0,COUNT([2]Work!$P$13:$P$65536),1)
Name chart_name: '[1]Valuation Charts'!$B$29
Name chart_type: [1]lists!$A$1:$A$9
Name checklist: '[1]Valuation Charts'!$B$2:$B$28
Name chk_400: '[1]Valuation Charts'!$B$13
Name chk_400g: '[1]Valuation Charts'!$B$11
Name chk_400v: '[1]Valuation Charts'!$B$12
Name chk_500: '[1]Valuation Charts'!$B$16
Name chk_500g: '[1]Valuation Charts'!$B$14
Name chk_500v: '[1]Valuation Charts'!$B$15
Name chk_600: '[1]Valuation Charts'!$B$19
Name chk_600g: '[1]Valuation Charts'!$B$17
Name chk_600v: '[1]Valuation Charts'!$B$18
Name chk_r1000: '[1]Valuation Charts'!$B$2
Name chk_r1000g: '[1]Valuation Charts'!$B$3
Name chk_r1000v: '[1]Valuation Charts'!$B$4
Name chk_r2000: '[1]Valuation Charts'!$B$5
Name chk_r2000g: '[1]Valuation Charts'!$B$6
Name chk_r2000v: '[1]Valuation Charts'!$B$7
Name chk_rMid: '[1]Valuation Charts'!$B$8
Name chk_rMidG: '[1]Valuation Charts'!$B$9
Name chk_rMidV: '[1]Valuation Charts'!$B$10
Name CMA: #REF!
Name CMAG: #REF!
Name CMQ: #REF!
Name CMQG: #REF!
Name CNA: #REF!
Name CNQ: #REF!
Name Date: OFFSET([2]Work!$B$12,0,0,COUNT([2]Work!$B$12:$B$65536),1)
Name date_from: '[1]Valuation Charts'!$A$30
Name date_to: '[1]Valuation Charts'!$A$31
Name dates: [1]lists!$C$1:$C$92
Name full_date: [1]combo_lists!$B$3
Name Fund_Cushion: OFFSET([2]Work!$J$12,0,0,COUNT([2]Work!$J$12:$J$65536),1)
Name Fund_Floor: OFFSET([2]Work!$I$12,0,0,COUNT([2]Work!$I$12:$I$65536),1)
Name Fund_NAV: OFFSET([2]Work!$E$12,0,0,COUNT([2]Work!$E$12:$E$65536),1)
Name Fund_Return: OFFSET([2]Work!$F$13,0,0,COUNT([2]Work!$F$13:$F$65536),1)
Name GS건설_순매수대금: OFFSET([3]data!$AA$15,COUNT([3]data!$AA$15:$AA$65536)-90,0,93,1)
Name GS건설_외국인보유비중: OFFSET([3]data!$Z$15,COUNT([3]data!$Z$15:$Z$65536)-90,0,93,1)
Name index: '[1]Monthly Return Charts'!$A$1
Name index_type: '[1]Valuation Charts'!$A$28
Name indices: [1]lists!$D$1:$D$18
Name indices_list: [1]lists!$E$1:$E$2
Name Kospi_1000: OFFSET('[2]BM Data'!$O$16,0,0,COUNT('[2]BM Data'!$O$16:$O$65536),1)
Name KT_순매수대금: OFFSET([3]data!$AK$15,COUNT([3]data!$AK$15:$AK$65536)-90,0,93,1)
Name KT_외국인보유비중: OFFSET([3]data!$AJ$15,COUNT([3]data!$AJ$15:$AJ$65536)-90,0,93,1)
Name LG디스플레이_순매수대금: OFFSET([3]data!$I$15,COUNT([3]data!$I$15:$I$65536)-90,0,93,1)
Name LG디스플레이_외국인보유비중: OFFSET([3]data!$H$15,COUNT([3]data!$H$15:$H$65536)-90,0,93,1)
Name LG전자_순매수대금: OFFSET([3]data!$G$15,COUNT([3]data!$G$15:$G$65536)-90,0,93,1)
Name LG전자_외국인보유비중: OFFSET([3]data!$F$15,COUNT([3]data!$F$15:$F$65536)-90,0,93,1)
Name LG화학_순매수대금: OFFSET([3]data!$AM$15,COUNT([3]data!$AM$15:$AM$65536)-90,0,93,1)
Name LG화학_외국인보유비중: OFFSET([3]data!$AL$15,COUNT([3]data!$AL$15:$AL$65536)-90,0,93,1)
Name LS_순매수대금: OFFSET([3]data!$BE$15,COUNT([3]data!$BE$15:$BE$65536)-90,0,93,1)
Name LS_외국인보유비중: OFFSET([3]data!$BD$15,COUNT([3]data!$BD$15:$BD$65536)-90,0,93,1)

Sheet 코스닥액티브
B3: ='코엑트 코스닥액티브'!A9 -> KoAct 코스닥액티브 | H3: ='타임 코스닥액티브'!A9 -> TIME 코스닥액티브 | N3: =플러스코스닥액티브!A9 -> PLUS 코스닥150액티브
B4: 종목명 | C4: ='코엑트 코스닥액티브'!B4 -> CPD [20260701] | D4: ='코엑트 코스닥액티브(과거)'!B4 -> 20260619 | E4: 비중차이 | F4: 증가율 | H4: 종목명 | I4: =C4 -> CPD [20260701] | J4: =D4 -> 20260619 | K4: 비중차 | L4: 증가율 | N4: 종목명 | O4: =C4 -> CPD [20260701] | P4: =D4 -> 20260619 | Q4: 비중차이 | R4: 증가율
A5: =VLOOKUP(B5,유니버스!$C$14:$D$2561,2,0) -> KQ | B5: ='코엑트 코스닥액티브'!B11 -> 테스 | C5: =VLOOKUP(B5,'코엑트 코스닥액티브'!$B$11:$E$1000,4,0) -> 10.34 | D5: =IFERROR(VLOOKUP(B5,'코엑트 코스닥액티브(과거)'!$B$11:$E$1000,4,0),0) -> 8.1 | E5: =C5-D5 -> 2.24 | F5: =IFERROR(C5/D5-1,"신규편입") -> 0.27654321 | G5: =VLOOKUP(H5,유니버스!$C$14:$D$2561,2,0) -> KQ | H5: ='타임 코스닥액티브'!B11 -> 테스 | I5: =VLOOKUP(H5,'타임 코스닥액티브'!$B$11:$E$1000,4,0) -> 10.24 | J5: =IFERROR(VLOOKUP(H5,'타임코스닥액티브(과거)'!$B$11:$E$1000,4,0),0) -> 8.18 | K5: =I5-J5 -> 2.06 | L5: =IFERROR(I5/J5-1,"신규편입") -> 0.25183374 | M5: =VLOOKUP(N5,유니버스!$C$14:$D$2561,2,0) -> KQ | N5: =플러스코스닥액티브!B11 -> 서진시스템 | O5: =VLOOKUP(N5,플러스코스닥액티브!$B$11:$E$1000,4,0) -> 7.5 | P5: =IFERROR(VLOOKUP(N5,'플러스코스닥액티브(과거)'!$B$11:$E$1000,4,0),0) -> 6.82 | Q5: =O5-P5 -> 0.68 | R5: =IFERROR(O5/P5-1,"신규편입") -> 0.099706745
A6: =VLOOKUP(B6,유니버스!$C$14:$D$2561,2,0) -> KQ | B6: ='코엑트 코스닥액티브'!B12 -> 리노공업 | C6: =VLOOKUP(B6,'코엑트 코스닥액티브'!$B$11:$E$1000,4,0) -> 5.72 | D6: =IFERROR(VLOOKUP(B6,'코엑트 코스닥액티브(과거)'!$B$11:$E$1000,4,0),0) -> 6.49 | E6: =C6-D6 -> -0.77 | F6: =IFERROR(C6/D6-1,"신규편입") -> -0.11864407 | G6: =VLOOKUP(H6,유니버스!$C$14:$D$2561,2,0) -> KQ | H6: ='타임 코스닥액티브'!B12 -> 인텍플러스 | I6: =VLOOKUP(H6,'타임 코스닥액티브'!$B$11:$E$1000,4,0) -> 5.42 | J6: =IFERROR(VLOOKUP(H6,'타임코스닥액티브(과거)'!$B$11:$E$1000,4,0),0) -> 5.3 | K6: =I6-J6 -> 0.12 | L6: =IFERROR(I6/J6-1,"신규편입") -> 0.022641509 | M6: =VLOOKUP(N6,유니버스!$C$14:$D$2561,2,0) -> KQ | N6: =플러스코스닥액티브!B12 -> 더블유씨피 | O6: =VLOOKUP(N6,플러스코스닥액티브!$B$11:$E$1000,4,0) -> 6.65 | P6: =IFERROR(VLOOKUP(N6,'플러스코스닥액티브(과거)'!$B$11:$E$1000,4,0),0) -> 6.43 | Q6: =O6-P6 -> 0.22 | R6: =IFERROR(O6/P6-1,"신규편입") -> 0.034214619
A7: =VLOOKUP(B7,유니버스!$C$14:$D$2561,2,0) -> KQ | B7: ='코엑트 코스닥액티브'!B13 -> 심텍 | C7: =VLOOKUP(B7,'코엑트 코스닥액티브'!$B$11:$E$1000,4,0) -> 4.42 | D7: =IFERROR(VLOOKUP(B7,'코엑트 코스닥액티브(과거)'!$B$11:$E$1000,4,0),0) -> 3.5 | E7: =C7-D7 -> 0.92 | F7: =IFERROR(C7/D7-1,"신규편입") -> 0.26285714 | G7: =VLOOKUP(H7,유니버스!$C$14:$D$2561,2,0) -> KQ | H7: ='타임 코스닥액티브'!B13 -> 원익IPS | I7: =VLOOKUP(H7,'타임 코스닥액티브'!$B$11:$E$1000,4,0) -> 5.26 | J7: =IFERROR(VLOOKUP(H7,'타임코스닥액티브(과거)'!$B$11:$E$1000,4,0),0) -> 5.08 | K7: =I7-J7 -> 0.18 | L7: =IFERROR(I7/J7-1,"신규편입") -> 0.035433071 | M7: =VLOOKUP(N7,유니버스!$C$14:$D$2561,2,0) -> KQ | N7: =플러스코스닥액티브!B13 -> 씨어스 | O7: =VLOOKUP(N7,플러스코스닥액티브!$B$11:$E$1000,4,0) -> 6.11 | P7: =IFERROR(VLOOKUP(N7,'플러스코스닥액티브(과거)'!$B$11:$E$1000,4,0),0) -> 6.3 | Q7: =O7-P7 -> -0.19 | R7: =IFERROR(O7/P7-1,"신규편입") -> -0.03015873
A8: =VLOOKUP(B8,유니버스!$C$14:$D$2561,2,0) -> KQ | B8: ='코엑트 코스닥액티브'!B14 -> 성호전자 | C8: =VLOOKUP(B8,'코엑트 코스닥액티브'!$B$11:$E$1000,4,0) -> 4.23 | D8: =IFERROR(VLOOKUP(B8,'코엑트 코스닥액티브(과거)'!$B$11:$E$1000,4,0),0) -> 5.28 | E8: =C8-D8 -> -1.05 | F8: =IFERROR(C8/D8-1,"신규편입") -> -0.19886364 | G8: =VLOOKUP(H8,유니버스!$C$14:$D$2561,2,0) -> KQ | H8: ='타임 코스닥액티브'!B14 -> 주성엔지니어링 | I8: =VLOOKUP(H8,'타임 코스닥액티브'!$B$11:$E$1000,4,0) -> 4.98 | J8: =IFERROR(VLOOKUP(H8,'타임코스닥액티브(과거)'!$B$11:$E$1000,4,0),0) -> 4.07 | K8: =I8-J8 -> 0.91 | L8: =IFERROR(I8/J8-1,"신규편입") -> 0.22358722 | M8: =VLOOKUP(N8,유니버스!$C$14:$D$2561,2,0) -> KQ | N8: =플러스코스닥액티브!B14 -> 브이엠 | O8: =VLOOKUP(N8,플러스코스닥액티브!$B$11:$E$1000,4,0) -> 3.64 | P8: =IFERROR(VLOOKUP(N8,'플러스코스닥액티브(과거)'!$B$11:$E$1000,4,0),0) -> 2.62 | Q8: =O8-P8 -> 1.02 | R8: =IFERROR(O8/P8-1,"신규편입") -> 0.38931298
A9: =VLOOKUP(B9,유니버스!$C$14:$D$2561,2,0) -> KQ | B9: ='코엑트 코스닥액티브'!B15 -> 피에스케이홀딩스 | C9: =VLOOKUP(B9,'코엑트 코스닥액티브'!$B$11:$E$1000,4,0) -> 3.4 | D9: =IFERROR(VLOOKUP(B9,'코엑트 코스닥액티브(과거)'!$B$11:$E$1000,4,0),0) -> 2.29 | E9: =C9-D9 -> 1.11 | F9: =IFERROR(C9/D9-1,"신규편입") -> 0.48471616 | G9: =VLOOKUP(H9,유니버스!$C$14:$D$2561,2,0) -> KQ | H9: ='타임 코스닥액티브'!B15 -> 기가비스 | I9: =VLOOKUP(H9,'타임 코스닥액티브'!$B$11:$E$1000,4,0) -> 3.85 | J9: =IFERROR(VLOOKUP(H9,'타임코스닥액티브(과거)'!$B$11:$E$1000,4,0),0) -> 2.9 | K9: =I9-J9 -> 0.95 | L9: =IFERROR(I9/J9-1,"신규편입") -> 0.32758621 | M9: =VLOOKUP(N9,유니버스!$C$14:$D$2561,2,0) -> KQ | N9: =플러스코스닥액티브!B15 -> 피에스케이홀딩스 | O9: =VLOOKUP(N9,플러스코스닥액티브!$B$11:$E$1000,4,0) -> 3.61 | P9: =IFERROR(VLOOKUP(N9,'플러스코스닥액티브(과거)'!$B$11:$E$1000,4,0),0) -> 2.69 | Q9: =O9-P9 -> 0.92 | R9: =IFERROR(O9/P9-1,"신규편입") -> 0.34200743
A10: =VLOOKUP(B10,유니버스!$C$14:$D$2561,2,0) -> KQ | B10: ='코엑트 코스닥액티브'!B16 -> 피에스케이 | C10: =VLOOKUP(B10,'코엑트 코스닥액티브'!$B$11:$E$1000,4,0) -> 3.12 | D10: =IFERROR(VLOOKUP(B10,'코엑트 코스닥액티브(과거)'!$B$11:$E$1000,4,0),0) -> 2.44 | E10: =C10-D10 -> 0.68 | F10: =IFERROR(C10/D10-1,"신규편입") -> 0.27868852 | G10: =VLOOKUP(H10,유니버스!$C$14:$D$2561,2,0) -> KQ | H10: ='타임 코스닥액티브'!B16 -> 알테오젠 | I10: =VLOOKUP(H10,'타임 코스닥액티브'!$B$11:$E$1000,4,0) -> 3.57 | J10: =IFERROR(VLOOKUP(H10,'타임코스닥액티브(과거)'!$B$11:$E$1000,4,0),0) -> 1.7 | K10: =I10-J10 -> 1.87 | L10: =IFERROR(I10/J10-1,"신규편입") -> 1.1 | M10: =VLOOKUP(N10,유니버스!$C$14:$D$2561,2,0) -> KQ | N10: =플러스코스닥액티브!B16 -> 스피어 | O10: =VLOOKUP(N10,플러스코스닥액티브!$B$11:$E$1000,4,0) -> 3.48 | P10: =IFERROR(VLOOKUP(N10,'플러스코스닥액티브(과거)'!$B$11:$E$1000,4,0),0) -> 2.56 | Q10: =O10-P10 -> 0.92 | R10: =IFERROR(O10/P10-1,"신규편입") -> 0.359375
A11: =VLOOKUP(B11,유니버스!$C$14:$D$2561,2,0) -> KQ | B11: ='코엑트 코스닥액티브'!B17 -> 알테오젠 | C11: =VLOOKUP(B11,'코엑트 코스닥액티브'!$B$11:$E$1000,4,0) -> 3.02 | D11: =IFERROR(VLOOKUP(B11,'코엑트 코스닥액티브(과거)'!$B$11:$E$1000,4,0),0) -> 2.95 | E11: =C11-D11 -> 0.07 | F11: =IFERROR(C11/D11-1,"신규편입") -> 0.023728814 | G11: =VLOOKUP(H11,유니버스!$C$14:$D$2561,2,0) -> KQ | H11: ='타임 코스닥액티브'!B17 -> 피에스케이 | I11: =VLOOKUP(H11,'타임 코스닥액티브'!$B$11:$E$1000,4,0) -> 3.4 | J11: =IFERROR(VLOOKUP(H11,'타임코스닥액티브(과거)'!$B$11:$E$1000,4,0),0) -> 2.07 | K11: =I11-J11 -> 1.33 | L11: =IFERROR(I11/J11-1,"신규편입") -> 0.64251208 | M11: =VLOOKUP(N11,유니버스!$C$14:$D$2561,2,0) -> KQ | N11: =플러스코스닥액티브!B17 -> 비나텍 | O11: =VLOOKUP(N11,플러스코스닥액티브!$B$11:$E$1000,4,0) -> 3.06 | P11: =IFERROR(VLOOKUP(N11,'플러스코스닥액티브(과거)'!$B$11:$E$1000,4,0),0) -> 3.56 | Q11: =O11-P11 -> -0.5 | R11: =IFERROR(O11/P11-1,"신규편입") -> -0.14044944
A12: =VLOOKUP(B12,유니버스!$C$14:$D$2561,2,0) -> KQ | B12: ='코엑트 코스닥액티브'!B18 -> 코미코 | C12: =VLOOKUP(B12,'코엑트 코스닥액티브'!$B$11:$E$1000,4,0) -> 2.67 | D12: =IFERROR(VLOOKUP(B12,'코엑트 코스닥액티브(과거)'!$B$11:$E$1000,4,0),0) -> 3.08 | E12: =C12-D12 -> -0.41 | F12: =IFERROR(C12/D12-1,"신규편입") -> -0.13311688 | G12: =VLOOKUP(H12,유니버스!$C$14:$D$2561,2,0) -> KQ | H12: ='타임 코스닥액티브'!B18 -> 심텍 | I12: =VLOOKUP(H12,'타임 코스닥액티브'!$B$11:$E$1000,4,0) -> 3.17 | J12: =IFERROR(VLOOKUP(H12,'타임코스닥액티브(과거)'!$B$11:$E$1000,4,0),0) -> 2.57 | K12: =I12-J12 -> 0.6 | L12: =IFERROR(I12/J12-1,"신규편입") -> 0.23346304 | M12: =VLOOKUP(N12,유니버스!$C$14:$D$2561,2,0) -> KQ | N12: =플러스코스닥액티브!B18 -> 테스 | O12: =VLOOKUP(N12,플러스코스닥액티브!$B$11:$E$1000,4,0) -> 2.81 | P12: =IFERROR(VLOOKUP(N12,'플러스코스닥액티브(과거)'!$B$11:$E$1000,4,0),0) -> 2.19 | Q12: =O12-P12 -> 0.62 | R12: =IFERROR(O12/P12-1,"신규편입") -> 0.28310502
A13: =VLOOKUP(B13,유니버스!$C$14:$D$2561,2,0) -> KQ | B13: ='코엑트 코스닥액티브'!B19 -> 티엘비 | C13: =VLOOKUP(B13,'코엑트 코스닥액티브'!$B$11:$E$1000,4,0) -> 2.49 | D13: =IFERROR(VLOOKUP(B13,'코엑트 코스닥액티브(과거)'!$B$11:$E$1000,4,0),0) -> 3 | E13: =C13-D13 -> -0.51 | F13: =IFERROR(C13/D13-1,"신규편입") -> -0.17 | G13: =VLOOKUP(H13,유니버스!$C$14:$D$2561,2,0) -> KQ | H13: ='타임 코스닥액티브'!B19 -> 제주반도체 | I13: =VLOOKUP(H13,'타임 코스닥액티브'!$B$11:$E$1000,4,0) -> 3.16 | J13: =IFERROR(VLOOKUP(H13,'타임코스닥액티브(과거)'!$B$11:$E$1000,4,0),0) -> 5.01 | K13: =I13-J13 -> -1.85 | L13: =IFERROR(I13/J13-1,"신규편입") -> -0.36926148 | M13: =VLOOKUP(N13,유니버스!$C$14:$D$2561,2,0) -> KQ | N13: =플러스코스닥액티브!B19 -> 씨에스베어링 | O13: =VLOOKUP(N13,플러스코스닥액티브!$B$11:$E$1000,4,0) -> 2.75 | P13: =IFERROR(VLOOKUP(N13,'플러스코스닥액티브(과거)'!$B$11:$E$1000,4,0),0) -> 2.75 | Q13: =O13-P13 -> 0 | R13: =IFERROR(O13/P13-1,"신규편입") -> 0
A14: =VLOOKUP(B14,유니버스!$C$14:$D$2561,2,0) -> KQ | B14: ='코엑트 코스닥액티브'!B20 -> 에이비엘바이오 | C14: =VLOOKUP(B14,'코엑트 코스닥액티브'!$B$11:$E$1000,4,0) -> 2.46 | D14: =IFERROR(VLOOKUP(B14,'코엑트 코스닥액티브(과거)'!$B$11:$E$1000,4,0),0) -> 2.41 | E14: =C14-D14 -> 0.05 | F14: =IFERROR(C14/D14-1,"신규편입") -> 0.020746888 | G14: =VLOOKUP(H14,유니버스!$C$14:$D$2561,2,0) -> KQ | H14: ='타임 코스닥액티브'!B20 -> 하나마이크론 | I14: =VLOOKUP(H14,'타임 코스닥액티브'!$B$11:$E$1000,4,0) -> 2.6 | J14: =IFERROR(VLOOKUP(H14,'타임코스닥액티브(과거)'!$B$11:$E$1000,4,0),0) -> 2.55 | K14: =I14-J14 -> 0.05 | L14: =IFERROR(I14/J14-1,"신규편입") -> 0.019607843 | M14: =VLOOKUP(N14,유니버스!$C$14:$D$2561,2,0) -> KQ | N14: =플러스코스닥액티브!B20 -> 코미코 | O14: =VLOOKUP(N14,플러스코스닥액티브!$B$11:$E$1000,4,0) -> 2.64 | P14: =IFERROR(VLOOKUP(N14,'플러스코스닥액티브(과거)'!$B$11:$E$1000,4,0),0) -> 3.08 | Q14: =O14-P14 -> -0.44 | R14: =IFERROR(O14/P14-1,"신규편입") -> -0.14285714
A15: =VLOOKUP(B15,유니버스!$C$14:$D$2561,2,0) -> KQ | B15: ='코엑트 코스닥액티브'!B21 -> 제주반도체 | C15: =VLOOKUP(B15,'코엑트 코스닥액티브'!$B$11:$E$1000,4,0) -> 2.42 | D15: =IFERROR(VLOOKUP(B15,'코엑트 코스닥액티브(과거)'!$B$11:$E$1000,4,0),0) -> 1.65 | E15: =C15-D15 -> 0.77 | F15: =IFERROR(C15/D15-1,"신규편입") -> 0.46666667 | G15: =VLOOKUP(H15,유니버스!$C$14:$D$2561,2,0) -> KQ | H15: ='타임 코스닥액티브'!B21 -> 피에스케이홀딩스 | I15: =VLOOKUP(H15,'타임 코스닥액티브'!$B$11:$E$1000,4,0) -> 2.34 | J15: =IFERROR(VLOOKUP(H15,'타임코스닥액티브(과거)'!$B$11:$E$1000,4,0),0) -> 1.62 | K15: =I15-J15 -> 0.72 | L15: =IFERROR(I15/J15-1,"신규편입") -> 0.44444444 | M15: =VLOOKUP(N15,유니버스!$C$14:$D$2561,2,0) -> KQ | N15: =플러스코스닥액티브!B21 -> 한중엔시에스 | O15: =VLOOKUP(N15,플러스코스닥액티브!$B$11:$E$1000,4,0) -> 2.59 | P15: =IFERROR(VLOOKUP(N15,'플러스코스닥액티브(과거)'!$B$11:$E$1000,4,0),0) -> 2.78 | Q15: =O15-P15 -> -0.19 | R15: =IFERROR(O15/P15-1,"신규편입") -> -0.068345324
A16: =VLOOKUP(B16,유니버스!$C$14:$D$2561,2,0) -> KQ | B16: ='코엑트 코스닥액티브'!B22 -> 파마리서치 | C16: =VLOOKUP(B16,'코엑트 코스닥액티브'!$B$11:$E$1000,4,0) -> 2.38 | D16: =IFERROR(VLOOKUP(B16,'코엑트 코스닥액티브(과거)'!$B$11:$E$1000,4,0),0) -> 1.23 | E16: =C16-D16 -> 1.15 | F16: =IFERROR(C16/D16-1,"신규편입") -> 0.93495935 | G16: =VLOOKUP(H16,유니버스!$C$14:$D$2561,2,0) -> KQ | H16: ='타임 코스닥액티브'!B22 -> 미코 | I16: =VLOOKUP(H16,'타임 코스닥액티브'!$B$11:$E$1000,4,0) -> 2.07 | J16: =IFERROR(VLOOKUP(H16,'타임코스닥액티브(과거)'!$B$11:$E$1000,4,0),0) -> 2.25 | K16: =I16-J16 -> -0.18 | L16: =IFERROR(I16/J16-1,"신규편입") -> -0.08 | M16: =VLOOKUP(N16,유니버스!$C$14:$D$2561,2,0) -> KQ | N16: =플러스코스닥액티브!B22 -> 피에스케이 | O16: =VLOOKUP(N16,플러스코스닥액티브!$B$11:$E$1000,4,0) -> 2.57 | P16: =IFERROR(VLOOKUP(N16,'플러스코스닥액티브(과거)'!$B$11:$E$1000,4,0),0) -> 1.77 | Q16: =O16-P16 -> 0.8 | R16: =IFERROR(O16/P16-1,"신규편입") -> 0.4519774
... A66: =VLOOKUP(B66,유니버스!$C$14:$D$2561,2,0) -> KQ | B66: ='코엑트 코스닥액티브'!B72 -> 에이치브이엠 | C66: =VLOOKUP(B66,'코엑트 코스닥액티브'!$B$11:$E$1000,4,0) -> 0.38 | D66: =IFERROR(VLOOKUP(B66,'코엑트 코스닥액티브(과거)'!$B$11:$E$1000,4,0),0) -> 0.5 | E66: =C66-D66 -> -0.12 | F66: =IFERROR(C66/D66-1,"신규편입") -> -0.24 | G66: =VLOOKUP(H66,유니버스!$C$14:$D$2561,2,0) -> #N/A | H66: ='타임 코스닥액티브'!B72 -> 원화현금 | I66: =VLOOKUP(H66,'타임 코스닥액티브'!$B$11:$E$1000,4,0) -> 1.37 | J66: =IFERROR(VLOOKUP(H66,'타임코스닥액티브(과거)'!$B$11:$E$1000,4,0),0) -> 1.69 | K66: =I66-J66 -> -0.32 | L66: =IFERROR(I66/J66-1,"신규편입") -> -0.18934911 | M66: =VLOOKUP(N66,유니버스!$C$14:$D$2561,2,0) -> KQ | N66: =플러스코스닥액티브!B72 -> 서부T&D | O66: =VLOOKUP(N66,플러스코스닥액티브!$B$11:$E$1000,4,0) -> 0.15 | P66: =IFERROR(VLOOKUP(N66,'플러스코스닥액티브(과거)'!$B$11:$E$1000,4,0),0) -> 0.15 | Q66: =O66-P66 -> 0 | R66: =IFERROR(O66/P66-1,"신규편입") -> 0
A67: =VLOOKUP(B67,유니버스!$C$14:$D$2561,2,0) -> KQ | B67: ='코엑트 코스닥액티브'!B73 -> 보로노이 | C67: =VLOOKUP(B67,'코엑트 코스닥액티브'!$B$11:$E$1000,4,0) -> 0.37 | D67: =IFERROR(VLOOKUP(B67,'코엑트 코스닥액티브(과거)'!$B$11:$E$1000,4,0),0) -> 0.37 | E67: =C67-D67 -> 0 | F67: =IFERROR(C67/D67-1,"신규편입") -> 0 | M67: =VLOOKUP(N67,유니버스!$C$14:$D$2561,2,0) -> KQ | N67: =플러스코스닥액티브!B73 -> 에스티팜 | O67: =VLOOKUP(N67,플러스코스닥액티브!$B$11:$E$1000,4,0) -> 0.11 | P67: =IFERROR(VLOOKUP(N67,'플러스코스닥액티브(과거)'!$B$11:$E$1000,4,0),0) -> 0.1 | Q67: =O67-P67 -> 0.01 | R67: =IFERROR(O67/P67-1,"신규편입") -> 0.1
A68: =VLOOKUP(B68,유니버스!$C$14:$D$2561,2,0) -> KQ | B68: ='코엑트 코스닥액티브'!B74 -> 선익시스템 | C68: =VLOOKUP(B68,'코엑트 코스닥액티브'!$B$11:$E$1000,4,0) -> 0.36 | D68: =IFERROR(VLOOKUP(B68,'코엑트 코스닥액티브(과거)'!$B$11:$E$1000,4,0),0) -> 0.5 | E68: =C68-D68 -> -0.14 | F68: =IFERROR(C68/D68-1,"신규편입") -> -0.28 | M68: =VLOOKUP(N68,유니버스!$C$14:$D$2561,2,0) -> KQ | N68: =플러스코스닥액티브!B74 -> 씨젠 | O68: =VLOOKUP(N68,플러스코스닥액티브!$B$11:$E$1000,4,0) -> 0.09 | P68: =IFERROR(VLOOKUP(N68,'플러스코스닥액티브(과거)'!$B$11:$E$1000,4,0),0) -> 0.35 | Q68: =O68-P68 -> -0.26 | R68: =IFERROR(O68/P68-1,"신규편입") -> -0.74285714
A69: =VLOOKUP(B69,유니버스!$C$14:$D$2561,2,0) -> KQ | B69: ='코엑트 코스닥액티브'!B75 -> 코오롱생명과학 | C69: =VLOOKUP(B69,'코엑트 코스닥액티브'!$B$11:$E$1000,4,0) -> 0.35 | D69: =IFERROR(VLOOKUP(B69,'코엑트 코스닥액티브(과거)'!$B$11:$E$1000,4,0),0) -> 0.38 | E69: =C69-D69 -> -0.03 | F69: =IFERROR(C69/D69-1,"신규편입") -> -0.078947368 | M69: =VLOOKUP(N69,유니버스!$C$14:$D$2561,2,0) -> KQ | N69: =플러스코스닥액티브!B75 -> HK이노엔 | O69: =VLOOKUP(N69,플러스코스닥액티브!$B$11:$E$1000,4,0) -> 0.09 | P69: =IFERROR(VLOOKUP(N69,'플러스코스닥액티브(과거)'!$B$11:$E$1000,4,0),0) -> 0 | Q69: =O69-P69 -> 0.09 | R69: =IFERROR(O69/P69-1,"신규편입") -> 신규편입
A70: =VLOOKUP(B70,유니버스!$C$14:$D$2561,2,0) -> KQ | B70: ='코엑트 코스닥액티브'!B76 -> 씨메스로보틱스 | C70: =VLOOKUP(B70,'코엑트 코스닥액티브'!$B$11:$E$1000,4,0) -> 0.35 | D70: =IFERROR(VLOOKUP(B70,'코엑트 코스닥액티브(과거)'!$B$11:$E$1000,4,0),0) -> 0.38 | E70: =C70-D70 -> -0.03 | F70: =IFERROR(C70/D70-1,"신규편입") -> -0.078947368 | M70: =VLOOKUP(N70,유니버스!$C$14:$D$2561,2,0) -> KQ | N70: =플러스코스닥액티브!B76 -> 덕산네오룩스 | O70: =VLOOKUP(N70,플러스코스닥액티브!$B$11:$E$1000,4,0) -> 0.09 | P70: =IFERROR(VLOOKUP(N70,'플러스코스닥액티브(과거)'!$B$11:$E$1000,4,0),0) -> 0.31 | Q70: =O70-P70 -> -0.22 | R70: =IFERROR(O70/P70-1,"신규편입") -> -0.70967742
A71: =VLOOKUP(B71,유니버스!$C$14:$D$2561,2,0) -> KQ | B71: ='코엑트 코스닥액티브'!B77 -> 이랜텍 | C71: =VLOOKUP(B71,'코엑트 코스닥액티브'!$B$11:$E$1000,4,0) -> 0.35 | D71: =IFERROR(VLOOKUP(B71,'코엑트 코스닥액티브(과거)'!$B$11:$E$1000,4,0),0) -> 0.36 | E71: =C71-D71 -> -0.01 | F71: =IFERROR(C71/D71-1,"신규편입") -> -0.027777778 | M71: =VLOOKUP(N71,유니버스!$C$14:$D$2561,2,0) -> KQ | N71: =플러스코스닥액티브!B77 -> 레이크머티리얼즈 | O71: =VLOOKUP(N71,플러스코스닥액티브!$B$11:$E$1000,4,0) -> 0.09 | P71: =IFERROR(VLOOKUP(N71,'플러스코스닥액티브(과거)'!$B$11:$E$1000,4,0),0) -> 0.24 | Q71: =O71-P71 -> -0.15 | R71: =IFERROR(O71/P71-1,"신규편입") -> -0.625
A72: =VLOOKUP(B72,유니버스!$C$14:$D$2561,2,0) -> KQ | B72: ='코엑트 코스닥액티브'!B78 -> 덕산네오룩스 | C72: =VLOOKUP(B72,'코엑트 코스닥액티브'!$B$11:$E$1000,4,0) -> 0.33 | D72: =IFERROR(VLOOKUP(B72,'코엑트 코스닥액티브(과거)'!$B$11:$E$1000,4,0),0) -> 0.35 | E72: =C72-D72 -> -0.02 | F72: =IFERROR(C72/D72-1,"신규편입") -> -0.057142857 | M72: =VLOOKUP(N72,유니버스!$C$14:$D$2561,2,0) -> KQ | N72: =플러스코스닥액티브!B78 -> 나노신소재 | O72: =VLOOKUP(N72,플러스코스닥액티브!$B$11:$E$1000,4,0) -> 0.08 | P72: =IFERROR(VLOOKUP(N72,'플러스코스닥액티브(과거)'!$B$11:$E$1000,4,0),0) -> 0.09 | Q72: =O72-P72 -> -0.01 | R72: =IFERROR(O72/P72-1,"신규편입") -> -0.11111111
A73: =VLOOKUP(B73,유니버스!$C$14:$D$2561,2,0) -> KQ | B73: ='코엑트 코스닥액티브'!B79 -> 파두 | C73: =VLOOKUP(B73,'코엑트 코스닥액티브'!$B$11:$E$1000,4,0) -> 0.28 | D73: =IFERROR(VLOOKUP(B73,'코엑트 코스닥액티브(과거)'!$B$11:$E$1000,4,0),0) -> 2.66 | E73: =C73-D73 -> -2.38 | F73: =IFERROR(C73/D73-1,"신규편입") -> -0.89473684 | M73: =VLOOKUP(N73,유니버스!$C$14:$D$2561,2,0) -> KQ | N73: =플러스코스닥액티브!B79 -> 오이솔루션 | O73: =VLOOKUP(N73,플러스코스닥액티브!$B$11:$E$1000,4,0) -> 0.07 | P73: =IFERROR(VLOOKUP(N73,'플러스코스닥액티브(과거)'!$B$11:$E$1000,4,0),0) -> 0.08 | Q73: =O73-P73 -> -0.01 | R73: =IFERROR(O73/P73-1,"신규편입") -> -0.125
A74: =VLOOKUP(B74,유니버스!$C$14:$D$2561,2,0) -> KQ | B74: ='코엑트 코스닥액티브'!B80 -> 엠케이전자 | C74: =VLOOKUP(B74,'코엑트 코스닥액티브'!$B$11:$E$1000,4,0) -> 0.25 | D74: =IFERROR(VLOOKUP(B74,'코엑트 코스닥액티브(과거)'!$B$11:$E$1000,4,0),0) -> 0.19 | E74: =C74-D74 -> 0.06 | F74: =IFERROR(C74/D74-1,"신규편입") -> 0.31578947 | M74: =VLOOKUP(N74,유니버스!$C$14:$D$2561,2,0) -> #N/A | N74: =플러스코스닥액티브!B80 -> 채비 | O74: =VLOOKUP(N74,플러스코스닥액티브!$B$11:$E$1000,4,0) -> 0.05 | P74: =IFERROR(VLOOKUP(N74,'플러스코스닥액티브(과거)'!$B$11:$E$1000,4,0),0) -> 0.05 | Q74: =O74-P74 -> 0 | R74: =IFERROR(O74/P74-1,"신규편입") -> 0
A75: =VLOOKUP(B75,유니버스!$C$14:$D$2561,2,0) -> KQ | B75: ='코엑트 코스닥액티브'!B81 -> 와이지엔터테인먼트 | C75: =VLOOKUP(B75,'코엑트 코스닥액티브'!$B$11:$E$1000,4,0) -> 0.21 | D75: =IFERROR(VLOOKUP(B75,'코엑트 코스닥액티브(과거)'!$B$11:$E$1000,4,0),0) -> 0.12 | E75: =C75-D75 -> 0.09 | F75: =IFERROR(C75/D75-1,"신규편입") -> 0.75 | M75: =VLOOKUP(N75,유니버스!$C$14:$D$2561,2,0) -> #N/A | N75: =플러스코스닥액티브!B81 -> 원화현금 | O75: =VLOOKUP(N75,플러스코스닥액티브!$B$11:$E$1000,4,0) -> 0.49 | P75: =IFERROR(VLOOKUP(N75,'플러스코스닥액티브(과거)'!$B$11:$E$1000,4,0),0) -> 0.74 | Q75: =O75-P75 -> -0.25 | R75: =IFERROR(O75/P75-1,"신규편입") -> -0.33783784
A76: =VLOOKUP(B76,유니버스!$C$14:$D$2561,2,0) -> KQ | B76: ='코엑트 코스닥액티브'!B82 -> LS머트리얼즈 | C76: =VLOOKUP(B76,'코엑트 코스닥액티브'!$B$11:$E$1000,4,0) -> 0.19 | D76: =IFERROR(VLOOKUP(B76,'코엑트 코스닥액티브(과거)'!$B$11:$E$1000,4,0),0) -> 0.26 | E76: =C76-D76 -> -0.07 | F76: =IFERROR(C76/D76-1,"신규편입") -> -0.26923077
A77: =VLOOKUP(B77,유니버스!$C$14:$D$2561,2,0) -> KQ | B77: ='코엑트 코스닥액티브'!B83 -> 알멕 | C77: =VLOOKUP(B77,'코엑트 코스닥액티브'!$B$11:$E$1000,4,0) -> 0.18 | D77: =IFERROR(VLOOKUP(B77,'코엑트 코스닥액티브(과거)'!$B$11:$E$1000,4,0),0) -> 0.56 | E77: =C77-D77 -> -0.38 | F77: =IFERROR(C77/D77-1,"신규편입") -> -0.67857143
A78: =VLOOKUP(B78,유니버스!$C$14:$D$2561,2,0) -> KQ | B78: ='코엑트 코스닥액티브'!B84 -> 레이크머티리얼즈 | C78: =VLOOKUP(B78,'코엑트 코스닥액티브'!$B$11:$E$1000,4,0) -> 0.13 | D78: =IFERROR(VLOOKUP(B78,'코엑트 코스닥액티브(과거)'!$B$11:$E$1000,4,0),0) -> 0.29 | E78: =C78-D78 -> -0.16 | F78: =IFERROR(C78/D78-1,"신규편입") -> -0.55172414

Sheet 반도체
B3: ='UNICORN SK하이닉스밸류체인액티브'!A9 -> UNICORN SK하이닉스밸류체인액티브 | H3: ='WON 반도체밸류체인액티브'!A9 -> WON 반도체밸류체인액티브 | N3: ='RISE 비메모리반도체액티브'!A9 -> RISE 비메모리반도체액티브
B4: 종목명 | C4: ='UNICORN SK하이닉스밸류체인액티브'!B4 -> CPD [20260701] | D4: ='UNICORN SK하이닉스밸류체인액티브(과거)'!B4 -> 20260619 | E4: 비중차이 | F4: 증가율 | H4: 종목명 | I4: =C4 -> CPD [20260701] | J4: =D4 -> 20260619 | K4: 비중차 | L4: 증가율 | N4: 종목명 | O4: =C4 -> CPD [20260701] | P4: =D4 -> 20260619 | Q4: 비중차이 | R4: 증가율
A5: =VLOOKUP(B5,유니버스!$C$14:$D$2561,2,0) -> KS | B5: ='UNICORN SK하이닉스밸류체인액티브'!B11 -> SK스퀘어 | C5: =VLOOKUP(B5,'UNICORN SK하이닉스밸류체인액티브'!$B$11:$E$1000,4,0) -> 21.64 | D5: =IFERROR(VLOOKUP(B5,'UNICORN SK하이닉스밸류체인액티브(과거)'!$B$11:$E$1000,4,0),0) -> 25.47 | E5: =C5-D5 -> -3.83 | F5: =IFERROR(C5/D5-1,"신규편입") -> -0.15037299 | G5: =VLOOKUP(H5,유니버스!$C$14:$D$2561,2,0) -> KS | H5: ='WON 반도체밸류체인액티브'!B11 -> SK하이닉스 | I5: =VLOOKUP(H5,'WON 반도체밸류체인액티브'!$B$11:$E$1000,4,0) -> 24.76 | J5: =IFERROR(VLOOKUP(H5,'WON 반도체밸류체인액티브(과거)'!$B$11:$E$1000,4,0),0) -> 27.1 | K5: =I5-J5 -> -2.34 | L5: =IFERROR(I5/J5-1,"신규편입") -> -0.086346863 | M5: =VLOOKUP(N5,유니버스!$C$14:$D$2561,2,0) -> KS | N5: ='RISE 비메모리반도체액티브'!B11 -> 삼성전자 | O5: =VLOOKUP(N5,'RISE 비메모리반도체액티브'!$B$11:$E$1000,4,0) -> 23.94 | P5: =IFERROR(VLOOKUP(N5,'RISE 비메모리반도체액티브(과거)'!$B$11:$E$1000,4,0),0) -> 26.03 | Q5: =O5-P5 -> -2.09 | R5: =IFERROR(O5/P5-1,"신규편입") -> -0.080291971
A6: =VLOOKUP(B6,유니버스!$C$14:$D$2561,2,0) -> KS | B6: ='UNICORN SK하이닉스밸류체인액티브'!B12 -> SK하이닉스 | C6: =VLOOKUP(B6,'UNICORN SK하이닉스밸류체인액티브'!$B$11:$E$1000,4,0) -> 21.2 | D6: =IFERROR(VLOOKUP(B6,'UNICORN SK하이닉스밸류체인액티브(과거)'!$B$11:$E$1000,4,0),0) -> 24.78 | E6: =C6-D6 -> -3.58 | F6: =IFERROR(C6/D6-1,"신규편입") -> -0.14447135 | G6: =VLOOKUP(H6,유니버스!$C$14:$D$2561,2,0) -> KS | H6: ='WON 반도체밸류체인액티브'!B12 -> 삼성전자 | I6: =VLOOKUP(H6,'WON 반도체밸류체인액티브'!$B$11:$E$1000,4,0) -> 20.67 | J6: =IFERROR(VLOOKUP(H6,'WON 반도체밸류체인액티브(과거)'!$B$11:$E$1000,4,0),0) -> 23.58 | K6: =I6-J6 -> -2.91 | L6: =IFERROR(I6/J6-1,"신규편입") -> -0.12340967 | M6: =VLOOKUP(N6,유니버스!$C$14:$D$2561,2,0) -> KS | N6: ='RISE 비메모리반도체액티브'!B12 -> SK하이닉스 | O6: =VLOOKUP(N6,'RISE 비메모리반도체액티브'!$B$11:$E$1000,4,0) -> 20.72 | P6: =IFERROR(VLOOKUP(N6,'RISE 비메모리반도체액티브(과거)'!$B$11:$E$1000,4,0),0) -> 21.62 | Q6: =O6-P6 -> -0.9 | R6: =IFERROR(O6/P6-1,"신규편입") -> -0.041628122
A7: =VLOOKUP(B7,유니버스!$C$14:$D$2561,2,0) -> KQ | B7: ='UNICORN SK하이닉스밸류체인액티브'!B13 -> 브이엠 | C7: =VLOOKUP(B7,'UNICORN SK하이닉스밸류체인액티브'!$B$11:$E$1000,4,0) -> 5.11 | D7: =IFERROR(VLOOKUP(B7,'UNICORN SK하이닉스밸류체인액티브(과거)'!$B$11:$E$1000,4,0),0) -> 3.85 | E7: =C7-D7 -> 1.26 | F7: =IFERROR(C7/D7-1,"신규편입") -> 0.32727273 | G7: =VLOOKUP(H7,유니버스!$C$14:$D$2561,2,0) -> KQ | H7: ='WON 반도체밸류체인액티브'!B13 -> 기가비스 | I7: =VLOOKUP(H7,'WON 반도체밸류체인액티브'!$B$11:$E$1000,4,0) -> 5.52 | J7: =IFERROR(VLOOKUP(H7,'WON 반도체밸류체인액티브(과거)'!$B$11:$E$1000,4,0),0) -> 4.11 | K7: =I7-J7 -> 1.41 | L7: =IFERROR(I7/J7-1,"신규편입") -> 0.34306569 | M7: =VLOOKUP(N7,유니버스!$C$14:$D$2561,2,0) -> KQ | N7: ='RISE 비메모리반도체액티브'!B13 -> 심텍 | O7: =VLOOKUP(N7,'RISE 비메모리반도체액티브'!$B$11:$E$1000,4,0) -> 7.82 | P7: =IFERROR(VLOOKUP(N7,'RISE 비메모리반도체액티브(과거)'!$B$11:$E$1000,4,0),0) -> 5.97 | Q7: =O7-P7 -> 1.85 | R7: =IFERROR(O7/P7-1,"신규편입") -> 0.30988275
A8: =VLOOKUP(B8,유니버스!$C$14:$D$2561,2,0) -> KQ | B8: ='UNICORN SK하이닉스밸류체인액티브'!B14 -> 피에스케이 | C8: =VLOOKUP(B8,'UNICORN SK하이닉스밸류체인액티브'!$B$11:$E$1000,4,0) -> 4.94 | D8: =IFERROR(VLOOKUP(B8,'UNICORN SK하이닉스밸류체인액티브(과거)'!$B$11:$E$1000,4,0),0) -> 3.93 | E8: =C8-D8 -> 1.01 | F8: =IFERROR(C8/D8-1,"신규편입") -> 0.25699746 | G8: =VLOOKUP(H8,유니버스!$C$14:$D$2561,2,0) -> KS | H8: ='WON 반도체밸류체인액티브'!B14 -> SK스퀘어 | I8: =VLOOKUP(H8,'WON 반도체밸류체인액티브'!$B$11:$E$1000,4,0) -> 5.16 | J8: =IFERROR(VLOOKUP(H8,'WON 반도체밸류체인액티브(과거)'!$B$11:$E$1000,4,0),0) -> 5.3 | K8: =I8-J8 -> -0.14 | L8: =IFERROR(I8/J8-1,"신규편입") -> -0.026415094 | M8: =VLOOKUP(N8,유니버스!$C$14:$D$2561,2,0) -> KS | N8: ='RISE 비메모리반도체액티브'!B14 -> 삼성전기 | O8: =VLOOKUP(N8,'RISE 비메모리반도체액티브'!$B$11:$E$1000,4,0) -> 6.62 | P8: =IFERROR(VLOOKUP(N8,'RISE 비메모리반도체액티브(과거)'!$B$11:$E$1000,4,0),0) -> 6.59 | Q8: =O8-P8 -> 0.03 | R8: =IFERROR(O8/P8-1,"신규편입") -> 0.004552352
A9: =VLOOKUP(B9,유니버스!$C$14:$D$2561,2,0) -> KS | B9: ='UNICORN SK하이닉스밸류체인액티브'!B15 -> 삼성전기 | C9: =VLOOKUP(B9,'UNICORN SK하이닉스밸류체인액티브'!$B$11:$E$1000,4,0) -> 4.71 | D9: =IFERROR(VLOOKUP(B9,'UNICORN SK하이닉스밸류체인액티브(과거)'!$B$11:$E$1000,4,0),0) -> 4.11 | E9: =C9-D9 -> 0.6 | F9: =IFERROR(C9/D9-1,"신규편입") -> 0.1459854 | G9: =VLOOKUP(H9,유니버스!$C$14:$D$2561,2,0) -> KS | H9: ='WON 반도체밸류체인액티브'!B15 -> 삼성전기 | I9: =VLOOKUP(H9,'WON 반도체밸류체인액티브'!$B$11:$E$1000,4,0) -> 5.05 | J9: =IFERROR(VLOOKUP(H9,'WON 반도체밸류체인액티브(과거)'!$B$11:$E$1000,4,0),0) -> 5.27 | K9: =I9-J9 -> -0.22 | L9: =IFERROR(I9/J9-1,"신규편입") -> -0.041745731 | M9: =VLOOKUP(N9,유니버스!$C$14:$D$2561,2,0) -> KQ | N9: ='RISE 비메모리반도체액티브'!B15 -> 브이엠 | O9: =VLOOKUP(N9,'RISE 비메모리반도체액티브'!$B$11:$E$1000,4,0) -> 5.92 | P9: =IFERROR(VLOOKUP(N9,'RISE 비메모리반도체액티브(과거)'!$B$11:$E$1000,4,0),0) -> 3.88 | Q9: =O9-P9 -> 2.04 | R9: =IFERROR(O9/P9-1,"신규편입") -> 0.5257732
A10: =VLOOKUP(B10,유니버스!$C$14:$D$2561,2,0) -> KQ | B10: ='UNICORN SK하이닉스밸류체인액티브'!B16 -> 피에스케이홀딩스 | C10: =VLOOKUP(B10,'UNICORN SK하이닉스밸류체인액티브'!$B$11:$E$1000,4,0) -> 4.41 | D10: =IFERROR(VLOOKUP(B10,'UNICORN SK하이닉스밸류체인액티브(과거)'!$B$11:$E$1000,4,0),0) -> 3.04 | E10: =C10-D10 -> 1.37 | F10: =IFERROR(C10/D10-1,"신규편입") -> 0.45065789 | G10: =VLOOKUP(H10,유니버스!$C$14:$D$2561,2,0) -> KQ | H10: ='WON 반도체밸류체인액티브'!B16 -> 피에스케이홀딩스 | I10: =VLOOKUP(H10,'WON 반도체밸류체인액티브'!$B$11:$E$1000,4,0) -> 4.77 | J10: =IFERROR(VLOOKUP(H10,'WON 반도체밸류체인액티브(과거)'!$B$11:$E$1000,4,0),0) -> 3.27 | K10: =I10-J10 -> 1.5 | L10: =IFERROR(I10/J10-1,"신규편입") -> 0.4587156 | M10: =VLOOKUP(N10,유니버스!$C$14:$D$2561,2,0) -> KS | N10: ='RISE 비메모리반도체액티브'!B16 -> 대덕전자 | O10: =VLOOKUP(N10,'RISE 비메모리반도체액티브'!$B$11:$E$1000,4,0) -> 4.54 | P10: =IFERROR(VLOOKUP(N10,'RISE 비메모리반도체액티브(과거)'!$B$11:$E$1000,4,0),0) -> 4.44 | Q10: =O10-P10 -> 0.1 | R10: =IFERROR(O10/P10-1,"신규편입") -> 0.022522523
A11: =VLOOKUP(B11,유니버스!$C$14:$D$2561,2,0) -> KS | B11: ='UNICORN SK하이닉스밸류체인액티브'!B17 -> LG이노텍 | C11: =VLOOKUP(B11,'UNICORN SK하이닉스밸류체인액티브'!$B$11:$E$1000,4,0) -> 4.12 | D11: =IFERROR(VLOOKUP(B11,'UNICORN SK하이닉스밸류체인액티브(과거)'!$B$11:$E$1000,4,0),0) -> 3.45 | E11: =C11-D11 -> 0.67 | F11: =IFERROR(C11/D11-1,"신규편입") -> 0.1942029 | G11: =VLOOKUP(H11,유니버스!$C$14:$D$2561,2,0) -> KQ | H11: ='WON 반도체밸류체인액티브'!B17 -> 피에스케이 | I11: =VLOOKUP(H11,'WON 반도체밸류체인액티브'!$B$11:$E$1000,4,0) -> 4.64 | J11: =IFERROR(VLOOKUP(H11,'WON 반도체밸류체인액티브(과거)'!$B$11:$E$1000,4,0),0) -> 3.67 | K11: =I11-J11 -> 0.97 | L11: =IFERROR(I11/J11-1,"신규편입") -> 0.26430518 | M11: =VLOOKUP(N11,유니버스!$C$14:$D$2561,2,0) -> KQ | N11: ='RISE 비메모리반도체액티브'!B17 -> 리노공업 | O11: =VLOOKUP(N11,'RISE 비메모리반도체액티브'!$B$11:$E$1000,4,0) -> 4.44 | P11: =IFERROR(VLOOKUP(N11,'RISE 비메모리반도체액티브(과거)'!$B$11:$E$1000,4,0),0) -> 4.86 | Q11: =O11-P11 -> -0.42 | R11: =IFERROR(O11/P11-1,"신규편입") -> -0.086419753
A12: =VLOOKUP(B12,유니버스!$C$14:$D$2561,2,0) -> KQ | B12: ='UNICORN SK하이닉스밸류체인액티브'!B18 -> 유진테크 | C12: =VLOOKUP(B12,'UNICORN SK하이닉스밸류체인액티브'!$B$11:$E$1000,4,0) -> 3.5 | D12: =IFERROR(VLOOKUP(B12,'UNICORN SK하이닉스밸류체인액티브(과거)'!$B$11:$E$1000,4,0),0) -> 2.9 | E12: =C12-D12 -> 0.6 | F12: =IFERROR(C12/D12-1,"신규편입") -> 0.20689655 | G12: =VLOOKUP(H12,유니버스!$C$14:$D$2561,2,0) -> KQ | H12: ='WON 반도체밸류체인액티브'!B18 -> 브이엠 | I12: =VLOOKUP(H12,'WON 반도체밸류체인액티브'!$B$11:$E$1000,4,0) -> 4.55 | J12: =IFERROR(VLOOKUP(H12,'WON 반도체밸류체인액티브(과거)'!$B$11:$E$1000,4,0),0) -> 3.4 | K12: =I12-J12 -> 1.15 | L12: =IFERROR(I12/J12-1,"신규편입") -> 0.33823529 | M12: =VLOOKUP(N12,유니버스!$C$14:$D$2561,2,0) -> KQ | N12: ='RISE 비메모리반도체액티브'!B18 -> 원익QnC | O12: =VLOOKUP(N12,'RISE 비메모리반도체액티브'!$B$11:$E$1000,4,0) -> 4.11 | P12: =IFERROR(VLOOKUP(N12,'RISE 비메모리반도체액티브(과거)'!$B$11:$E$1000,4,0),0) -> 3.85 | Q12: =O12-P12 -> 0.26 | R12: =IFERROR(O12/P12-1,"신규편입") -> 0.067532468
A13: =VLOOKUP(B13,유니버스!$C$14:$D$2561,2,0) -> KQ | B13: ='UNICORN SK하이닉스밸류체인액티브'!B19 -> 심텍 | C13: =VLOOKUP(B13,'UNICORN SK하이닉스밸류체인액티브'!$B$11:$E$1000,4,0) -> 3.35 | D13: =IFERROR(VLOOKUP(B13,'UNICORN SK하이닉스밸류체인액티브(과거)'!$B$11:$E$1000,4,0),0) -> 2.7 | E13: =C13-D13 -> 0.65 | F13: =IFERROR(C13/D13-1,"신규편입") -> 0.24074074 | G13: =VLOOKUP(H13,유니버스!$C$14:$D$2561,2,0) -> KS | H13: ='WON 반도체밸류체인액티브'!B19 -> 대덕전자 | I13: =VLOOKUP(H13,'WON 반도체밸류체인액티브'!$B$11:$E$1000,4,0) -> 4.04 | J13: =IFERROR(VLOOKUP(H13,'WON 반도체밸류체인액티브(과거)'!$B$11:$E$1000,4,0),0) -> 4.15 | K13: =I13-J13 -> -0.11 | L13: =IFERROR(I13/J13-1,"신규편입") -> -0.026506024 | M13: =VLOOKUP(N13,유니버스!$C$14:$D$2561,2,0) -> KS | N13: ='RISE 비메모리반도체액티브'!B19 -> 이수페타시스 | O13: =VLOOKUP(N13,'RISE 비메모리반도체액티브'!$B$11:$E$1000,4,0) -> 3.75 | P13: =IFERROR(VLOOKUP(N13,'RISE 비메모리반도체액티브(과거)'!$B$11:$E$1000,4,0),0) -> 3.79 | Q13: =O13-P13 -> -0.04 | R13: =IFERROR(O13/P13-1,"신규편입") -> -0.01055409
A14: =VLOOKUP(B14,유니버스!$C$14:$D$2561,2,0) -> KQ | B14: ='UNICORN SK하이닉스밸류체인액티브'!B20 -> 티씨케이 | C14: =VLOOKUP(B14,'UNICORN SK하이닉스밸류체인액티브'!$B$11:$E$1000,4,0) -> 3.28 | D14: =IFERROR(VLOOKUP(B14,'UNICORN SK하이닉스밸류체인액티브(과거)'!$B$11:$E$1000,4,0),0) -> 3.01 | E14: =C14-D14 -> 0.27 | F14: =IFERROR(C14/D14-1,"신규편입") -> 0.089700997 | G14: =VLOOKUP(H14,유니버스!$C$14:$D$2561,2,0) -> KQ | H14: ='WON 반도체밸류체인액티브'!B20 -> 주성엔지니어링 | I14: =VLOOKUP(H14,'WON 반도체밸류체인액티브'!$B$11:$E$1000,4,0) -> 3.33 | J14: =IFERROR(VLOOKUP(H14,'WON 반도체밸류체인액티브(과거)'!$B$11:$E$1000,4,0),0) -> 2.7 | K14: =I14-J14 -> 0.63 | L14: =IFERROR(I14/J14-1,"신규편입") -> 0.23333333 | M14: =VLOOKUP(N14,유니버스!$C$14:$D$2561,2,0) -> KQ | N14: ='RISE 비메모리반도체액티브'!B20 -> 피에스케이 | O14: =VLOOKUP(N14,'RISE 비메모리반도체액티브'!$B$11:$E$1000,4,0) -> 3.62 | P14: =IFERROR(VLOOKUP(N14,'RISE 비메모리반도체액티브(과거)'!$B$11:$E$1000,4,0),0) -> 0 | Q14: =O14-P14 -> 3.62 | R14: =IFERROR(O14/P14-1,"신규편입") -> 신규편입
A15: =VLOOKUP(B15,유니버스!$C$14:$D$2561,2,0) -> KQ | B15: ='UNICORN SK하이닉스밸류체인액티브'!B21 -> 샘씨엔에스 | C15: =VLOOKUP(B15,'UNICORN SK하이닉스밸류체인액티브'!$B$11:$E$1000,4,0) -> 2.98 | D15: =IFERROR(VLOOKUP(B15,'UNICORN SK하이닉스밸류체인액티브(과거)'!$B$11:$E$1000,4,0),0) -> 3.11 | E15: =C15-D15 -> -0.13 | F15: =IFERROR(C15/D15-1,"신규편입") -> -0.041800643 | G15: =VLOOKUP(H15,유니버스!$C$14:$D$2561,2,0) -> KQ | H15: ='WON 반도체밸류체인액티브'!B21 -> 이오테크닉스 | I15: =VLOOKUP(H15,'WON 반도체밸류체인액티브'!$B$11:$E$1000,4,0) -> 2.94 | J15: =IFERROR(VLOOKUP(H15,'WON 반도체밸류체인액티브(과거)'!$B$11:$E$1000,4,0),0) -> 3.42 | K15: =I15-J15 -> -0.48 | L15: =IFERROR(I15/J15-1,"신규편입") -> -0.14035088 | M15: =VLOOKUP(N15,유니버스!$C$14:$D$2561,2,0) -> KQ | N15: ='RISE 비메모리반도체액티브'!B21 -> 코미코 | O15: =VLOOKUP(N15,'RISE 비메모리반도체액티브'!$B$11:$E$1000,4,0) -> 3.46 | P15: =IFERROR(VLOOKUP(N15,'RISE 비메모리반도체액티브(과거)'!$B$11:$E$1000,4,0),0) -> 3.85 | Q15: =O15-P15 -> -0.39 | R15: =IFERROR(O15/P15-1,"신규편입") -> -0.1012987
A16: =VLOOKUP(B16,유니버스!$C$14:$D$2561,2,0) -> KS | B16: ='UNICORN SK하이닉스밸류체인액티브'!B22 -> 디아이 | C16: =VLOOKUP(B16,'UNICORN SK하이닉스밸류체인액티브'!$B$11:$E$1000,4,0) -> 2.56 | D16: =IFERROR(VLOOKUP(B16,'UNICORN SK하이닉스밸류체인액티브(과거)'!$B$11:$E$1000,4,0),0) -> 1.85 | E16: =C16-D16 -> 0.71 | F16: =IFERROR(C16/D16-1,"신규편입") -> 0.38378378 | G16: =VLOOKUP(H16,유니버스!$C$14:$D$2561,2,0) -> KQ | H16: ='WON 반도체밸류체인액티브'!B22 -> 테스 | I16: =VLOOKUP(H16,'WON 반도체밸류체인액티브'!$B$11:$E$1000,4,0) -> 2.86 | J16: =IFERROR(VLOOKUP(H16,'WON 반도체밸류체인액티브(과거)'!$B$11:$E$1000,4,0),0) -> 2.26 | K16: =I16-J16 -> 0.6 | L16: =IFERROR(I16/J16-1,"신규편입") -> 0.26548673 | M16: =VLOOKUP(N16,유니버스!$C$14:$D$2561,2,0) -> KQ | N16: ='RISE 비메모리반도체액티브'!B22 -> 기가비스 | O16: =VLOOKUP(N16,'RISE 비메모리반도체액티브'!$B$11:$E$1000,4,0) -> 3.41 | P16: =IFERROR(VLOOKUP(N16,'RISE 비메모리반도체액티브(과거)'!$B$11:$E$1000,4,0),0) -> 0 | Q16: =O16-P16 -> 3.41 | R16: =IFERROR(O16/P16-1,"신규편입") -> 신규편입
... A21: =VLOOKUP(B21,유니버스!$C$14:$D$2561,2,0) -> KQ | B21: ='UNICORN SK하이닉스밸류체인액티브'!B27 -> 이오테크닉스 | C21: =VLOOKUP(B21,'UNICORN SK하이닉스밸류체인액티브'!$B$11:$E$1000,4,0) -> 2.23 | D21: =IFERROR(VLOOKUP(B21,'UNICORN SK하이닉스밸류체인액티브(과거)'!$B$11:$E$1000,4,0),0) -> 2.6 | E21: =C21-D21 -> -0.37 | F21: =IFERROR(C21/D21-1,"신규편입") -> -0.14230769 | G21: =VLOOKUP(H21,유니버스!$C$14:$D$2561,2,0) -> KQ | H21: ='WON 반도체밸류체인액티브'!B27 -> 원익IPS | I21: =VLOOKUP(H21,'WON 반도체밸류체인액티브'!$B$11:$E$1000,4,0) -> 1.2 | J21: =IFERROR(VLOOKUP(H21,'WON 반도체밸류체인액티브(과거)'!$B$11:$E$1000,4,0),0) -> 1.15 | K21: =I21-J21 -> 0.05 | L21: =IFERROR(I21/J21-1,"신규편입") -> 0.043478261 | M21: =VLOOKUP(N21,유니버스!$C$14:$D$2561,2,0) -> #N/A | N21: ='RISE 비메모리반도체액티브'!B27 -> 0 | O21: =VLOOKUP(N21,'RISE 비메모리반도체액티브'!$B$11:$E$1000,4,0) -> #N/A | P21: =IFERROR(VLOOKUP(N21,'RISE 비메모리반도체액티브(과거)'!$B$11:$E$1000,4,0),0) -> 0 | Q21: =O21-P21 -> #N/A | R21: =IFERROR(O21/P21-1,"신규편입") -> 신규편입
A22: =VLOOKUP(B22,유니버스!$C$14:$D$2561,2,0) -> KQ | B22: ='UNICORN SK하이닉스밸류체인액티브'!B28 -> 테크윙 | C22: =VLOOKUP(B22,'UNICORN SK하이닉스밸류체인액티브'!$B$11:$E$1000,4,0) -> 2.05 | D22: =IFERROR(VLOOKUP(B22,'UNICORN SK하이닉스밸류체인액티브(과거)'!$B$11:$E$1000,4,0),0) -> 2.16 | E22: =C22-D22 -> -0.11 | F22: =IFERROR(C22/D22-1,"신규편입") -> -0.050925926 | G22: =VLOOKUP(H22,유니버스!$C$14:$D$2561,2,0) -> KQ | H22: ='WON 반도체밸류체인액티브'!B28 -> 코미코 | I22: =VLOOKUP(H22,'WON 반도체밸류체인액티브'!$B$11:$E$1000,4,0) -> 0.9 | J22: =IFERROR(VLOOKUP(H22,'WON 반도체밸류체인액티브(과거)'!$B$11:$E$1000,4,0),0) -> 0.81 | K22: =I22-J22 -> 0.09 | L22: =IFERROR(I22/J22-1,"신규편입") -> 0.11111111
A23: =VLOOKUP(B23,유니버스!$C$14:$D$2561,2,0) -> KQ | B23: ='UNICORN SK하이닉스밸류체인액티브'!B29 -> HPSP | C23: =VLOOKUP(B23,'UNICORN SK하이닉스밸류체인액티브'!$B$11:$E$1000,4,0) -> 1.21 | D23: =IFERROR(VLOOKUP(B23,'UNICORN SK하이닉스밸류체인액티브(과거)'!$B$11:$E$1000,4,0),0) -> 1.4 | E23: =C23-D23 -> -0.19 | F23: =IFERROR(C23/D23-1,"신규편입") -> -0.13571429 | G23: =VLOOKUP(H23,유니버스!$C$14:$D$2561,2,0) -> KS | H23: ='WON 반도체밸류체인액티브'!B29 -> 삼화콘덴서 | I23: =VLOOKUP(H23,'WON 반도체밸류체인액티브'!$B$11:$E$1000,4,0) -> 0.76 | J23: =IFERROR(VLOOKUP(H23,'WON 반도체밸류체인액티브(과거)'!$B$11:$E$1000,4,0),0) -> 0.85 | K23: =I23-J23 -> -0.09 | L23: =IFERROR(I23/J23-1,"신규편입") -> -0.10588235
A24: =VLOOKUP(B24,유니버스!$C$14:$D$2561,2,0) -> KQ | B24: ='UNICORN SK하이닉스밸류체인액티브'!B30 -> 이엔에프테크놀로지 | C24: =VLOOKUP(B24,'UNICORN SK하이닉스밸류체인액티브'!$B$11:$E$1000,4,0) -> 0.98 | D24: =IFERROR(VLOOKUP(B24,'UNICORN SK하이닉스밸류체인액티브(과거)'!$B$11:$E$1000,4,0),0) -> 0.99 | E24: =C24-D24 -> -0.01 | F24: =IFERROR(C24/D24-1,"신규편입") -> -0.01010101 | G24: =VLOOKUP(H24,유니버스!$C$14:$D$2561,2,0) -> KQ | H24: ='WON 반도체밸류체인액티브'!B30 -> 에치에프알 | I24: =VLOOKUP(H24,'WON 반도체밸류체인액티브'!$B$11:$E$1000,4,0) -> 0.49 | J24: =IFERROR(VLOOKUP(H24,'WON 반도체밸류체인액티브(과거)'!$B$11:$E$1000,4,0),0) -> 0.59 | K24: =I24-J24 -> -0.1 | L24: =IFERROR(I24/J24-1,"신규편입") -> -0.16949153
A25: =VLOOKUP(B25,유니버스!$C$14:$D$2561,2,0) -> KQ | B25: ='UNICORN SK하이닉스밸류체인액티브'!B31 -> GST | C25: =VLOOKUP(B25,'UNICORN SK하이닉스밸류체인액티브'!$B$11:$E$1000,4,0) -> 0.84 | D25: =IFERROR(VLOOKUP(B25,'UNICORN SK하이닉스밸류체인액티브(과거)'!$B$11:$E$1000,4,0),0) -> 0.86 | E25: =C25-D25 -> -0.02 | F25: =IFERROR(C25/D25-1,"신규편입") -> -0.023255814 | G25: =VLOOKUP(H25,유니버스!$C$14:$D$2561,2,0) -> KQ | H25: ='WON 반도체밸류체인액티브'!B31 -> RFHIC | I25: =VLOOKUP(H25,'WON 반도체밸류체인액티브'!$B$11:$E$1000,4,0) -> 0.4 | J25: =IFERROR(VLOOKUP(H25,'WON 반도체밸류체인액티브(과거)'!$B$11:$E$1000,4,0),0) -> 0.46 | K25: =I25-J25 -> -0.06 | L25: =IFERROR(I25/J25-1,"신규편입") -> -0.13043478
A26: =VLOOKUP(B26,유니버스!$C$14:$D$2561,2,0) -> KQ | B26: ='UNICORN SK하이닉스밸류체인액티브'!B32 -> 오로스테크놀로지 | C26: =VLOOKUP(B26,'UNICORN SK하이닉스밸류체인액티브'!$B$11:$E$1000,4,0) -> 0.69 | D26: =IFERROR(VLOOKUP(B26,'UNICORN SK하이닉스밸류체인액티브(과거)'!$B$11:$E$1000,4,0),0) -> 0.85 | E26: =C26-D26 -> -0.16 | F26: =IFERROR(C26/D26-1,"신규편입") -> -0.18823529 | G26: =VLOOKUP(H26,유니버스!$C$14:$D$2561,2,0) -> #N/A | H26: ='WON 반도체밸류체인액티브'!B32 -> 원화예금 | I26: =VLOOKUP(H26,'WON 반도체밸류체인액티브'!$B$11:$E$1000,4,0) -> 0 | J26: =IFERROR(VLOOKUP(H26,'WON 반도체밸류체인액티브(과거)'!$B$11:$E$1000,4,0),0) -> 0 | K26: =I26-J26 -> 0 | L26: =IFERROR(I26/J26-1,"신규편입") -> 신규편입
A27: =VLOOKUP(B27,유니버스!$C$14:$D$2561,2,0) -> #N/A | B27: ='UNICORN SK하이닉스밸류체인액티브'!B33 -> 원화현금 | C27: =VLOOKUP(B27,'UNICORN SK하이닉스밸류체인액티브'!$B$11:$E$1000,4,0) -> 0.52 | D27: =IFERROR(VLOOKUP(B27,'UNICORN SK하이닉스밸류체인액티브(과거)'!$B$11:$E$1000,4,0),0) -> 1.38 | E27: =C27-D27 -> -0.86 | F27: =IFERROR(C27/D27-1,"신규편입") -> -0.62318841
A28: =VLOOKUP(B28,유니버스!$C$14:$D$2561,2,0) -> #N/A | B28: ='UNICORN SK하이닉스밸류체인액티브'!B34 -> 0 | C28: =VLOOKUP(B28,'UNICORN SK하이닉스밸류체인액티브'!$B$11:$E$1000,4,0) -> #N/A | D28: =IFERROR(VLOOKUP(B28,'UNICORN SK하이닉스밸류체인액티브(과거)'!$B$11:$E$1000,4,0),0) -> 0 | E28: =C28-D28 -> #N/A | F28: =IFERROR(C28/D28-1,"신규편입") -> 신규편입

Sheet 코스닥액티브2, 배당성장
B3: ='KoAct 코스닥액티브'!A9 -> TIGER 코스닥액티브 | H3: ='KoAct 배당성장액티브'!A9 -> KoAct 배당성장액티브 | N3: ='TIMEFOLIO Korea플러스배당액티브'!A9 -> TIME Korea플러스배당액티브
B4: 종목명 | C4: ='KoAct 코스닥액티브'!B4 -> CPD [20260701] | D4: ='KoAct 코스닥액티브(과거)'!B4 -> 20260619 | E4: 비중차이 | F4: 증가율 | H4: 종목명 | I4: =C4 -> CPD [20260701] | J4: =D4 -> 20260619 | K4: 비중차 | L4: 증가율 | N4: 종목명 | O4: =C4 -> CPD [20260701] | P4: =D4 -> 20260619 | Q4: 비중차이 | R4: 증가율
A5: =VLOOKUP(B5,유니버스!$C$14:$D$2561,2,0) -> KQ | B5: ='KoAct 코스닥액티브'!B11 -> 심텍 | C5: =VLOOKUP(B5,'KoAct 코스닥액티브'!$B$11:$E$1000,4,0) -> 6.62 | D5: =IFERROR(VLOOKUP(B5,'KoAct 코스닥액티브(과거)'!$B$11:$E$1000,4,0),0) -> 3.48 | E5: =C5-D5 -> 3.14 | F5: =IFERROR(C5/D5-1,"신규편입") -> 0.90229885 | G5: =VLOOKUP(H5,유니버스!$C$14:$D$2561,2,0) -> KS | H5: ='KoAct 배당성장액티브'!B11 -> SK하이닉스 | I5: =VLOOKUP(H5,'KoAct 배당성장액티브'!$B$11:$E$1000,4,0) -> 22.68 | J5: =IFERROR(VLOOKUP(H5,'KoAct 배당성장액티브(과거)'!$B$11:$E$1000,4,0),0) -> 24.74 | K5: =I5-J5 -> -2.06 | L5: =IFERROR(I5/J5-1,"신규편입") -> -0.083265966 | M5: =VLOOKUP(N5,유니버스!$C$14:$D$2561,2,0) -> KS | N5: ='TIMEFOLIO Korea플러스배당액티브'!B11 -> SK하이닉스 | O5: =VLOOKUP(N5,'TIMEFOLIO Korea플러스배당액티브'!$B$11:$E$1000,4,0) -> 18.87 | P5: =IFERROR(VLOOKUP(N5,'TIMEFOLIO Korea플러스배당액티브(과거)'!$B$11:$E$1000,4,0),0) -> 18.83 | Q5: =O5-P5 -> 0.04 | R5: =IFERROR(O5/P5-1,"신규편입") -> 0.0021242698
A6: =VLOOKUP(B6,유니버스!$C$14:$D$2561,2,0) -> KQ | B6: ='KoAct 코스닥액티브'!B12 -> 브이엠 | C6: =VLOOKUP(B6,'KoAct 코스닥액티브'!$B$11:$E$1000,4,0) -> 6.4 | D6: =IFERROR(VLOOKUP(B6,'KoAct 코스닥액티브(과거)'!$B$11:$E$1000,4,0),0) -> 4.66 | E6: =C6-D6 -> 1.74 | F6: =IFERROR(C6/D6-1,"신규편입") -> 0.37339056 | G6: =VLOOKUP(H6,유니버스!$C$14:$D$2561,2,0) -> #N/A | H6: ='KoAct 배당성장액티브'!B12 -> 삼성전자우 | I6: =VLOOKUP(H6,'KoAct 배당성장액티브'!$B$11:$E$1000,4,0) -> 22.49 | J6: =IFERROR(VLOOKUP(H6,'KoAct 배당성장액티브(과거)'!$B$11:$E$1000,4,0),0) -> 22.65 | K6: =I6-J6 -> -0.16 | L6: =IFERROR(I6/J6-1,"신규편입") -> -0.0070640177 | M6: =VLOOKUP(N6,유니버스!$C$14:$D$2561,2,0) -> KS | N6: ='TIMEFOLIO Korea플러스배당액티브'!B12 -> 삼성전자 | O6: =VLOOKUP(N6,'TIMEFOLIO Korea플러스배당액티브'!$B$11:$E$1000,4,0) -> 13.86 | P6: =IFERROR(VLOOKUP(N6,'TIMEFOLIO Korea플러스배당액티브(과거)'!$B$11:$E$1000,4,0),0) -> 14.42 | Q6: =O6-P6 -> -0.56 | R6: =IFERROR(O6/P6-1,"신규편입") -> -0.038834951
A7: =VLOOKUP(B7,유니버스!$C$14:$D$2561,2,0) -> KQ | B7: ='KoAct 코스닥액티브'!B13 -> 엘티씨 | C7: =VLOOKUP(B7,'KoAct 코스닥액티브'!$B$11:$E$1000,4,0) -> 6.16 | D7: =IFERROR(VLOOKUP(B7,'KoAct 코스닥액티브(과거)'!$B$11:$E$1000,4,0),0) -> 6.25 | E7: =C7-D7 -> -0.09 | F7: =IFERROR(C7/D7-1,"신규편입") -> -0.0144 | G7: =VLOOKUP(H7,유니버스!$C$14:$D$2561,2,0) -> KS | H7: ='KoAct 배당성장액티브'!B13 -> HD현대중공업 | I7: =VLOOKUP(H7,'KoAct 배당성장액티브'!$B$11:$E$1000,4,0) -> 4.29 | J7: =IFERROR(VLOOKUP(H7,'KoAct 배당성장액티브(과거)'!$B$11:$E$1000,4,0),0) -> 3.91 | K7: =I7-J7 -> 0.38 | L7: =IFERROR(I7/J7-1,"신규편입") -> 0.097186701 | M7: =VLOOKUP(N7,유니버스!$C$14:$D$2561,2,0) -> KS | N7: ='TIMEFOLIO Korea플러스배당액티브'!B13 -> SK스퀘어 | O7: =VLOOKUP(N7,'TIMEFOLIO Korea플러스배당액티브'!$B$11:$E$1000,4,0) -> 5.08 | P7: =IFERROR(VLOOKUP(N7,'TIMEFOLIO Korea플러스배당액티브(과거)'!$B$11:$E$1000,4,0),0) -> 3.8 | Q7: =O7-P7 -> 1.28 | R7: =IFERROR(O7/P7-1,"신규편입") -> 0.33684211
A8: =VLOOKUP(B8,유니버스!$C$14:$D$2561,2,0) -> KQ | B8: ='KoAct 코스닥액티브'!B14 -> 제주반도체 | C8: =VLOOKUP(B8,'KoAct 코스닥액티브'!$B$11:$E$1000,4,0) -> 5.64 | D8: =IFERROR(VLOOKUP(B8,'KoAct 코스닥액티브(과거)'!$B$11:$E$1000,4,0),0) -> 5.76 | E8: =C8-D8 -> -0.12 | F8: =IFERROR(C8/D8-1,"신규편입") -> -0.020833333 | G8: =VLOOKUP(H8,유니버스!$C$14:$D$2561,2,0) -> KS | H8: ='KoAct 배당성장액티브'!B14 -> SK스퀘어 | I8: =VLOOKUP(H8,'KoAct 배당성장액티브'!$B$11:$E$1000,4,0) -> 3.58 | J8: =IFERROR(VLOOKUP(H8,'KoAct 배당성장액티브(과거)'!$B$11:$E$1000,4,0),0) -> 3.39 | K8: =I8-J8 -> 0.19 | L8: =IFERROR(I8/J8-1,"신규편입") -> 0.056047198 | M8: =VLOOKUP(N8,유니버스!$C$14:$D$2561,2,0) -> KS | N8: ='TIMEFOLIO Korea플러스배당액티브'!B14 -> 삼성전기 | O8: =VLOOKUP(N8,'TIMEFOLIO Korea플러스배당액티브'!$B$11:$E$1000,4,0) -> 4.46 | P8: =IFERROR(VLOOKUP(N8,'TIMEFOLIO Korea플러스배당액티브(과거)'!$B$11:$E$1000,4,0),0) -> 6.67 | Q8: =O8-P8 -> -2.21 | R8: =IFERROR(O8/P8-1,"신규편입") -> -0.33133433
A9: =VLOOKUP(B9,유니버스!$C$14:$D$2561,2,0) -> KQ | B9: ='KoAct 코스닥액티브'!B15 -> 테스 | C9: =VLOOKUP(B9,'KoAct 코스닥액티브'!$B$11:$E$1000,4,0) -> 5.57 | D9: =IFERROR(VLOOKUP(B9,'KoAct 코스닥액티브(과거)'!$B$11:$E$1000,4,0),0) -> 2.98 | E9: =C9-D9 -> 2.59 | F9: =IFERROR(C9/D9-1,"신규편입") -> 0.86912752 | G9: =VLOOKUP(H9,유니버스!$C$14:$D$2561,2,0) -> KS | H9: ='KoAct 배당성장액티브'!B15 -> 한국금융지주 | I9: =VLOOKUP(H9,'KoAct 배당성장액티브'!$B$11:$E$1000,4,0) -> 2.38 | J9: =IFERROR(VLOOKUP(H9,'KoAct 배당성장액티브(과거)'!$B$11:$E$1000,4,0),0) -> 2.25 | K9: =I9-J9 -> 0.13 | L9: =IFERROR(I9/J9-1,"신규편입") -> 0.057777778 | M9: =VLOOKUP(N9,유니버스!$C$14:$D$2561,2,0) -> KS | N9: ='TIMEFOLIO Korea플러스배당액티브'!B15 -> 삼양식품 | O9: =VLOOKUP(N9,'TIMEFOLIO Korea플러스배당액티브'!$B$11:$E$1000,4,0) -> 4.03 | P9: =IFERROR(VLOOKUP(N9,'TIMEFOLIO Korea플러스배당액티브(과거)'!$B$11:$E$1000,4,0),0) -> 3.68 | Q9: =O9-P9 -> 0.35 | R9: =IFERROR(O9/P9-1,"신규편입") -> 0.095108696
A10: =VLOOKUP(B10,유니버스!$C$14:$D$2561,2,0) -> KQ | B10: ='KoAct 코스닥액티브'!B16 -> 엘앤씨바이오 | C10: =VLOOKUP(B10,'KoAct 코스닥액티브'!$B$11:$E$1000,4,0) -> 4.44 | D10: =IFERROR(VLOOKUP(B10,'KoAct 코스닥액티브(과거)'!$B$11:$E$1000,4,0),0) -> 2.18 | E10: =C10-D10 -> 2.26 | F10: =IFERROR(C10/D10-1,"신규편입") -> 1.0366972 | G10: =VLOOKUP(H10,유니버스!$C$14:$D$2561,2,0) -> KS | H10: ='KoAct 배당성장액티브'!B16 -> 삼성전기 | I10: =VLOOKUP(H10,'KoAct 배당성장액티브'!$B$11:$E$1000,4,0) -> 2.25 | J10: =IFERROR(VLOOKUP(H10,'KoAct 배당성장액티브(과거)'!$B$11:$E$1000,4,0),0) -> 2.33 | K10: =I10-J10 -> -0.08 | L10: =IFERROR(I10/J10-1,"신규편입") -> -0.034334764 | M10: =VLOOKUP(N10,유니버스!$C$14:$D$2561,2,0) -> KS | N10: ='TIMEFOLIO Korea플러스배당액티브'!B16 -> 키움증권 | O10: =VLOOKUP(N10,'TIMEFOLIO Korea플러스배당액티브'!$B$11:$E$1000,4,0) -> 3.52 | P10: =IFERROR(VLOOKUP(N10,'TIMEFOLIO Korea플러스배당액티브(과거)'!$B$11:$E$1000,4,0),0) -> 2.54 | Q10: =O10-P10 -> 0.98 | R10: =IFERROR(O10/P10-1,"신규편입") -> 0.38582677
A11: =VLOOKUP(B11,유니버스!$C$14:$D$2561,2,0) -> KQ | B11: ='KoAct 코스닥액티브'!B17 -> 샘씨엔에스 | C11: =VLOOKUP(B11,'KoAct 코스닥액티브'!$B$11:$E$1000,4,0) -> 4.41 | D11: =IFERROR(VLOOKUP(B11,'KoAct 코스닥액티브(과거)'!$B$11:$E$1000,4,0),0) -> 4.44 | E11: =C11-D11 -> -0.03 | F11: =IFERROR(C11/D11-1,"신규편입") -> -0.0067567568 | G11: =VLOOKUP(H11,유니버스!$C$14:$D$2561,2,0) -> KS | H11: ='KoAct 배당성장액티브'!B17 -> KB금융 | I11: =VLOOKUP(H11,'KoAct 배당성장액티브'!$B$11:$E$1000,4,0) -> 1.95 | J11: =IFERROR(VLOOKUP(H11,'KoAct 배당성장액티브(과거)'!$B$11:$E$1000,4,0),0) -> 1.32 | K11: =I11-J11 -> 0.63 | L11: =IFERROR(I11/J11-1,"신규편입") -> 0.47727273 | M11: =VLOOKUP(N11,유니버스!$C$14:$D$2561,2,0) -> KS | N11: ='TIMEFOLIO Korea플러스배당액티브'!B17 -> 삼성물산 | O11: =VLOOKUP(N11,'TIMEFOLIO Korea플러스배당액티브'!$B$11:$E$1000,4,0) -> 3.45 | P11: =IFERROR(VLOOKUP(N11,'TIMEFOLIO Korea플러스배당액티브(과거)'!$B$11:$E$1000,4,0),0) -> 3.61 | Q11: =O11-P11 -> -0.16 | R11: =IFERROR(O11/P11-1,"신규편입") -> -0.04432133
A12: =VLOOKUP(B12,유니버스!$C$14:$D$2561,2,0) -> KQ | B12: ='KoAct 코스닥액티브'!B18 -> 디앤디파마텍 | C12: =VLOOKUP(B12,'KoAct 코스닥액티브'!$B$11:$E$1000,4,0) -> 4.2 | D12: =IFERROR(VLOOKUP(B12,'KoAct 코스닥액티브(과거)'!$B$11:$E$1000,4,0),0) -> 4.98 | E12: =C12-D12 -> -0.78 | F12: =IFERROR(C12/D12-1,"신규편입") -> -0.15662651 | G12: =VLOOKUP(H12,유니버스!$C$14:$D$2561,2,0) -> KS | H12: ='KoAct 배당성장액티브'!B18 -> 키움증권 | I12: =VLOOKUP(H12,'KoAct 배당성장액티브'!$B$11:$E$1000,4,0) -> 1.66 | J12: =IFERROR(VLOOKUP(H12,'KoAct 배당성장액티브(과거)'!$B$11:$E$1000,4,0),0) -> 1.55 | K12: =I12-J12 -> 0.11 | L12: =IFERROR(I12/J12-1,"신규편입") -> 0.070967742 | M12: =VLOOKUP(N12,유니버스!$C$14:$D$2561,2,0) -> KS | N12: ='TIMEFOLIO Korea플러스배당액티브'!B18 -> SK | O12: =VLOOKUP(N12,'TIMEFOLIO Korea플러스배당액티브'!$B$11:$E$1000,4,0) -> 3.31 | P12: =IFERROR(VLOOKUP(N12,'TIMEFOLIO Korea플러스배당액티브(과거)'!$B$11:$E$1000,4,0),0) -> 2.9 | Q12: =O12-P12 -> 0.41 | R12: =IFERROR(O12/P12-1,"신규편입") -> 0.14137931
A13: =VLOOKUP(B13,유니버스!$C$14:$D$2561,2,0) -> KQ | B13: ='KoAct 코스닥액티브'!B19 -> 알테오젠 | C13: =VLOOKUP(B13,'KoAct 코스닥액티브'!$B$11:$E$1000,4,0) -> 4.07 | D13: =IFERROR(VLOOKUP(B13,'KoAct 코스닥액티브(과거)'!$B$11:$E$1000,4,0),0) -> 4.36 | E13: =C13-D13 -> -0.29 | F13: =IFERROR(C13/D13-1,"신규편입") -> -0.066513761 | G13: =VLOOKUP(H13,유니버스!$C$14:$D$2561,2,0) -> KS | H13: ='KoAct 배당성장액티브'!B19 -> HD한국조선해양 | I13: =VLOOKUP(H13,'KoAct 배당성장액티브'!$B$11:$E$1000,4,0) -> 1.6 | J13: =IFERROR(VLOOKUP(H13,'KoAct 배당성장액티브(과거)'!$B$11:$E$1000,4,0),0) -> 1.75 | K13: =I13-J13 -> -0.15 | L13: =IFERROR(I13/J13-1,"신규편입") -> -0.085714286 | M13: =VLOOKUP(N13,유니버스!$C$14:$D$2561,2,0) -> KS | N13: ='TIMEFOLIO Korea플러스배당액티브'!B19 -> NH투자증권 | O13: =VLOOKUP(N13,'TIMEFOLIO Korea플러스배당액티브'!$B$11:$E$1000,4,0) -> 3.2 | P13: =IFERROR(VLOOKUP(N13,'TIMEFOLIO Korea플러스배당액티브(과거)'!$B$11:$E$1000,4,0),0) -> 2.99 | Q13: =O13-P13 -> 0.21 | R13: =IFERROR(O13/P13-1,"신규편입") -> 0.070234114
A14: =VLOOKUP(B14,유니버스!$C$14:$D$2561,2,0) -> KQ | B14: ='KoAct 코스닥액티브'!B20 -> 엠케이전자 | C14: =VLOOKUP(B14,'KoAct 코스닥액티브'!$B$11:$E$1000,4,0) -> 3.22 | D14: =IFERROR(VLOOKUP(B14,'KoAct 코스닥액티브(과거)'!$B$11:$E$1000,4,0),0) -> 4.83 | E14: =C14-D14 -> -1.61 | F14: =IFERROR(C14/D14-1,"신규편입") -> -0.33333333 | G14: =VLOOKUP(H14,유니버스!$C$14:$D$2561,2,0) -> KS | H14: ='KoAct 배당성장액티브'!B20 -> F&F | I14: =VLOOKUP(H14,'KoAct 배당성장액티브'!$B$11:$E$1000,4,0) -> 1.6 | J14: =IFERROR(VLOOKUP(H14,'KoAct 배당성장액티브(과거)'!$B$11:$E$1000,4,0),0) -> 1.47 | K14: =I14-J14 -> 0.13 | L14: =IFERROR(I14/J14-1,"신규편입") -> 0.088435374 | M14: =VLOOKUP(N14,유니버스!$C$14:$D$2561,2,0) -> KS | N14: ='TIMEFOLIO Korea플러스배당액티브'!B20 -> 메리츠금융지주 | O14: =VLOOKUP(N14,'TIMEFOLIO Korea플러스배당액티브'!$B$11:$E$1000,4,0) -> 3.09 | P14: =IFERROR(VLOOKUP(N14,'TIMEFOLIO Korea플러스배당액티브(과거)'!$B$11:$E$1000,4,0),0) -> 1.59 | Q14: =O14-P14 -> 1.5 | R14: =IFERROR(O14/P14-1,"신규편입") -> 0.94339623
A15: =VLOOKUP(B15,유니버스!$C$14:$D$2561,2,0) -> KQ | B15: ='KoAct 코스닥액티브'!B21 -> 피에스케이 | C15: =VLOOKUP(B15,'KoAct 코스닥액티브'!$B$11:$E$1000,4,0) -> 2.65 | D15: =IFERROR(VLOOKUP(B15,'KoAct 코스닥액티브(과거)'!$B$11:$E$1000,4,0),0) -> 2.59 | E15: =C15-D15 -> 0.06 | F15: =IFERROR(C15/D15-1,"신규편입") -> 0.023166023 | G15: =VLOOKUP(H15,유니버스!$C$14:$D$2561,2,0) -> KS | H15: ='KoAct 배당성장액티브'!B21 -> 삼성물산 | I15: =VLOOKUP(H15,'KoAct 배당성장액티브'!$B$11:$E$1000,4,0) -> 1.57 | J15: =IFERROR(VLOOKUP(H15,'KoAct 배당성장액티브(과거)'!$B$11:$E$1000,4,0),0) -> 1.19 | K15: =I15-J15 -> 0.38 | L15: =IFERROR(I15/J15-1,"신규편입") -> 0.31932773 | M15: =VLOOKUP(N15,유니버스!$C$14:$D$2561,2,0) -> KS | N15: ='TIMEFOLIO Korea플러스배당액티브'!B21 -> 한국금융지주 | O15: =VLOOKUP(N15,'TIMEFOLIO Korea플러스배당액티브'!$B$11:$E$1000,4,0) -> 2.97 | P15: =IFERROR(VLOOKUP(N15,'TIMEFOLIO Korea플러스배당액티브(과거)'!$B$11:$E$1000,4,0),0) -> 1.85 | Q15: =O15-P15 -> 1.12 | R15: =IFERROR(O15/P15-1,"신규편입") -> 0.60540541
A16: =VLOOKUP(B16,유니버스!$C$14:$D$2561,2,0) -> KQ | B16: ='KoAct 코스닥액티브'!B22 -> 리가켐바이오 | C16: =VLOOKUP(B16,'KoAct 코스닥액티브'!$B$11:$E$1000,4,0) -> 2.39 | D16: =IFERROR(VLOOKUP(B16,'KoAct 코스닥액티브(과거)'!$B$11:$E$1000,4,0),0) -> 0.9 | E16: =C16-D16 -> 1.49 | F16: =IFERROR(C16/D16-1,"신규편입") -> 1.6555556 | G16: =VLOOKUP(H16,유니버스!$C$14:$D$2561,2,0) -> KS | H16: ='KoAct 배당성장액티브'!B22 -> 더블유게임즈 | I16: =VLOOKUP(H16,'KoAct 배당성장액티브'!$B$11:$E$1000,4,0) -> 1.51 | J16: =IFERROR(VLOOKUP(H16,'KoAct 배당성장액티브(과거)'!$B$11:$E$1000,4,0),0) -> 1.41 | K16: =I16-J16 -> 0.1 | L16: =IFERROR(I16/J16-1,"신규편입") -> 0.070921986 | M16: =VLOOKUP(N16,유니버스!$C$14:$D$2561,2,0) -> KS | N16: ='TIMEFOLIO Korea플러스배당액티브'!B22 -> 삼성증권 | O16: =VLOOKUP(N16,'TIMEFOLIO Korea플러스배당액티브'!$B$11:$E$1000,4,0) -> 2.93 | P16: =IFERROR(VLOOKUP(N16,'TIMEFOLIO Korea플러스배당액티브(과거)'!$B$11:$E$1000,4,0),0) -> 3.21 | Q16: =O16-P16 -> -0.28 | R16: =IFERROR(O16/P16-1,"신규편입") -> -0.087227414
... A40: =VLOOKUP(B40,유니버스!$C$14:$D$2561,2,0) -> KQ | B40: ='KoAct 코스닥액티브'!B46 -> 에이비엘바이오 | C40: =VLOOKUP(B40,'KoAct 코스닥액티브'!$B$11:$E$1000,4,0) -> 0.92 | D40: =IFERROR(VLOOKUP(B40,'KoAct 코스닥액티브(과거)'!$B$11:$E$1000,4,0),0) -> 0.89 | E40: =C40-D40 -> 0.03 | F40: =IFERROR(C40/D40-1,"신규편입") -> 0.033707865 | G40: =VLOOKUP(H40,유니버스!$C$14:$D$2561,2,0) -> KS | H40: ='KoAct 배당성장액티브'!B46 -> SK | I40: =VLOOKUP(H40,'KoAct 배당성장액티브'!$B$11:$E$1000,4,0) -> 0.6 | J40: =IFERROR(VLOOKUP(H40,'KoAct 배당성장액티브(과거)'!$B$11:$E$1000,4,0),0) -> 0.74 | K40: =I40-J40 -> -0.14 | L40: =IFERROR(I40/J40-1,"신규편입") -> -0.18918919 | M40: =VLOOKUP(N40,유니버스!$C$14:$D$2561,2,0) -> #N/A | N40: ='TIMEFOLIO Korea플러스배당액티브'!B46 -> 원화현금 | O40: =VLOOKUP(N40,'TIMEFOLIO Korea플러스배당액티브'!$B$11:$E$1000,4,0) -> 1.89 | P40: =IFERROR(VLOOKUP(N40,'TIMEFOLIO Korea플러스배당액티브(과거)'!$B$11:$E$1000,4,0),0) -> 0.96 | Q40: =O40-P40 -> 0.93 | R40: =IFERROR(O40/P40-1,"신규편입") -> 0.96875
A41: =VLOOKUP(B41,유니버스!$C$14:$D$2561,2,0) -> KQ | B41: ='KoAct 코스닥액티브'!B47 -> 두산테스나 | C41: =VLOOKUP(B41,'KoAct 코스닥액티브'!$B$11:$E$1000,4,0) -> 0.9 | D41: =IFERROR(VLOOKUP(B41,'KoAct 코스닥액티브(과거)'!$B$11:$E$1000,4,0),0) -> 3.46 | E41: =C41-D41 -> -2.56 | F41: =IFERROR(C41/D41-1,"신규편입") -> -0.73988439 | G41: =VLOOKUP(H41,유니버스!$C$14:$D$2561,2,0) -> KS | H41: ='KoAct 배당성장액티브'!B47 -> 미스토홀딩스 | I41: =VLOOKUP(H41,'KoAct 배당성장액티브'!$B$11:$E$1000,4,0) -> 0.56 | J41: =IFERROR(VLOOKUP(H41,'KoAct 배당성장액티브(과거)'!$B$11:$E$1000,4,0),0) -> 0.29 | K41: =I41-J41 -> 0.27 | L41: =IFERROR(I41/J41-1,"신규편입") -> 0.93103448
A42: =VLOOKUP(B42,유니버스!$C$14:$D$2561,2,0) -> KQ | B42: ='KoAct 코스닥액티브'!B48 -> 다우데이타 | C42: =VLOOKUP(B42,'KoAct 코스닥액티브'!$B$11:$E$1000,4,0) -> 0.88 | D42: =IFERROR(VLOOKUP(B42,'KoAct 코스닥액티브(과거)'!$B$11:$E$1000,4,0),0) -> 1.53 | E42: =C42-D42 -> -0.65 | F42: =IFERROR(C42/D42-1,"신규편입") -> -0.4248366 | G42: =VLOOKUP(H42,유니버스!$C$14:$D$2561,2,0) -> KS | H42: ='KoAct 배당성장액티브'!B48 -> HD현대일렉트릭 | I42: =VLOOKUP(H42,'KoAct 배당성장액티브'!$B$11:$E$1000,4,0) -> 0.56 | J42: =IFERROR(VLOOKUP(H42,'KoAct 배당성장액티브(과거)'!$B$11:$E$1000,4,0),0) -> 0.55 | K42: =I42-J42 -> 0.01 | L42: =IFERROR(I42/J42-1,"신규편입") -> 0.018181818
A43: =VLOOKUP(B43,유니버스!$C$14:$D$2561,2,0) -> KQ | B43: ='KoAct 코스닥액티브'!B49 -> 에이프릴바이오 | C43: =VLOOKUP(B43,'KoAct 코스닥액티브'!$B$11:$E$1000,4,0) -> 0.75 | D43: =IFERROR(VLOOKUP(B43,'KoAct 코스닥액티브(과거)'!$B$11:$E$1000,4,0),0) -> 1.23 | E43: =C43-D43 -> -0.48 | F43: =IFERROR(C43/D43-1,"신규편입") -> -0.3902439 | G43: =VLOOKUP(H43,유니버스!$C$14:$D$2561,2,0) -> KS | H43: ='KoAct 배당성장액티브'!B49 -> 케이씨 | I43: =VLOOKUP(H43,'KoAct 배당성장액티브'!$B$11:$E$1000,4,0) -> 0.54 | J43: =IFERROR(VLOOKUP(H43,'KoAct 배당성장액티브(과거)'!$B$11:$E$1000,4,0),0) -> 0.46 | K43: =I43-J43 -> 0.08 | L43: =IFERROR(I43/J43-1,"신규편입") -> 0.17391304
A44: =VLOOKUP(B44,유니버스!$C$14:$D$2561,2,0) -> KQ | B44: ='KoAct 코스닥액티브'!B50 -> 알지노믹스 | C44: =VLOOKUP(B44,'KoAct 코스닥액티브'!$B$11:$E$1000,4,0) -> 0.7 | D44: =IFERROR(VLOOKUP(B44,'KoAct 코스닥액티브(과거)'!$B$11:$E$1000,4,0),0) -> 0.72 | E44: =C44-D44 -> -0.02 | F44: =IFERROR(C44/D44-1,"신규편입") -> -0.027777778 | G44: =VLOOKUP(H44,유니버스!$C$14:$D$2561,2,0) -> KS | H44: ='KoAct 배당성장액티브'!B50 -> 한미약품 | I44: =VLOOKUP(H44,'KoAct 배당성장액티브'!$B$11:$E$1000,4,0) -> 0.53 | J44: =IFERROR(VLOOKUP(H44,'KoAct 배당성장액티브(과거)'!$B$11:$E$1000,4,0),0) -> 0.48 | K44: =I44-J44 -> 0.05 | L44: =IFERROR(I44/J44-1,"신규편입") -> 0.10416667
A45: =VLOOKUP(B45,유니버스!$C$14:$D$2561,2,0) -> KQ | B45: ='KoAct 코스닥액티브'!B51 -> 나노 | C45: =VLOOKUP(B45,'KoAct 코스닥액티브'!$B$11:$E$1000,4,0) -> 0.68 | D45: =IFERROR(VLOOKUP(B45,'KoAct 코스닥액티브(과거)'!$B$11:$E$1000,4,0),0) -> 0.72 | E45: =C45-D45 -> -0.04 | F45: =IFERROR(C45/D45-1,"신규편입") -> -0.055555556 | G45: =VLOOKUP(H45,유니버스!$C$14:$D$2561,2,0) -> KS | H45: ='KoAct 배당성장액티브'!B51 -> GS | I45: =VLOOKUP(H45,'KoAct 배당성장액티브'!$B$11:$E$1000,4,0) -> 0.51 | J45: =IFERROR(VLOOKUP(H45,'KoAct 배당성장액티브(과거)'!$B$11:$E$1000,4,0),0) -> 0.46 | K45: =I45-J45 -> 0.05 | L45: =IFERROR(I45/J45-1,"신규편입") -> 0.10869565
A46: =VLOOKUP(B46,유니버스!$C$14:$D$2561,2,0) -> KQ | B46: ='KoAct 코스닥액티브'!B52 -> RFHIC | C46: =VLOOKUP(B46,'KoAct 코스닥액티브'!$B$11:$E$1000,4,0) -> 0.59 | D46: =IFERROR(VLOOKUP(B46,'KoAct 코스닥액티브(과거)'!$B$11:$E$1000,4,0),0) -> 0.66 | E46: =C46-D46 -> -0.07 | F46: =IFERROR(C46/D46-1,"신규편입") -> -0.10606061 | G46: =VLOOKUP(H46,유니버스!$C$14:$D$2561,2,0) -> KS | H46: ='KoAct 배당성장액티브'!B52 -> 대한항공 | I46: =VLOOKUP(H46,'KoAct 배당성장액티브'!$B$11:$E$1000,4,0) -> 0.51 | J46: =IFERROR(VLOOKUP(H46,'KoAct 배당성장액티브(과거)'!$B$11:$E$1000,4,0),0) -> 0 | K46: =I46-J46 -> 0.51 | L46: =IFERROR(I46/J46-1,"신규편입") -> 신규편입
A47: =VLOOKUP(B47,유니버스!$C$14:$D$2561,2,0) -> KQ | B47: ='KoAct 코스닥액티브'!B53 -> 성호전자 | C47: =VLOOKUP(B47,'KoAct 코스닥액티브'!$B$11:$E$1000,4,0) -> 0.52 | D47: =IFERROR(VLOOKUP(B47,'KoAct 코스닥액티브(과거)'!$B$11:$E$1000,4,0),0) -> 0.64 | E47: =C47-D47 -> -0.12 | F47: =IFERROR(C47/D47-1,"신규편입") -> -0.1875 | G47: =VLOOKUP(H47,유니버스!$C$14:$D$2561,2,0) -> KS | H47: ='KoAct 배당성장액티브'!B53 -> 두산 | I47: =VLOOKUP(H47,'KoAct 배당성장액티브'!$B$11:$E$1000,4,0) -> 0.5 | J47: =IFERROR(VLOOKUP(H47,'KoAct 배당성장액티브(과거)'!$B$11:$E$1000,4,0),0) -> 0.48 | K47: =I47-J47 -> 0.02 | L47: =IFERROR(I47/J47-1,"신규편입") -> 0.041666667
A48: =VLOOKUP(B48,유니버스!$C$14:$D$2561,2,0) -> KQ | B48: ='KoAct 코스닥액티브'!B54 -> 비나텍 | C48: =VLOOKUP(B48,'KoAct 코스닥액티브'!$B$11:$E$1000,4,0) -> 0.49 | D48: =IFERROR(VLOOKUP(B48,'KoAct 코스닥액티브(과거)'!$B$11:$E$1000,4,0),0) -> 1.36 | E48: =C48-D48 -> -0.87 | F48: =IFERROR(C48/D48-1,"신규편입") -> -0.63970588 | G48: =VLOOKUP(H48,유니버스!$C$14:$D$2561,2,0) -> KS | H48: ='KoAct 배당성장액티브'!B54 -> 현대엘리베이터 | I48: =VLOOKUP(H48,'KoAct 배당성장액티브'!$B$11:$E$1000,4,0) -> 0.48 | J48: =IFERROR(VLOOKUP(H48,'KoAct 배당성장액티브(과거)'!$B$11:$E$1000,4,0),0) -> 0.47 | K48: =I48-J48 -> 0.01 | L48: =IFERROR(I48/J48-1,"신규편입") -> 0.021276596
A49: =VLOOKUP(B49,유니버스!$C$14:$D$2561,2,0) -> KQ | B49: ='KoAct 코스닥액티브'!B55 -> 코스텍시스 | C49: =VLOOKUP(B49,'KoAct 코스닥액티브'!$B$11:$E$1000,4,0) -> 0.47 | D49: =IFERROR(VLOOKUP(B49,'KoAct 코스닥액티브(과거)'!$B$11:$E$1000,4,0),0) -> 0.53 | E49: =C49-D49 -> -0.06 | F49: =IFERROR(C49/D49-1,"신규편입") -> -0.11320755 | G49: =VLOOKUP(H49,유니버스!$C$14:$D$2561,2,0) -> KQ | H49: ='KoAct 배당성장액티브'!B55 -> 이지홀딩스 | I49: =VLOOKUP(H49,'KoAct 배당성장액티브'!$B$11:$E$1000,4,0) -> 0.46 | J49: =IFERROR(VLOOKUP(H49,'KoAct 배당성장액티브(과거)'!$B$11:$E$1000,4,0),0) -> 0.45 | K49: =I49-J49 -> 0.01 | L49: =IFERROR(I49/J49-1,"신규편입") -> 0.022222222
A50: =VLOOKUP(B50,유니버스!$C$14:$D$2561,2,0) -> KQ | B50: ='KoAct 코스닥액티브'!B56 -> 지앤비에스 에코 | C50: =VLOOKUP(B50,'KoAct 코스닥액티브'!$B$11:$E$1000,4,0) -> 0.43 | D50: =IFERROR(VLOOKUP(B50,'KoAct 코스닥액티브(과거)'!$B$11:$E$1000,4,0),0) -> 0.48 | E50: =C50-D50 -> -0.05 | F50: =IFERROR(C50/D50-1,"신규편입") -> -0.10416667 | G50: =VLOOKUP(H50,유니버스!$C$14:$D$2561,2,0) -> KS | H50: ='KoAct 배당성장액티브'!B56 -> 삼양식품 | I50: =VLOOKUP(H50,'KoAct 배당성장액티브'!$B$11:$E$1000,4,0) -> 0.46 | J50: =IFERROR(VLOOKUP(H50,'KoAct 배당성장액티브(과거)'!$B$11:$E$1000,4,0),0) -> 0.57 | K50: =I50-J50 -> -0.11 | L50: =IFERROR(I50/J50-1,"신규편입") -> -0.19298246
G51: =VLOOKUP(H51,유니버스!$C$14:$D$2561,2,0) -> KS | H51: ='KoAct 배당성장액티브'!B57 -> SK텔레콤 | I51: =VLOOKUP(H51,'KoAct 배당성장액티브'!$B$11:$E$1000,4,0) -> 0.45 | J51: =IFERROR(VLOOKUP(H51,'KoAct 배당성장액티브(과거)'!$B$11:$E$1000,4,0),0) -> 0.55 | K51: =I51-J51 -> -0.1 | L51: =IFERROR(I51/J51-1,"신규편입") -> -0.18181818
G52: =VLOOKUP(H52,유니버스!$C$14:$D$2561,2,0) -> KS | H52: ='KoAct 배당성장액티브'!B58 -> DB손해보험 | I52: =VLOOKUP(H52,'KoAct 배당성장액티브'!$B$11:$E$1000,4,0) -> 0.45 | J52: =IFERROR(VLOOKUP(H52,'KoAct 배당성장액티브(과거)'!$B$11:$E$1000,4,0),0) -> 0.45 | K52: =I52-J52 -> 0 | L52: =IFERROR(I52/J52-1,"신규편입") -> 0
G53: =VLOOKUP(H53,유니버스!$C$14:$D$2561,2,0) -> KS | H53: ='KoAct 배당성장액티브'!B59 -> 한국토지신탁 | I53: =VLOOKUP(H53,'KoAct 배당성장액티브'!$B$11:$E$1000,4,0) -> 0.42 | J53: =IFERROR(VLOOKUP(H53,'KoAct 배당성장액티브(과거)'!$B$11:$E$1000,4,0),0) -> 0.41 | K53: =I53-J53 -> 0.01 | L53: =IFERROR(I53/J53-1,"신규편입") -> 0.024390244
G54: =VLOOKUP(H54,유니버스!$C$14:$D$2561,2,0) -> KS | H54: ='KoAct 배당성장액티브'!B60 -> HL홀딩스 | I54: =VLOOKUP(H54,'KoAct 배당성장액티브'!$B$11:$E$1000,4,0) -> 0.4 | J54: =IFERROR(VLOOKUP(H54,'KoAct 배당성장액티브(과거)'!$B$11:$E$1000,4,0),0) -> 0.41 | K54: =I54-J54 -> -0.01 | L54: =IFERROR(I54/J54-1,"신규편입") -> -0.024390244
G55: =VLOOKUP(H55,유니버스!$C$14:$D$2561,2,0) -> KQ | H55: ='KoAct 배당성장액티브'!B61 -> 고영 | I55: =VLOOKUP(H55,'KoAct 배당성장액티브'!$B$11:$E$1000,4,0) -> 0.37 | J55: =IFERROR(VLOOKUP(H55,'KoAct 배당성장액티브(과거)'!$B$11:$E$1000,4,0),0) -> 0.88 | K55: =I55-J55 -> -0.51 | L55: =IFERROR(I55/J55-1,"신규편입") -> -0.57954545
G56: =VLOOKUP(H56,유니버스!$C$14:$D$2561,2,0) -> KQ | H56: ='KoAct 배당성장액티브'!B62 -> 한텍 | I56: =VLOOKUP(H56,'KoAct 배당성장액티브'!$B$11:$E$1000,4,0) -> 0.33 | J56: =IFERROR(VLOOKUP(H56,'KoAct 배당성장액티브(과거)'!$B$11:$E$1000,4,0),0) -> 0.54 | K56: =I56-J56 -> -0.21 | L56: =IFERROR(I56/J56-1,"신규편입") -> -0.38888889
G57: =VLOOKUP(H57,유니버스!$C$14:$D$2561,2,0) -> KS | H57: ='KoAct 배당성장액티브'!B63 -> LIG디펜스앤에어로스페이스 | I57: =VLOOKUP(H57,'KoAct 배당성장액티브'!$B$11:$E$1000,4,0) -> 0.3 | J57: =IFERROR(VLOOKUP(H57,'KoAct 배당성장액티브(과거)'!$B$11:$E$1000,4,0),0) -> 0.25 | K57: =I57-J57 -> 0.05 | L57: =IFERROR(I57/J57-1,"신규편입") -> 0.2
G58: =VLOOKUP(H58,유니버스!$C$14:$D$2561,2,0) -> KS | H58: ='KoAct 배당성장액티브'!B64 -> JB금융지주 | I58: =VLOOKUP(H58,'KoAct 배당성장액티브'!$B$11:$E$1000,4,0) -> 0.28 | J58: =IFERROR(VLOOKUP(H58,'KoAct 배당성장액티브(과거)'!$B$11:$E$1000,4,0),0) -> 0.28 | K58: =I58-J58 -> 0 | L58: =IFERROR(I58/J58-1,"신규편입") -> 0
G59: =VLOOKUP(H59,유니버스!$C$14:$D$2561,2,0) -> KS | H59: ='KoAct 배당성장액티브'!B65 -> 한화솔루션 | I59: =VLOOKUP(H59,'KoAct 배당성장액티브'!$B$11:$E$1000,4,0) -> 0.23 | J59: =IFERROR(VLOOKUP(H59,'KoAct 배당성장액티브(과거)'!$B$11:$E$1000,4,0),0) -> 0.23 | K59: =I59-J59 -> 0 | L59: =IFERROR(I59/J59-1,"신규편입") -> 0
G60: =VLOOKUP(H60,유니버스!$C$14:$D$2561,2,0) -> KS | H60: ='KoAct 배당성장액티브'!B66 -> 비에이치 | I60: =VLOOKUP(H60,'KoAct 배당성장액티브'!$B$11:$E$1000,4,0) -> 0.22 | J60: =IFERROR(VLOOKUP(H60,'KoAct 배당성장액티브(과거)'!$B$11:$E$1000,4,0),0) -> 1.19 | K60: =I60-J60 -> -0.97 | L60: =IFERROR(I60/J60-1,"신규편입") -> -0.81512605
G61: =VLOOKUP(H61,유니버스!$C$14:$D$2561,2,0) -> KS | H61: ='KoAct 배당성장액티브'!B67 -> 오리온홀딩스 | I61: =VLOOKUP(H61,'KoAct 배당성장액티브'!$B$11:$E$1000,4,0) -> 0.22 | J61: =IFERROR(VLOOKUP(H61,'KoAct 배당성장액티브(과거)'!$B$11:$E$1000,4,0),0) -> 0.2 | K61: =I61-J61 -> 0.02 | L61: =IFERROR(I61/J61-1,"신규편입") -> 0.1
G62: =VLOOKUP(H62,유니버스!$C$14:$D$2561,2,0) -> KS | H62: ='KoAct 배당성장액티브'!B68 -> 포스코인터내셔널 | I62: =VLOOKUP(H62,'KoAct 배당성장액티브'!$B$11:$E$1000,4,0) -> 0.19 | J62: =IFERROR(VLOOKUP(H62,'KoAct 배당성장액티브(과거)'!$B$11:$E$1000,4,0),0) -> 0.19 | K62: =I62-J62 -> 0 | L62: =IFERROR(I62/J62-1,"신규편입") -> 0
... G65: =VLOOKUP(H65,유니버스!$C$14:$D$2561,2,0) -> #N/A | H65: ='KoAct 배당성장액티브'!B71 -> 0 | I65: =VLOOKUP(H65,'KoAct 배당성장액티브'!$B$11:$E$1000,4,0) -> #N/A | J65: =IFERROR(VLOOKUP(H65,'KoAct 배당성장액티브(과거)'!$B$11:$E$1000,4,0),0) -> 0 | K65: =I65-J65 -> #N/A | L65: =IFERROR(I65/J65-1,"신규편입") -> 신규편입

Sheet 신재생, 2차전지
B3: ='KODEX 신재생에너지액티브'!A9 -> KODEX 신재생에너지액티브 | H3: ='TIMEFOLIO K신재생에너지액티브'!A9 -> TIME K신재생에너지액티브 | N3: ='RISE 2차전지액티브'!A9 -> RISE 2차전지액티브
B4: 종목명 | C4: ='KODEX 신재생에너지액티브'!B4 -> CPD [20260701] | D4: ='KODEX 신재생에너지액티브(과거)'!B4 -> 20260619 | E4: 비중차이 | F4: 증가율 | H4: 종목명 | I4: =C4 -> CPD [20260701] | J4: =D4 -> 20260619 | K4: 비중차 | L4: 증가율 | N4: 종목명 | O4: =C4 -> CPD [20260701] | P4: =D4 -> 20260619 | Q4: 비중차이 | R4: 증가율
