Workbook
Name bench2_list: [1]combo_lists!$C$1:$C$5
Name bench3_list: [1]combo_lists!$D$1:$D$2
Name benchmark_list: [1]combo_lists!$A$1:$A$2
Name Bm_Cushion: OFFSET([2]Work!$S$12,0,0,COUNT([2]Work!$S$12:$S$65536),1)
Name Bm_Floor: OFFSET([2]Work!$R$13,0,0,COUNT([2]Work!$R$13:$R$65536),1)
Name Bm_NAV: OFFSET([2]Work!$O$12,0,0,COUNT([2]Work!$O$12:$O$65536),1)
Name BM_Return: OFFSET([2]Work!$P$13,0,0,COUNT([2]Work!$P$13:$P$65536),1)
Name chart_name: '[1]Valuation Charts'!$B$29
Name chart_type: [1]lists!$A$1:$A$9
Name checklist: '[1]Valuation Charts'!$B$2:$B$28
Name chk_400: '[1]Valuation Charts'!$B$13
Name chk_400g: '[1]Valuation Charts'!$B$11
Name chk_400v: '[1]Valuation Charts'!$B$12
Name chk_500: '[1]Valuation Charts'!$B$16
Name chk_500g: '[1]Valuation Charts'!$B$14
Name chk_500v: '[1]Valuation Charts'!$B$15
Name chk_600: '[1]Valuation Charts'!$B$19
Name chk_600g: '[1]Valuation Charts'!$B$17
Name chk_600v: '[1]Valuation Charts'!$B$18
Name chk_r1000: '[1]Valuation Charts'!$B$2
Name chk_r1000g: '[1]Valuation Charts'!$B$3
Name chk_r1000v: '[1]Valuation Charts'!$B$4
Name chk_r2000: '[1]Valuation Charts'!$B$5
Name chk_r2000g: '[1]Valuation Charts'!$B$6
Name chk_r2000v: '[1]Valuation Charts'!$B$7
Name chk_rMid: '[1]Valuation Charts'!$B$8
Name chk_rMidG: '[1]Valuation Charts'!$B$9
Name chk_rMidV: '[1]Valuation Charts'!$B$10
Name CMA: #REF!
Name CMAG: #REF!
Name CMQ: #REF!
Name CMQG: #REF!
Name CNA: #REF!
Name CNQ: #REF!
Name Date: OFFSET([2]Work!$B$12,0,0,COUNT([2]Work!$B$12:$B$65536),1)
Name date_from: '[1]Valuation Charts'!$A$30
Name date_to: '[1]Valuation Charts'!$A$31
Name dates: [1]lists!$C$1:$C$92
Name full_date: [1]combo_lists!$B$3
Name Fund_Cushion: OFFSET([2]Work!$J$12,0,0,COUNT([2]Work!$J$12:$J$65536),1)
Name Fund_Floor: OFFSET([2]Work!$I$12,0,0,COUNT([2]Work!$I$12:$I$65536),1)
Name Fund_NAV: OFFSET([2]Work!$E$12,0,0,COUNT([2]Work!$E$12:$E$65536),1)
Name Fund_Return: OFFSET([2]Work!$F$13,0,0,COUNT([2]Work!$F$13:$F$65536),1)
Name GS건설_순매수대금: OFFSET([3]data!$AA$15,COUNT([3]data!$AA$15:$AA$65536)-90,0,93,1)
Name GS건설_외국인보유비중: OFFSET([3]data!$Z$15,COUNT([3]data!$Z$15:$Z$65536)-90,0,93,1)
Name index: '[1]Monthly Return Charts'!$A$1
Name index_type: '[1]Valuation Charts'!$A$28
Name indices: [1]lists!$D$1:$D$18
Name indices_list: [1]lists!$E$1:$E$2
Name Kospi_1000: OFFSET('[2]BM Data'!$O$16,0,0,COUNT('[2]BM Data'!$O$16:$O$65536),1)
Name KT_순매수대금: OFFSET([3]data!$AK$15,COUNT([3]data!$AK$15:$AK$65536)-90,0,93,1)
Name KT_외국인보유비중: OFFSET([3]data!$AJ$15,COUNT([3]data!$AJ$15:$AJ$65536)-90,0,93,1)
Name LG디스플레이_순매수대금: OFFSET([3]data!$I$15,COUNT([3]data!$I$15:$I$65536)-90,0,93,1)
Name LG디스플레이_외국인보유비중: OFFSET([3]data!$H$15,COUNT([3]data!$H$15:$H$65536)-90,0,93,1)
Name LG전자_순매수대금: OFFSET([3]data!$G$15,COUNT([3]data!$G$15:$G$65536)-90,0,93,1)
Name LG전자_외국인보유비중: OFFSET([3]data!$F$15,COUNT([3]data!$F$15:$F$65536)-90,0,93,1)
Name LG화학_순매수대금: OFFSET([3]data!$AM$15,COUNT([3]data!$AM$15:$AM$65536)-90,0,93,1)
Name LG화학_외국인보유비중: OFFSET([3]data!$AL$15,COUNT([3]data!$AL$15:$AL$65536)-90,0,93,1)
Name LS_순매수대금: OFFSET([3]data!$BE$15,COUNT([3]data!$BE$15:$BE$65536)-90,0,93,1)
Name LS_외국인보유비중: OFFSET([3]data!$BD$15,COUNT([3]data!$BD$15:$BD$65536)-90,0,93,1)

Sheet 코스닥액티브
B3: ='코엑트 코스닥액티브'!A9 -> KoAct 코스닥액티브 | H3: ='타임 코스닥액티브'!A9 -> TIME 코스닥액티브 | N3: =플러스코스닥액티브!A9 -> PLUS 코스닥150액티브
B4: 종목명 | C4: ='코엑트 코스닥액티브'!B4 -> CPD [20260522] | D4: ='코엑트 코스닥액티브(과거)'!B4 -> 20260515 | E4: 비중차이 | F4: 증가율 | H4: 종목명 | I4: =C4 -> CPD [20260522] | J4: =D4 -> 20260515 | K4: 비중차 | L4: 증가율 | N4: 종목명 | O4: =C4 -> CPD [20260522] | P4: =D4 -> 20260515 | Q4: 비중차이 | R4: 증가율
A5: =VLOOKUP(B5,유니버스!$C$14:$D$2561,2,0) -> KQ | B5: ='코엑트 코스닥액티브'!B11 -> 성호전자 | C5: =VLOOKUP(B5,'코엑트 코스닥액티브'!$B$11:$E$1000,4,0) -> 5.86 | D5: =IFERROR(VLOOKUP(B5,'코엑트 코스닥액티브(과거)'!$B$11:$E$1000,4,0),0) -> 6.15 | E5: =C5-D5 -> -0.29 | F5: =IFERROR(C5/D5-1,"신규편입") -> -0.047154472 | G5: =VLOOKUP(H5,유니버스!$C$14:$D$2561,2,0) -> KQ | H5: ='타임 코스닥액티브'!B11 -> 파두 | I5: =VLOOKUP(H5,'타임 코스닥액티브'!$B$11:$E$1000,4,0) -> 9.64 | J5: =IFERROR(VLOOKUP(H5,'타임코스닥액티브(과거)'!$B$11:$E$1000,4,0),0) -> 9.03 | K5: =I5-J5 -> 0.61 | L5: =IFERROR(I5/J5-1,"신규편입") -> 0.067552602 | M5: =VLOOKUP(N5,유니버스!$C$14:$D$2561,2,0) -> KQ | N5: =플러스코스닥액티브!B11 -> 더블유씨피 | O5: =VLOOKUP(N5,플러스코스닥액티브!$B$11:$E$1000,4,0) -> 6.1 | P5: =IFERROR(VLOOKUP(N5,'플러스코스닥액티브(과거)'!$B$11:$E$1000,4,0),0) -> 5.44 | Q5: =O5-P5 -> 0.66 | R5: =IFERROR(O5/P5-1,"신규편입") -> 0.12132353
A6: =VLOOKUP(B6,유니버스!$C$14:$D$2561,2,0) -> KQ | B6: ='코엑트 코스닥액티브'!B12 -> 테스 | C6: =VLOOKUP(B6,'코엑트 코스닥액티브'!$B$11:$E$1000,4,0) -> 5.56 | D6: =IFERROR(VLOOKUP(B6,'코엑트 코스닥액티브(과거)'!$B$11:$E$1000,4,0),0) -> 4.64 | E6: =C6-D6 -> 0.92 | F6: =IFERROR(C6/D6-1,"신규편입") -> 0.19827586 | G6: =VLOOKUP(H6,유니버스!$C$14:$D$2561,2,0) -> KQ | H6: ='타임 코스닥액티브'!B12 -> 제주반도체 | I6: =VLOOKUP(H6,'타임 코스닥액티브'!$B$11:$E$1000,4,0) -> 7.26 | J6: =IFERROR(VLOOKUP(H6,'타임코스닥액티브(과거)'!$B$11:$E$1000,4,0),0) -> 0 | K6: =I6-J6 -> 7.26 | L6: =IFERROR(I6/J6-1,"신규편입") -> 신규편입 | M6: =VLOOKUP(N6,유니버스!$C$14:$D$2561,2,0) -> KQ | N6: =플러스코스닥액티브!B12 -> 씨어스 | O6: =VLOOKUP(N6,플러스코스닥액티브!$B$11:$E$1000,4,0) -> 5.46 | P6: =IFERROR(VLOOKUP(N6,'플러스코스닥액티브(과거)'!$B$11:$E$1000,4,0),0) -> 4.86 | Q6: =O6-P6 -> 0.6 | R6: =IFERROR(O6/P6-1,"신규편입") -> 0.12345679
A7: =VLOOKUP(B7,유니버스!$C$14:$D$2561,2,0) -> KQ | B7: ='코엑트 코스닥액티브'!B13 -> 리노공업 | C7: =VLOOKUP(B7,'코엑트 코스닥액티브'!$B$11:$E$1000,4,0) -> 5 | D7: =IFERROR(VLOOKUP(B7,'코엑트 코스닥액티브(과거)'!$B$11:$E$1000,4,0),0) -> 4.82 | E7: =C7-D7 -> 0.18 | F7: =IFERROR(C7/D7-1,"신규편입") -> 0.037344398 | G7: =VLOOKUP(H7,유니버스!$C$14:$D$2561,2,0) -> KQ | H7: ='타임 코스닥액티브'!B13 -> 레인보우로보틱스 | I7: =VLOOKUP(H7,'타임 코스닥액티브'!$B$11:$E$1000,4,0) -> 3.96 | J7: =IFERROR(VLOOKUP(H7,'타임코스닥액티브(과거)'!$B$11:$E$1000,4,0),0) -> 5.95 | K7: =I7-J7 -> -1.99 | L7: =IFERROR(I7/J7-1,"신규편입") -> -0.33445378 | M7: =VLOOKUP(N7,유니버스!$C$14:$D$2561,2,0) -> KQ | N7: =플러스코스닥액티브!B13 -> 비나텍 | O7: =VLOOKUP(N7,플러스코스닥액티브!$B$11:$E$1000,4,0) -> 5.18 | P7: =IFERROR(VLOOKUP(N7,'플러스코스닥액티브(과거)'!$B$11:$E$1000,4,0),0) -> 5.05 | Q7: =O7-P7 -> 0.13 | R7: =IFERROR(O7/P7-1,"신규편입") -> 0.025742574
A8: =VLOOKUP(B8,유니버스!$C$14:$D$2561,2,0) -> KQ | B8: ='코엑트 코스닥액티브'!B14 -> 파두 | C8: =VLOOKUP(B8,'코엑트 코스닥액티브'!$B$11:$E$1000,4,0) -> 4.44 | D8: =IFERROR(VLOOKUP(B8,'코엑트 코스닥액티브(과거)'!$B$11:$E$1000,4,0),0) -> 3.78 | E8: =C8-D8 -> 0.66 | F8: =IFERROR(C8/D8-1,"신규편입") -> 0.17460317 | G8: =VLOOKUP(H8,유니버스!$C$14:$D$2561,2,0) -> KQ | H8: ='타임 코스닥액티브'!B14 -> 두산테스나 | I8: =VLOOKUP(H8,'타임 코스닥액티브'!$B$11:$E$1000,4,0) -> 3.76 | J8: =IFERROR(VLOOKUP(H8,'타임코스닥액티브(과거)'!$B$11:$E$1000,4,0),0) -> 3.25 | K8: =I8-J8 -> 0.51 | L8: =IFERROR(I8/J8-1,"신규편입") -> 0.15692308 | M8: =VLOOKUP(N8,유니버스!$C$14:$D$2561,2,0) -> KQ | N8: =플러스코스닥액티브!B14 -> 서진시스템 | O8: =VLOOKUP(N8,플러스코스닥액티브!$B$11:$E$1000,4,0) -> 4.82 | P8: =IFERROR(VLOOKUP(N8,'플러스코스닥액티브(과거)'!$B$11:$E$1000,4,0),0) -> 3.83 | Q8: =O8-P8 -> 0.99 | R8: =IFERROR(O8/P8-1,"신규편입") -> 0.25848564
A9: =VLOOKUP(B9,유니버스!$C$14:$D$2561,2,0) -> KQ | B9: ='코엑트 코스닥액티브'!B15 -> 두산테스나 | C9: =VLOOKUP(B9,'코엑트 코스닥액티브'!$B$11:$E$1000,4,0) -> 3.19 | D9: =IFERROR(VLOOKUP(B9,'코엑트 코스닥액티브(과거)'!$B$11:$E$1000,4,0),0) -> 2.93 | E9: =C9-D9 -> 0.26 | F9: =IFERROR(C9/D9-1,"신규편입") -> 0.088737201 | G9: =VLOOKUP(H9,유니버스!$C$14:$D$2561,2,0) -> KQ | H9: ='타임 코스닥액티브'!B15 -> 한선엔지니어링 | I9: =VLOOKUP(H9,'타임 코스닥액티브'!$B$11:$E$1000,4,0) -> 3.03 | J9: =IFERROR(VLOOKUP(H9,'타임코스닥액티브(과거)'!$B$11:$E$1000,4,0),0) -> 1.08 | K9: =I9-J9 -> 1.95 | L9: =IFERROR(I9/J9-1,"신규편입") -> 1.8055556 | M9: =VLOOKUP(N9,유니버스!$C$14:$D$2561,2,0) -> KQ | N9: =플러스코스닥액티브!B15 -> 두산테스나 | O9: =VLOOKUP(N9,플러스코스닥액티브!$B$11:$E$1000,4,0) -> 3.6 | P9: =IFERROR(VLOOKUP(N9,'플러스코스닥액티브(과거)'!$B$11:$E$1000,4,0),0) -> 3.69 | Q9: =O9-P9 -> -0.09 | R9: =IFERROR(O9/P9-1,"신규편입") -> -0.024390244
A10: =VLOOKUP(B10,유니버스!$C$14:$D$2561,2,0) -> KQ | B10: ='코엑트 코스닥액티브'!B16 -> 심텍 | C10: =VLOOKUP(B10,'코엑트 코스닥액티브'!$B$11:$E$1000,4,0) -> 2.95 | D10: =IFERROR(VLOOKUP(B10,'코엑트 코스닥액티브(과거)'!$B$11:$E$1000,4,0),0) -> 2.17 | E10: =C10-D10 -> 0.78 | F10: =IFERROR(C10/D10-1,"신규편입") -> 0.359447 | G10: =VLOOKUP(H10,유니버스!$C$14:$D$2561,2,0) -> KQ | H10: ='타임 코스닥액티브'!B16 -> 미래에셋벤처투자 | I10: =VLOOKUP(H10,'타임 코스닥액티브'!$B$11:$E$1000,4,0) -> 2.99 | J10: =IFERROR(VLOOKUP(H10,'타임코스닥액티브(과거)'!$B$11:$E$1000,4,0),0) -> 2.99 | K10: =I10-J10 -> 0 | L10: =IFERROR(I10/J10-1,"신규편입") -> 0 | M10: =VLOOKUP(N10,유니버스!$C$14:$D$2561,2,0) -> KQ | N10: =플러스코스닥액티브!B16 -> 스피어 | O10: =VLOOKUP(N10,플러스코스닥액티브!$B$11:$E$1000,4,0) -> 3.42 | P10: =IFERROR(VLOOKUP(N10,'플러스코스닥액티브(과거)'!$B$11:$E$1000,4,0),0) -> 3.3 | Q10: =O10-P10 -> 0.12 | R10: =IFERROR(O10/P10-1,"신규편입") -> 0.036363636
A11: =VLOOKUP(B11,유니버스!$C$14:$D$2561,2,0) -> KQ | B11: ='코엑트 코스닥액티브'!B17 -> 에이치브이엠 | C11: =VLOOKUP(B11,'코엑트 코스닥액티브'!$B$11:$E$1000,4,0) -> 2.82 | D11: =IFERROR(VLOOKUP(B11,'코엑트 코스닥액티브(과거)'!$B$11:$E$1000,4,0),0) -> 2.29 | E11: =C11-D11 -> 0.53 | F11: =IFERROR(C11/D11-1,"신규편입") -> 0.23144105 | G11: =VLOOKUP(H11,유니버스!$C$14:$D$2561,2,0) -> KQ | H11: ='타임 코스닥액티브'!B17 -> 테스 | I11: =VLOOKUP(H11,'타임 코스닥액티브'!$B$11:$E$1000,4,0) -> 2.76 | J11: =IFERROR(VLOOKUP(H11,'타임코스닥액티브(과거)'!$B$11:$E$1000,4,0),0) -> 1.78 | K11: =I11-J11 -> 0.98 | L11: =IFERROR(I11/J11-1,"신규편입") -> 0.5505618 | M11: =VLOOKUP(N11,유니버스!$C$14:$D$2561,2,0) -> KQ | N11: =플러스코스닥액티브!B17 -> 코미코 | O11: =VLOOKUP(N11,플러스코스닥액티브!$B$11:$E$1000,4,0) -> 3.23 | P11: =IFERROR(VLOOKUP(N11,'플러스코스닥액티브(과거)'!$B$11:$E$1000,4,0),0) -> 3.07 | Q11: =O11-P11 -> 0.16 | R11: =IFERROR(O11/P11-1,"신규편입") -> 0.052117264
A12: =VLOOKUP(B12,유니버스!$C$14:$D$2561,2,0) -> KQ | B12: ='코엑트 코스닥액티브'!B18 -> 티엘비 | C12: =VLOOKUP(B12,'코엑트 코스닥액티브'!$B$11:$E$1000,4,0) -> 2.8 | D12: =IFERROR(VLOOKUP(B12,'코엑트 코스닥액티브(과거)'!$B$11:$E$1000,4,0),0) -> 1.95 | E12: =C12-D12 -> 0.85 | F12: =IFERROR(C12/D12-1,"신규편입") -> 0.43589744 | G12: =VLOOKUP(H12,유니버스!$C$14:$D$2561,2,0) -> KQ | H12: ='타임 코스닥액티브'!B18 -> 서진시스템 | I12: =VLOOKUP(H12,'타임 코스닥액티브'!$B$11:$E$1000,4,0) -> 2.4 | J12: =IFERROR(VLOOKUP(H12,'타임코스닥액티브(과거)'!$B$11:$E$1000,4,0),0) -> 1.26 | K12: =I12-J12 -> 1.14 | L12: =IFERROR(I12/J12-1,"신규편입") -> 0.9047619 | M12: =VLOOKUP(N12,유니버스!$C$14:$D$2561,2,0) -> KQ | N12: =플러스코스닥액티브!B18 -> 에프앤가이드 | O12: =VLOOKUP(N12,플러스코스닥액티브!$B$11:$E$1000,4,0) -> 3.2 | P12: =IFERROR(VLOOKUP(N12,'플러스코스닥액티브(과거)'!$B$11:$E$1000,4,0),0) -> 3.22 | Q12: =O12-P12 -> -0.02 | R12: =IFERROR(O12/P12-1,"신규편입") -> -0.0062111801
A13: =VLOOKUP(B13,유니버스!$C$14:$D$2561,2,0) -> KQ | B13: ='코엑트 코스닥액티브'!B19 -> 서진시스템 | C13: =VLOOKUP(B13,'코엑트 코스닥액티브'!$B$11:$E$1000,4,0) -> 2.51 | D13: =IFERROR(VLOOKUP(B13,'코엑트 코스닥액티브(과거)'!$B$11:$E$1000,4,0),0) -> 2.23 | E13: =C13-D13 -> 0.28 | F13: =IFERROR(C13/D13-1,"신규편입") -> 0.12556054 | G13: =VLOOKUP(H13,유니버스!$C$14:$D$2561,2,0) -> KQ | H13: ='타임 코스닥액티브'!B19 -> 티엘비 | I13: =VLOOKUP(H13,'타임 코스닥액티브'!$B$11:$E$1000,4,0) -> 2.34 | J13: =IFERROR(VLOOKUP(H13,'타임코스닥액티브(과거)'!$B$11:$E$1000,4,0),0) -> 2.28 | K13: =I13-J13 -> 0.06 | L13: =IFERROR(I13/J13-1,"신규편입") -> 0.026315789 | M13: =VLOOKUP(N13,유니버스!$C$14:$D$2561,2,0) -> KQ | N13: =플러스코스닥액티브!B19 -> 새로닉스 | O13: =VLOOKUP(N13,플러스코스닥액티브!$B$11:$E$1000,4,0) -> 3 | P13: =IFERROR(VLOOKUP(N13,'플러스코스닥액티브(과거)'!$B$11:$E$1000,4,0),0) -> 2.91 | Q13: =O13-P13 -> 0.09 | R13: =IFERROR(O13/P13-1,"신규편입") -> 0.030927835
A14: =VLOOKUP(B14,유니버스!$C$14:$D$2561,2,0) -> KQ | B14: ='코엑트 코스닥액티브'!B20 -> 주성엔지니어링 | C14: =VLOOKUP(B14,'코엑트 코스닥액티브'!$B$11:$E$1000,4,0) -> 2.45 | D14: =IFERROR(VLOOKUP(B14,'코엑트 코스닥액티브(과거)'!$B$11:$E$1000,4,0),0) -> 2.13 | E14: =C14-D14 -> 0.32 | F14: =IFERROR(C14/D14-1,"신규편입") -> 0.15023474 | G14: =VLOOKUP(H14,유니버스!$C$14:$D$2561,2,0) -> KQ | H14: ='타임 코스닥액티브'!B20 -> 기가비스 | I14: =VLOOKUP(H14,'타임 코스닥액티브'!$B$11:$E$1000,4,0) -> 2.31 | J14: =IFERROR(VLOOKUP(H14,'타임코스닥액티브(과거)'!$B$11:$E$1000,4,0),0) -> 2.26 | K14: =I14-J14 -> 0.05 | L14: =IFERROR(I14/J14-1,"신규편입") -> 0.022123894 | M14: =VLOOKUP(N14,유니버스!$C$14:$D$2561,2,0) -> KQ | N14: =플러스코스닥액티브!B20 -> 씨에스베어링 | O14: =VLOOKUP(N14,플러스코스닥액티브!$B$11:$E$1000,4,0) -> 2.93 | P14: =IFERROR(VLOOKUP(N14,'플러스코스닥액티브(과거)'!$B$11:$E$1000,4,0),0) -> 2.82 | Q14: =O14-P14 -> 0.11 | R14: =IFERROR(O14/P14-1,"신규편입") -> 0.039007092
A15: =VLOOKUP(B15,유니버스!$C$14:$D$2561,2,0) -> KQ | B15: ='코엑트 코스닥액티브'!B21 -> 에이비엘바이오 | C15: =VLOOKUP(B15,'코엑트 코스닥액티브'!$B$11:$E$1000,4,0) -> 2.34 | D15: =IFERROR(VLOOKUP(B15,'코엑트 코스닥액티브(과거)'!$B$11:$E$1000,4,0),0) -> 2.52 | E15: =C15-D15 -> -0.18 | F15: =IFERROR(C15/D15-1,"신규편입") -> -0.071428571 | G15: =VLOOKUP(H15,유니버스!$C$14:$D$2561,2,0) -> KQ | H15: ='타임 코스닥액티브'!B21 -> 대주전자재료 | I15: =VLOOKUP(H15,'타임 코스닥액티브'!$B$11:$E$1000,4,0) -> 2.27 | J15: =IFERROR(VLOOKUP(H15,'타임코스닥액티브(과거)'!$B$11:$E$1000,4,0),0) -> 1.38 | K15: =I15-J15 -> 0.89 | L15: =IFERROR(I15/J15-1,"신규편입") -> 0.64492754 | M15: =VLOOKUP(N15,유니버스!$C$14:$D$2561,2,0) -> KQ | N15: =플러스코스닥액티브!B21 -> 한중엔시에스 | O15: =VLOOKUP(N15,플러스코스닥액티브!$B$11:$E$1000,4,0) -> 2.93 | P15: =IFERROR(VLOOKUP(N15,'플러스코스닥액티브(과거)'!$B$11:$E$1000,4,0),0) -> 3.09 | Q15: =O15-P15 -> -0.16 | R15: =IFERROR(O15/P15-1,"신규편입") -> -0.051779935
A16: =VLOOKUP(B16,유니버스!$C$14:$D$2561,2,0) -> KQ | B16: ='코엑트 코스닥액티브'!B22 -> 알테오젠 | C16: =VLOOKUP(B16,'코엑트 코스닥액티브'!$B$11:$E$1000,4,0) -> 2.27 | D16: =IFERROR(VLOOKUP(B16,'코엑트 코스닥액티브(과거)'!$B$11:$E$1000,4,0),0) -> 2.19 | E16: =C16-D16 -> 0.08 | F16: =IFERROR(C16/D16-1,"신규편입") -> 0.03652968 | G16: =VLOOKUP(H16,유니버스!$C$14:$D$2561,2,0) -> KQ | H16: ='타임 코스닥액티브'!B22 -> 주성엔지니어링 | I16: =VLOOKUP(H16,'타임 코스닥액티브'!$B$11:$E$1000,4,0) -> 2.22 | J16: =IFERROR(VLOOKUP(H16,'타임코스닥액티브(과거)'!$B$11:$E$1000,4,0),0) -> 5.1 | K16: =I16-J16 -> -2.88 | L16: =IFERROR(I16/J16-1,"신규편입") -> -0.56470588 | M16: =VLOOKUP(N16,유니버스!$C$14:$D$2561,2,0) -> KQ | N16: =플러스코스닥액티브!B22 -> 피에스케이홀딩스 | O16: =VLOOKUP(N16,플러스코스닥액티브!$B$11:$E$1000,4,0) -> 2.74 | P16: =IFERROR(VLOOKUP(N16,'플러스코스닥액티브(과거)'!$B$11:$E$1000,4,0),0) -> 2.8 | Q16: =O16-P16 -> -0.06 | R16: =IFERROR(O16/P16-1,"신규편입") -> -0.021428571
... A70: =VLOOKUP(B70,유니버스!$C$14:$D$2561,2,0) -> KQ | B70: ='코엑트 코스닥액티브'!B76 -> 오이솔루션 | C70: =VLOOKUP(B70,'코엑트 코스닥액티브'!$B$11:$E$1000,4,0) -> 0.34 | D70: =IFERROR(VLOOKUP(B70,'코엑트 코스닥액티브(과거)'!$B$11:$E$1000,4,0),0) -> 0.36 | E70: =C70-D70 -> -0.02 | F70: =IFERROR(C70/D70-1,"신규편입") -> -0.055555556 | G70: =VLOOKUP(H70,유니버스!$C$14:$D$2561,2,0) -> #N/A | H70: ='타임 코스닥액티브'!B76 -> 원화현금 | I70: =VLOOKUP(H70,'타임 코스닥액티브'!$B$11:$E$1000,4,0) -> 0.91 | J70: =IFERROR(VLOOKUP(H70,'타임코스닥액티브(과거)'!$B$11:$E$1000,4,0),0) -> 1.19 | K70: =I70-J70 -> -0.28 | L70: =IFERROR(I70/J70-1,"신규편입") -> -0.23529412 | M70: =VLOOKUP(N70,유니버스!$C$14:$D$2561,2,0) -> KQ | N70: =플러스코스닥액티브!B76 -> HPSP | O70: =VLOOKUP(N70,플러스코스닥액티브!$B$11:$E$1000,4,0) -> 0.1 | P70: =IFERROR(VLOOKUP(N70,'플러스코스닥액티브(과거)'!$B$11:$E$1000,4,0),0) -> 0 | Q70: =O70-P70 -> 0.1 | R70: =IFERROR(O70/P70-1,"신규편입") -> 신규편입
A71: =VLOOKUP(B71,유니버스!$C$14:$D$2561,2,0) -> KQ | B71: ='코엑트 코스닥액티브'!B77 -> LS머트리얼즈 | C71: =VLOOKUP(B71,'코엑트 코스닥액티브'!$B$11:$E$1000,4,0) -> 0.33 | D71: =IFERROR(VLOOKUP(B71,'코엑트 코스닥액티브(과거)'!$B$11:$E$1000,4,0),0) -> 0.33 | E71: =C71-D71 -> 0 | F71: =IFERROR(C71/D71-1,"신규편입") -> 0 | M71: =VLOOKUP(N71,유니버스!$C$14:$D$2561,2,0) -> KQ | N71: =플러스코스닥액티브!B77 -> 에스티팜 | O71: =VLOOKUP(N71,플러스코스닥액티브!$B$11:$E$1000,4,0) -> 0.09 | P71: =IFERROR(VLOOKUP(N71,'플러스코스닥액티브(과거)'!$B$11:$E$1000,4,0),0) -> 0.1 | Q71: =O71-P71 -> -0.01 | R71: =IFERROR(O71/P71-1,"신규편입") -> -0.1
A72: =VLOOKUP(B72,유니버스!$C$14:$D$2561,2,0) -> KQ | B72: ='코엑트 코스닥액티브'!B78 -> 씨어스 | C72: =VLOOKUP(B72,'코엑트 코스닥액티브'!$B$11:$E$1000,4,0) -> 0.32 | D72: =IFERROR(VLOOKUP(B72,'코엑트 코스닥액티브(과거)'!$B$11:$E$1000,4,0),0) -> 0.34 | E72: =C72-D72 -> -0.02 | F72: =IFERROR(C72/D72-1,"신규편입") -> -0.058823529 | M72: =VLOOKUP(N72,유니버스!$C$14:$D$2561,2,0) -> #N/A | N72: =플러스코스닥액티브!B78 -> 채비 | O72: =VLOOKUP(N72,플러스코스닥액티브!$B$11:$E$1000,4,0) -> 0.09 | P72: =IFERROR(VLOOKUP(N72,'플러스코스닥액티브(과거)'!$B$11:$E$1000,4,0),0) -> 0.1 | Q72: =O72-P72 -> -0.01 | R72: =IFERROR(O72/P72-1,"신규편입") -> -0.1
A73: =VLOOKUP(B73,유니버스!$C$14:$D$2561,2,0) -> KQ | B73: ='코엑트 코스닥액티브'!B79 -> 레이크머티리얼즈 | C73: =VLOOKUP(B73,'코엑트 코스닥액티브'!$B$11:$E$1000,4,0) -> 0.31 | D73: =IFERROR(VLOOKUP(B73,'코엑트 코스닥액티브(과거)'!$B$11:$E$1000,4,0),0) -> 0.32 | E73: =C73-D73 -> -0.01 | F73: =IFERROR(C73/D73-1,"신규편입") -> -0.03125 | M73: =VLOOKUP(N73,유니버스!$C$14:$D$2561,2,0) -> KQ | N73: =플러스코스닥액티브!B79 -> 큐리언트 | O73: =VLOOKUP(N73,플러스코스닥액티브!$B$11:$E$1000,4,0) -> 0.08 | P73: =IFERROR(VLOOKUP(N73,'플러스코스닥액티브(과거)'!$B$11:$E$1000,4,0),0) -> 0.08 | Q73: =O73-P73 -> 0 | R73: =IFERROR(O73/P73-1,"신규편입") -> 0
A74: =VLOOKUP(B74,유니버스!$C$14:$D$2561,2,0) -> KQ | B74: ='코엑트 코스닥액티브'!B80 -> 삼현 | C74: =VLOOKUP(B74,'코엑트 코스닥액티브'!$B$11:$E$1000,4,0) -> 0.3 | D74: =IFERROR(VLOOKUP(B74,'코엑트 코스닥액티브(과거)'!$B$11:$E$1000,4,0),0) -> 0.29 | E74: =C74-D74 -> 0.01 | F74: =IFERROR(C74/D74-1,"신규편입") -> 0.034482759 | M74: =VLOOKUP(N74,유니버스!$C$14:$D$2561,2,0) -> #N/A | N74: =플러스코스닥액티브!B80 -> 원화현금 | O74: =VLOOKUP(N74,플러스코스닥액티브!$B$11:$E$1000,4,0) -> 0.79 | P74: =IFERROR(VLOOKUP(N74,'플러스코스닥액티브(과거)'!$B$11:$E$1000,4,0),0) -> 1.41 | Q74: =O74-P74 -> -0.62 | R74: =IFERROR(O74/P74-1,"신규편입") -> -0.43971631
A75: =VLOOKUP(B75,유니버스!$C$14:$D$2561,2,0) -> KQ | B75: ='코엑트 코스닥액티브'!B81 -> 에치에프알 | C75: =VLOOKUP(B75,'코엑트 코스닥액티브'!$B$11:$E$1000,4,0) -> 0.26 | D75: =IFERROR(VLOOKUP(B75,'코엑트 코스닥액티브(과거)'!$B$11:$E$1000,4,0),0) -> 0.37 | E75: =C75-D75 -> -0.11 | F75: =IFERROR(C75/D75-1,"신규편입") -> -0.2972973
A76: =VLOOKUP(B76,유니버스!$C$14:$D$2561,2,0) -> KQ | B76: ='코엑트 코스닥액티브'!B82 -> 에스엔시스 | C76: =VLOOKUP(B76,'코엑트 코스닥액티브'!$B$11:$E$1000,4,0) -> 0.25 | D76: =IFERROR(VLOOKUP(B76,'코엑트 코스닥액티브(과거)'!$B$11:$E$1000,4,0),0) -> 0.29 | E76: =C76-D76 -> -0.04 | F76: =IFERROR(C76/D76-1,"신규편입") -> -0.13793103
A77: =VLOOKUP(B77,유니버스!$C$14:$D$2561,2,0) -> KQ | B77: ='코엑트 코스닥액티브'!B83 -> 아모그린텍 | C77: =VLOOKUP(B77,'코엑트 코스닥액티브'!$B$11:$E$1000,4,0) -> 0.25 | D77: =IFERROR(VLOOKUP(B77,'코엑트 코스닥액티브(과거)'!$B$11:$E$1000,4,0),0) -> 0.28 | E77: =C77-D77 -> -0.03 | F77: =IFERROR(C77/D77-1,"신규편입") -> -0.10714286
A78: =VLOOKUP(B78,유니버스!$C$14:$D$2561,2,0) -> KQ | B78: ='코엑트 코스닥액티브'!B84 -> 쎄트렉아이 | C78: =VLOOKUP(B78,'코엑트 코스닥액티브'!$B$11:$E$1000,4,0) -> 0.21 | D78: =IFERROR(VLOOKUP(B78,'코엑트 코스닥액티브(과거)'!$B$11:$E$1000,4,0),0) -> 0.23 | E78: =C78-D78 -> -0.02 | F78: =IFERROR(C78/D78-1,"신규편입") -> -0.086956522
A79: =VLOOKUP(B79,유니버스!$C$14:$D$2561,2,0) -> KQ | B79: ='코엑트 코스닥액티브'!B85 -> 브이엠 | C79: =VLOOKUP(B79,'코엑트 코스닥액티브'!$B$11:$E$1000,4,0) -> 0.21 | D79: =IFERROR(VLOOKUP(B79,'코엑트 코스닥액티브(과거)'!$B$11:$E$1000,4,0),0) -> 0.39 | E79: =C79-D79 -> -0.18 | F79: =IFERROR(C79/D79-1,"신규편입") -> -0.46153846
A80: =VLOOKUP(B80,유니버스!$C$14:$D$2561,2,0) -> KQ | B80: ='코엑트 코스닥액티브'!B86 -> 이지홀딩스 | C80: =VLOOKUP(B80,'코엑트 코스닥액티브'!$B$11:$E$1000,4,0) -> 0.2 | D80: =IFERROR(VLOOKUP(B80,'코엑트 코스닥액티브(과거)'!$B$11:$E$1000,4,0),0) -> 0.24 | E80: =C80-D80 -> -0.04 | F80: =IFERROR(C80/D80-1,"신규편입") -> -0.16666667
A81: =VLOOKUP(B81,유니버스!$C$14:$D$2561,2,0) -> KQ | B81: ='코엑트 코스닥액티브'!B87 -> 한라캐스트 | C81: =VLOOKUP(B81,'코엑트 코스닥액티브'!$B$11:$E$1000,4,0) -> 0.19 | D81: =IFERROR(VLOOKUP(B81,'코엑트 코스닥액티브(과거)'!$B$11:$E$1000,4,0),0) -> 0.2 | E81: =C81-D81 -> -0.01 | F81: =IFERROR(C81/D81-1,"신규편입") -> -0.05
A82: =VLOOKUP(B82,유니버스!$C$14:$D$2561,2,0) -> KQ | B82: ='코엑트 코스닥액티브'!B88 -> 제이브이엠 | C82: =VLOOKUP(B82,'코엑트 코스닥액티브'!$B$11:$E$1000,4,0) -> 0.19 | D82: =IFERROR(VLOOKUP(B82,'코엑트 코스닥액티브(과거)'!$B$11:$E$1000,4,0),0) -> 0.24 | E82: =C82-D82 -> -0.05 | F82: =IFERROR(C82/D82-1,"신규편입") -> -0.20833333
A83: =VLOOKUP(B83,유니버스!$C$14:$D$2561,2,0) -> KQ | B83: ='코엑트 코스닥액티브'!B89 -> 코오롱생명과학 | C83: =VLOOKUP(B83,'코엑트 코스닥액티브'!$B$11:$E$1000,4,0) -> 0.19 | D83: =IFERROR(VLOOKUP(B83,'코엑트 코스닥액티브(과거)'!$B$11:$E$1000,4,0),0) -> 0.19 | E83: =C83-D83 -> 0 | F83: =IFERROR(C83/D83-1,"신규편입") -> 0
A84: =VLOOKUP(B84,유니버스!$C$14:$D$2561,2,0) -> KQ | B84: ='코엑트 코스닥액티브'!B90 -> 바디텍메드 | C84: =VLOOKUP(B84,'코엑트 코스닥액티브'!$B$11:$E$1000,4,0) -> 0.18 | D84: =IFERROR(VLOOKUP(B84,'코엑트 코스닥액티브(과거)'!$B$11:$E$1000,4,0),0) -> 0.23 | E84: =C84-D84 -> -0.05 | F84: =IFERROR(C84/D84-1,"신규편입") -> -0.2173913
A85: =VLOOKUP(B85,유니버스!$C$14:$D$2561,2,0) -> KQ | B85: ='코엑트 코스닥액티브'!B91 -> 아이티센글로벌 | C85: =VLOOKUP(B85,'코엑트 코스닥액티브'!$B$11:$E$1000,4,0) -> 0.12 | D85: =IFERROR(VLOOKUP(B85,'코엑트 코스닥액티브(과거)'!$B$11:$E$1000,4,0),0) -> 0.92 | E85: =C85-D85 -> -0.8 | F85: =IFERROR(C85/D85-1,"신규편입") -> -0.86956522
A86: =VLOOKUP(B86,유니버스!$C$14:$D$2561,2,0) -> KQ | B86: ='코엑트 코스닥액티브'!B92 -> 와이지엔터테인먼트 | C86: =VLOOKUP(B86,'코엑트 코스닥액티브'!$B$11:$E$1000,4,0) -> 0.09 | D86: =IFERROR(VLOOKUP(B86,'코엑트 코스닥액티브(과거)'!$B$11:$E$1000,4,0),0) -> 0.1 | E86: =C86-D86 -> -0.01 | F86: =IFERROR(C86/D86-1,"신규편입") -> -0.1
A87: =VLOOKUP(B87,유니버스!$C$14:$D$2561,2,0) -> #N/A | B87: ='코엑트 코스닥액티브'!B93 -> 원화현금 | C87: =VLOOKUP(B87,'코엑트 코스닥액티브'!$B$11:$E$1000,4,0) -> 0.17 | D87: =IFERROR(VLOOKUP(B87,'코엑트 코스닥액티브(과거)'!$B$11:$E$1000,4,0),0) -> 0 | E87: =C87-D87 -> 0.17 | F87: =IFERROR(C87/D87-1,"신규편입") -> 신규편입

Sheet 반도체
B3: ='UNICORN SK하이닉스밸류체인액티브'!A9 -> UNICORN SK하이닉스밸류체인액티브 | H3: ='WON 반도체밸류체인액티브'!A9 -> WON 반도체밸류체인액티브 | N3: ='RISE 비메모리반도체액티브'!A9 -> RISE 비메모리반도체액티브
B4: 종목명 | C4: ='UNICORN SK하이닉스밸류체인액티브'!B4 -> CPD [20260522] | D4: ='UNICORN SK하이닉스밸류체인액티브(과거)'!B4 -> 20260515 | E4: 비중차이 | F4: 증가율 | H4: 종목명 | I4: =C4 -> CPD [20260522] | J4: =D4 -> 20260515 | K4: 비중차 | L4: 증가율 | N4: 종목명 | O4: =C4 -> CPD [20260522] | P4: =D4 -> 20260515 | Q4: 비중차이 | R4: 증가율
A5: =VLOOKUP(B5,유니버스!$C$14:$D$2561,2,0) -> KS | B5: ='UNICORN SK하이닉스밸류체인액티브'!B11 -> SK스퀘어 | C5: =VLOOKUP(B5,'UNICORN SK하이닉스밸류체인액티브'!$B$11:$E$1000,4,0) -> 24.4 | D5: =IFERROR(VLOOKUP(B5,'UNICORN SK하이닉스밸류체인액티브(과거)'!$B$11:$E$1000,4,0),0) -> 24.31 | E5: =C5-D5 -> 0.09 | F5: =IFERROR(C5/D5-1,"신규편입") -> 0.0037021802 | G5: =VLOOKUP(H5,유니버스!$C$14:$D$2561,2,0) -> KS | H5: ='WON 반도체밸류체인액티브'!B11 -> SK하이닉스 | I5: =VLOOKUP(H5,'WON 반도체밸류체인액티브'!$B$11:$E$1000,4,0) -> 28.88 | J5: =IFERROR(VLOOKUP(H5,'WON 반도체밸류체인액티브(과거)'!$B$11:$E$1000,4,0),0) -> 29.34 | K5: =I5-J5 -> -0.46 | L5: =IFERROR(I5/J5-1,"신규편입") -> -0.015678255 | M5: =VLOOKUP(N5,유니버스!$C$14:$D$2561,2,0) -> KS | N5: ='RISE 비메모리반도체액티브'!B11 -> 삼성전자 | O5: =VLOOKUP(N5,'RISE 비메모리반도체액티브'!$B$11:$E$1000,4,0) -> 23.97 | P5: =IFERROR(VLOOKUP(N5,'RISE 비메모리반도체액티브(과거)'!$B$11:$E$1000,4,0),0) -> 23.23 | Q5: =O5-P5 -> 0.74 | R5: =IFERROR(O5/P5-1,"신규편입") -> 0.031855359
A6: =VLOOKUP(B6,유니버스!$C$14:$D$2561,2,0) -> KS | B6: ='UNICORN SK하이닉스밸류체인액티브'!B12 -> SK하이닉스 | C6: =VLOOKUP(B6,'UNICORN SK하이닉스밸류체인액티브'!$B$11:$E$1000,4,0) -> 24.16 | D6: =IFERROR(VLOOKUP(B6,'UNICORN SK하이닉스밸류체인액티브(과거)'!$B$11:$E$1000,4,0),0) -> 24.24 | E6: =C6-D6 -> -0.08 | F6: =IFERROR(C6/D6-1,"신규편입") -> -0.00330033 | G6: =VLOOKUP(H6,유니버스!$C$14:$D$2561,2,0) -> KS | H6: ='WON 반도체밸류체인액티브'!B12 -> 삼성전자 | I6: =VLOOKUP(H6,'WON 반도체밸류체인액티브'!$B$11:$E$1000,4,0) -> 24.34 | J6: =IFERROR(VLOOKUP(H6,'WON 반도체밸류체인액티브(과거)'!$B$11:$E$1000,4,0),0) -> 23.83 | K6: =I6-J6 -> 0.51 | L6: =IFERROR(I6/J6-1,"신규편입") -> 0.021401595 | M6: =VLOOKUP(N6,유니버스!$C$14:$D$2561,2,0) -> KS | N6: ='RISE 비메모리반도체액티브'!B12 -> SK하이닉스 | O6: =VLOOKUP(N6,'RISE 비메모리반도체액티브'!$B$11:$E$1000,4,0) -> 19.1 | P6: =IFERROR(VLOOKUP(N6,'RISE 비메모리반도체액티브(과거)'!$B$11:$E$1000,4,0),0) -> 19.21 | Q6: =O6-P6 -> -0.11 | R6: =IFERROR(O6/P6-1,"신규편입") -> -0.0057261843
A7: =VLOOKUP(B7,유니버스!$C$14:$D$2561,2,0) -> KQ | B7: ='UNICORN SK하이닉스밸류체인액티브'!B13 -> 티씨케이 | C7: =VLOOKUP(B7,'UNICORN SK하이닉스밸류체인액티브'!$B$11:$E$1000,4,0) -> 4.35 | D7: =IFERROR(VLOOKUP(B7,'UNICORN SK하이닉스밸류체인액티브(과거)'!$B$11:$E$1000,4,0),0) -> 4.7 | E7: =C7-D7 -> -0.35 | F7: =IFERROR(C7/D7-1,"신규편입") -> -0.074468085 | G7: =VLOOKUP(H7,유니버스!$C$14:$D$2561,2,0) -> KS | H7: ='WON 반도체밸류체인액티브'!B13 -> 삼성전기 | I7: =VLOOKUP(H7,'WON 반도체밸류체인액티브'!$B$11:$E$1000,4,0) -> 5.51 | J7: =IFERROR(VLOOKUP(H7,'WON 반도체밸류체인액티브(과거)'!$B$11:$E$1000,4,0),0) -> 5.01 | K7: =I7-J7 -> 0.5 | L7: =IFERROR(I7/J7-1,"신규편입") -> 0.099800399 | M7: =VLOOKUP(N7,유니버스!$C$14:$D$2561,2,0) -> KS | N7: ='RISE 비메모리반도체액티브'!B13 -> SK스퀘어 | O7: =VLOOKUP(N7,'RISE 비메모리반도체액티브'!$B$11:$E$1000,4,0) -> 7.06 | P7: =IFERROR(VLOOKUP(N7,'RISE 비메모리반도체액티브(과거)'!$B$11:$E$1000,4,0),0) -> 7.06 | Q7: =O7-P7 -> 0 | R7: =IFERROR(O7/P7-1,"신규편입") -> 0
A8: =VLOOKUP(B8,유니버스!$C$14:$D$2561,2,0) -> KQ | B8: ='UNICORN SK하이닉스밸류체인액티브'!B14 -> 피에스케이홀딩스 | C8: =VLOOKUP(B8,'UNICORN SK하이닉스밸류체인액티브'!$B$11:$E$1000,4,0) -> 4.33 | D8: =IFERROR(VLOOKUP(B8,'UNICORN SK하이닉스밸류체인액티브(과거)'!$B$11:$E$1000,4,0),0) -> 4.32 | E8: =C8-D8 -> 0.01 | F8: =IFERROR(C8/D8-1,"신규편입") -> 0.0023148148 | G8: =VLOOKUP(H8,유니버스!$C$14:$D$2561,2,0) -> KS | H8: ='WON 반도체밸류체인액티브'!B14 -> SK스퀘어 | I8: =VLOOKUP(H8,'WON 반도체밸류체인액티브'!$B$11:$E$1000,4,0) -> 5.4 | J8: =IFERROR(VLOOKUP(H8,'WON 반도체밸류체인액티브(과거)'!$B$11:$E$1000,4,0),0) -> 5.45 | K8: =I8-J8 -> -0.05 | L8: =IFERROR(I8/J8-1,"신규편입") -> -0.0091743119 | M8: =VLOOKUP(N8,유니버스!$C$14:$D$2561,2,0) -> KS | N8: ='RISE 비메모리반도체액티브'!B14 -> DB하이텍 | O8: =VLOOKUP(N8,'RISE 비메모리반도체액티브'!$B$11:$E$1000,4,0) -> 6.56 | P8: =IFERROR(VLOOKUP(N8,'RISE 비메모리반도체액티브(과거)'!$B$11:$E$1000,4,0),0) -> 6.36 | Q8: =O8-P8 -> 0.2 | R8: =IFERROR(O8/P8-1,"신규편입") -> 0.031446541
A9: =VLOOKUP(B9,유니버스!$C$14:$D$2561,2,0) -> KQ | B9: ='UNICORN SK하이닉스밸류체인액티브'!B15 -> 피에스케이 | C9: =VLOOKUP(B9,'UNICORN SK하이닉스밸류체인액티브'!$B$11:$E$1000,4,0) -> 4 | D9: =IFERROR(VLOOKUP(B9,'UNICORN SK하이닉스밸류체인액티브(과거)'!$B$11:$E$1000,4,0),0) -> 3.95 | E9: =C9-D9 -> 0.05 | F9: =IFERROR(C9/D9-1,"신규편입") -> 0.012658228 | G9: =VLOOKUP(H9,유니버스!$C$14:$D$2561,2,0) -> KQ | H9: ='WON 반도체밸류체인액티브'!B15 -> 기가비스 | I9: =VLOOKUP(H9,'WON 반도체밸류체인액티브'!$B$11:$E$1000,4,0) -> 4.48 | J9: =IFERROR(VLOOKUP(H9,'WON 반도체밸류체인액티브(과거)'!$B$11:$E$1000,4,0),0) -> 4.63 | K9: =I9-J9 -> -0.15 | L9: =IFERROR(I9/J9-1,"신규편입") -> -0.032397408 | M9: =VLOOKUP(N9,유니버스!$C$14:$D$2561,2,0) -> KQ | N9: ='RISE 비메모리반도체액티브'!B15 -> 심텍 | O9: =VLOOKUP(N9,'RISE 비메모리반도체액티브'!$B$11:$E$1000,4,0) -> 5.69 | P9: =IFERROR(VLOOKUP(N9,'RISE 비메모리반도체액티브(과거)'!$B$11:$E$1000,4,0),0) -> 4.88 | Q9: =O9-P9 -> 0.81 | R9: =IFERROR(O9/P9-1,"신규편입") -> 0.16598361
A10: =VLOOKUP(B10,유니버스!$C$14:$D$2561,2,0) -> KQ | B10: ='UNICORN SK하이닉스밸류체인액티브'!B16 -> 브이엠 | C10: =VLOOKUP(B10,'UNICORN SK하이닉스밸류체인액티브'!$B$11:$E$1000,4,0) -> 3.87 | D10: =IFERROR(VLOOKUP(B10,'UNICORN SK하이닉스밸류체인액티브(과거)'!$B$11:$E$1000,4,0),0) -> 3.74 | E10: =C10-D10 -> 0.13 | F10: =IFERROR(C10/D10-1,"신규편입") -> 0.034759358 | G10: =VLOOKUP(H10,유니버스!$C$14:$D$2561,2,0) -> KQ | H10: ='WON 반도체밸류체인액티브'!B16 -> 이오테크닉스 | I10: =VLOOKUP(H10,'WON 반도체밸류체인액티브'!$B$11:$E$1000,4,0) -> 3.92 | J10: =IFERROR(VLOOKUP(H10,'WON 반도체밸류체인액티브(과거)'!$B$11:$E$1000,4,0),0) -> 3.42 | K10: =I10-J10 -> 0.5 | L10: =IFERROR(I10/J10-1,"신규편입") -> 0.14619883 | M10: =VLOOKUP(N10,유니버스!$C$14:$D$2561,2,0) -> KS | N10: ='RISE 비메모리반도체액티브'!B16 -> 대덕전자 | O10: =VLOOKUP(N10,'RISE 비메모리반도체액티브'!$B$11:$E$1000,4,0) -> 5.64 | P10: =IFERROR(VLOOKUP(N10,'RISE 비메모리반도체액티브(과거)'!$B$11:$E$1000,4,0),0) -> 5.61 | Q10: =O10-P10 -> 0.03 | R10: =IFERROR(O10/P10-1,"신규편입") -> 0.0053475936
A11: =VLOOKUP(B11,유니버스!$C$14:$D$2561,2,0) -> KQ | B11: ='UNICORN SK하이닉스밸류체인액티브'!B17 -> 덕산하이메탈 | C11: =VLOOKUP(B11,'UNICORN SK하이닉스밸류체인액티브'!$B$11:$E$1000,4,0) -> 3.82 | D11: =IFERROR(VLOOKUP(B11,'UNICORN SK하이닉스밸류체인액티브(과거)'!$B$11:$E$1000,4,0),0) -> 4.26 | E11: =C11-D11 -> -0.44 | F11: =IFERROR(C11/D11-1,"신규편입") -> -0.10328638 | G11: =VLOOKUP(H11,유니버스!$C$14:$D$2561,2,0) -> KQ | H11: ='WON 반도체밸류체인액티브'!B17 -> 피에스케이홀딩스 | I11: =VLOOKUP(H11,'WON 반도체밸류체인액티브'!$B$11:$E$1000,4,0) -> 3.78 | J11: =IFERROR(VLOOKUP(H11,'WON 반도체밸류체인액티브(과거)'!$B$11:$E$1000,4,0),0) -> 3.83 | K11: =I11-J11 -> -0.05 | L11: =IFERROR(I11/J11-1,"신규편입") -> -0.01305483 | M11: =VLOOKUP(N11,유니버스!$C$14:$D$2561,2,0) -> KS | N11: ='RISE 비메모리반도체액티브'!B17 -> 삼성전기 | O11: =VLOOKUP(N11,'RISE 비메모리반도체액티브'!$B$11:$E$1000,4,0) -> 5.32 | P11: =IFERROR(VLOOKUP(N11,'RISE 비메모리반도체액티브(과거)'!$B$11:$E$1000,4,0),0) -> 4.79 | Q11: =O11-P11 -> 0.53 | R11: =IFERROR(O11/P11-1,"신규편입") -> 0.11064718
A12: =VLOOKUP(B12,유니버스!$C$14:$D$2561,2,0) -> KS | B12: ='UNICORN SK하이닉스밸류체인액티브'!B18 -> 두산 | C12: =VLOOKUP(B12,'UNICORN SK하이닉스밸류체인액티브'!$B$11:$E$1000,4,0) -> 3.77 | D12: =IFERROR(VLOOKUP(B12,'UNICORN SK하이닉스밸류체인액티브(과거)'!$B$11:$E$1000,4,0),0) -> 4.07 | E12: =C12-D12 -> -0.3 | F12: =IFERROR(C12/D12-1,"신규편입") -> -0.073710074 | G12: =VLOOKUP(H12,유니버스!$C$14:$D$2561,2,0) -> KQ | H12: ='WON 반도체밸류체인액티브'!B18 -> 티에스이 | I12: =VLOOKUP(H12,'WON 반도체밸류체인액티브'!$B$11:$E$1000,4,0) -> 2.97 | J12: =IFERROR(VLOOKUP(H12,'WON 반도체밸류체인액티브(과거)'!$B$11:$E$1000,4,0),0) -> 2.58 | K12: =I12-J12 -> 0.39 | L12: =IFERROR(I12/J12-1,"신규편입") -> 0.15116279 | M12: =VLOOKUP(N12,유니버스!$C$14:$D$2561,2,0) -> KS | N12: ='RISE 비메모리반도체액티브'!B18 -> 이수페타시스 | O12: =VLOOKUP(N12,'RISE 비메모리반도체액티브'!$B$11:$E$1000,4,0) -> 4.76 | P12: =IFERROR(VLOOKUP(N12,'RISE 비메모리반도체액티브(과거)'!$B$11:$E$1000,4,0),0) -> 5.11 | Q12: =O12-P12 -> -0.35 | R12: =IFERROR(O12/P12-1,"신규편입") -> -0.068493151
A13: =VLOOKUP(B13,유니버스!$C$14:$D$2561,2,0) -> KQ | B13: ='UNICORN SK하이닉스밸류체인액티브'!B19 -> 이오테크닉스 | C13: =VLOOKUP(B13,'UNICORN SK하이닉스밸류체인액티브'!$B$11:$E$1000,4,0) -> 3.54 | D13: =IFERROR(VLOOKUP(B13,'UNICORN SK하이닉스밸류체인액티브(과거)'!$B$11:$E$1000,4,0),0) -> 3.05 | E13: =C13-D13 -> 0.49 | F13: =IFERROR(C13/D13-1,"신규편입") -> 0.16065574 | G13: =VLOOKUP(H13,유니버스!$C$14:$D$2561,2,0) -> KQ | H13: ='WON 반도체밸류체인액티브'!B19 -> 피에스케이 | I13: =VLOOKUP(H13,'WON 반도체밸류체인액티브'!$B$11:$E$1000,4,0) -> 2.88 | J13: =IFERROR(VLOOKUP(H13,'WON 반도체밸류체인액티브(과거)'!$B$11:$E$1000,4,0),0) -> 2.89 | K13: =I13-J13 -> -0.01 | L13: =IFERROR(I13/J13-1,"신규편입") -> -0.0034602076 | M13: =VLOOKUP(N13,유니버스!$C$14:$D$2561,2,0) -> KQ | N13: ='RISE 비메모리반도체액티브'!B19 -> 두산테스나 | O13: =VLOOKUP(N13,'RISE 비메모리반도체액티브'!$B$11:$E$1000,4,0) -> 4.04 | P13: =IFERROR(VLOOKUP(N13,'RISE 비메모리반도체액티브(과거)'!$B$11:$E$1000,4,0),0) -> 4.52 | Q13: =O13-P13 -> -0.48 | R13: =IFERROR(O13/P13-1,"신규편입") -> -0.10619469
A14: =VLOOKUP(B14,유니버스!$C$14:$D$2561,2,0) -> KQ | B14: ='UNICORN SK하이닉스밸류체인액티브'!B20 -> 샘씨엔에스 | C14: =VLOOKUP(B14,'UNICORN SK하이닉스밸류체인액티브'!$B$11:$E$1000,4,0) -> 3.51 | D14: =IFERROR(VLOOKUP(B14,'UNICORN SK하이닉스밸류체인액티브(과거)'!$B$11:$E$1000,4,0),0) -> 3.37 | E14: =C14-D14 -> 0.14 | F14: =IFERROR(C14/D14-1,"신규편입") -> 0.041543027 | G14: =VLOOKUP(H14,유니버스!$C$14:$D$2561,2,0) -> KQ | H14: ='WON 반도체밸류체인액티브'!B20 -> 브이엠 | I14: =VLOOKUP(H14,'WON 반도체밸류체인액티브'!$B$11:$E$1000,4,0) -> 2.85 | J14: =IFERROR(VLOOKUP(H14,'WON 반도체밸류체인액티브(과거)'!$B$11:$E$1000,4,0),0) -> 2.79 | K14: =I14-J14 -> 0.06 | L14: =IFERROR(I14/J14-1,"신규편입") -> 0.021505376 | M14: =VLOOKUP(N14,유니버스!$C$14:$D$2561,2,0) -> KQ | N14: ='RISE 비메모리반도체액티브'!B20 -> 리노공업 | O14: =VLOOKUP(N14,'RISE 비메모리반도체액티브'!$B$11:$E$1000,4,0) -> 3.83 | P14: =IFERROR(VLOOKUP(N14,'RISE 비메모리반도체액티브(과거)'!$B$11:$E$1000,4,0),0) -> 3.99 | Q14: =O14-P14 -> -0.16 | R14: =IFERROR(O14/P14-1,"신규편입") -> -0.040100251
A15: =VLOOKUP(B15,유니버스!$C$14:$D$2561,2,0) -> KQ | B15: ='UNICORN SK하이닉스밸류체인액티브'!B21 -> 오킨스전자 | C15: =VLOOKUP(B15,'UNICORN SK하이닉스밸류체인액티브'!$B$11:$E$1000,4,0) -> 3.42 | D15: =IFERROR(VLOOKUP(B15,'UNICORN SK하이닉스밸류체인액티브(과거)'!$B$11:$E$1000,4,0),0) -> 3.48 | E15: =C15-D15 -> -0.06 | F15: =IFERROR(C15/D15-1,"신규편입") -> -0.017241379 | G15: =VLOOKUP(H15,유니버스!$C$14:$D$2561,2,0) -> KS | H15: ='WON 반도체밸류체인액티브'!B21 -> 대덕전자 | I15: =VLOOKUP(H15,'WON 반도체밸류체인액티브'!$B$11:$E$1000,4,0) -> 2.05 | J15: =IFERROR(VLOOKUP(H15,'WON 반도체밸류체인액티브(과거)'!$B$11:$E$1000,4,0),0) -> 2.06 | K15: =I15-J15 -> -0.01 | L15: =IFERROR(I15/J15-1,"신규편입") -> -0.0048543689 | M15: =VLOOKUP(N15,유니버스!$C$14:$D$2561,2,0) -> KQ | N15: ='RISE 비메모리반도체액티브'!B21 -> 테스 | O15: =VLOOKUP(N15,'RISE 비메모리반도체액티브'!$B$11:$E$1000,4,0) -> 3.8 | P15: =IFERROR(VLOOKUP(N15,'RISE 비메모리반도체액티브(과거)'!$B$11:$E$1000,4,0),0) -> 4.01 | Q15: =O15-P15 -> -0.21 | R15: =IFERROR(O15/P15-1,"신규편입") -> -0.052369077
A16: =VLOOKUP(B16,유니버스!$C$14:$D$2561,2,0) -> KQ | B16: ='UNICORN SK하이닉스밸류체인액티브'!B22 -> 심텍 | C16: =VLOOKUP(B16,'UNICORN SK하이닉스밸류체인액티브'!$B$11:$E$1000,4,0) -> 3.37 | D16: =IFERROR(VLOOKUP(B16,'UNICORN SK하이닉스밸류체인액티브(과거)'!$B$11:$E$1000,4,0),0) -> 2.89 | E16: =C16-D16 -> 0.48 | F16: =IFERROR(C16/D16-1,"신규편입") -> 0.16608997 | G16: =VLOOKUP(H16,유니버스!$C$14:$D$2561,2,0) -> KQ | H16: ='WON 반도체밸류체인액티브'!B22 -> RFHIC | I16: =VLOOKUP(H16,'WON 반도체밸류체인액티브'!$B$11:$E$1000,4,0) -> 1.95 | J16: =IFERROR(VLOOKUP(H16,'WON 반도체밸류체인액티브(과거)'!$B$11:$E$1000,4,0),0) -> 2.07 | K16: =I16-J16 -> -0.12 | L16: =IFERROR(I16/J16-1,"신규편입") -> -0.057971014 | M16: =VLOOKUP(N16,유니버스!$C$14:$D$2561,2,0) -> KS | N16: ='RISE 비메모리반도체액티브'!B22 -> 한솔테크닉스 | O16: =VLOOKUP(N16,'RISE 비메모리반도체액티브'!$B$11:$E$1000,4,0) -> 3.27 | P16: =IFERROR(VLOOKUP(N16,'RISE 비메모리반도체액티브(과거)'!$B$11:$E$1000,4,0),0) -> 3.15 | Q16: =O16-P16 -> 0.12 | R16: =IFERROR(O16/P16-1,"신규편입") -> 0.038095238
... A22: =VLOOKUP(B22,유니버스!$C$14:$D$2561,2,0) -> KQ | B22: ='UNICORN SK하이닉스밸류체인액티브'!B28 -> GST | C22: =VLOOKUP(B22,'UNICORN SK하이닉스밸류체인액티브'!$B$11:$E$1000,4,0) -> 1.12 | D22: =IFERROR(VLOOKUP(B22,'UNICORN SK하이닉스밸류체인액티브(과거)'!$B$11:$E$1000,4,0),0) -> 1.23 | E22: =C22-D22 -> -0.11 | F22: =IFERROR(C22/D22-1,"신규편입") -> -0.089430894 | G22: =VLOOKUP(H22,유니버스!$C$14:$D$2561,2,0) -> KQ | H22: ='WON 반도체밸류체인액티브'!B28 -> 샘씨엔에스 | I22: =VLOOKUP(H22,'WON 반도체밸류체인액티브'!$B$11:$E$1000,4,0) -> 1.01 | J22: =IFERROR(VLOOKUP(H22,'WON 반도체밸류체인액티브(과거)'!$B$11:$E$1000,4,0),0) -> 0.98 | K22: =I22-J22 -> 0.03 | L22: =IFERROR(I22/J22-1,"신규편입") -> 0.030612245 | M22: =VLOOKUP(N22,유니버스!$C$14:$D$2561,2,0) -> #N/A | N22: ='RISE 비메모리반도체액티브'!B28 -> 원화현금 | O22: =VLOOKUP(N22,'RISE 비메모리반도체액티브'!$B$11:$E$1000,4,0) -> 0 | P22: =IFERROR(VLOOKUP(N22,'RISE 비메모리반도체액티브(과거)'!$B$11:$E$1000,4,0),0) -> 0 | Q22: =O22-P22 -> 0 | R22: =IFERROR(O22/P22-1,"신규편입") -> 신규편입
A23: =VLOOKUP(B23,유니버스!$C$14:$D$2561,2,0) -> KQ | B23: ='UNICORN SK하이닉스밸류체인액티브'!B29 -> 오로스테크놀로지 | C23: =VLOOKUP(B23,'UNICORN SK하이닉스밸류체인액티브'!$B$11:$E$1000,4,0) -> 0.77 | D23: =IFERROR(VLOOKUP(B23,'UNICORN SK하이닉스밸류체인액티브(과거)'!$B$11:$E$1000,4,0),0) -> 0.79 | E23: =C23-D23 -> -0.02 | F23: =IFERROR(C23/D23-1,"신규편입") -> -0.025316456 | G23: =VLOOKUP(H23,유니버스!$C$14:$D$2561,2,0) -> KQ | H23: ='WON 반도체밸류체인액티브'!B29 -> 인텍플러스 | I23: =VLOOKUP(H23,'WON 반도체밸류체인액티브'!$B$11:$E$1000,4,0) -> 0.76 | J23: =IFERROR(VLOOKUP(H23,'WON 반도체밸류체인액티브(과거)'!$B$11:$E$1000,4,0),0) -> 0.78 | K23: =I23-J23 -> -0.02 | L23: =IFERROR(I23/J23-1,"신규편입") -> -0.025641026
A24: =VLOOKUP(B24,유니버스!$C$14:$D$2561,2,0) -> KQ | B24: ='UNICORN SK하이닉스밸류체인액티브'!B30 -> HPSP | C24: =VLOOKUP(B24,'UNICORN SK하이닉스밸류체인액티브'!$B$11:$E$1000,4,0) -> 0.54 | D24: =IFERROR(VLOOKUP(B24,'UNICORN SK하이닉스밸류체인액티브(과거)'!$B$11:$E$1000,4,0),0) -> 0.53 | E24: =C24-D24 -> 0.01 | F24: =IFERROR(C24/D24-1,"신규편입") -> 0.018867925 | G24: =VLOOKUP(H24,유니버스!$C$14:$D$2561,2,0) -> KQ | H24: ='WON 반도체밸류체인액티브'!B30 -> 덕산테코피아 | I24: =VLOOKUP(H24,'WON 반도체밸류체인액티브'!$B$11:$E$1000,4,0) -> 0.74 | J24: =IFERROR(VLOOKUP(H24,'WON 반도체밸류체인액티브(과거)'!$B$11:$E$1000,4,0),0) -> 0.92 | K24: =I24-J24 -> -0.18 | L24: =IFERROR(I24/J24-1,"신규편입") -> -0.19565217
A25: =VLOOKUP(B25,유니버스!$C$14:$D$2561,2,0) -> KQ | B25: ='UNICORN SK하이닉스밸류체인액티브'!B31 -> 이엔에프테크놀로지 | C25: =VLOOKUP(B25,'UNICORN SK하이닉스밸류체인액티브'!$B$11:$E$1000,4,0) -> 0.12 | D25: =IFERROR(VLOOKUP(B25,'UNICORN SK하이닉스밸류체인액티브(과거)'!$B$11:$E$1000,4,0),0) -> 0.12 | E25: =C25-D25 -> 0 | F25: =IFERROR(C25/D25-1,"신규편입") -> 0 | G25: =VLOOKUP(H25,유니버스!$C$14:$D$2561,2,0) -> KQ | H25: ='WON 반도체밸류체인액티브'!B31 -> 에이디테크놀로지 | I25: =VLOOKUP(H25,'WON 반도체밸류체인액티브'!$B$11:$E$1000,4,0) -> 0.6 | J25: =IFERROR(VLOOKUP(H25,'WON 반도체밸류체인액티브(과거)'!$B$11:$E$1000,4,0),0) -> 0.66 | K25: =I25-J25 -> -0.06 | L25: =IFERROR(I25/J25-1,"신규편입") -> -0.090909091
A26: =VLOOKUP(B26,유니버스!$C$14:$D$2561,2,0) -> #N/A | B26: ='UNICORN SK하이닉스밸류체인액티브'!B32 -> 원화현금 | C26: =VLOOKUP(B26,'UNICORN SK하이닉스밸류체인액티브'!$B$11:$E$1000,4,0) -> 0.86 | D26: =IFERROR(VLOOKUP(B26,'UNICORN SK하이닉스밸류체인액티브(과거)'!$B$11:$E$1000,4,0),0) -> 0.93 | E26: =C26-D26 -> -0.07 | F26: =IFERROR(C26/D26-1,"신규편입") -> -0.075268817 | G26: =VLOOKUP(H26,유니버스!$C$14:$D$2561,2,0) -> KQ | H26: ='WON 반도체밸류체인액티브'!B32 -> 에치에프알 | I26: =VLOOKUP(H26,'WON 반도체밸류체인액티브'!$B$11:$E$1000,4,0) -> 0.56 | J26: =IFERROR(VLOOKUP(H26,'WON 반도체밸류체인액티브(과거)'!$B$11:$E$1000,4,0),0) -> 0.63 | K26: =I26-J26 -> -0.07 | L26: =IFERROR(I26/J26-1,"신규편입") -> -0.11111111
G27: =VLOOKUP(H27,유니버스!$C$14:$D$2561,2,0) -> #N/A | H27: ='WON 반도체밸류체인액티브'!B33 -> 원화예금 | I27: =VLOOKUP(H27,'WON 반도체밸류체인액티브'!$B$11:$E$1000,4,0) -> 0 | J27: =IFERROR(VLOOKUP(H27,'WON 반도체밸류체인액티브(과거)'!$B$11:$E$1000,4,0),0) -> 0 | K27: =I27-J27 -> 0 | L27: =IFERROR(I27/J27-1,"신규편입") -> 신규편입

Sheet 수급, 배당성장
B3: ='SOL 코리아메가테크액티브'!A9 -> SOL 코리아메가테크액티브 | H3: ='KoAct 배당성장액티브'!A9 -> KoAct 배당성장액티브 | N3: ='TIMEFOLIO Korea플러스배당액티브'!A9 -> TIME Korea플러스배당액티브
B4: 종목명 | C4: ='SOL 코리아메가테크액티브'!B4 -> CPD [20260522] | D4: ='SOL 코리아메가테크액티브(과거)'!B4 -> 20260515 | E4: 비중차이 | F4: 증가율 | H4: 종목명 | I4: =C4 -> CPD [20260522] | J4: =D4 -> 20260515 | K4: 비중차 | L4: 증가율 | N4: 종목명 | O4: =C4 -> CPD [20260522] | P4: =D4 -> 20260515 | Q4: 비중차이 | R4: 증가율
A5: =VLOOKUP(B5,유니버스!$C$14:$D$2561,2,0) -> KS | B5: ='SOL 코리아메가테크액티브'!B11 -> 삼성전자 | C5: =VLOOKUP(B5,'SOL 코리아메가테크액티브'!$B$11:$E$1000,4,0) -> 17.02 | D5: =IFERROR(VLOOKUP(B5,'SOL 코리아메가테크액티브(과거)'!$B$11:$E$1000,4,0),0) -> 15.76 | E5: =C5-D5 -> 1.26 | F5: =IFERROR(C5/D5-1,"신규편입") -> 0.079949239 | G5: =VLOOKUP(H5,유니버스!$C$14:$D$2561,2,0) -> #N/A | H5: ='KoAct 배당성장액티브'!B11 -> 삼성전자우 | I5: =VLOOKUP(H5,'KoAct 배당성장액티브'!$B$11:$E$1000,4,0) -> 23.19 | J5: =IFERROR(VLOOKUP(H5,'KoAct 배당성장액티브(과거)'!$B$11:$E$1000,4,0),0) -> 23.11 | K5: =I5-J5 -> 0.08 | L5: =IFERROR(I5/J5-1,"신규편입") -> 0.0034617049 | M5: =VLOOKUP(N5,유니버스!$C$14:$D$2561,2,0) -> KS | N5: ='TIMEFOLIO Korea플러스배당액티브'!B11 -> SK하이닉스 | O5: =VLOOKUP(N5,'TIMEFOLIO Korea플러스배당액티브'!$B$11:$E$1000,4,0) -> 28.71 | P5: =IFERROR(VLOOKUP(N5,'TIMEFOLIO Korea플러스배당액티브(과거)'!$B$11:$E$1000,4,0),0) -> 27.59 | Q5: =O5-P5 -> 1.12 | R5: =IFERROR(O5/P5-1,"신규편입") -> 0.040594418
A6: =VLOOKUP(B6,유니버스!$C$14:$D$2561,2,0) -> KS | B6: ='SOL 코리아메가테크액티브'!B12 -> SK하이닉스 | C6: =VLOOKUP(B6,'SOL 코리아메가테크액티브'!$B$11:$E$1000,4,0) -> 16.48 | D6: =IFERROR(VLOOKUP(B6,'SOL 코리아메가테크액티브(과거)'!$B$11:$E$1000,4,0),0) -> 15.85 | E6: =C6-D6 -> 0.63 | F6: =IFERROR(C6/D6-1,"신규편입") -> 0.039747634 | G6: =VLOOKUP(H6,유니버스!$C$14:$D$2561,2,0) -> KS | H6: ='KoAct 배당성장액티브'!B12 -> SK하이닉스 | I6: =VLOOKUP(H6,'KoAct 배당성장액티브'!$B$11:$E$1000,4,0) -> 22.33 | J6: =IFERROR(VLOOKUP(H6,'KoAct 배당성장액티브(과거)'!$B$11:$E$1000,4,0),0) -> 21.41 | K6: =I6-J6 -> 0.92 | L6: =IFERROR(I6/J6-1,"신규편입") -> 0.042970574 | M6: =VLOOKUP(N6,유니버스!$C$14:$D$2561,2,0) -> KS | N6: ='TIMEFOLIO Korea플러스배당액티브'!B12 -> 삼성전자 | O6: =VLOOKUP(N6,'TIMEFOLIO Korea플러스배당액티브'!$B$11:$E$1000,4,0) -> 11.64 | P6: =IFERROR(VLOOKUP(N6,'TIMEFOLIO Korea플러스배당액티브(과거)'!$B$11:$E$1000,4,0),0) -> 10.77 | Q6: =O6-P6 -> 0.87 | R6: =IFERROR(O6/P6-1,"신규편입") -> 0.080779944
A7: =VLOOKUP(B7,유니버스!$C$14:$D$2561,2,0) -> KS | B7: ='SOL 코리아메가테크액티브'!B13 -> 현대차 | C7: =VLOOKUP(B7,'SOL 코리아메가테크액티브'!$B$11:$E$1000,4,0) -> 7.63 | D7: =IFERROR(VLOOKUP(B7,'SOL 코리아메가테크액티브(과거)'!$B$11:$E$1000,4,0),0) -> 8.22 | E7: =C7-D7 -> -0.59 | F7: =IFERROR(C7/D7-1,"신규편입") -> -0.071776156 | G7: =VLOOKUP(H7,유니버스!$C$14:$D$2561,2,0) -> KS | H7: ='KoAct 배당성장액티브'!B13 -> HD현대중공업 | I7: =VLOOKUP(H7,'KoAct 배당성장액티브'!$B$11:$E$1000,4,0) -> 3.17 | J7: =IFERROR(VLOOKUP(H7,'KoAct 배당성장액티브(과거)'!$B$11:$E$1000,4,0),0) -> 3.09 | K7: =I7-J7 -> 0.08 | L7: =IFERROR(I7/J7-1,"신규편입") -> 0.025889968 | M7: =VLOOKUP(N7,유니버스!$C$14:$D$2561,2,0) -> KS | N7: ='TIMEFOLIO Korea플러스배당액티브'!B13 -> 현대차 | O7: =VLOOKUP(N7,'TIMEFOLIO Korea플러스배당액티브'!$B$11:$E$1000,4,0) -> 6.16 | P7: =IFERROR(VLOOKUP(N7,'TIMEFOLIO Korea플러스배당액티브(과거)'!$B$11:$E$1000,4,0),0) -> 6.64 | Q7: =O7-P7 -> -0.48 | R7: =IFERROR(O7/P7-1,"신규편입") -> -0.072289157
A8: =VLOOKUP(B8,유니버스!$C$14:$D$2561,2,0) -> KS | B8: ='SOL 코리아메가테크액티브'!B14 -> SK스퀘어 | C8: =VLOOKUP(B8,'SOL 코리아메가테크액티브'!$B$11:$E$1000,4,0) -> 5.19 | D8: =IFERROR(VLOOKUP(B8,'SOL 코리아메가테크액티브(과거)'!$B$11:$E$1000,4,0),0) -> 4.96 | E8: =C8-D8 -> 0.23 | F8: =IFERROR(C8/D8-1,"신규편입") -> 0.046370968 | G8: =VLOOKUP(H8,유니버스!$C$14:$D$2561,2,0) -> KS | H8: ='KoAct 배당성장액티브'!B14 -> HD한국조선해양 | I8: =VLOOKUP(H8,'KoAct 배당성장액티브'!$B$11:$E$1000,4,0) -> 1.96 | J8: =IFERROR(VLOOKUP(H8,'KoAct 배당성장액티브(과거)'!$B$11:$E$1000,4,0),0) -> 2.01 | K8: =I8-J8 -> -0.05 | L8: =IFERROR(I8/J8-1,"신규편입") -> -0.024875622 | M8: =VLOOKUP(N8,유니버스!$C$14:$D$2561,2,0) -> KS | N8: ='TIMEFOLIO Korea플러스배당액티브'!B14 -> LS | O8: =VLOOKUP(N8,'TIMEFOLIO Korea플러스배당액티브'!$B$11:$E$1000,4,0) -> 4.08 | P8: =IFERROR(VLOOKUP(N8,'TIMEFOLIO Korea플러스배당액티브(과거)'!$B$11:$E$1000,4,0),0) -> 3.79 | Q8: =O8-P8 -> 0.29 | R8: =IFERROR(O8/P8-1,"신규편입") -> 0.07651715
A9: =VLOOKUP(B9,유니버스!$C$14:$D$2561,2,0) -> KS | B9: ='SOL 코리아메가테크액티브'!B15 -> LS ELECTRIC | C9: =VLOOKUP(B9,'SOL 코리아메가테크액티브'!$B$11:$E$1000,4,0) -> 4.65 | D9: =IFERROR(VLOOKUP(B9,'SOL 코리아메가테크액티브(과거)'!$B$11:$E$1000,4,0),0) -> 4.55 | E9: =C9-D9 -> 0.1 | F9: =IFERROR(C9/D9-1,"신규편입") -> 0.021978022 | G9: =VLOOKUP(H9,유니버스!$C$14:$D$2561,2,0) -> KS | H9: ='KoAct 배당성장액티브'!B15 -> KB금융 | I9: =VLOOKUP(H9,'KoAct 배당성장액티브'!$B$11:$E$1000,4,0) -> 1.83 | J9: =IFERROR(VLOOKUP(H9,'KoAct 배당성장액티브(과거)'!$B$11:$E$1000,4,0),0) -> 1.46 | K9: =I9-J9 -> 0.37 | L9: =IFERROR(I9/J9-1,"신규편입") -> 0.25342466 | M9: =VLOOKUP(N9,유니버스!$C$14:$D$2561,2,0) -> KS | N9: ='TIMEFOLIO Korea플러스배당액티브'!B15 -> 미래에셋증권 | O9: =VLOOKUP(N9,'TIMEFOLIO Korea플러스배당액티브'!$B$11:$E$1000,4,0) -> 3.79 | P9: =IFERROR(VLOOKUP(N9,'TIMEFOLIO Korea플러스배당액티브(과거)'!$B$11:$E$1000,4,0),0) -> 4.08 | Q9: =O9-P9 -> -0.29 | R9: =IFERROR(O9/P9-1,"신규편입") -> -0.071078431
A10: =VLOOKUP(B10,유니버스!$C$14:$D$2561,2,0) -> KS | B10: ='SOL 코리아메가테크액티브'!B16 -> 한화에어로스페이스 | C10: =VLOOKUP(B10,'SOL 코리아메가테크액티브'!$B$11:$E$1000,4,0) -> 4.31 | D10: =IFERROR(VLOOKUP(B10,'SOL 코리아메가테크액티브(과거)'!$B$11:$E$1000,4,0),0) -> 4.31 | E10: =C10-D10 -> 0 | F10: =IFERROR(C10/D10-1,"신규편입") -> 0 | G10: =VLOOKUP(H10,유니버스!$C$14:$D$2561,2,0) -> KQ | H10: ='KoAct 배당성장액티브'!B16 -> 코나아이 | I10: =VLOOKUP(H10,'KoAct 배당성장액티브'!$B$11:$E$1000,4,0) -> 1.79 | J10: =IFERROR(VLOOKUP(H10,'KoAct 배당성장액티브(과거)'!$B$11:$E$1000,4,0),0) -> 2.12 | K10: =I10-J10 -> -0.33 | L10: =IFERROR(I10/J10-1,"신규편입") -> -0.15566038 | M10: =VLOOKUP(N10,유니버스!$C$14:$D$2561,2,0) -> KS | N10: ='TIMEFOLIO Korea플러스배당액티브'!B16 -> 삼성증권 | O10: =VLOOKUP(N10,'TIMEFOLIO Korea플러스배당액티브'!$B$11:$E$1000,4,0) -> 3.52 | P10: =IFERROR(VLOOKUP(N10,'TIMEFOLIO Korea플러스배당액티브(과거)'!$B$11:$E$1000,4,0),0) -> 3.63 | Q10: =O10-P10 -> -0.11 | R10: =IFERROR(O10/P10-1,"신규편입") -> -0.03030303
A11: =VLOOKUP(B11,유니버스!$C$14:$D$2561,2,0) -> KS | B11: ='SOL 코리아메가테크액티브'!B17 -> 기아 | C11: =VLOOKUP(B11,'SOL 코리아메가테크액티브'!$B$11:$E$1000,4,0) -> 3.36 | D11: =IFERROR(VLOOKUP(B11,'SOL 코리아메가테크액티브(과거)'!$B$11:$E$1000,4,0),0) -> 3.44 | E11: =C11-D11 -> -0.08 | F11: =IFERROR(C11/D11-1,"신규편입") -> -0.023255814 | G11: =VLOOKUP(H11,유니버스!$C$14:$D$2561,2,0) -> KS | H11: ='KoAct 배당성장액티브'!B17 -> 현대차 | I11: =VLOOKUP(H11,'KoAct 배당성장액티브'!$B$11:$E$1000,4,0) -> 1.77 | J11: =IFERROR(VLOOKUP(H11,'KoAct 배당성장액티브(과거)'!$B$11:$E$1000,4,0),0) -> 1.9 | K11: =I11-J11 -> -0.13 | L11: =IFERROR(I11/J11-1,"신규편입") -> -0.068421053 | M11: =VLOOKUP(N11,유니버스!$C$14:$D$2561,2,0) -> KS | N11: ='TIMEFOLIO Korea플러스배당액티브'!B17 -> 삼성물산 | O11: =VLOOKUP(N11,'TIMEFOLIO Korea플러스배당액티브'!$B$11:$E$1000,4,0) -> 3.51 | P11: =IFERROR(VLOOKUP(N11,'TIMEFOLIO Korea플러스배당액티브(과거)'!$B$11:$E$1000,4,0),0) -> 3.41 | Q11: =O11-P11 -> 0.1 | R11: =IFERROR(O11/P11-1,"신규편입") -> 0.029325513
A12: =VLOOKUP(B12,유니버스!$C$14:$D$2561,2,0) -> KS | B12: ='SOL 코리아메가테크액티브'!B18 -> 현대모비스 | C12: =VLOOKUP(B12,'SOL 코리아메가테크액티브'!$B$11:$E$1000,4,0) -> 3.26 | D12: =IFERROR(VLOOKUP(B12,'SOL 코리아메가테크액티브(과거)'!$B$11:$E$1000,4,0),0) -> 3.14 | E12: =C12-D12 -> 0.12 | F12: =IFERROR(C12/D12-1,"신규편입") -> 0.038216561 | G12: =VLOOKUP(H12,유니버스!$C$14:$D$2561,2,0) -> KS | H12: ='KoAct 배당성장액티브'!B18 -> 한국금융지주 | I12: =VLOOKUP(H12,'KoAct 배당성장액티브'!$B$11:$E$1000,4,0) -> 1.67 | J12: =IFERROR(VLOOKUP(H12,'KoAct 배당성장액티브(과거)'!$B$11:$E$1000,4,0),0) -> 1.77 | K12: =I12-J12 -> -0.1 | L12: =IFERROR(I12/J12-1,"신규편입") -> -0.056497175 | M12: =VLOOKUP(N12,유니버스!$C$14:$D$2561,2,0) -> KS | N12: ='TIMEFOLIO Korea플러스배당액티브'!B18 -> 키움증권 | O12: =VLOOKUP(N12,'TIMEFOLIO Korea플러스배당액티브'!$B$11:$E$1000,4,0) -> 3.21 | P12: =IFERROR(VLOOKUP(N12,'TIMEFOLIO Korea플러스배당액티브(과거)'!$B$11:$E$1000,4,0),0) -> 3.18 | Q12: =O12-P12 -> 0.03 | R12: =IFERROR(O12/P12-1,"신규편입") -> 0.0094339623
A13: =VLOOKUP(B13,유니버스!$C$14:$D$2561,2,0) -> KS | B13: ='SOL 코리아메가테크액티브'!B19 -> HD현대일렉트릭 | C13: =VLOOKUP(B13,'SOL 코리아메가테크액티브'!$B$11:$E$1000,4,0) -> 2.96 | D13: =IFERROR(VLOOKUP(B13,'SOL 코리아메가테크액티브(과거)'!$B$11:$E$1000,4,0),0) -> 3.15 | E13: =C13-D13 -> -0.19 | F13: =IFERROR(C13/D13-1,"신규편입") -> -0.06031746 | G13: =VLOOKUP(H13,유니버스!$C$14:$D$2561,2,0) -> KS | H13: ='KoAct 배당성장액티브'!B19 -> 키움증권 | I13: =VLOOKUP(H13,'KoAct 배당성장액티브'!$B$11:$E$1000,4,0) -> 1.49 | J13: =IFERROR(VLOOKUP(H13,'KoAct 배당성장액티브(과거)'!$B$11:$E$1000,4,0),0) -> 1.48 | K13: =I13-J13 -> 0.01 | L13: =IFERROR(I13/J13-1,"신규편입") -> 0.0067567568 | M13: =VLOOKUP(N13,유니버스!$C$14:$D$2561,2,0) -> KS | N13: ='TIMEFOLIO Korea플러스배당액티브'!B19 -> 삼성생명 | O13: =VLOOKUP(N13,'TIMEFOLIO Korea플러스배당액티브'!$B$11:$E$1000,4,0) -> 2.48 | P13: =IFERROR(VLOOKUP(N13,'TIMEFOLIO Korea플러스배당액티브(과거)'!$B$11:$E$1000,4,0),0) -> 2.22 | Q13: =O13-P13 -> 0.26 | R13: =IFERROR(O13/P13-1,"신규편입") -> 0.11711712
A14: =VLOOKUP(B14,유니버스!$C$14:$D$2561,2,0) -> KS | B14: ='SOL 코리아메가테크액티브'!B20 -> LIG디펜스앤에어로스페이스 | C14: =VLOOKUP(B14,'SOL 코리아메가테크액티브'!$B$11:$E$1000,4,0) -> 2.83 | D14: =IFERROR(VLOOKUP(B14,'SOL 코리아메가테크액티브(과거)'!$B$11:$E$1000,4,0),0) -> 2.8 | E14: =C14-D14 -> 0.03 | F14: =IFERROR(C14/D14-1,"신규편입") -> 0.010714286 | G14: =VLOOKUP(H14,유니버스!$C$14:$D$2561,2,0) -> KS | H14: ='KoAct 배당성장액티브'!B20 -> SK스퀘어 | I14: =VLOOKUP(H14,'KoAct 배당성장액티브'!$B$11:$E$1000,4,0) -> 1.46 | J14: =IFERROR(VLOOKUP(H14,'KoAct 배당성장액티브(과거)'!$B$11:$E$1000,4,0),0) -> 1.39 | K14: =I14-J14 -> 0.07 | L14: =IFERROR(I14/J14-1,"신규편입") -> 0.050359712 | M14: =VLOOKUP(N14,유니버스!$C$14:$D$2561,2,0) -> KS | N14: ='TIMEFOLIO Korea플러스배당액티브'!B20 -> SK | O14: =VLOOKUP(N14,'TIMEFOLIO Korea플러스배당액티브'!$B$11:$E$1000,4,0) -> 2.46 | P14: =IFERROR(VLOOKUP(N14,'TIMEFOLIO Korea플러스배당액티브(과거)'!$B$11:$E$1000,4,0),0) -> 2.2 | Q14: =O14-P14 -> 0.26 | R14: =IFERROR(O14/P14-1,"신규편입") -> 0.11818182
A15: =VLOOKUP(B15,유니버스!$C$14:$D$2561,2,0) -> KS | B15: ='SOL 코리아메가테크액티브'!B21 -> 한국항공우주 | C15: =VLOOKUP(B15,'SOL 코리아메가테크액티브'!$B$11:$E$1000,4,0) -> 2.82 | D15: =IFERROR(VLOOKUP(B15,'SOL 코리아메가테크액티브(과거)'!$B$11:$E$1000,4,0),0) -> 2.83 | E15: =C15-D15 -> -0.01 | F15: =IFERROR(C15/D15-1,"신규편입") -> -0.0035335689 | G15: =VLOOKUP(H15,유니버스!$C$14:$D$2561,2,0) -> KQ | H15: ='KoAct 배당성장액티브'!B21 -> 다우데이타 | I15: =VLOOKUP(H15,'KoAct 배당성장액티브'!$B$11:$E$1000,4,0) -> 1.45 | J15: =IFERROR(VLOOKUP(H15,'KoAct 배당성장액티브(과거)'!$B$11:$E$1000,4,0),0) -> 1.53 | K15: =I15-J15 -> -0.08 | L15: =IFERROR(I15/J15-1,"신규편입") -> -0.052287582 | M15: =VLOOKUP(N15,유니버스!$C$14:$D$2561,2,0) -> KS | N15: ='TIMEFOLIO Korea플러스배당액티브'!B21 -> 삼양식품 | O15: =VLOOKUP(N15,'TIMEFOLIO Korea플러스배당액티브'!$B$11:$E$1000,4,0) -> 2.44 | P15: =IFERROR(VLOOKUP(N15,'TIMEFOLIO Korea플러스배당액티브(과거)'!$B$11:$E$1000,4,0),0) -> 2.74 | Q15: =O15-P15 -> -0.3 | R15: =IFERROR(O15/P15-1,"신규편입") -> -0.10948905
A16: =VLOOKUP(B16,유니버스!$C$14:$D$2561,2,0) -> KS | B16: ='SOL 코리아메가테크액티브'!B22 -> 두산에너빌리티 | C16: =VLOOKUP(B16,'SOL 코리아메가테크액티브'!$B$11:$E$1000,4,0) -> 2.7 | D16: =IFERROR(VLOOKUP(B16,'SOL 코리아메가테크액티브(과거)'!$B$11:$E$1000,4,0),0) -> 2.83 | E16: =C16-D16 -> -0.13 | F16: =IFERROR(C16/D16-1,"신규편입") -> -0.045936396 | G16: =VLOOKUP(H16,유니버스!$C$14:$D$2561,2,0) -> KS | H16: ='KoAct 배당성장액티브'!B22 -> 삼성전기 | I16: =VLOOKUP(H16,'KoAct 배당성장액티브'!$B$11:$E$1000,4,0) -> 1.4 | J16: =IFERROR(VLOOKUP(H16,'KoAct 배당성장액티브(과거)'!$B$11:$E$1000,4,0),0) -> 1.2 | K16: =I16-J16 -> 0.2 | L16: =IFERROR(I16/J16-1,"신규편입") -> 0.16666667 | M16: =VLOOKUP(N16,유니버스!$C$14:$D$2561,2,0) -> KS | N16: ='TIMEFOLIO Korea플러스배당액티브'!B22 -> KB금융 | O16: =VLOOKUP(N16,'TIMEFOLIO Korea플러스배당액티브'!$B$11:$E$1000,4,0) -> 2.44 | P16: =IFERROR(VLOOKUP(N16,'TIMEFOLIO Korea플러스배당액티브(과거)'!$B$11:$E$1000,4,0),0) -> 2.5 | Q16: =O16-P16 -> -0.06 | R16: =IFERROR(O16/P16-1,"신규편입") -> -0.024
... A37: =VLOOKUP(B37,유니버스!$C$14:$D$2561,2,0) -> KQ | B37: ='SOL 코리아메가테크액티브'!B43 -> 리가켐바이오 | C37: =VLOOKUP(B37,'SOL 코리아메가테크액티브'!$B$11:$E$1000,4,0) -> 0.36 | D37: =IFERROR(VLOOKUP(B37,'SOL 코리아메가테크액티브(과거)'!$B$11:$E$1000,4,0),0) -> 0.51 | E37: =C37-D37 -> -0.15 | F37: =IFERROR(C37/D37-1,"신규편입") -> -0.29411765 | G37: =VLOOKUP(H37,유니버스!$C$14:$D$2561,2,0) -> KS | H37: ='KoAct 배당성장액티브'!B43 -> 삼성화재 | I37: =VLOOKUP(H37,'KoAct 배당성장액티브'!$B$11:$E$1000,4,0) -> 0.61 | J37: =IFERROR(VLOOKUP(H37,'KoAct 배당성장액티브(과거)'!$B$11:$E$1000,4,0),0) -> 0.33 | K37: =I37-J37 -> 0.28 | L37: =IFERROR(I37/J37-1,"신규편입") -> 0.84848485 | M37: =VLOOKUP(N37,유니버스!$C$14:$D$2561,2,0) -> #N/A | N37: ='TIMEFOLIO Korea플러스배당액티브'!B43 -> 원화현금 | O37: =VLOOKUP(N37,'TIMEFOLIO Korea플러스배당액티브'!$B$11:$E$1000,4,0) -> 0.76 | P37: =IFERROR(VLOOKUP(N37,'TIMEFOLIO Korea플러스배당액티브(과거)'!$B$11:$E$1000,4,0),0) -> 0.97 | Q37: =O37-P37 -> -0.21 | R37: =IFERROR(O37/P37-1,"신규편입") -> -0.21649485
A38: =VLOOKUP(B38,유니버스!$C$14:$D$2561,2,0) -> KS | B38: ='SOL 코리아메가테크액티브'!B44 -> NAVER | C38: =VLOOKUP(B38,'SOL 코리아메가테크액티브'!$B$11:$E$1000,4,0) -> 0.31 | D38: =IFERROR(VLOOKUP(B38,'SOL 코리아메가테크액티브(과거)'!$B$11:$E$1000,4,0),0) -> 0.32 | E38: =C38-D38 -> -0.01 | F38: =IFERROR(C38/D38-1,"신규편입") -> -0.03125 | G38: =VLOOKUP(H38,유니버스!$C$14:$D$2561,2,0) -> KS | H38: ='KoAct 배당성장액티브'!B44 -> 롯데쇼핑 | I38: =VLOOKUP(H38,'KoAct 배당성장액티브'!$B$11:$E$1000,4,0) -> 0.59 | J38: =IFERROR(VLOOKUP(H38,'KoAct 배당성장액티브(과거)'!$B$11:$E$1000,4,0),0) -> 0.63 | K38: =I38-J38 -> -0.04 | L38: =IFERROR(I38/J38-1,"신규편입") -> -0.063492063
A39: =VLOOKUP(B39,유니버스!$C$14:$D$2561,2,0) -> KS | B39: ='SOL 코리아메가테크액티브'!B45 -> 한화비전 | C39: =VLOOKUP(B39,'SOL 코리아메가테크액티브'!$B$11:$E$1000,4,0) -> 0.3 | D39: =IFERROR(VLOOKUP(B39,'SOL 코리아메가테크액티브(과거)'!$B$11:$E$1000,4,0),0) -> 0.3 | E39: =C39-D39 -> 0 | F39: =IFERROR(C39/D39-1,"신규편입") -> 0 | G39: =VLOOKUP(H39,유니버스!$C$14:$D$2561,2,0) -> KS | H39: ='KoAct 배당성장액티브'!B45 -> 이노션 | I39: =VLOOKUP(H39,'KoAct 배당성장액티브'!$B$11:$E$1000,4,0) -> 0.59 | J39: =IFERROR(VLOOKUP(H39,'KoAct 배당성장액티브(과거)'!$B$11:$E$1000,4,0),0) -> 0 | K39: =I39-J39 -> 0.59 | L39: =IFERROR(I39/J39-1,"신규편입") -> 신규편입
A40: =VLOOKUP(B40,유니버스!$C$14:$D$2561,2,0) -> KQ | B40: ='SOL 코리아메가테크액티브'!B46 -> 에이비엘바이오 | C40: =VLOOKUP(B40,'SOL 코리아메가테크액티브'!$B$11:$E$1000,4,0) -> 0.29 | D40: =IFERROR(VLOOKUP(B40,'SOL 코리아메가테크액티브(과거)'!$B$11:$E$1000,4,0),0) -> 0.32 | E40: =C40-D40 -> -0.03 | F40: =IFERROR(C40/D40-1,"신규편입") -> -0.09375 | G40: =VLOOKUP(H40,유니버스!$C$14:$D$2561,2,0) -> KS | H40: ='KoAct 배당성장액티브'!B46 -> 크래프톤 | I40: =VLOOKUP(H40,'KoAct 배당성장액티브'!$B$11:$E$1000,4,0) -> 0.58 | J40: =IFERROR(VLOOKUP(H40,'KoAct 배당성장액티브(과거)'!$B$11:$E$1000,4,0),0) -> 0.64 | K40: =I40-J40 -> -0.06 | L40: =IFERROR(I40/J40-1,"신규편입") -> -0.09375
A41: =VLOOKUP(B41,유니버스!$C$14:$D$2561,2,0) -> KQ | B41: ='SOL 코리아메가테크액티브'!B47 -> 인텔리안테크 | C41: =VLOOKUP(B41,'SOL 코리아메가테크액티브'!$B$11:$E$1000,4,0) -> 0.26 | D41: =IFERROR(VLOOKUP(B41,'SOL 코리아메가테크액티브(과거)'!$B$11:$E$1000,4,0),0) -> 0.31 | E41: =C41-D41 -> -0.05 | F41: =IFERROR(C41/D41-1,"신규편입") -> -0.16129032 | G41: =VLOOKUP(H41,유니버스!$C$14:$D$2561,2,0) -> KS | H41: ='KoAct 배당성장액티브'!B47 -> 한화시스템 | I41: =VLOOKUP(H41,'KoAct 배당성장액티브'!$B$11:$E$1000,4,0) -> 0.57 | J41: =IFERROR(VLOOKUP(H41,'KoAct 배당성장액티브(과거)'!$B$11:$E$1000,4,0),0) -> 0.58 | K41: =I41-J41 -> -0.01 | L41: =IFERROR(I41/J41-1,"신규편입") -> -0.017241379
A42: =VLOOKUP(B42,유니버스!$C$14:$D$2561,2,0) -> KQ | B42: ='SOL 코리아메가테크액티브'!B48 -> 에코프로 | C42: =VLOOKUP(B42,'SOL 코리아메가테크액티브'!$B$11:$E$1000,4,0) -> 0.25 | D42: =IFERROR(VLOOKUP(B42,'SOL 코리아메가테크액티브(과거)'!$B$11:$E$1000,4,0),0) -> 0.25 | E42: =C42-D42 -> 0 | F42: =IFERROR(C42/D42-1,"신규편입") -> 0 | G42: =VLOOKUP(H42,유니버스!$C$14:$D$2561,2,0) -> KS | H42: ='KoAct 배당성장액티브'!B48 -> GS | I42: =VLOOKUP(H42,'KoAct 배당성장액티브'!$B$11:$E$1000,4,0) -> 0.56 | J42: =IFERROR(VLOOKUP(H42,'KoAct 배당성장액티브(과거)'!$B$11:$E$1000,4,0),0) -> 0.58 | K42: =I42-J42 -> -0.02 | L42: =IFERROR(I42/J42-1,"신규편입") -> -0.034482759
A43: =VLOOKUP(B43,유니버스!$C$14:$D$2561,2,0) -> KQ | B43: ='SOL 코리아메가테크액티브'!B49 -> 쎄트렉아이 | C43: =VLOOKUP(B43,'SOL 코리아메가테크액티브'!$B$11:$E$1000,4,0) -> 0.25 | D43: =IFERROR(VLOOKUP(B43,'SOL 코리아메가테크액티브(과거)'!$B$11:$E$1000,4,0),0) -> 0.27 | E43: =C43-D43 -> -0.02 | F43: =IFERROR(C43/D43-1,"신규편입") -> -0.074074074 | G43: =VLOOKUP(H43,유니버스!$C$14:$D$2561,2,0) -> KS | H43: ='KoAct 배당성장액티브'!B49 -> 현대백화점 | I43: =VLOOKUP(H43,'KoAct 배당성장액티브'!$B$11:$E$1000,4,0) -> 0.55 | J43: =IFERROR(VLOOKUP(H43,'KoAct 배당성장액티브(과거)'!$B$11:$E$1000,4,0),0) -> 0.55 | K43: =I43-J43 -> 0 | L43: =IFERROR(I43/J43-1,"신규편입") -> 0
A44: =VLOOKUP(B44,유니버스!$C$14:$D$2561,2,0) -> KS | B44: ='SOL 코리아메가테크액티브'!B50 -> 유한양행 | C44: =VLOOKUP(B44,'SOL 코리아메가테크액티브'!$B$11:$E$1000,4,0) -> 0.23 | D44: =IFERROR(VLOOKUP(B44,'SOL 코리아메가테크액티브(과거)'!$B$11:$E$1000,4,0),0) -> 0.25 | E44: =C44-D44 -> -0.02 | F44: =IFERROR(C44/D44-1,"신규편입") -> -0.08 | G44: =VLOOKUP(H44,유니버스!$C$14:$D$2561,2,0) -> KS | H44: ='KoAct 배당성장액티브'!B50 -> 한국토지신탁 | I44: =VLOOKUP(H44,'KoAct 배당성장액티브'!$B$11:$E$1000,4,0) -> 0.55 | J44: =IFERROR(VLOOKUP(H44,'KoAct 배당성장액티브(과거)'!$B$11:$E$1000,4,0),0) -> 0.61 | K44: =I44-J44 -> -0.06 | L44: =IFERROR(I44/J44-1,"신규편입") -> -0.098360656
A45: =VLOOKUP(B45,유니버스!$C$14:$D$2561,2,0) -> KQ | B45: ='SOL 코리아메가테크액티브'!B51 -> ISC | C45: =VLOOKUP(B45,'SOL 코리아메가테크액티브'!$B$11:$E$1000,4,0) -> 0.16 | D45: =IFERROR(VLOOKUP(B45,'SOL 코리아메가테크액티브(과거)'!$B$11:$E$1000,4,0),0) -> 0.17 | E45: =C45-D45 -> -0.01 | F45: =IFERROR(C45/D45-1,"신규편입") -> -0.058823529 | G45: =VLOOKUP(H45,유니버스!$C$14:$D$2561,2,0) -> KS | H45: ='KoAct 배당성장액티브'!B51 -> DB손해보험 | I45: =VLOOKUP(H45,'KoAct 배당성장액티브'!$B$11:$E$1000,4,0) -> 0.54 | J45: =IFERROR(VLOOKUP(H45,'KoAct 배당성장액티브(과거)'!$B$11:$E$1000,4,0),0) -> 0.59 | K45: =I45-J45 -> -0.05 | L45: =IFERROR(I45/J45-1,"신규편입") -> -0.084745763
A46: =VLOOKUP(B46,유니버스!$C$14:$D$2561,2,0) -> KS | B46: ='SOL 코리아메가테크액티브'!B52 -> HL만도 | C46: =VLOOKUP(B46,'SOL 코리아메가테크액티브'!$B$11:$E$1000,4,0) -> 0.16 | D46: =IFERROR(VLOOKUP(B46,'SOL 코리아메가테크액티브(과거)'!$B$11:$E$1000,4,0),0) -> 0.17 | E46: =C46-D46 -> -0.01 | F46: =IFERROR(C46/D46-1,"신규편입") -> -0.058823529 | G46: =VLOOKUP(H46,유니버스!$C$14:$D$2561,2,0) -> KS | H46: ='KoAct 배당성장액티브'!B52 -> 두산 | I46: =VLOOKUP(H46,'KoAct 배당성장액티브'!$B$11:$E$1000,4,0) -> 0.53 | J46: =IFERROR(VLOOKUP(H46,'KoAct 배당성장액티브(과거)'!$B$11:$E$1000,4,0),0) -> 0.55 | K46: =I46-J46 -> -0.02 | L46: =IFERROR(I46/J46-1,"신규편입") -> -0.036363636
A47: =VLOOKUP(B47,유니버스!$C$14:$D$2561,2,0) -> KS | B47: ='SOL 코리아메가테크액티브'!B53 -> 한미약품 | C47: =VLOOKUP(B47,'SOL 코리아메가테크액티브'!$B$11:$E$1000,4,0) -> 0.14 | D47: =IFERROR(VLOOKUP(B47,'SOL 코리아메가테크액티브(과거)'!$B$11:$E$1000,4,0),0) -> 0.15 | E47: =C47-D47 -> -0.01 | F47: =IFERROR(C47/D47-1,"신규편입") -> -0.066666667 | G47: =VLOOKUP(H47,유니버스!$C$14:$D$2561,2,0) -> KS | H47: ='KoAct 배당성장액티브'!B53 -> 포스코인터내셔널 | I47: =VLOOKUP(H47,'KoAct 배당성장액티브'!$B$11:$E$1000,4,0) -> 0.52 | J47: =IFERROR(VLOOKUP(H47,'KoAct 배당성장액티브(과거)'!$B$11:$E$1000,4,0),0) -> 0.57 | K47: =I47-J47 -> -0.05 | L47: =IFERROR(I47/J47-1,"신규편입") -> -0.087719298
A48: =VLOOKUP(B48,유니버스!$C$14:$D$2561,2,0) -> KS | B48: ='SOL 코리아메가테크액티브'!B54 -> SK바이오팜 | C48: =VLOOKUP(B48,'SOL 코리아메가테크액티브'!$B$11:$E$1000,4,0) -> 0.13 | D48: =IFERROR(VLOOKUP(B48,'SOL 코리아메가테크액티브(과거)'!$B$11:$E$1000,4,0),0) -> 0.14 | E48: =C48-D48 -> -0.01 | F48: =IFERROR(C48/D48-1,"신규편입") -> -0.071428571 | G48: =VLOOKUP(H48,유니버스!$C$14:$D$2561,2,0) -> KS | H48: ='KoAct 배당성장액티브'!B54 -> 대신증권 | I48: =VLOOKUP(H48,'KoAct 배당성장액티브'!$B$11:$E$1000,4,0) -> 0.52 | J48: =IFERROR(VLOOKUP(H48,'KoAct 배당성장액티브(과거)'!$B$11:$E$1000,4,0),0) -> 0.55 | K48: =I48-J48 -> -0.03 | L48: =IFERROR(I48/J48-1,"신규편입") -> -0.054545455
A49: =VLOOKUP(B49,유니버스!$C$14:$D$2561,2,0) -> #N/A | B49: ='SOL 코리아메가테크액티브'!B55 -> 원화현금 | C49: =VLOOKUP(B49,'SOL 코리아메가테크액티브'!$B$11:$E$1000,4,0) -> 0.04 | D49: =IFERROR(VLOOKUP(B49,'SOL 코리아메가테크액티브(과거)'!$B$11:$E$1000,4,0),0) -> 0.12 | E49: =C49-D49 -> -0.08 | F49: =IFERROR(C49/D49-1,"신규편입") -> -0.66666667 | G49: =VLOOKUP(H49,유니버스!$C$14:$D$2561,2,0) -> KS | H49: ='KoAct 배당성장액티브'!B55 -> LIG디펜스앤에어로스페이스 | I49: =VLOOKUP(H49,'KoAct 배당성장액티브'!$B$11:$E$1000,4,0) -> 0.5 | J49: =IFERROR(VLOOKUP(H49,'KoAct 배당성장액티브(과거)'!$B$11:$E$1000,4,0),0) -> 0.21 | K49: =I49-J49 -> 0.29 | L49: =IFERROR(I49/J49-1,"신규편입") -> 1.3809524
G50: =VLOOKUP(H50,유니버스!$C$14:$D$2561,2,0) -> KS | H50: ='KoAct 배당성장액티브'!B56 -> 비에이치 | I50: =VLOOKUP(H50,'KoAct 배당성장액티브'!$B$11:$E$1000,4,0) -> 0.49 | J50: =IFERROR(VLOOKUP(H50,'KoAct 배당성장액티브(과거)'!$B$11:$E$1000,4,0),0) -> 0 | K50: =I50-J50 -> 0.49 | L50: =IFERROR(I50/J50-1,"신규편입") -> 신규편입
G51: =VLOOKUP(H51,유니버스!$C$14:$D$2561,2,0) -> KS | H51: ='KoAct 배당성장액티브'!B57 -> DN오토모티브 | I51: =VLOOKUP(H51,'KoAct 배당성장액티브'!$B$11:$E$1000,4,0) -> 0.48 | J51: =IFERROR(VLOOKUP(H51,'KoAct 배당성장액티브(과거)'!$B$11:$E$1000,4,0),0) -> 0.56 | K51: =I51-J51 -> -0.08 | L51: =IFERROR(I51/J51-1,"신규편입") -> -0.14285714
G52: =VLOOKUP(H52,유니버스!$C$14:$D$2561,2,0) -> KS | H52: ='KoAct 배당성장액티브'!B58 -> SK가스 | I52: =VLOOKUP(H52,'KoAct 배당성장액티브'!$B$11:$E$1000,4,0) -> 0.48 | J52: =IFERROR(VLOOKUP(H52,'KoAct 배당성장액티브(과거)'!$B$11:$E$1000,4,0),0) -> 0.56 | K52: =I52-J52 -> -0.08 | L52: =IFERROR(I52/J52-1,"신규편입") -> -0.14285714
G53: =VLOOKUP(H53,유니버스!$C$14:$D$2561,2,0) -> KS | H53: ='KoAct 배당성장액티브'!B59 -> 현대엘리베이터 | I53: =VLOOKUP(H53,'KoAct 배당성장액티브'!$B$11:$E$1000,4,0) -> 0.47 | J53: =IFERROR(VLOOKUP(H53,'KoAct 배당성장액티브(과거)'!$B$11:$E$1000,4,0),0) -> 0.53 | K53: =I53-J53 -> -0.06 | L53: =IFERROR(I53/J53-1,"신규편입") -> -0.11320755
G54: =VLOOKUP(H54,유니버스!$C$14:$D$2561,2,0) -> KS | H54: ='KoAct 배당성장액티브'!B60 -> LS | I54: =VLOOKUP(H54,'KoAct 배당성장액티브'!$B$11:$E$1000,4,0) -> 0.47 | J54: =IFERROR(VLOOKUP(H54,'KoAct 배당성장액티브(과거)'!$B$11:$E$1000,4,0),0) -> 0.68 | K54: =I54-J54 -> -0.21 | L54: =IFERROR(I54/J54-1,"신규편입") -> -0.30882353
G55: =VLOOKUP(H55,유니버스!$C$14:$D$2561,2,0) -> KS | H55: ='KoAct 배당성장액티브'!B61 -> 삼성바이오로직스 | I55: =VLOOKUP(H55,'KoAct 배당성장액티브'!$B$11:$E$1000,4,0) -> 0.46 | J55: =IFERROR(VLOOKUP(H55,'KoAct 배당성장액티브(과거)'!$B$11:$E$1000,4,0),0) -> 0.48 | K55: =I55-J55 -> -0.02 | L55: =IFERROR(I55/J55-1,"신규편입") -> -0.041666667
G56: =VLOOKUP(H56,유니버스!$C$14:$D$2561,2,0) -> KS | H56: ='KoAct 배당성장액티브'!B62 -> 에이피알 | I56: =VLOOKUP(H56,'KoAct 배당성장액티브'!$B$11:$E$1000,4,0) -> 0.4 | J56: =IFERROR(VLOOKUP(H56,'KoAct 배당성장액티브(과거)'!$B$11:$E$1000,4,0),0) -> 0.41 | K56: =I56-J56 -> -0.01 | L56: =IFERROR(I56/J56-1,"신규편입") -> -0.024390244
G57: =VLOOKUP(H57,유니버스!$C$14:$D$2561,2,0) -> KS | H57: ='KoAct 배당성장액티브'!B63 -> 한미약품 | I57: =VLOOKUP(H57,'KoAct 배당성장액티브'!$B$11:$E$1000,4,0) -> 0.36 | J57: =IFERROR(VLOOKUP(H57,'KoAct 배당성장액티브(과거)'!$B$11:$E$1000,4,0),0) -> 0.4 | K57: =I57-J57 -> -0.04 | L57: =IFERROR(I57/J57-1,"신규편입") -> -0.1
G58: =VLOOKUP(H58,유니버스!$C$14:$D$2561,2,0) -> KS | H58: ='KoAct 배당성장액티브'!B64 -> 제이에스코퍼레이션 | I58: =VLOOKUP(H58,'KoAct 배당성장액티브'!$B$11:$E$1000,4,0) -> 0.35 | J58: =IFERROR(VLOOKUP(H58,'KoAct 배당성장액티브(과거)'!$B$11:$E$1000,4,0),0) -> 0.4 | K58: =I58-J58 -> -0.05 | L58: =IFERROR(I58/J58-1,"신규편입") -> -0.125
G59: =VLOOKUP(H59,유니버스!$C$14:$D$2561,2,0) -> KQ | H59: ='KoAct 배당성장액티브'!B65 -> 이지홀딩스 | I59: =VLOOKUP(H59,'KoAct 배당성장액티브'!$B$11:$E$1000,4,0) -> 0.35 | J59: =IFERROR(VLOOKUP(H59,'KoAct 배당성장액티브(과거)'!$B$11:$E$1000,4,0),0) -> 0.34 | K59: =I59-J59 -> 0.01 | L59: =IFERROR(I59/J59-1,"신규편입") -> 0.029411765
G60: =VLOOKUP(H60,유니버스!$C$14:$D$2561,2,0) -> KS | H60: ='KoAct 배당성장액티브'!B66 -> 포스코퓨처엠 | I60: =VLOOKUP(H60,'KoAct 배당성장액티브'!$B$11:$E$1000,4,0) -> 0.35 | J60: =IFERROR(VLOOKUP(H60,'KoAct 배당성장액티브(과거)'!$B$11:$E$1000,4,0),0) -> 0.36 | K60: =I60-J60 -> -0.01 | L60: =IFERROR(I60/J60-1,"신규편입") -> -0.027777778
G61: =VLOOKUP(H61,유니버스!$C$14:$D$2561,2,0) -> KS | H61: ='KoAct 배당성장액티브'!B67 -> 메리츠금융지주 | I61: =VLOOKUP(H61,'KoAct 배당성장액티브'!$B$11:$E$1000,4,0) -> 0.33 | J61: =IFERROR(VLOOKUP(H61,'KoAct 배당성장액티브(과거)'!$B$11:$E$1000,4,0),0) -> 0.33 | K61: =I61-J61 -> 0 | L61: =IFERROR(I61/J61-1,"신규편입") -> 0
... G83: =VLOOKUP(H83,유니버스!$C$14:$D$2561,2,0) -> #N/A | H83: ='KoAct 배당성장액티브'!B89 -> 원화현금 | I83: =VLOOKUP(H83,'KoAct 배당성장액티브'!$B$11:$E$1000,4,0) -> 0.84 | J83: =IFERROR(VLOOKUP(H83,'KoAct 배당성장액티브(과거)'!$B$11:$E$1000,4,0),0) -> 0.57 | K83: =I83-J83 -> 0.27 | L83: =IFERROR(I83/J83-1,"신규편입") -> 0.47368421

Sheet 신재생, 2차전지
B3: ='KODEX 신재생에너지액티브'!A9 -> KODEX 신재생에너지액티브 | H3: ='TIMEFOLIO K신재생에너지액티브'!A9 -> TIME K신재생에너지액티브 | N3: ='RISE 2차전지액티브'!A9 -> RISE 2차전지액티브
B4: 종목명 | C4: ='KODEX 신재생에너지액티브'!B4 -> CPD [20260522] | D4: ='KODEX 신재생에너지액티브(과거)'!B4 -> 20260515 | E4: 비중차이 | F4: 증가율 | H4: 종목명 | I4: =C4 -> CPD [20260522] | J4: =D4 -> 20260515 | K4: 비중차 | L4: 증가율 | N4: 종목명 | O4: =C4 -> CPD [20260522] | P4: =D4 -> 20260515 | Q4: 비중차이 | R4: 증가율
