Workbook

Sheet 2027전망(10일)
B3: 추정영업이익 변화에따른 실적 쇼크 조심하기 15일 변화 기준
D5: 2 | E5: =D5+1 -> 3 | F5: 10 | G5: =E5+1 -> 4 | H5: =G5+1 -> 5 | I5: =H5+1 -> 6 | J5: =K5+1 -> 8 | K5: =I5+1 -> 7 | L5: =J5+1 -> 9 | N5: ='2027'!L1 -> 11 | P5: ='2027'!N1 -> 13 | Q5: 14 | R5: 14 | S5: ='2027'!O1 -> 14 | T5: ='2027'!P1 -> 15
H6: EPS참여 | I6: 3개월 평균추정 | J6: 1개월 평균추정 | K6: 3개월 평균추정 | L6: 1개월 평균추정 | M6: 1개월대비 | N6: 잠정치 | P6: 잠정치 | R6: 실제 | S6: 1M | T6: 3M
G7: 20260702 | H7: 증권사 | I7: 2027AS | J7: =K7 -> 2027AS | K7: =I7 -> 2027AS | L7: =J7 -> 2027AS | M7: 3개월 | N7: =K7 -> 2027AS | P7: =N7 -> 2027AS | Q7: 예상 | R7: Surprise | S7: 수익률 | T7: 수익률 | Y7: Surprise
G8: KRW BIL | H8: # | I8: KRW bil | J8: KRW bil | K8: KRW bil | L8: KRW bil | M8: % | N8: KRW bil | O8: TEST | P8: KRW bil | Q8: =COUNT($B$11:$B$178) -> 168 | R8: Shock | S8: % | T8: % | Y8: Shock
B9: 시총 | E9: 시장 | H9: =G7 -> 20260702 | I9: CPD-10TD | J9: =I9 -> CPD-10TD | K9: =H9 -> 20260702 | L9: =K9 -> 20260702 | O9: 1 = Surprise | P9: 발표예정일 | Q9: =COUNTIF($Q$11:$Q$178,"Surprise") -> 40 | R9: 0.05
B10: Rank | C10: Code | D10: 종목명 | F10: Sector | G10: 시가총액 | I10: 영업이익 | J10: 영업이익 | K10: 영업이익 | L10: 영업이익 | M10: 괴리율 | N10: 영업이익 | O10: -1 = Shock | P10: 영업이익 | Q10: =COUNTIF($Q$11:$Q$178,"Shock") -> 23 | R10: 기준 | X10: 1 | Y10: A000150 | Z10: 두산
B11: 1 | C11: =VLOOKUP(B11,'2027'!$A$14:$B$4000,2,FALSE) -> A005930 | D11: =VLOOKUP($C11,'2027'!$B$14:$T$4000,D$5,FALSE) -> 삼성전자 | E11: =VLOOKUP($C11,'2027'!$B$14:$T$4000,E$5,FALSE) -> KS | F11: =VLOOKUP($C11,'2027'!$B$14:$T$4000,F$5,FALSE) -> 반도체 | G11: =VLOOKUP($C11,'2027'!$B$14:$T$4000,G$5,FALSE) -> 1838654.6 | H11: =VLOOKUP($C11,'2027'!$B$14:$T$4000,H$5,FALSE) -> 24 | I11: =VLOOKUP($C11,'2027'!$B$14:$T$4000,I$5,FALSE) -> 482079.57 | J11: =VLOOKUP($C11,'2027'!$B$14:$T$4000,J$5,FALSE) -> 515147.02 | K11: =VLOOKUP($C11,'2027'!$B$14:$T$4000,K$5,FALSE) -> 522500.28 | L11: =VLOOKUP($C11,'2027'!$B$14:$T$4000,L$5,FALSE) -> 529240.6 | M11: =(L11-K11)/ABS(K11)*100 -> 1.2900127 | N11: =IF(ISBLANK(VLOOKUP($C11,'2027'!$B$14:$T$3000,N$5,FALSE)),"",VLOOKUP($C11,'2027'!$B$14:$T$3000,N$5,FALSE)) | O11: =IF(AND(I11<K11,J11<L11,K11<L11),1,IF(AND(I11>K11,J11>L11,K11>L11),-1,0)) -> 1 | P11: =IF(ISBLANK(VLOOKUP($C11,'2027'!$B$14:$T$3000,P$5,FALSE)),"",VLOOKUP($C11,'2027'!$B$14:$T$3000,P$5,FALSE)) | Q11: =IF(O11=1,"Surprise",IF(O11=-1,"Shock","")) -> Surprise | R11: =IF(N11="","",IF((N11-L11)/ABS(L11)>$R$9,"Surprise",IF((N11-L11)/ABS(L11)<$R$9*-1,"Shock",""))) | S11: =VLOOKUP($C11,'2027'!$B$14:$T$3000,S$5,FALSE) -> -9.89 | T11: =VLOOKUP($C11,'2027'!$B$14:$T$3000,T$5,FALSE) -> 65.88 | X11: =X97+1 -> 14 | Y11: A010520 | Z11: 현대하이스코
B12: 2 | C12: =VLOOKUP(B12,'2027'!$A$14:$B$4000,2,FALSE) -> A000660 | D12: =VLOOKUP($C12,'2027'!$B$14:$T$4000,D$5,FALSE) -> SK하이닉스 | E12: =VLOOKUP($C12,'2027'!$B$14:$T$4000,E$5,FALSE) -> KS | F12: =VLOOKUP($C12,'2027'!$B$14:$T$4000,F$5,FALSE) -> 반도체 | G12: =VLOOKUP($C12,'2027'!$B$14:$T$4000,G$5,FALSE) -> 1824518.1 | H12: =VLOOKUP($C12,'2027'!$B$14:$T$4000,H$5,FALSE) -> 24 | I12: =VLOOKUP($C12,'2027'!$B$14:$T$4000,I$5,FALSE) -> 373423.04 | J12: =VLOOKUP($C12,'2027'!$B$14:$T$4000,J$5,FALSE) -> 406325.81 | K12: =VLOOKUP($C12,'2027'!$B$14:$T$4000,K$5,FALSE) -> 395865.72 | L12: =VLOOKUP($C12,'2027'!$B$14:$T$4000,L$5,FALSE) -> 418657.53 | M12: =(L12-K12)/ABS(K12)*100 -> 5.7574599 | N12: =IF(ISBLANK(VLOOKUP($C12,'2027'!$B$14:$T$3000,N$5,FALSE)),"",VLOOKUP($C12,'2027'!$B$14:$T$3000,N$5,FALSE)) | O12: =IF(AND(I12<K12,J12<L12,K12<L12),1,IF(AND(I12>K12,J12>L12,K12>L12),-1,0)) -> 1 | P12: =IF(ISBLANK(VLOOKUP($C12,'2027'!$B$14:$T$3000,P$5,FALSE)),"",VLOOKUP($C12,'2027'!$B$14:$T$3000,P$5,FALSE)) | Q12: =IF(O12=1,"Surprise",IF(O12=-1,"Shock","")) -> Surprise | R12: =IF(N12="","",IF((N12-L12)/ABS(L12)>$R$9,"Surprise",IF((N12-L12)/ABS(L12)<$R$9*-1,"Shock",""))) | S12: =VLOOKUP($C12,'2027'!$B$14:$T$3000,S$5,FALSE) -> 8.34 | T12: =VLOOKUP($C12,'2027'!$B$14:$T$3000,T$5,FALSE) -> 186.67 | X12: =X11+1 -> 15 | Y12: A042670 | Z12: 두산인프라코어
B13: 4 | C13: =VLOOKUP(B13,'2027'!$A$14:$B$4000,2,FALSE) -> A009150 | D13: =VLOOKUP($C13,'2027'!$B$14:$T$4000,D$5,FALSE) -> 삼성전기 | E13: =VLOOKUP($C13,'2027'!$B$14:$T$4000,E$5,FALSE) -> KS | F13: =VLOOKUP($C13,'2027'!$B$14:$T$4000,F$5,FALSE) -> 전자장비,사무용전자제품 | G13: =VLOOKUP($C13,'2027'!$B$14:$T$4000,G$5,FALSE) -> 164699.6 | H13: =VLOOKUP($C13,'2027'!$B$14:$T$4000,H$5,FALSE) -> 20 | I13: =VLOOKUP($C13,'2027'!$B$14:$T$4000,I$5,FALSE) -> 2721.95 | J13: =VLOOKUP($C13,'2027'!$B$14:$T$4000,J$5,FALSE) -> 2974.91 | K13: =VLOOKUP($C13,'2027'!$B$14:$T$4000,K$5,FALSE) -> 2808.48 | L13: =VLOOKUP($C13,'2027'!$B$14:$T$4000,L$5,FALSE) -> 3246.99 | M13: =(L13-K13)/ABS(K13)*100 -> 15.613784 | N13: =IF(ISBLANK(VLOOKUP($C13,'2027'!$B$14:$T$3000,N$5,FALSE)),"",VLOOKUP($C13,'2027'!$B$14:$T$3000,N$5,FALSE)) | O13: =IF(AND(I13<K13,J13<L13,K13<L13),1,IF(AND(I13>K13,J13>L13,K13>L13),-1,0)) -> 1 | P13: =IF(ISBLANK(VLOOKUP($C13,'2027'!$B$14:$T$3000,P$5,FALSE)),"",VLOOKUP($C13,'2027'!$B$14:$T$3000,P$5,FALSE)) | Q13: =IF(O13=1,"Surprise",IF(O13=-1,"Shock","")) -> Surprise | R13: =IF(N13="","",IF((N13-L13)/ABS(L13)>$R$9,"Surprise",IF((N13-L13)/ABS(L13)<$R$9*-1,"Shock",""))) | S13: =VLOOKUP($C13,'2027'!$B$14:$T$3000,S$5,FALSE) -> 9.98 | T13: =VLOOKUP($C13,'2027'!$B$14:$T$3000,T$5,FALSE) -> 396.06 | X13: =X12+1 -> 16 | Y13: A036460 | Z13: 한국가스공사
B14: 3 | C14: =VLOOKUP(B14,'2027'!$A$14:$B$4000,2,FALSE) -> A402340 | D14: =VLOOKUP($C14,'2027'!$B$14:$T$4000,D$5,FALSE) -> SK스퀘어 | E14: =VLOOKUP($C14,'2027'!$B$14:$T$4000,E$5,FALSE) -> KS | F14: =VLOOKUP($C14,'2027'!$B$14:$T$4000,F$5,FALSE) -> 반도체 | G14: =VLOOKUP($C14,'2027'!$B$14:$T$4000,G$5,FALSE) -> 231850.88 | H14: =VLOOKUP($C14,'2027'!$B$14:$T$4000,H$5,FALSE) -> 6 | I14: =VLOOKUP($C14,'2027'!$B$14:$T$4000,I$5,FALSE) -> 48854.77 | J14: =VLOOKUP($C14,'2027'!$B$14:$T$4000,J$5,FALSE) -> 52770.5 | K14: =VLOOKUP($C14,'2027'!$B$14:$T$4000,K$5,FALSE) -> 52343.23 | L14: =VLOOKUP($C14,'2027'!$B$14:$T$4000,L$5,FALSE) -> 56536.33 | M14: =(L14-K14)/ABS(K14)*100 -> 8.0107781 | N14: =IF(ISBLANK(VLOOKUP($C14,'2027'!$B$14:$T$3000,N$5,FALSE)),"",VLOOKUP($C14,'2027'!$B$14:$T$3000,N$5,FALSE)) | O14: =IF(AND(I14<K14,J14<L14,K14<L14),1,IF(AND(I14>K14,J14>L14,K14>L14),-1,0)) -> 1 | P14: =IF(ISBLANK(VLOOKUP($C14,'2027'!$B$14:$T$3000,P$5,FALSE)),"",VLOOKUP($C14,'2027'!$B$14:$T$3000,P$5,FALSE)) | Q14: =IF(O14=1,"Surprise",IF(O14=-1,"Shock","")) -> Surprise | R14: =IF(N14="","",IF((N14-L14)/ABS(L14)>$R$9,"Surprise",IF((N14-L14)/ABS(L14)<$R$9*-1,"Shock",""))) | S14: =VLOOKUP($C14,'2027'!$B$14:$T$3000,S$5,FALSE) -> 39.89 | T14: =VLOOKUP($C14,'2027'!$B$14:$T$3000,T$5,FALSE) -> 250.7 | X14: =X13+1 -> 17 | Y14: A003490 | Z14: 대한항공
B15: 61 | C15: =VLOOKUP(B15,'2027'!$A$14:$B$4000,2,FALSE) -> A006260 | D15: =VLOOKUP($C15,'2027'!$B$14:$T$4000,D$5,FALSE) -> LS | E15: =VLOOKUP($C15,'2027'!$B$14:$T$4000,E$5,FALSE) -> KS | F15: =VLOOKUP($C15,'2027'!$B$14:$T$4000,F$5,FALSE) -> 전기장비 | G15: =VLOOKUP($C15,'2027'!$B$14:$T$4000,G$5,FALSE) -> 12448.8 | H15: =VLOOKUP($C15,'2027'!$B$14:$T$4000,H$5,FALSE) -> 11 | I15: =VLOOKUP($C15,'2027'!$B$14:$T$4000,I$5,FALSE) -> 1890.23 | J15: =VLOOKUP($C15,'2027'!$B$14:$T$4000,J$5,FALSE) -> 1876.2 | K15: =VLOOKUP($C15,'2027'!$B$14:$T$4000,K$5,FALSE) -> 1900.79 | L15: =VLOOKUP($C15,'2027'!$B$14:$T$4000,L$5,FALSE) -> 1945.28 | M15: =(L15-K15)/ABS(K15)*100 -> 2.3406057 | N15: =IF(ISBLANK(VLOOKUP($C15,'2027'!$B$14:$T$3000,N$5,FALSE)),"",VLOOKUP($C15,'2027'!$B$14:$T$3000,N$5,FALSE)) | O15: =IF(AND(I15<K15,J15<L15,K15<L15),1,IF(AND(I15>K15,J15>L15,K15>L15),-1,0)) -> 1 | P15: =IF(ISBLANK(VLOOKUP($C15,'2027'!$B$14:$T$3000,P$5,FALSE)),"",VLOOKUP($C15,'2027'!$B$14:$T$3000,P$5,FALSE)) | Q15: =IF(O15=1,"Surprise",IF(O15=-1,"Shock","")) -> Surprise | R15: =IF(N15="","",IF((N15-L15)/ABS(L15)>$R$9,"Surprise",IF((N15-L15)/ABS(L15)<$R$9*-1,"Shock",""))) | S15: =VLOOKUP($C15,'2027'!$B$14:$T$3000,S$5,FALSE) -> -14.38 | T15: =VLOOKUP($C15,'2027'!$B$14:$T$3000,T$5,FALSE) -> 43.27 | X15: =X14+1 -> 18 | Y15: A005380 | Z15: 현대차
B16: 20 | C16: =VLOOKUP(B16,'2027'!$A$14:$B$4000,2,FALSE) -> A010120 | D16: =VLOOKUP($C16,'2027'!$B$14:$T$4000,D$5,FALSE) -> LS ELECTRIC | E16: =VLOOKUP($C16,'2027'!$B$14:$T$4000,E$5,FALSE) -> KS | F16: =VLOOKUP($C16,'2027'!$B$14:$T$4000,F$5,FALSE) -> 전기장비 | G16: =VLOOKUP($C16,'2027'!$B$14:$T$4000,G$5,FALSE) -> 39525 | H16: =VLOOKUP($C16,'2027'!$B$14:$T$4000,H$5,FALSE) -> 13 | I16: =VLOOKUP($C16,'2027'!$B$14:$T$4000,I$5,FALSE) -> 918.79 | J16: =VLOOKUP($C16,'2027'!$B$14:$T$4000,J$5,FALSE) -> 998.58 | K16: =VLOOKUP($C16,'2027'!$B$14:$T$4000,K$5,FALSE) -> 922.8 | L16: =VLOOKUP($C16,'2027'!$B$14:$T$4000,L$5,FALSE) -> 1017.25 | M16: =(L16-K16)/ABS(K16)*100 -> 10.235154 | N16: =IF(ISBLANK(VLOOKUP($C16,'2027'!$B$14:$T$3000,N$5,FALSE)),"",VLOOKUP($C16,'2027'!$B$14:$T$3000,N$5,FALSE)) | O16: =IF(AND(I16<K16,J16<L16,K16<L16),1,IF(AND(I16>K16,J16>L16,K16>L16),-1,0)) -> 1 | P16: =IF(ISBLANK(VLOOKUP($C16,'2027'!$B$14:$T$3000,P$5,FALSE)),"",VLOOKUP($C16,'2027'!$B$14:$T$3000,P$5,FALSE)) | Q16: =IF(O16=1,"Surprise",IF(O16=-1,"Shock","")) -> Surprise | R16: =IF(N16="","",IF((N16-L16)/ABS(L16)>$R$9,"Surprise",IF((N16-L16)/ABS(L16)<$R$9*-1,"Shock",""))) | S16: =VLOOKUP($C16,'2027'!$B$14:$T$3000,S$5,FALSE) -> -1.31 | T16: =VLOOKUP($C16,'2027'!$B$14:$T$3000,T$5,FALSE) -> 65.93 | X16: =X15+1 -> 19 | Y16: A012450 | Z16: 삼성테크윈
B17: 97 | C17: =VLOOKUP(B17,'2027'!$A$14:$B$4000,2,FALSE) -> A023530 | D17: =VLOOKUP($C17,'2027'!$B$14:$T$4000,D$5,FALSE) -> 롯데쇼핑 | E17: =VLOOKUP($C17,'2027'!$B$14:$T$4000,E$5,FALSE) -> KS | F17: =VLOOKUP($C17,'2027'!$B$14:$T$4000,F$5,FALSE) -> 백화점 | G17: =VLOOKUP($C17,'2027'!$B$14:$T$4000,G$5,FALSE) -> 5233.42 | H17: =VLOOKUP($C17,'2027'!$B$14:$T$4000,H$5,FALSE) -> 15 | I17: =VLOOKUP($C17,'2027'!$B$14:$T$4000,I$5,FALSE) -> 854.54 | J17: =VLOOKUP($C17,'2027'!$B$14:$T$4000,J$5,FALSE) -> 883.18 | K17: =VLOOKUP($C17,'2027'!$B$14:$T$4000,K$5,FALSE) -> 856.27 | L17: =VLOOKUP($C17,'2027'!$B$14:$T$4000,L$5,FALSE) -> 887.86 | M17: =(L17-K17)/ABS(K17)*100 -> 3.6892569 | N17: =IF(ISBLANK(VLOOKUP($C17,'2027'!$B$14:$T$3000,N$5,FALSE)),"",VLOOKUP($C17,'2027'!$B$14:$T$3000,N$5,FALSE)) | O17: =IF(AND(I17<K17,J17<L17,K17<L17),1,IF(AND(I17>K17,J17>L17,K17>L17),-1,0)) -> 1 | P17: =IF(ISBLANK(VLOOKUP($C17,'2027'!$B$14:$T$3000,P$5,FALSE)),"",VLOOKUP($C17,'2027'!$B$14:$T$3000,P$5,FALSE)) | Q17: =IF(O17=1,"Surprise",IF(O17=-1,"Shock","")) -> Surprise | R17: =IF(N17="","",IF((N17-L17)/ABS(L17)>$R$9,"Surprise",IF((N17-L17)/ABS(L17)<$R$9*-1,"Shock",""))) | S17: =VLOOKUP($C17,'2027'!$B$14:$T$3000,S$5,FALSE) -> 25.42 | T17: =VLOOKUP($C17,'2027'!$B$14:$T$3000,T$5,FALSE) -> 74.53 | X17: =X16+1 -> 20 | Y17: A036570 | Z17: 엔씨소프트
B18: 62 | C18: =VLOOKUP(B18,'2027'!$A$14:$B$4000,2,FALSE) -> A010950 | D18: =VLOOKUP($C18,'2027'!$B$14:$T$4000,D$5,FALSE) -> S-Oil | E18: =VLOOKUP($C18,'2027'!$B$14:$T$4000,E$5,FALSE) -> KS | F18: =VLOOKUP($C18,'2027'!$B$14:$T$4000,F$5,FALSE) -> 에너지 | G18: =VLOOKUP($C18,'2027'!$B$14:$T$4000,G$5,FALSE) -> 12339.07 | H18: =VLOOKUP($C18,'2027'!$B$14:$T$4000,H$5,FALSE) -> 16 | I18: =VLOOKUP($C18,'2027'!$B$14:$T$4000,I$5,FALSE) -> 2358.06 | J18: =VLOOKUP($C18,'2027'!$B$14:$T$4000,J$5,FALSE) -> 2467.58 | K18: =VLOOKUP($C18,'2027'!$B$14:$T$4000,K$5,FALSE) -> 2397.16 | L18: =VLOOKUP($C18,'2027'!$B$14:$T$4000,L$5,FALSE) -> 2560.83 | M18: =(L18-K18)/ABS(K18)*100 -> 6.8276627 | N18: =IF(ISBLANK(VLOOKUP($C18,'2027'!$B$14:$T$3000,N$5,FALSE)),"",VLOOKUP($C18,'2027'!$B$14:$T$3000,N$5,FALSE)) | O18: =IF(AND(I18<K18,J18<L18,K18<L18),1,IF(AND(I18>K18,J18>L18,K18>L18),-1,0)) -> 1 | P18: =IF(ISBLANK(VLOOKUP($C18,'2027'!$B$14:$T$3000,P$5,FALSE)),"",VLOOKUP($C18,'2027'!$B$14:$T$3000,P$5,FALSE)) | Q18: =IF(O18=1,"Surprise",IF(O18=-1,"Shock","")) -> Surprise | R18: =IF(N18="","",IF((N18-L18)/ABS(L18)>$R$9,"Surprise",IF((N18-L18)/ABS(L18)<$R$9*-1,"Shock",""))) | S18: =VLOOKUP($C18,'2027'!$B$14:$T$3000,S$5,FALSE) -> 4.68 | T18: =VLOOKUP($C18,'2027'!$B$14:$T$3000,T$5,FALSE) -> -3.09 | X18: =X17+1 -> 21 | Y18: A139480 | Z18: 이마트
B19: 12 | C19: =VLOOKUP(B19,'2027'!$A$14:$B$4000,2,FALSE) -> A012450 | D19: =VLOOKUP($C19,'2027'!$B$14:$T$4000,D$5,FALSE) -> 한화에어로스페이스 | E19: =VLOOKUP($C19,'2027'!$B$14:$T$4000,E$5,FALSE) -> KS | F19: =VLOOKUP($C19,'2027'!$B$14:$T$4000,F$5,FALSE) -> 기타자본재 | G19: =VLOOKUP($C19,'2027'!$B$14:$T$4000,G$5,FALSE) -> 56255.67 | H19: =VLOOKUP($C19,'2027'!$B$14:$T$4000,H$5,FALSE) -> 19 | I19: =VLOOKUP($C19,'2027'!$B$14:$T$4000,I$5,FALSE) -> 5455.88 | J19: =VLOOKUP($C19,'2027'!$B$14:$T$4000,J$5,FALSE) -> 5565.7 | K19: =VLOOKUP($C19,'2027'!$B$14:$T$4000,K$5,FALSE) -> 5493.64 | L19: =VLOOKUP($C19,'2027'!$B$14:$T$4000,L$5,FALSE) -> 5671.2 | M19: =(L19-K19)/ABS(K19)*100 -> 3.2321011 | N19: =IF(ISBLANK(VLOOKUP($C19,'2027'!$B$14:$T$3000,N$5,FALSE)),"",VLOOKUP($C19,'2027'!$B$14:$T$3000,N$5,FALSE)) | O19: =IF(AND(I19<K19,J19<L19,K19<L19),1,IF(AND(I19>K19,J19>L19,K19>L19),-1,0)) -> 1 | P19: =IF(ISBLANK(VLOOKUP($C19,'2027'!$B$14:$T$3000,P$5,FALSE)),"",VLOOKUP($C19,'2027'!$B$14:$T$3000,P$5,FALSE)) | Q19: =IF(O19=1,"Surprise",IF(O19=-1,"Shock","")) -> Surprise | R19: =IF(N19="","",IF((N19-L19)/ABS(L19)>$R$9,"Surprise",IF((N19-L19)/ABS(L19)<$R$9*-1,"Shock",""))) | S19: =VLOOKUP($C19,'2027'!$B$14:$T$3000,S$5,FALSE) -> -4.13 | T19: =VLOOKUP($C19,'2027'!$B$14:$T$3000,T$5,FALSE) -> -18.15 | X19: =X18+1 -> 22 | Y19: A071840 | Z19: 롯데하이마트
B20: 14 | C20: =VLOOKUP(B20,'2027'!$A$14:$B$4000,2,FALSE) -> A034730 | D20: =VLOOKUP($C20,'2027'!$B$14:$T$4000,D$5,FALSE) -> SK | E20: =VLOOKUP($C20,'2027'!$B$14:$T$4000,E$5,FALSE) -> KS | F20: =VLOOKUP($C20,'2027'!$B$14:$T$4000,F$5,FALSE) -> 에너지 | G20: =VLOOKUP($C20,'2027'!$B$14:$T$4000,G$5,FALSE) -> 55319.56 | H20: =VLOOKUP($C20,'2027'!$B$14:$T$4000,H$5,FALSE) -> 13 | I20: =VLOOKUP($C20,'2027'!$B$14:$T$4000,I$5,FALSE) -> 9286.45 | J20: =VLOOKUP($C20,'2027'!$B$14:$T$4000,J$5,FALSE) -> 13526.82 | K20: =VLOOKUP($C20,'2027'!$B$14:$T$4000,K$5,FALSE) -> 11535.82 | L20: =VLOOKUP($C20,'2027'!$B$14:$T$4000,L$5,FALSE) -> 13771.5 | M20: =(L20-K20)/ABS(K20)*100 -> 19.38033 | N20: =IF(ISBLANK(VLOOKUP($C20,'2027'!$B$14:$T$3000,N$5,FALSE)),"",VLOOKUP($C20,'2027'!$B$14:$T$3000,N$5,FALSE)) | O20: =IF(AND(I20<K20,J20<L20,K20<L20),1,IF(AND(I20>K20,J20>L20,K20>L20),-1,0)) -> 1 | P20: =IF(ISBLANK(VLOOKUP($C20,'2027'!$B$14:$T$3000,P$5,FALSE)),"",VLOOKUP($C20,'2027'!$B$14:$T$3000,P$5,FALSE)) | Q20: =IF(O20=1,"Surprise",IF(O20=-1,"Shock","")) -> Surprise | R20: =IF(N20="","",IF((N20-L20)/ABS(L20)>$R$9,"Surprise",IF((N20-L20)/ABS(L20)<$R$9*-1,"Shock",""))) | S20: =VLOOKUP($C20,'2027'!$B$14:$T$3000,S$5,FALSE) -> 16.13 | T20: =VLOOKUP($C20,'2027'!$B$14:$T$3000,T$5,FALSE) -> 137.69 | X20: =X19+1 -> 23 | Y20: A000270 | Z20: 기아차
B21: 76 | C21: =VLOOKUP(B21,'2027'!$A$14:$B$4000,2,FALSE) -> A047040 | D21: =VLOOKUP($C21,'2027'!$B$14:$T$4000,D$5,FALSE) -> 대우건설 | E21: =VLOOKUP($C21,'2027'!$B$14:$T$4000,E$5,FALSE) -> KS | F21: =VLOOKUP($C21,'2027'!$B$14:$T$4000,F$5,FALSE) -> 건설,건축제품,건축자재 | G21: =VLOOKUP($C21,'2027'!$B$14:$T$4000,G$5,FALSE) -> 7979.83 | H21: =VLOOKUP($C21,'2027'!$B$14:$T$4000,H$5,FALSE) -> 13 | I21: =VLOOKUP($C21,'2027'!$B$14:$T$4000,I$5,FALSE) -> 708.3 | J21: =VLOOKUP($C21,'2027'!$B$14:$T$4000,J$5,FALSE) -> 708.83 | K21: =VLOOKUP($C21,'2027'!$B$14:$T$4000,K$5,FALSE) -> 715.04 | L21: =VLOOKUP($C21,'2027'!$B$14:$T$4000,L$5,FALSE) -> 715.75 | M21: =(L21-K21)/ABS(K21)*100 -> 0.099295144 | N21: =IF(ISBLANK(VLOOKUP($C21,'2027'!$B$14:$T$3000,N$5,FALSE)),"",VLOOKUP($C21,'2027'!$B$14:$T$3000,N$5,FALSE)) | O21: =IF(AND(I21<K21,J21<L21,K21<L21),1,IF(AND(I21>K21,J21>L21,K21>L21),-1,0)) -> 1 | P21: =IF(ISBLANK(VLOOKUP($C21,'2027'!$B$14:$T$3000,P$5,FALSE)),"",VLOOKUP($C21,'2027'!$B$14:$T$3000,P$5,FALSE)) | Q21: =IF(O21=1,"Surprise",IF(O21=-1,"Shock","")) -> Surprise | R21: =IF(N21="","",IF((N21-L21)/ABS(L21)>$R$9,"Surprise",IF((N21-L21)/ABS(L21)<$R$9*-1,"Shock",""))) | S21: =VLOOKUP($C21,'2027'!$B$14:$T$3000,S$5,FALSE) -> -19.92 | T21: =VLOOKUP($C21,'2027'!$B$14:$T$3000,T$5,FALSE) -> -0.05 | X21: =X20+1 -> 24 | Y21: A035760 | Z21: CJ오쇼핑
B22: 130 | C22: =VLOOKUP(B22,'2027'!$A$14:$B$4000,2,FALSE) -> A097950 | D22: =VLOOKUP($C22,'2027'!$B$14:$T$4000,D$5,FALSE) -> CJ제일제당 | E22: =VLOOKUP($C22,'2027'!$B$14:$T$4000,E$5,FALSE) -> KS | F22: =VLOOKUP($C22,'2027'!$B$14:$T$4000,F$5,FALSE) -> 식품,음료 | G22: =VLOOKUP($C22,'2027'!$B$14:$T$4000,G$5,FALSE) -> 2827.18 | H22: =VLOOKUP($C22,'2027'!$B$14:$T$4000,H$5,FALSE) -> 12 | I22: =VLOOKUP($C22,'2027'!$B$14:$T$4000,I$5,FALSE) -> 1467.58 | J22: =VLOOKUP($C22,'2027'!$B$14:$T$4000,J$5,FALSE) -> 1465.76 | K22: =VLOOKUP($C22,'2027'!$B$14:$T$4000,K$5,FALSE) -> 1468.42 | L22: =VLOOKUP($C22,'2027'!$B$14:$T$4000,L$5,FALSE) -> 1474.93 | M22: =(L22-K22)/ABS(K22)*100 -> 0.44333365 | N22: =IF(ISBLANK(VLOOKUP($C22,'2027'!$B$14:$T$3000,N$5,FALSE)),"",VLOOKUP($C22,'2027'!$B$14:$T$3000,N$5,FALSE)) | O22: =IF(AND(I22<K22,J22<L22,K22<L22),1,IF(AND(I22>K22,J22>L22,K22>L22),-1,0)) -> 1 | P22: =IF(ISBLANK(VLOOKUP($C22,'2027'!$B$14:$T$3000,P$5,FALSE)),"",VLOOKUP($C22,'2027'!$B$14:$T$3000,P$5,FALSE)) | Q22: =IF(O22=1,"Surprise",IF(O22=-1,"Shock","")) -> Surprise | R22: =IF(N22="","",IF((N22-L22)/ABS(L22)>$R$9,"Surprise",IF((N22-L22)/ABS(L22)<$R$9*-1,"Shock",""))) | S22: =VLOOKUP($C22,'2027'!$B$14:$T$3000,S$5,FALSE) -> -7.71 | T22: =VLOOKUP($C22,'2027'!$B$14:$T$3000,T$5,FALSE) -> -14.64 | X22: =#REF!+1 -> #REF! | Y22: A063080 | Z22: 게임빌
B23: 80 | C23: =VLOOKUP(B23,'2027'!$A$14:$B$4000,2,FALSE) -> A004170 | D23: =VLOOKUP($C23,'2027'!$B$14:$T$4000,D$5,FALSE) -> 신세계 | E23: =VLOOKUP($C23,'2027'!$B$14:$T$4000,E$5,FALSE) -> KS | F23: =VLOOKUP($C23,'2027'!$B$14:$T$4000,F$5,FALSE) -> 백화점 | G23: =VLOOKUP($C23,'2027'!$B$14:$T$4000,G$5,FALSE) -> 7329.46 | H23: =VLOOKUP($C23,'2027'!$B$14:$T$4000,H$5,FALSE) -> 18 | I23: =VLOOKUP($C23,'2027'!$B$14:$T$4000,I$5,FALSE) -> 831.38 | J23: =VLOOKUP($C23,'2027'!$B$14:$T$4000,J$5,FALSE) -> 874.93 | K23: =VLOOKUP($C23,'2027'!$B$14:$T$4000,K$5,FALSE) -> 836.96 | L23: =VLOOKUP($C23,'2027'!$B$14:$T$4000,L$5,FALSE) -> 883.19 | M23: =(L23-K23)/ABS(K23)*100 -> 5.5235615 | N23: =IF(ISBLANK(VLOOKUP($C23,'2027'!$B$14:$T$3000,N$5,FALSE)),"",VLOOKUP($C23,'2027'!$B$14:$T$3000,N$5,FALSE)) | O23: =IF(AND(I23<K23,J23<L23,K23<L23),1,IF(AND(I23>K23,J23>L23,K23>L23),-1,0)) -> 1 | P23: =IF(ISBLANK(VLOOKUP($C23,'2027'!$B$14:$T$3000,P$5,FALSE)),"",VLOOKUP($C23,'2027'!$B$14:$T$3000,P$5,FALSE)) | Q23: =IF(O23=1,"Surprise",IF(O23=-1,"Shock","")) -> Surprise | R23: =IF(N23="","",IF((N23-L23)/ABS(L23)>$R$9,"Surprise",IF((N23-L23)/ABS(L23)<$R$9*-1,"Shock",""))) | S23: =VLOOKUP($C23,'2027'!$B$14:$T$3000,S$5,FALSE) -> 50.39 | T23: =VLOOKUP($C23,'2027'!$B$14:$T$3000,T$5,FALSE) -> 145.18 | X23: =X22+1 -> #REF! | Y23: A009150 | Z23: 삼성전기
B24: 89 | C24: =VLOOKUP(B24,'2027'!$A$14:$B$4000,2,FALSE) -> A222800 | D24: =VLOOKUP($C24,'2027'!$B$14:$T$4000,D$5,FALSE) -> 심텍 | E24: =VLOOKUP($C24,'2027'!$B$14:$T$4000,E$5,FALSE) -> KQ | F24: =VLOOKUP($C24,'2027'!$B$14:$T$4000,F$5,FALSE) -> 전자장비,사무용전자제품 | G24: =VLOOKUP($C24,'2027'!$B$14:$T$4000,G$5,FALSE) -> 5893.08 | H24: =VLOOKUP($C24,'2027'!$B$14:$T$4000,H$5,FALSE) -> 8 | I24: =VLOOKUP($C24,'2027'!$B$14:$T$4000,I$5,FALSE) -> 271.44 | J24: =VLOOKUP($C24,'2027'!$B$14:$T$4000,J$5,FALSE) -> 287.24 | K24: =VLOOKUP($C24,'2027'!$B$14:$T$4000,K$5,FALSE) -> 284.26 | L24: =VLOOKUP($C24,'2027'!$B$14:$T$4000,L$5,FALSE) -> 299.1 | M24: =(L24-K24)/ABS(K24)*100 -> 5.2205727 | N24: =IF(ISBLANK(VLOOKUP($C24,'2027'!$B$14:$T$3000,N$5,FALSE)),"",VLOOKUP($C24,'2027'!$B$14:$T$3000,N$5,FALSE)) | O24: =IF(AND(I24<K24,J24<L24,K24<L24),1,IF(AND(I24>K24,J24>L24,K24>L24),-1,0)) -> 1 | P24: =IF(ISBLANK(VLOOKUP($C24,'2027'!$B$14:$T$3000,P$5,FALSE)),"",VLOOKUP($C24,'2027'!$B$14:$T$3000,P$5,FALSE)) | Q24: =IF(O24=1,"Surprise",IF(O24=-1,"Shock","")) -> Surprise | R24: =IF(N24="","",IF((N24-L24)/ABS(L24)>$R$9,"Surprise",IF((N24-L24)/ABS(L24)<$R$9*-1,"Shock",""))) | S24: =VLOOKUP($C24,'2027'!$B$14:$T$3000,S$5,FALSE) -> 56.99 | T24: =VLOOKUP($C24,'2027'!$B$14:$T$3000,T$5,FALSE) -> 197.35 | X24: =X23+1 -> #REF! | Y24: A108670 | Z24: LG하우시스
B25: 141 | C25: =VLOOKUP(B25,'2027'!$A$14:$B$4000,2,FALSE) -> A263750 | D25: =VLOOKUP($C25,'2027'!$B$14:$T$4000,D$5,FALSE) -> 펄어비스 | E25: =VLOOKUP($C25,'2027'!$B$14:$T$4000,E$5,FALSE) -> KQ | F25: =VLOOKUP($C25,'2027'!$B$14:$T$4000,F$5,FALSE) -> 게임소프트웨어 | G25: =VLOOKUP($C25,'2027'!$B$14:$T$4000,G$5,FALSE) -> 2372.36 | H25: =VLOOKUP($C25,'2027'!$B$14:$T$4000,H$5,FALSE) -> 9 | I25: =VLOOKUP($C25,'2027'!$B$14:$T$4000,I$5,FALSE) -> 176.48 | J25: =VLOOKUP($C25,'2027'!$B$14:$T$4000,J$5,FALSE) -> 68.9 | K25: =VLOOKUP($C25,'2027'!$B$14:$T$4000,K$5,FALSE) -> 177.79 | L25: =VLOOKUP($C25,'2027'!$B$14:$T$4000,L$5,FALSE) -> 188.3 | M25: =(L25-K25)/ABS(K25)*100 -> 5.9114686 | N25: =IF(ISBLANK(VLOOKUP($C25,'2027'!$B$14:$T$3000,N$5,FALSE)),"",VLOOKUP($C25,'2027'!$B$14:$T$3000,N$5,FALSE)) | O25: =IF(AND(I25<K25,J25<L25,K25<L25),1,IF(AND(I25>K25,J25>L25,K25>L25),-1,0)) -> 1 | P25: =IF(ISBLANK(VLOOKUP($C25,'2027'!$B$14:$T$3000,P$5,FALSE)),"",VLOOKUP($C25,'2027'!$B$14:$T$3000,P$5,FALSE)) | Q25: =IF(O25=1,"Surprise",IF(O25=-1,"Shock","")) -> Surprise | R25: =IF(N25="","",IF((N25-L25)/ABS(L25)>$R$9,"Surprise",IF((N25-L25)/ABS(L25)<$R$9*-1,"Shock",""))) | S25: =VLOOKUP($C25,'2027'!$B$14:$T$3000,S$5,FALSE) -> -13.42 | T25: =VLOOKUP($C25,'2027'!$B$14:$T$3000,T$5,FALSE) -> -47.57 | X25: =X24+1 -> #REF! | Y25: A097230 | Z25: 한진중공업
B26: 64 | C26: =VLOOKUP(B26,'2027'!$A$14:$B$4000,2,FALSE) -> A005940 | D26: =VLOOKUP($C26,'2027'!$B$14:$T$4000,D$5,FALSE) -> NH투자증권 | E26: =VLOOKUP($C26,'2027'!$B$14:$T$4000,E$5,FALSE) -> KS | F26: =VLOOKUP($C26,'2027'!$B$14:$T$4000,F$5,FALSE) -> 증권 | G26: =VLOOKUP($C26,'2027'!$B$14:$T$4000,G$5,FALSE) -> 10529.98 | H26: =VLOOKUP($C26,'2027'!$B$14:$T$4000,H$5,FALSE) -> 17 | I26: =VLOOKUP($C26,'2027'!$B$14:$T$4000,I$5,FALSE) -> 1915.35 | J26: =VLOOKUP($C26,'2027'!$B$14:$T$4000,J$5,FALSE) -> 1912.78 | K26: =VLOOKUP($C26,'2027'!$B$14:$T$4000,K$5,FALSE) -> 1927.88 | L26: =VLOOKUP($C26,'2027'!$B$14:$T$4000,L$5,FALSE) -> 1937.53 | M26: =(L26-K26)/ABS(K26)*100 -> 0.50054983 | N26: =IF(ISBLANK(VLOOKUP($C26,'2027'!$B$14:$T$3000,N$5,FALSE)),"",VLOOKUP($C26,'2027'!$B$14:$T$3000,N$5,FALSE)) | O26: =IF(AND(I26<K26,J26<L26,K26<L26),1,IF(AND(I26>K26,J26>L26,K26>L26),-1,0)) -> 1 | P26: =IF(ISBLANK(VLOOKUP($C26,'2027'!$B$14:$T$3000,P$5,FALSE)),"",VLOOKUP($C26,'2027'!$B$14:$T$3000,P$5,FALSE)) | Q26: =IF(O26=1,"Surprise",IF(O26=-1,"Shock","")) -> Surprise | R26: =IF(N26="","",IF((N26-L26)/ABS(L26)>$R$9,"Surprise",IF((N26-L26)/ABS(L26)<$R$9*-1,"Shock",""))) | S26: =VLOOKUP($C26,'2027'!$B$14:$T$3000,S$5,FALSE) -> -5.29 | T26: =VLOOKUP($C26,'2027'!$B$14:$T$3000,T$5,FALSE) -> -7.22 | X26: =X25+1 -> #REF! | Y26: A020560 | Z26: 아시아나항공
B27: 22 | C27: =VLOOKUP(B27,'2027'!$A$14:$B$4000,2,FALSE) -> A298040 | D27: =VLOOKUP($C27,'2027'!$B$14:$T$4000,D$5,FALSE) -> 효성중공업 | E27: =VLOOKUP($C27,'2027'!$B$14:$T$4000,E$5,FALSE) -> KS | F27: =VLOOKUP($C27,'2027'!$B$14:$T$4000,F$5,FALSE) -> 전기장비 | G27: =VLOOKUP($C27,'2027'!$B$14:$T$4000,G$5,FALSE) -> 34668.67 | H27: =VLOOKUP($C27,'2027'!$B$14:$T$4000,H$5,FALSE) -> 13 | I27: =VLOOKUP($C27,'2027'!$B$14:$T$4000,I$5,FALSE) -> 1534.45 | J27: =VLOOKUP($C27,'2027'!$B$14:$T$4000,J$5,FALSE) -> 1515.36 | K27: =VLOOKUP($C27,'2027'!$B$14:$T$4000,K$5,FALSE) -> 1547.76 | L27: =VLOOKUP($C27,'2027'!$B$14:$T$4000,L$5,FALSE) -> 1559.23 | M27: =(L27-K27)/ABS(K27)*100 -> 0.74107097 | N27: =IF(ISBLANK(VLOOKUP($C27,'2027'!$B$14:$T$3000,N$5,FALSE)),"",VLOOKUP($C27,'2027'!$B$14:$T$3000,N$5,FALSE)) | O27: =IF(AND(I27<K27,J27<L27,K27<L27),1,IF(AND(I27>K27,J27>L27,K27>L27),-1,0)) -> 1 | P27: =IF(ISBLANK(VLOOKUP($C27,'2027'!$B$14:$T$3000,P$5,FALSE)),"",VLOOKUP($C27,'2027'!$B$14:$T$3000,P$5,FALSE)) | Q27: =IF(O27=1,"Surprise",IF(O27=-1,"Shock","")) -> Surprise | R27: =IF(N27="","",IF((N27-L27)/ABS(L27)>$R$9,"Surprise",IF((N27-L27)/ABS(L27)<$R$9*-1,"Shock",""))) | S27: =VLOOKUP($C27,'2027'!$B$14:$T$3000,S$5,FALSE) -> -2.44 | T27: =VLOOKUP($C27,'2027'!$B$14:$T$3000,T$5,FALSE) -> 40.14 | X27: =X26+1 -> #REF! | Y27: A117930 | Z27: 한진해운
B28: 13 | C28: =VLOOKUP(B28,'2027'!$A$14:$B$4000,2,FALSE) -> A105560 | D28: =VLOOKUP($C28,'2027'!$B$14:$T$4000,D$5,FALSE) -> KB금융 | E28: =VLOOKUP($C28,'2027'!$B$14:$T$4000,E$5,FALSE) -> KS | F28: =VLOOKUP($C28,'2027'!$B$14:$T$4000,F$5,FALSE) -> 은행 | G28: =VLOOKUP($C28,'2027'!$B$14:$T$4000,G$5,FALSE) -> 56218.01 | H28: =VLOOKUP($C28,'2027'!$B$14:$T$4000,H$5,FALSE) -> 19 | I28: =VLOOKUP($C28,'2027'!$B$14:$T$4000,I$5,FALSE) -> 9339.91 | J28: =VLOOKUP($C28,'2027'!$B$14:$T$4000,J$5,FALSE) -> 9436.96 | K28: =VLOOKUP($C28,'2027'!$B$14:$T$4000,K$5,FALSE) -> 9437.97 | L28: =VLOOKUP($C28,'2027'!$B$14:$T$4000,L$5,FALSE) -> 9543.57 | M28: =(L28-K28)/ABS(K28)*100 -> 1.1188847 | N28: =IF(ISBLANK(VLOOKUP($C28,'2027'!$B$14:$T$3000,N$5,FALSE)),"",VLOOKUP($C28,'2027'!$B$14:$T$3000,N$5,FALSE)) | O28: =IF(AND(I28<K28,J28<L28,K28<L28),1,IF(AND(I28>K28,J28>L28,K28>L28),-1,0)) -> 1 | P28: =IF(ISBLANK(VLOOKUP($C28,'2027'!$B$14:$T$3000,P$5,FALSE)),"",VLOOKUP($C28,'2027'!$B$14:$T$3000,P$5,FALSE)) | Q28: =IF(O28=1,"Surprise",IF(O28=-1,"Shock","")) -> Surprise | R28: =IF(N28="","",IF((N28-L28)/ABS(L28)>$R$9,"Surprise",IF((N28-L28)/ABS(L28)<$R$9*-1,"Shock",""))) | S28: =VLOOKUP($C28,'2027'!$B$14:$T$3000,S$5,FALSE) -> 4.21 | T28: =VLOOKUP($C28,'2027'!$B$14:$T$3000,T$5,FALSE) -> 6.88 | X28: =X27+1 -> #REF! | Y28: A010060 | Z28: OCI | AE28: 1
B29: 102 | C29: =VLOOKUP(B29,'2027'!$A$14:$B$4000,2,FALSE) -> A066970 | D29: =VLOOKUP($C29,'2027'!$B$14:$T$4000,D$5,FALSE) -> 엘앤에프 | E29: =VLOOKUP($C29,'2027'!$B$14:$T$4000,E$5,FALSE) -> KS | F29: =VLOOKUP($C29,'2027'!$B$14:$T$4000,F$5,FALSE) -> 전기제품 | G29: =VLOOKUP($C29,'2027'!$B$14:$T$4000,G$5,FALSE) -> 4462.47 | H29: =VLOOKUP($C29,'2027'!$B$14:$T$4000,H$5,FALSE) -> 20 | I29: =VLOOKUP($C29,'2027'!$B$14:$T$4000,I$5,FALSE) -> 222.13 | J29: =VLOOKUP($C29,'2027'!$B$14:$T$4000,J$5,FALSE) -> 232.67 | K29: =VLOOKUP($C29,'2027'!$B$14:$T$4000,K$5,FALSE) -> 230.54 | L29: =VLOOKUP($C29,'2027'!$B$14:$T$4000,L$5,FALSE) -> 242.18 | M29: =(L29-K29)/ABS(K29)*100 -> 5.0490154 | N29: =IF(ISBLANK(VLOOKUP($C29,'2027'!$B$14:$T$3000,N$5,FALSE)),"",VLOOKUP($C29,'2027'!$B$14:$T$3000,N$5,FALSE)) | O29: =IF(AND(I29<K29,J29<L29,K29<L29),1,IF(AND(I29>K29,J29>L29,K29>L29),-1,0)) -> 1 | P29: =IF(ISBLANK(VLOOKUP($C29,'2027'!$B$14:$T$3000,P$5,FALSE)),"",VLOOKUP($C29,'2027'!$B$14:$T$3000,P$5,FALSE)) | Q29: =IF(O29=1,"Surprise",IF(O29=-1,"Shock","")) -> Surprise | R29: =IF(N29="","",IF((N29-L29)/ABS(L29)>$R$9,"Surprise",IF((N29-L29)/ABS(L29)<$R$9*-1,"Shock",""))) | S29: =VLOOKUP($C29,'2027'!$B$14:$T$3000,S$5,FALSE) -> -29.03 | T29: =VLOOKUP($C29,'2027'!$B$14:$T$3000,T$5,FALSE) -> -25.37 | X29: =X28+1 -> #REF! | Y29: A006800 | Z29: 대우증권
B30: 105 | C30: =VLOOKUP(B30,'2027'!$A$14:$B$4000,2,FALSE) -> A095610 | D30: =VLOOKUP($C30,'2027'!$B$14:$T$4000,D$5,FALSE) -> 테스 | E30: =VLOOKUP($C30,'2027'!$B$14:$T$4000,E$5,FALSE) -> KQ | F30: =VLOOKUP($C30,'2027'!$B$14:$T$4000,F$5,FALSE) -> 반도체 | G30: =VLOOKUP($C30,'2027'!$B$14:$T$4000,G$5,FALSE) -> 4123.68 | H30: =VLOOKUP($C30,'2027'!$B$14:$T$4000,H$5,FALSE) -> 7 | I30: =VLOOKUP($C30,'2027'!$B$14:$T$4000,I$5,FALSE) -> 127.43 | J30: =VLOOKUP($C30,'2027'!$B$14:$T$4000,J$5,FALSE) -> 138.95 | K30: =VLOOKUP($C30,'2027'!$B$14:$T$4000,K$5,FALSE) -> 132.16 | L30: =VLOOKUP($C30,'2027'!$B$14:$T$4000,L$5,FALSE) -> 139.1 | M30: =(L30-K30)/ABS(K30)*100 -> 5.2512107 | N30: =IF(ISBLANK(VLOOKUP($C30,'2027'!$B$14:$T$3000,N$5,FALSE)),"",VLOOKUP($C30,'2027'!$B$14:$T$3000,N$5,FALSE)) | O30: =IF(AND(I30<K30,J30<L30,K30<L30),1,IF(AND(I30>K30,J30>L30,K30>L30),-1,0)) -> 1 | P30: =IF(ISBLANK(VLOOKUP($C30,'2027'!$B$14:$T$3000,P$5,FALSE)),"",VLOOKUP($C30,'2027'!$B$14:$T$3000,P$5,FALSE)) | Q30: =IF(O30=1,"Surprise",IF(O30=-1,"Shock","")) -> Surprise | R30: =IF(N30="","",IF((N30-L30)/ABS(L30)>$R$9,"Surprise",IF((N30-L30)/ABS(L30)<$R$9*-1,"Shock",""))) | S30: =VLOOKUP($C30,'2027'!$B$14:$T$3000,S$5,FALSE) -> 91.37 | T30: =VLOOKUP($C30,'2027'!$B$14:$T$3000,T$5,FALSE) -> 247.47
B31: 44 | C31: =VLOOKUP(B31,'2027'!$A$14:$B$4000,2,FALSE) -> A079550 | D31: =VLOOKUP($C31,'2027'!$B$14:$T$4000,D$5,FALSE) -> LIG디펜스앤에어로스페이스 | E31: =VLOOKUP($C31,'2027'!$B$14:$T$4000,E$5,FALSE) -> KS | F31: =VLOOKUP($C31,'2027'!$B$14:$T$4000,F$5,FALSE) -> 기타자본재 | G31: =VLOOKUP($C31,'2027'!$B$14:$T$4000,G$5,FALSE) -> 16940 | H31: =VLOOKUP($C31,'2027'!$B$14:$T$4000,H$5,FALSE) -> 18 | I31: =VLOOKUP($C31,'2027'!$B$14:$T$4000,I$5,FALSE) -> 616.78 | J31: =VLOOKUP($C31,'2027'!$B$14:$T$4000,J$5,FALSE) -> 626.09 | K31: =VLOOKUP($C31,'2027'!$B$14:$T$4000,K$5,FALSE) -> 618.43 | L31: =VLOOKUP($C31,'2027'!$B$14:$T$4000,L$5,FALSE) -> 671.48 | M31: =(L31-K31)/ABS(K31)*100 -> 8.5781738 | N31: =IF(ISBLANK(VLOOKUP($C31,'2027'!$B$14:$T$3000,N$5,FALSE)),"",VLOOKUP($C31,'2027'!$B$14:$T$3000,N$5,FALSE)) | O31: =IF(AND(I31<K31,J31<L31,K31<L31),1,IF(AND(I31>K31,J31>L31,K31>L31),-1,0)) -> 1 | P31: =IF(ISBLANK(VLOOKUP($C31,'2027'!$B$14:$T$3000,P$5,FALSE)),"",VLOOKUP($C31,'2027'!$B$14:$T$3000,P$5,FALSE)) | Q31: =IF(O31=1,"Surprise",IF(O31=-1,"Shock","")) -> Surprise | R31: =IF(N31="","",IF((N31-L31)/ABS(L31)>$R$9,"Surprise",IF((N31-L31)/ABS(L31)<$R$9*-1,"Shock",""))) | S31: =VLOOKUP($C31,'2027'!$B$14:$T$3000,S$5,FALSE) -> -0.77 | T31: =VLOOKUP($C31,'2027'!$B$14:$T$3000,T$5,FALSE) -> -3.02 | X31: =X30+1 -> 1 | Y31: A170900 | Z31: 동아에스티 | AE31: 1
B32: 138 | C32: =VLOOKUP(B32,'2027'!$A$14:$B$4000,2,FALSE) -> A161890 | D32: =VLOOKUP($C32,'2027'!$B$14:$T$4000,D$5,FALSE) -> 한국콜마 | E32: =VLOOKUP($C32,'2027'!$B$14:$T$4000,E$5,FALSE) -> KS | F32: =VLOOKUP($C32,'2027'!$B$14:$T$4000,F$5,FALSE) -> 화장품 | G32: =VLOOKUP($C32,'2027'!$B$14:$T$4000,G$5,FALSE) -> 2521.02 | H32: =VLOOKUP($C32,'2027'!$B$14:$T$4000,H$5,FALSE) -> 19 | I32: =VLOOKUP($C32,'2027'!$B$14:$T$4000,I$5,FALSE) -> 352.46 | J32: =VLOOKUP($C32,'2027'!$B$14:$T$4000,J$5,FALSE) -> 358.9 | K32: =VLOOKUP($C32,'2027'!$B$14:$T$4000,K$5,FALSE) -> 356.8 | L32: =VLOOKUP($C32,'2027'!$B$14:$T$4000,L$5,FALSE) -> 364.85 | M32: =(L32-K32)/ABS(K32)*100 -> 2.2561659 | N32: =IF(ISBLANK(VLOOKUP($C32,'2027'!$B$14:$T$3000,N$5,FALSE)),"",VLOOKUP($C32,'2027'!$B$14:$T$3000,N$5,FALSE)) | O32: =IF(AND(I32<K32,J32<L32,K32<L32),1,IF(AND(I32>K32,J32>L32,K32>L32),-1,0)) -> 1 | P32: =IF(ISBLANK(VLOOKUP($C32,'2027'!$B$14:$T$3000,P$5,FALSE)),"",VLOOKUP($C32,'2027'!$B$14:$T$3000,P$5,FALSE)) | Q32: =IF(O32=1,"Surprise",IF(O32=-1,"Shock","")) -> Surprise | R32: =IF(N32="","",IF((N32-L32)/ABS(L32)>$R$9,"Surprise",IF((N32-L32)/ABS(L32)<$R$9*-1,"Shock",""))) | S32: =VLOOKUP($C32,'2027'!$B$14:$T$3000,S$5,FALSE) -> 24.91 | T32: =VLOOKUP($C32,'2027'!$B$14:$T$3000,T$5,FALSE) -> 35.88
B33: 117 | C33: =VLOOKUP(B33,'2027'!$A$14:$B$4000,2,FALSE) -> A145020 | D33: =VLOOKUP($C33,'2027'!$B$14:$T$4000,D$5,FALSE) -> 휴젤 | E33: =VLOOKUP($C33,'2027'!$B$14:$T$4000,E$5,FALSE) -> KQ | F33: =VLOOKUP($C33,'2027'!$B$14:$T$4000,F$5,FALSE) -> 생명과학 | G33: =VLOOKUP($C33,'2027'!$B$14:$T$4000,G$5,FALSE) -> 3377.46 | H33: =VLOOKUP($C33,'2027'!$B$14:$T$4000,H$5,FALSE) -> 13 | I33: =VLOOKUP($C33,'2027'!$B$14:$T$4000,I$5,FALSE) -> 276.8 | J33: =VLOOKUP($C33,'2027'!$B$14:$T$4000,J$5,FALSE) -> 279.1 | K33: =VLOOKUP($C33,'2027'!$B$14:$T$4000,K$5,FALSE) -> 278.82 | L33: =VLOOKUP($C33,'2027'!$B$14:$T$4000,L$5,FALSE) -> 287.07 | M33: =(L33-K33)/ABS(K33)*100 -> 2.9588982 | N33: =IF(ISBLANK(VLOOKUP($C33,'2027'!$B$14:$T$3000,N$5,FALSE)),"",VLOOKUP($C33,'2027'!$B$14:$T$3000,N$5,FALSE)) | O33: =IF(AND(I33<K33,J33<L33,K33<L33),1,IF(AND(I33>K33,J33>L33,K33>L33),-1,0)) -> 1 | P33: =IF(ISBLANK(VLOOKUP($C33,'2027'!$B$14:$T$3000,P$5,FALSE)),"",VLOOKUP($C33,'2027'!$B$14:$T$3000,P$5,FALSE)) | Q33: =IF(O33=1,"Surprise",IF(O33=-1,"Shock","")) -> Surprise | R33: =IF(N33="","",IF((N33-L33)/ABS(L33)>$R$9,"Surprise",IF((N33-L33)/ABS(L33)<$R$9*-1,"Shock",""))) | S33: =VLOOKUP($C33,'2027'!$B$14:$T$3000,S$5,FALSE) -> 10.46 | T33: =VLOOKUP($C33,'2027'!$B$14:$T$3000,T$5,FALSE) -> 6.81
B34: 51 | C34: =VLOOKUP(B34,'2027'!$A$14:$B$4000,2,FALSE) -> A003670 | D34: =VLOOKUP($C34,'2027'!$B$14:$T$4000,D$5,FALSE) -> 포스코퓨처엠 | E34: =VLOOKUP($C34,'2027'!$B$14:$T$4000,E$5,FALSE) -> KS | F34: =VLOOKUP($C34,'2027'!$B$14:$T$4000,F$5,FALSE) -> 화학 | G34: =VLOOKUP($C34,'2027'!$B$14:$T$4000,G$5,FALSE) -> 15138.65 | H34: =VLOOKUP($C34,'2027'!$B$14:$T$4000,H$5,FALSE) -> 16 | I34: =VLOOKUP($C34,'2027'!$B$14:$T$4000,I$5,FALSE) -> 161.56 | J34: =VLOOKUP($C34,'2027'!$B$14:$T$4000,J$5,FALSE) -> 158.7 | K34: =VLOOKUP($C34,'2027'!$B$14:$T$4000,K$5,FALSE) -> 167.06 | L34: =VLOOKUP($C34,'2027'!$B$14:$T$4000,L$5,FALSE) -> 207.73 | M34: =(L34-K34)/ABS(K34)*100 -> 24.344547 | N34: =IF(ISBLANK(VLOOKUP($C34,'2027'!$B$14:$T$3000,N$5,FALSE)),"",VLOOKUP($C34,'2027'!$B$14:$T$3000,N$5,FALSE)) | O34: =IF(AND(I34<K34,J34<L34,K34<L34),1,IF(AND(I34>K34,J34>L34,K34>L34),-1,0)) -> 1 | P34: =IF(ISBLANK(VLOOKUP($C34,'2027'!$B$14:$T$3000,P$5,FALSE)),"",VLOOKUP($C34,'2027'!$B$14:$T$3000,P$5,FALSE)) | Q34: =IF(O34=1,"Surprise",IF(O34=-1,"Shock","")) -> Surprise | R34: =IF(N34="","",IF((N34-L34)/ABS(L34)>$R$9,"Surprise",IF((N34-L34)/ABS(L34)<$R$9*-1,"Shock",""))) | S34: =VLOOKUP($C34,'2027'!$B$14:$T$3000,S$5,FALSE) -> -26.32 | T34: =VLOOKUP($C34,'2027'!$B$14:$T$3000,T$5,FALSE) -> -19.53
B35: 34 | C35: =VLOOKUP(B35,'2027'!$A$14:$B$4000,2,FALSE) -> A011070 | D35: =VLOOKUP($C35,'2027'!$B$14:$T$4000,D$5,FALSE) -> LG이노텍 | E35: =VLOOKUP($C35,'2027'!$B$14:$T$4000,E$5,FALSE) -> KS | F35: =VLOOKUP($C35,'2027'!$B$14:$T$4000,F$5,FALSE) -> 전자장비,사무용전자제품 | G35: =VLOOKUP($C35,'2027'!$B$14:$T$4000,G$5,FALSE) -> 21466.07 | H35: =VLOOKUP($C35,'2027'!$B$14:$T$4000,H$5,FALSE) -> 21 | I35: =VLOOKUP($C35,'2027'!$B$14:$T$4000,I$5,FALSE) -> 1308.03 | J35: =VLOOKUP($C35,'2027'!$B$14:$T$4000,J$5,FALSE) -> 1414.76 | K35: =VLOOKUP($C35,'2027'!$B$14:$T$4000,K$5,FALSE) -> 1318.53 | L35: =VLOOKUP($C35,'2027'!$B$14:$T$4000,L$5,FALSE) -> 1446.02 | M35: =(L35-K35)/ABS(K35)*100 -> 9.6691012 | N35: =IF(ISBLANK(VLOOKUP($C35,'2027'!$B$14:$T$3000,N$5,FALSE)),"",VLOOKUP($C35,'2027'!$B$14:$T$3000,N$5,FALSE)) | O35: =IF(AND(I35<K35,J35<L35,K35<L35),1,IF(AND(I35>K35,J35>L35,K35>L35),-1,0)) -> 1 | P35: =IF(ISBLANK(VLOOKUP($C35,'2027'!$B$14:$T$3000,P$5,FALSE)),"",VLOOKUP($C35,'2027'!$B$14:$T$3000,P$5,FALSE)) | Q35: =IF(O35=1,"Surprise",IF(O35=-1,"Shock","")) -> Surprise | R35: =IF(N35="","",IF((N35-L35)/ABS(L35)>$R$9,"Surprise",IF((N35-L35)/ABS(L35)<$R$9*-1,"Shock",""))) | S35: =VLOOKUP($C35,'2027'!$B$14:$T$3000,S$5,FALSE) -> -40.72 | T35: =VLOOKUP($C35,'2027'!$B$14:$T$3000,T$5,FALSE) -> 164.43 | X35: =X34+1 -> 1 | Y35: A097950 | Z35: CJ제일제당
B36: 10 | C36: =VLOOKUP(B36,'2027'!$A$14:$B$4000,2,FALSE) -> A329180 | D36: =VLOOKUP($C36,'2027'!$B$14:$T$4000,D$5,FALSE) -> HD현대중공업 | E36: =VLOOKUP($C36,'2027'!$B$14:$T$4000,E$5,FALSE) -> KS | F36: =VLOOKUP($C36,'2027'!$B$14:$T$4000,F$5,FALSE) -> 조선 | G36: =VLOOKUP($C36,'2027'!$B$14:$T$4000,G$5,FALSE) -> 64551.15 | H36: =VLOOKUP($C36,'2027'!$B$14:$T$4000,H$5,FALSE) -> 20 | I36: =VLOOKUP($C36,'2027'!$B$14:$T$4000,I$5,FALSE) -> 4532.36 | J36: =VLOOKUP($C36,'2027'!$B$14:$T$4000,J$5,FALSE) -> 4458.38 | K36: =VLOOKUP($C36,'2027'!$B$14:$T$4000,K$5,FALSE) -> 4534.42 | L36: =VLOOKUP($C36,'2027'!$B$14:$T$4000,L$5,FALSE) -> 4666.04 | M36: =(L36-K36)/ABS(K36)*100 -> 2.9026866 | N36: =IF(ISBLANK(VLOOKUP($C36,'2027'!$B$14:$T$3000,N$5,FALSE)),"",VLOOKUP($C36,'2027'!$B$14:$T$3000,N$5,FALSE)) | O36: =IF(AND(I36<K36,J36<L36,K36<L36),1,IF(AND(I36>K36,J36>L36,K36>L36),-1,0)) -> 1 | P36: =IF(ISBLANK(VLOOKUP($C36,'2027'!$B$14:$T$3000,P$5,FALSE)),"",VLOOKUP($C36,'2027'!$B$14:$T$3000,P$5,FALSE)) | Q36: =IF(O36=1,"Surprise",IF(O36=-1,"Shock","")) -> Surprise | R36: =IF(N36="","",IF((N36-L36)/ABS(L36)>$R$9,"Surprise",IF((N36-L36)/ABS(L36)<$R$9*-1,"Shock",""))) | S36: =VLOOKUP($C36,'2027'!$B$14:$T$3000,S$5,FALSE) -> -10.09 | T36: =VLOOKUP($C36,'2027'!$B$14:$T$3000,T$5,FALSE) -> 36.21 | X36: =X35+1 -> 2 | Y36: A112040 | Z36: 위메이드
B37: 43 | C37: =VLOOKUP(B37,'2027'!$A$14:$B$4000,2,FALSE) -> A033780 | D37: =VLOOKUP($C37,'2027'!$B$14:$T$4000,D$5,FALSE) -> KT&G | E37: =VLOOKUP($C37,'2027'!$B$14:$T$4000,E$5,FALSE) -> KS | F37: =VLOOKUP($C37,'2027'!$B$14:$T$4000,F$5,FALSE) -> 담배 | G37: =VLOOKUP($C37,'2027'!$B$14:$T$4000,G$5,FALSE) -> 17346.73 | H37: =VLOOKUP($C37,'2027'!$B$14:$T$4000,H$5,FALSE) -> 14 | I37: =VLOOKUP($C37,'2027'!$B$14:$T$4000,I$5,FALSE) -> 1624.68 | J37: =VLOOKUP($C37,'2027'!$B$14:$T$4000,J$5,FALSE) -> 1625.14 | K37: =VLOOKUP($C37,'2027'!$B$14:$T$4000,K$5,FALSE) -> 1627.27 | L37: =VLOOKUP($C37,'2027'!$B$14:$T$4000,L$5,FALSE) -> 1631.23 | M37: =(L37-K37)/ABS(K37)*100 -> 0.24335236 | N37: =IF(ISBLANK(VLOOKUP($C37,'2027'!$B$14:$T$3000,N$5,FALSE)),"",VLOOKUP($C37,'2027'!$B$14:$T$3000,N$5,FALSE)) | O37: =IF(AND(I37<K37,J37<L37,K37<L37),1,IF(AND(I37>K37,J37>L37,K37>L37),-1,0)) -> 1 | P37: =IF(ISBLANK(VLOOKUP($C37,'2027'!$B$14:$T$3000,P$5,FALSE)),"",VLOOKUP($C37,'2027'!$B$14:$T$3000,P$5,FALSE)) | Q37: =IF(O37=1,"Surprise",IF(O37=-1,"Shock","")) -> Surprise | R37: =IF(N37="","",IF((N37-L37)/ABS(L37)>$R$9,"Surprise",IF((N37-L37)/ABS(L37)<$R$9*-1,"Shock",""))) | S37: =VLOOKUP($C37,'2027'!$B$14:$T$3000,S$5,FALSE) -> -9.72 | T37: =VLOOKUP($C37,'2027'!$B$14:$T$3000,T$5,FALSE) -> 4.44 | X37: =X36+1 -> 3 | Y37: A035720 | Z37: 다음
B38: 85 | C38: =VLOOKUP(B38,'2027'!$A$14:$B$4000,2,FALSE) -> A319660 | D38: =VLOOKUP($C38,'2027'!$B$14:$T$4000,D$5,FALSE) -> 피에스케이 | E38: =VLOOKUP($C38,'2027'!$B$14:$T$4000,E$5,FALSE) -> KQ | F38: =VLOOKUP($C38,'2027'!$B$14:$T$4000,F$5,FALSE) -> 반도체 | G38: =VLOOKUP($C38,'2027'!$B$14:$T$4000,G$5,FALSE) -> 6126.46 | H38: =VLOOKUP($C38,'2027'!$B$14:$T$4000,H$5,FALSE) -> 5 | I38: =VLOOKUP($C38,'2027'!$B$14:$T$4000,I$5,FALSE) -> 211.57 | J38: =VLOOKUP($C38,'2027'!$B$14:$T$4000,J$5,FALSE) -> 223.8 | K38: =VLOOKUP($C38,'2027'!$B$14:$T$4000,K$5,FALSE) -> 220 | L38: =VLOOKUP($C38,'2027'!$B$14:$T$4000,L$5,FALSE) -> 230.07 | M38: =(L38-K38)/ABS(K38)*100 -> 4.5772727 | N38: =IF(ISBLANK(VLOOKUP($C38,'2027'!$B$14:$T$3000,N$5,FALSE)),"",VLOOKUP($C38,'2027'!$B$14:$T$3000,N$5,FALSE)) | O38: =IF(AND(I38<K38,J38<L38,K38<L38),1,IF(AND(I38>K38,J38>L38,K38>L38),-1,0)) -> 1 | P38: =IF(ISBLANK(VLOOKUP($C38,'2027'!$B$14:$T$3000,P$5,FALSE)),"",VLOOKUP($C38,'2027'!$B$14:$T$3000,P$5,FALSE)) | Q38: =IF(O38=1,"Surprise",IF(O38=-1,"Shock","")) -> Surprise | R38: =IF(N38="","",IF((N38-L38)/ABS(L38)>$R$9,"Surprise",IF((N38-L38)/ABS(L38)<$R$9*-1,"Shock",""))) | S38: =VLOOKUP($C38,'2027'!$B$14:$T$3000,S$5,FALSE) -> 125.48 | T38: =VLOOKUP($C38,'2027'!$B$14:$T$3000,T$5,FALSE) -> 144.79 | X38: =X37+1 -> 4 | Y38: A000830 | Z38: 삼성물산
B39: 158 | C39: =VLOOKUP(B39,'2027'!$A$14:$B$4000,2,FALSE) -> A282330 | D39: =VLOOKUP($C39,'2027'!$B$14:$T$4000,D$5,FALSE) -> BGF리테일 | E39: =VLOOKUP($C39,'2027'!$B$14:$T$4000,E$5,FALSE) -> KS | F39: =VLOOKUP($C39,'2027'!$B$14:$T$4000,F$5,FALSE) -> 백화점 | G39: =VLOOKUP($C39,'2027'!$B$14:$T$4000,G$5,FALSE) -> 1998.02 | H39: =VLOOKUP($C39,'2027'!$B$14:$T$4000,H$5,FALSE) -> 15 | I39: =VLOOKUP($C39,'2027'!$B$14:$T$4000,I$5,FALSE) -> 314.55 | J39: =VLOOKUP($C39,'2027'!$B$14:$T$4000,J$5,FALSE) -> 311.75 | K39: =VLOOKUP($C39,'2027'!$B$14:$T$4000,K$5,FALSE) -> 316.04 | L39: =VLOOKUP($C39,'2027'!$B$14:$T$4000,L$5,FALSE) -> 335.17 | M39: =(L39-K39)/ABS(K39)*100 -> 6.0530313 | N39: =IF(ISBLANK(VLOOKUP($C39,'2027'!$B$14:$T$3000,N$5,FALSE)),"",VLOOKUP($C39,'2027'!$B$14:$T$3000,N$5,FALSE)) | O39: =IF(AND(I39<K39,J39<L39,K39<L39),1,IF(AND(I39>K39,J39>L39,K39>L39),-1,0)) -> 1 | P39: =IF(ISBLANK(VLOOKUP($C39,'2027'!$B$14:$T$3000,P$5,FALSE)),"",VLOOKUP($C39,'2027'!$B$14:$T$3000,P$5,FALSE)) | Q39: =IF(O39=1,"Surprise",IF(O39=-1,"Shock","")) -> Surprise | R39: =IF(N39="","",IF((N39-L39)/ABS(L39)>$R$9,"Surprise",IF((N39-L39)/ABS(L39)<$R$9*-1,"Shock",""))) | S39: =VLOOKUP($C39,'2027'!$B$14:$T$3000,S$5,FALSE) -> -7.15 | T39: =VLOOKUP($C39,'2027'!$B$14:$T$3000,T$5,FALSE) -> -15.99 | X39: =X38+1 -> 5 | Y39: A053000 | Z39: 우리금융
B40: 122 | C40: =VLOOKUP(B40,'2027'!$A$14:$B$4000,2,FALSE) -> A214150 | D40: =VLOOKUP($C40,'2027'!$B$14:$T$4000,D$5,FALSE) -> 클래시스 | E40: =VLOOKUP($C40,'2027'!$B$14:$T$4000,E$5,FALSE) -> KQ | F40: =VLOOKUP($C40,'2027'!$B$14:$T$4000,F$5,FALSE) -> 건강관리장비,서비스 | G40: =VLOOKUP($C40,'2027'!$B$14:$T$4000,G$5,FALSE) -> 3131.31 | H40: =VLOOKUP($C40,'2027'!$B$14:$T$4000,H$5,FALSE) -> 16 | I40: =VLOOKUP($C40,'2027'!$B$14:$T$4000,I$5,FALSE) -> 289.83 | J40: =VLOOKUP($C40,'2027'!$B$14:$T$4000,J$5,FALSE) -> 295 | K40: =VLOOKUP($C40,'2027'!$B$14:$T$4000,K$5,FALSE) -> 290.66 | L40: =VLOOKUP($C40,'2027'!$B$14:$T$4000,L$5,FALSE) -> 303.2 | M40: =(L40-K40)/ABS(K40)*100 -> 4.3143191 | N40: =IF(ISBLANK(VLOOKUP($C40,'2027'!$B$14:$T$3000,N$5,FALSE)),"",VLOOKUP($C40,'2027'!$B$14:$T$3000,N$5,FALSE)) | O40: =IF(AND(I40<K40,J40<L40,K40<L40),1,IF(AND(I40>K40,J40>L40,K40>L40),-1,0)) -> 1 | P40: =IF(ISBLANK(VLOOKUP($C40,'2027'!$B$14:$T$3000,P$5,FALSE)),"",VLOOKUP($C40,'2027'!$B$14:$T$3000,P$5,FALSE)) | Q40: =IF(O40=1,"Surprise",IF(O40=-1,"Shock","")) -> Surprise | R40: =IF(N40="","",IF((N40-L40)/ABS(L40)>$R$9,"Surprise",IF((N40-L40)/ABS(L40)<$R$9*-1,"Shock",""))) | S40: =VLOOKUP($C40,'2027'!$B$14:$T$3000,S$5,FALSE) -> 7.99 | T40: =VLOOKUP($C40,'2027'!$B$14:$T$3000,T$5,FALSE) -> -12.09
B41: 28 | C41: =VLOOKUP(B41,'2027'!$A$14:$B$4000,2,FALSE) -> A000150 | D41: =VLOOKUP($C41,'2027'!$B$14:$T$4000,D$5,FALSE) -> 두산 | E41: =VLOOKUP($C41,'2027'!$B$14:$T$4000,E$5,FALSE) -> KS | F41: =VLOOKUP($C41,'2027'!$B$14:$T$4000,F$5,FALSE) -> 복합기업 | G41: =VLOOKUP($C41,'2027'!$B$14:$T$4000,G$5,FALSE) -> 25748.2 | H41: =VLOOKUP($C41,'2027'!$B$14:$T$4000,H$5,FALSE) -> 11 | I41: =VLOOKUP($C41,'2027'!$B$14:$T$4000,I$5,FALSE) -> 2317.54 | J41: =VLOOKUP($C41,'2027'!$B$14:$T$4000,J$5,FALSE) -> 2274.04 | K41: =VLOOKUP($C41,'2027'!$B$14:$T$4000,K$5,FALSE) -> 2341.28 | L41: =VLOOKUP($C41,'2027'!$B$14:$T$4000,L$5,FALSE) -> 2558.8 | M41: =(L41-K41)/ABS(K41)*100 -> 9.2906444 | N41: =IF(ISBLANK(VLOOKUP($C41,'2027'!$B$14:$T$3000,N$5,FALSE)),"",VLOOKUP($C41,'2027'!$B$14:$T$3000,N$5,FALSE)) | O41: =IF(AND(I41<K41,J41<L41,K41<L41),1,IF(AND(I41>K41,J41>L41,K41>L41),-1,0)) -> 1 | P41: =IF(ISBLANK(VLOOKUP($C41,'2027'!$B$14:$T$3000,P$5,FALSE)),"",VLOOKUP($C41,'2027'!$B$14:$T$3000,P$5,FALSE)) | Q41: =IF(O41=1,"Surprise",IF(O41=-1,"Shock","")) -> Surprise | R41: =IF(N41="","",IF((N41-L41)/ABS(L41)>$R$9,"Surprise",IF((N41-L41)/ABS(L41)<$R$9*-1,"Shock",""))) | S41: =VLOOKUP($C41,'2027'!$B$14:$T$3000,S$5,FALSE) -> -27.83 | T41: =VLOOKUP($C41,'2027'!$B$14:$T$3000,T$5,FALSE) -> 42.6
B42: 70 | C42: =VLOOKUP(B42,'2027'!$A$14:$B$4000,2,FALSE) -> A039490 | D42: =VLOOKUP($C42,'2027'!$B$14:$T$4000,D$5,FALSE) -> 키움증권 | E42: =VLOOKUP($C42,'2027'!$B$14:$T$4000,E$5,FALSE) -> KS | F42: =VLOOKUP($C42,'2027'!$B$14:$T$4000,F$5,FALSE) -> 증권 | G42: =VLOOKUP($C42,'2027'!$B$14:$T$4000,G$5,FALSE) -> 9114.34 | H42: =VLOOKUP($C42,'2027'!$B$14:$T$4000,H$5,FALSE) -> 15 | I42: =VLOOKUP($C42,'2027'!$B$14:$T$4000,I$5,FALSE) -> 1973.36 | J42: =VLOOKUP($C42,'2027'!$B$14:$T$4000,J$5,FALSE) -> 2161.57 | K42: =VLOOKUP($C42,'2027'!$B$14:$T$4000,K$5,FALSE) -> 1985.01 | L42: =VLOOKUP($C42,'2027'!$B$14:$T$4000,L$5,FALSE) -> 2199.23 | M42: =(L42-K42)/ABS(K42)*100 -> 10.791885 | N42: =IF(ISBLANK(VLOOKUP($C42,'2027'!$B$14:$T$3000,N$5,FALSE)),"",VLOOKUP($C42,'2027'!$B$14:$T$3000,N$5,FALSE)) | O42: =IF(AND(I42<K42,J42<L42,K42<L42),1,IF(AND(I42>K42,J42>L42,K42>L42),-1,0)) -> 1 | P42: =IF(ISBLANK(VLOOKUP($C42,'2027'!$B$14:$T$3000,P$5,FALSE)),"",VLOOKUP($C42,'2027'!$B$14:$T$3000,P$5,FALSE)) | Q42: =IF(O42=1,"Surprise",IF(O42=-1,"Shock","")) -> Surprise | R42: =IF(N42="","",IF((N42-L42)/ABS(L42)>$R$9,"Surprise",IF((N42-L42)/ABS(L42)<$R$9*-1,"Shock",""))) | S42: =VLOOKUP($C42,'2027'!$B$14:$T$3000,S$5,FALSE) -> -8.79 | T42: =VLOOKUP($C42,'2027'!$B$14:$T$3000,T$5,FALSE) -> -20.57 | X42: =X41+1 -> 1 | Y42: A028050 | Z42: 삼성엔지니어링
B43: 121 | C43: =VLOOKUP(B43,'2027'!$A$14:$B$4000,2,FALSE) -> A064760 | D43: =VLOOKUP($C43,'2027'!$B$14:$T$4000,D$5,FALSE) -> 티씨케이 | E43: =VLOOKUP($C43,'2027'!$B$14:$T$4000,E$5,FALSE) -> KQ | F43: =VLOOKUP($C43,'2027'!$B$14:$T$4000,F$5,FALSE) -> 반도체 | G43: =VLOOKUP($C43,'2027'!$B$14:$T$4000,G$5,FALSE) -> 3214.08 | H43: =VLOOKUP($C43,'2027'!$B$14:$T$4000,H$5,FALSE) -> 4 | I43: =VLOOKUP($C43,'2027'!$B$14:$T$4000,I$5,FALSE) -> 165.98 | J43: =VLOOKUP($C43,'2027'!$B$14:$T$4000,J$5,FALSE) -> 161.77 | K43: =VLOOKUP($C43,'2027'!$B$14:$T$4000,K$5,FALSE) -> 166.08 | L43: =VLOOKUP($C43,'2027'!$B$14:$T$4000,L$5,FALSE) -> 166.27 | M43: =(L43-K43)/ABS(K43)*100 -> 0.1144027 | N43: =IF(ISBLANK(VLOOKUP($C43,'2027'!$B$14:$T$3000,N$5,FALSE)),"",VLOOKUP($C43,'2027'!$B$14:$T$3000,N$5,FALSE)) | O43: =IF(AND(I43<K43,J43<L43,K43<L43),1,IF(AND(I43>K43,J43>L43,K43>L43),-1,0)) -> 1 | P43: =IF(ISBLANK(VLOOKUP($C43,'2027'!$B$14:$T$3000,P$5,FALSE)),"",VLOOKUP($C43,'2027'!$B$14:$T$3000,P$5,FALSE)) | Q43: =IF(O43=1,"Surprise",IF(O43=-1,"Shock","")) -> Surprise | R43: =IF(N43="","",IF((N43-L43)/ABS(L43)>$R$9,"Surprise",IF((N43-L43)/ABS(L43)<$R$9*-1,"Shock",""))) | S43: =VLOOKUP($C43,'2027'!$B$14:$T$3000,S$5,FALSE) -> 12.97 | T43: =VLOOKUP($C43,'2027'!$B$14:$T$3000,T$5,FALSE) -> 23.66 | X43: =X42+1 -> 2 | Y43: A033630 | Z43: SK브로드밴드
...

Sheet 2Q26전망(10일)
B3: 추정영업이익 변화에따른 실적 쇼크 조심하기 15일 변화 기준
D5: 2 | E5: =D5+1 -> 3 | F5: 10 | G5: =E5+1 -> 4 | H5: =G5+1 -> 5 | I5: =H5+1 -> 6 | J5: =K5+1 -> 8 | K5: =I5+1 -> 7 | L5: =J5+1 -> 9 | N5: ='2Q26'!L1 -> 11 | P5: ='2Q26'!N1 -> 13 | Q5: 14 | R5: 14 | S5: ='2Q26'!O1 -> 14 | T5: ='2Q26'!P1 -> 15
H6: EPS참여 | I6: 3개월 평균추정 | J6: 1개월 평균추정 | K6: 3개월 평균추정 | L6: 1개월 평균추정 | M6: 1개월대비 | N6: 잠정치 | P6: 잠정치 | R6: 실제 | S6: 1M | T6: 3M
G7: ='2027전망(10일)'!G7 -> 20260702 | H7: 증권사 | I7: 202606 | J7: =K7 -> 202606 | K7: =I7 -> 202606 | L7: =J7 -> 202606 | M7: 3개월 | N7: =K7 -> 202606 | P7: =N7 -> 202606 | Q7: 예상 | R7: Surprise | S7: 수익률 | T7: 수익률 | Y7: Surprise
G8: KRW BIL | H8: # | I8: KRW bil | J8: KRW bil | K8: KRW bil | L8: KRW bil | M8: % | N8: KRW bil | O8: TEST | P8: KRW bil | Q8: =COUNT($B$11:$B$178) -> 168 | R8: Shock | S8: % | T8: % | Y8: Shock
B9: 시총 | E9: 시장 | H9: =G7 -> 20260702 | I9: ='2027전망(10일)'!I9 -> CPD-10TD | J9: =I9 -> CPD-10TD | K9: =H9 -> 20260702 | L9: =K9 -> 20260702 | O9: 1 = Surprise | P9: 발표예정일 | Q9: =COUNTIF($Q$11:$Q$178,"Surprise") -> 45 | R9: 0.05
B10: Rank | C10: Code | D10: 종목명 | F10: Sector | G10: 시가총액 | I10: 영업이익 | J10: 영업이익 | K10: 영업이익 | L10: 영업이익 | M10: 괴리율 | N10: 영업이익 | O10: -1 = Shock | P10: 영업이익 | Q10: =COUNTIF($Q$11:$Q$178,"Shock") -> 24 | R10: 기준 | X10: 1 | Y10: A000150 | Z10: 두산
B11: 51 | C11: =VLOOKUP(B11,'2Q26'!$A$14:$B$4000,2,FALSE) -> A030200 | D11: =VLOOKUP($C11,'2Q26'!$B$14:$T$4000,D$5,FALSE) -> KT | E11: =VLOOKUP($C11,'2Q26'!$B$14:$T$4000,E$5,FALSE) -> KS | F11: =VLOOKUP($C11,'2Q26'!$B$14:$T$4000,F$5,FALSE) -> 통신서비스 | G11: =VLOOKUP($C11,'2Q26'!$B$14:$T$4000,G$5,FALSE) -> 13533.56 | H11: =VLOOKUP($C11,'2Q26'!$B$14:$T$4000,H$5,FALSE) -> 17 | I11: =VLOOKUP($C11,'2Q26'!$B$14:$T$4000,I$5,FALSE) -> 609.01 | J11: =VLOOKUP($C11,'2Q26'!$B$14:$T$4000,J$5,FALSE) -> 562 | K11: =VLOOKUP($C11,'2Q26'!$B$14:$T$4000,K$5,FALSE) -> 613.72 | L11: =VLOOKUP($C11,'2Q26'!$B$14:$T$4000,L$5,FALSE) -> 625.5 | M11: =(L11-K11)/ABS(K11)*100 -> 1.9194421 | N11: =IF(ISBLANK(VLOOKUP($C11,'2Q26'!$B$14:$T$3000,N$5,FALSE)),"",VLOOKUP($C11,'2Q26'!$B$14:$T$3000,N$5,FALSE)) | O11: =IF(AND(I11<K11,J11<L11,K11<L11),1,IF(AND(I11>K11,J11>L11,K11>L11),-1,0)) -> 1 | P11: =IF(ISBLANK(VLOOKUP($C11,'2Q26'!$B$14:$T$3000,P$5,FALSE)),"",VLOOKUP($C11,'2Q26'!$B$14:$T$3000,P$5,FALSE)) | Q11: =IF(O11=1,"Surprise",IF(O11=-1,"Shock","")) -> Surprise | R11: =IF(N11="","",IF((N11-L11)/ABS(L11)>$R$9,"Surprise",IF((N11-L11)/ABS(L11)<$R$9*-1,"Shock",""))) | S11: =VLOOKUP($C11,'2Q26'!$B$14:$T$3000,S$5,FALSE) -> 0.94 | T11: =VLOOKUP($C11,'2Q26'!$B$14:$T$3000,T$5,FALSE) -> -12.54 | X11: =X97+1 -> 14 | Y11: A010520 | Z11: 현대하이스코
B12: 57 | C12: =VLOOKUP(B12,'2Q26'!$A$14:$B$4000,2,FALSE) -> A005940 | D12: =VLOOKUP($C12,'2Q26'!$B$14:$T$4000,D$5,FALSE) -> NH투자증권 | E12: =VLOOKUP($C12,'2Q26'!$B$14:$T$4000,E$5,FALSE) -> KS | F12: =VLOOKUP($C12,'2Q26'!$B$14:$T$4000,F$5,FALSE) -> 증권 | G12: =VLOOKUP($C12,'2Q26'!$B$14:$T$4000,G$5,FALSE) -> 10529.98 | H12: =VLOOKUP($C12,'2Q26'!$B$14:$T$4000,H$5,FALSE) -> 17 | I12: =VLOOKUP($C12,'2Q26'!$B$14:$T$4000,I$5,FALSE) -> 520.53 | J12: =VLOOKUP($C12,'2Q26'!$B$14:$T$4000,J$5,FALSE) -> 575.2 | K12: =VLOOKUP($C12,'2Q26'!$B$14:$T$4000,K$5,FALSE) -> 547.11 | L12: =VLOOKUP($C12,'2Q26'!$B$14:$T$4000,L$5,FALSE) -> 629.57 | M12: =(L12-K12)/ABS(K12)*100 -> 15.071923 | N12: =IF(ISBLANK(VLOOKUP($C12,'2Q26'!$B$14:$T$3000,N$5,FALSE)),"",VLOOKUP($C12,'2Q26'!$B$14:$T$3000,N$5,FALSE)) | O12: =IF(AND(I12<K12,J12<L12,K12<L12),1,IF(AND(I12>K12,J12>L12,K12>L12),-1,0)) -> 1 | P12: =IF(ISBLANK(VLOOKUP($C12,'2Q26'!$B$14:$T$3000,P$5,FALSE)),"",VLOOKUP($C12,'2Q26'!$B$14:$T$3000,P$5,FALSE)) | Q12: =IF(O12=1,"Surprise",IF(O12=-1,"Shock","")) -> Surprise | R12: =IF(N12="","",IF((N12-L12)/ABS(L12)>$R$9,"Surprise",IF((N12-L12)/ABS(L12)<$R$9*-1,"Shock",""))) | S12: =VLOOKUP($C12,'2Q26'!$B$14:$T$3000,S$5,FALSE) -> -5.29 | T12: =VLOOKUP($C12,'2Q26'!$B$14:$T$3000,T$5,FALSE) -> -7.22 | X12: =X11+1 -> 15 | Y12: A042670 | Z12: 두산인프라코어
B13: 165 | C13: =VLOOKUP(B13,'2Q26'!$A$14:$B$4000,2,FALSE) -> A232140 | D13: =VLOOKUP($C13,'2Q26'!$B$14:$T$4000,D$5,FALSE) -> 와이씨 | E13: =VLOOKUP($C13,'2Q26'!$B$14:$T$4000,E$5,FALSE) -> KQ | F13: =VLOOKUP($C13,'2Q26'!$B$14:$T$4000,F$5,FALSE) -> 반도체 | G13: =VLOOKUP($C13,'2Q26'!$B$14:$T$4000,G$5,FALSE) -> 1101.87 | H13: =VLOOKUP($C13,'2Q26'!$B$14:$T$4000,H$5,FALSE) -> 4 | I13: =VLOOKUP($C13,'2Q26'!$B$14:$T$4000,I$5,FALSE) -> 9.6 | J13: =VLOOKUP($C13,'2Q26'!$B$14:$T$4000,J$5,FALSE) -> 9.55 | K13: =VLOOKUP($C13,'2Q26'!$B$14:$T$4000,K$5,FALSE) -> 9.7 | L13: =VLOOKUP($C13,'2Q26'!$B$14:$T$4000,L$5,FALSE) -> 10.35 | M13: =(L13-K13)/ABS(K13)*100 -> 6.7010309 | N13: =IF(ISBLANK(VLOOKUP($C13,'2Q26'!$B$14:$T$3000,N$5,FALSE)),"",VLOOKUP($C13,'2Q26'!$B$14:$T$3000,N$5,FALSE)) | O13: =IF(AND(I13<K13,J13<L13,K13<L13),1,IF(AND(I13>K13,J13>L13,K13>L13),-1,0)) -> 1 | P13: =IF(ISBLANK(VLOOKUP($C13,'2Q26'!$B$14:$T$3000,P$5,FALSE)),"",VLOOKUP($C13,'2Q26'!$B$14:$T$3000,P$5,FALSE)) | Q13: =IF(O13=1,"Surprise",IF(O13=-1,"Shock","")) -> Surprise | R13: =IF(N13="","",IF((N13-L13)/ABS(L13)>$R$9,"Surprise",IF((N13-L13)/ABS(L13)<$R$9*-1,"Shock",""))) | S13: =VLOOKUP($C13,'2Q26'!$B$14:$T$3000,S$5,FALSE) -> -15.38 | T13: =VLOOKUP($C13,'2Q26'!$B$14:$T$3000,T$5,FALSE) -> -27.64 | X13: =X12+1 -> 16 | Y13: A036460 | Z13: 한국가스공사
B14: 159 | C14: =VLOOKUP(B14,'2Q26'!$A$14:$B$4000,2,FALSE) -> A077970 | D14: =VLOOKUP($C14,'2Q26'!$B$14:$T$4000,D$5,FALSE) -> STX엔진 | E14: =VLOOKUP($C14,'2Q26'!$B$14:$T$4000,E$5,FALSE) -> KS | F14: =VLOOKUP($C14,'2Q26'!$B$14:$T$4000,F$5,FALSE) -> 조선 | G14: =VLOOKUP($C14,'2Q26'!$B$14:$T$4000,G$5,FALSE) -> 1238.57 | H14: =VLOOKUP($C14,'2Q26'!$B$14:$T$4000,H$5,FALSE) -> 2 | I14: =VLOOKUP($C14,'2Q26'!$B$14:$T$4000,I$5,FALSE) -> 26.85 | J14: =VLOOKUP($C14,'2Q26'!$B$14:$T$4000,J$5,FALSE) -> 23 | K14: =VLOOKUP($C14,'2Q26'!$B$14:$T$4000,K$5,FALSE) -> 26.9 | L14: =VLOOKUP($C14,'2Q26'!$B$14:$T$4000,L$5,FALSE) -> 30.8 | M14: =(L14-K14)/ABS(K14)*100 -> 14.498141 | N14: =IF(ISBLANK(VLOOKUP($C14,'2Q26'!$B$14:$T$3000,N$5,FALSE)),"",VLOOKUP($C14,'2Q26'!$B$14:$T$3000,N$5,FALSE)) | O14: =IF(AND(I14<K14,J14<L14,K14<L14),1,IF(AND(I14>K14,J14>L14,K14>L14),-1,0)) -> 1 | P14: =IF(ISBLANK(VLOOKUP($C14,'2Q26'!$B$14:$T$3000,P$5,FALSE)),"",VLOOKUP($C14,'2Q26'!$B$14:$T$3000,P$5,FALSE)) | Q14: =IF(O14=1,"Surprise",IF(O14=-1,"Shock","")) -> Surprise | R14: =IF(N14="","",IF((N14-L14)/ABS(L14)>$R$9,"Surprise",IF((N14-L14)/ABS(L14)<$R$9*-1,"Shock",""))) | S14: =VLOOKUP($C14,'2Q26'!$B$14:$T$3000,S$5,FALSE) -> -21 | T14: =VLOOKUP($C14,'2Q26'!$B$14:$T$3000,T$5,FALSE) -> -4.78 | X14: =X13+1 -> 17 | Y14: A003490 | Z14: 대한항공
B15: 168 | C15: =VLOOKUP(B15,'2Q26'!$A$14:$B$4000,2,FALSE) -> A005300 | D15: =VLOOKUP($C15,'2Q26'!$B$14:$T$4000,D$5,FALSE) -> 롯데칠성 | E15: =VLOOKUP($C15,'2Q26'!$B$14:$T$4000,E$5,FALSE) -> KS | F15: =VLOOKUP($C15,'2Q26'!$B$14:$T$4000,F$5,FALSE) -> 식품,음료 | G15: =VLOOKUP($C15,'2Q26'!$B$14:$T$4000,G$5,FALSE) -> 914.9 | H15: =VLOOKUP($C15,'2Q26'!$B$14:$T$4000,H$5,FALSE) -> 11 | I15: =VLOOKUP($C15,'2Q26'!$B$14:$T$4000,I$5,FALSE) -> 62.15 | J15: =VLOOKUP($C15,'2Q26'!$B$14:$T$4000,J$5,FALSE) -> 61.6 | K15: =VLOOKUP($C15,'2Q26'!$B$14:$T$4000,K$5,FALSE) -> 62.15 | L15: =VLOOKUP($C15,'2Q26'!$B$14:$T$4000,L$5,FALSE) -> 59.8 | M15: =(L15-K15)/ABS(K15)*100 -> -3.7811746 | N15: =IF(ISBLANK(VLOOKUP($C15,'2Q26'!$B$14:$T$3000,N$5,FALSE)),"",VLOOKUP($C15,'2Q26'!$B$14:$T$3000,N$5,FALSE)) | O15: =IF(AND(I15<K15,J15<L15,K15<L15),1,IF(AND(I15>K15,J15>L15,K15>L15),-1,0)) -> 0 | P15: =IF(ISBLANK(VLOOKUP($C15,'2Q26'!$B$14:$T$3000,P$5,FALSE)),"",VLOOKUP($C15,'2Q26'!$B$14:$T$3000,P$5,FALSE)) | Q15: =IF(O15=1,"Surprise",IF(O15=-1,"Shock","")) | R15: =IF(N15="","",IF((N15-L15)/ABS(L15)>$R$9,"Surprise",IF((N15-L15)/ABS(L15)<$R$9*-1,"Shock",""))) | S15: =VLOOKUP($C15,'2Q26'!$B$14:$T$3000,S$5,FALSE) -> -8.87 | T15: =VLOOKUP($C15,'2Q26'!$B$14:$T$3000,T$5,FALSE) -> -16.16 | X15: =X14+1 -> 18 | Y15: A005380 | Z15: 현대차
B16: 155 | C16: =VLOOKUP(B16,'2Q26'!$A$14:$B$4000,2,FALSE) -> A017960 | D16: =VLOOKUP($C16,'2Q26'!$B$14:$T$4000,D$5,FALSE) -> 한국카본 | E16: =VLOOKUP($C16,'2Q26'!$B$14:$T$4000,E$5,FALSE) -> KS | F16: =VLOOKUP($C16,'2Q26'!$B$14:$T$4000,F$5,FALSE) -> 조선 | G16: =VLOOKUP($C16,'2Q26'!$B$14:$T$4000,G$5,FALSE) -> 1421.1 | H16: =VLOOKUP($C16,'2Q26'!$B$14:$T$4000,H$5,FALSE) -> 3 | I16: =VLOOKUP($C16,'2Q26'!$B$14:$T$4000,I$5,FALSE) -> 46.97 | J16: =VLOOKUP($C16,'2Q26'!$B$14:$T$4000,J$5,FALSE) -> 46.97 | K16: =VLOOKUP($C16,'2Q26'!$B$14:$T$4000,K$5,FALSE) -> 46.97 | L16: =VLOOKUP($C16,'2Q26'!$B$14:$T$4000,L$5,FALSE) -> 45.45 | M16: =(L16-K16)/ABS(K16)*100 -> -3.2361082 | N16: =IF(ISBLANK(VLOOKUP($C16,'2Q26'!$B$14:$T$3000,N$5,FALSE)),"",VLOOKUP($C16,'2Q26'!$B$14:$T$3000,N$5,FALSE)) | O16: =IF(AND(I16<K16,J16<L16,K16<L16),1,IF(AND(I16>K16,J16>L16,K16>L16),-1,0)) -> 0 | P16: =IF(ISBLANK(VLOOKUP($C16,'2Q26'!$B$14:$T$3000,P$5,FALSE)),"",VLOOKUP($C16,'2Q26'!$B$14:$T$3000,P$5,FALSE)) | Q16: =IF(O16=1,"Surprise",IF(O16=-1,"Shock","")) | R16: =IF(N16="","",IF((N16-L16)/ABS(L16)>$R$9,"Surprise",IF((N16-L16)/ABS(L16)<$R$9*-1,"Shock",""))) | S16: =VLOOKUP($C16,'2Q26'!$B$14:$T$3000,S$5,FALSE) -> -14.46 | T16: =VLOOKUP($C16,'2Q26'!$B$14:$T$3000,T$5,FALSE) -> -33.25 | X16: =X15+1 -> 19 | Y16: A012450 | Z16: 삼성테크윈
B17: 161 | C17: =VLOOKUP(B17,'2Q26'!$A$14:$B$4000,2,FALSE) -> A195870 | D17: =VLOOKUP($C17,'2Q26'!$B$14:$T$4000,D$5,FALSE) -> 해성디에스 | E17: =VLOOKUP($C17,'2Q26'!$B$14:$T$4000,E$5,FALSE) -> KS | F17: =VLOOKUP($C17,'2Q26'!$B$14:$T$4000,F$5,FALSE) -> 반도체 | G17: =VLOOKUP($C17,'2Q26'!$B$14:$T$4000,G$5,FALSE) -> 1200.2 | H17: =VLOOKUP($C17,'2Q26'!$B$14:$T$4000,H$5,FALSE) -> 8 | I17: =VLOOKUP($C17,'2Q26'!$B$14:$T$4000,I$5,FALSE) -> 22.38 | J17: =VLOOKUP($C17,'2Q26'!$B$14:$T$4000,J$5,FALSE) -> 22.7 | K17: =VLOOKUP($C17,'2Q26'!$B$14:$T$4000,K$5,FALSE) -> 22.16 | L17: =VLOOKUP($C17,'2Q26'!$B$14:$T$4000,L$5,FALSE) -> 20.3 | M17: =(L17-K17)/ABS(K17)*100 -> -8.3935018 | N17: =IF(ISBLANK(VLOOKUP($C17,'2Q26'!$B$14:$T$3000,N$5,FALSE)),"",VLOOKUP($C17,'2Q26'!$B$14:$T$3000,N$5,FALSE)) | O17: =IF(AND(I17<K17,J17<L17,K17<L17),1,IF(AND(I17>K17,J17>L17,K17>L17),-1,0)) -> -1 | P17: =IF(ISBLANK(VLOOKUP($C17,'2Q26'!$B$14:$T$3000,P$5,FALSE)),"",VLOOKUP($C17,'2Q26'!$B$14:$T$3000,P$5,FALSE)) | Q17: =IF(O17=1,"Surprise",IF(O17=-1,"Shock","")) -> Shock | R17: =IF(N17="","",IF((N17-L17)/ABS(L17)>$R$9,"Surprise",IF((N17-L17)/ABS(L17)<$R$9*-1,"Shock",""))) | S17: =VLOOKUP($C17,'2Q26'!$B$14:$T$3000,S$5,FALSE) -> -12.41 | T17: =VLOOKUP($C17,'2Q26'!$B$14:$T$3000,T$5,FALSE) -> 26.75 | X17: =X16+1 -> 20 | Y17: A036570 | Z17: 엔씨소프트
B18: 162 | C18: =VLOOKUP(B18,'2Q26'!$A$14:$B$4000,2,FALSE) -> A032350 | D18: =VLOOKUP($C18,'2Q26'!$B$14:$T$4000,D$5,FALSE) -> 롯데관광개발 | E18: =VLOOKUP($C18,'2Q26'!$B$14:$T$4000,E$5,FALSE) -> KS | F18: =VLOOKUP($C18,'2Q26'!$B$14:$T$4000,F$5,FALSE) -> 호텔,레저서비스 | G18: =VLOOKUP($C18,'2Q26'!$B$14:$T$4000,G$5,FALSE) -> 1188.71 | H18: =VLOOKUP($C18,'2Q26'!$B$14:$T$4000,H$5,FALSE) -> 13 | I18: =VLOOKUP($C18,'2Q26'!$B$14:$T$4000,I$5,FALSE) -> 50.98 | J18: =VLOOKUP($C18,'2Q26'!$B$14:$T$4000,J$5,FALSE) -> 52.42 | K18: =VLOOKUP($C18,'2Q26'!$B$14:$T$4000,K$5,FALSE) -> 50.98 | L18: =VLOOKUP($C18,'2Q26'!$B$14:$T$4000,L$5,FALSE) -> 51 | M18: =(L18-K18)/ABS(K18)*100 -> 0.039231071 | N18: =IF(ISBLANK(VLOOKUP($C18,'2Q26'!$B$14:$T$3000,N$5,FALSE)),"",VLOOKUP($C18,'2Q26'!$B$14:$T$3000,N$5,FALSE)) | O18: =IF(AND(I18<K18,J18<L18,K18<L18),1,IF(AND(I18>K18,J18>L18,K18>L18),-1,0)) -> 0 | P18: =IF(ISBLANK(VLOOKUP($C18,'2Q26'!$B$14:$T$3000,P$5,FALSE)),"",VLOOKUP($C18,'2Q26'!$B$14:$T$3000,P$5,FALSE)) | Q18: =IF(O18=1,"Surprise",IF(O18=-1,"Shock","")) | R18: =IF(N18="","",IF((N18-L18)/ABS(L18)>$R$9,"Surprise",IF((N18-L18)/ABS(L18)<$R$9*-1,"Shock",""))) | S18: =VLOOKUP($C18,'2Q26'!$B$14:$T$3000,S$5,FALSE) -> -19.01 | T18: =VLOOKUP($C18,'2Q26'!$B$14:$T$3000,T$5,FALSE) -> -17.72 | X18: =X17+1 -> 21 | Y18: A139480 | Z18: 이마트
B19: 166 | C19: =VLOOKUP(B19,'2Q26'!$A$14:$B$4000,2,FALSE) -> A000080 | D19: =VLOOKUP($C19,'2Q26'!$B$14:$T$4000,D$5,FALSE) -> 하이트진로 | E19: =VLOOKUP($C19,'2Q26'!$B$14:$T$4000,E$5,FALSE) -> KS | F19: =VLOOKUP($C19,'2Q26'!$B$14:$T$4000,F$5,FALSE) -> 식품,음료 | G19: =VLOOKUP($C19,'2Q26'!$B$14:$T$4000,G$5,FALSE) -> 1020.44 | H19: =VLOOKUP($C19,'2Q26'!$B$14:$T$4000,H$5,FALSE) -> 6 | I19: =VLOOKUP($C19,'2Q26'!$B$14:$T$4000,I$5,FALSE) -> 60.13 | J19: =VLOOKUP($C19,'2Q26'!$B$14:$T$4000,J$5,FALSE) -> 58.8 | K19: =VLOOKUP($C19,'2Q26'!$B$14:$T$4000,K$5,FALSE) -> 60.13 | L19: =VLOOKUP($C19,'2Q26'!$B$14:$T$4000,L$5,FALSE) -> 57.05 | M19: =(L19-K19)/ABS(K19)*100 -> -5.1222352 | N19: =IF(ISBLANK(VLOOKUP($C19,'2Q26'!$B$14:$T$3000,N$5,FALSE)),"",VLOOKUP($C19,'2Q26'!$B$14:$T$3000,N$5,FALSE)) | O19: =IF(AND(I19<K19,J19<L19,K19<L19),1,IF(AND(I19>K19,J19>L19,K19>L19),-1,0)) -> 0 | P19: =IF(ISBLANK(VLOOKUP($C19,'2Q26'!$B$14:$T$3000,P$5,FALSE)),"",VLOOKUP($C19,'2Q26'!$B$14:$T$3000,P$5,FALSE)) | Q19: =IF(O19=1,"Surprise",IF(O19=-1,"Shock","")) | R19: =IF(N19="","",IF((N19-L19)/ABS(L19)>$R$9,"Surprise",IF((N19-L19)/ABS(L19)<$R$9*-1,"Shock",""))) | S19: =VLOOKUP($C19,'2Q26'!$B$14:$T$3000,S$5,FALSE) -> -8.49 | T19: =VLOOKUP($C19,'2Q26'!$B$14:$T$3000,T$5,FALSE) -> -14.11 | X19: =X18+1 -> 22 | Y19: A071840 | Z19: 롯데하이마트
B20: 164 | C20: =VLOOKUP(B20,'2Q26'!$A$14:$B$4000,2,FALSE) -> A089860 | D20: =VLOOKUP($C20,'2Q26'!$B$14:$T$4000,D$5,FALSE) -> 롯데렌탈 | E20: =VLOOKUP($C20,'2Q26'!$B$14:$T$4000,E$5,FALSE) -> KS | F20: =VLOOKUP($C20,'2Q26'!$B$14:$T$4000,F$5,FALSE) -> 운송 | G20: =VLOOKUP($C20,'2Q26'!$B$14:$T$4000,G$5,FALSE) -> 1160.08 | H20: =VLOOKUP($C20,'2Q26'!$B$14:$T$4000,H$5,FALSE) -> 9 | I20: =VLOOKUP($C20,'2Q26'!$B$14:$T$4000,I$5,FALSE) -> 87.96 | J20: =VLOOKUP($C20,'2Q26'!$B$14:$T$4000,J$5,FALSE) -> 89.9 | K20: =VLOOKUP($C20,'2Q26'!$B$14:$T$4000,K$5,FALSE) -> 87.87 | L20: =VLOOKUP($C20,'2Q26'!$B$14:$T$4000,L$5,FALSE) -> 89.1 | M20: =(L20-K20)/ABS(K20)*100 -> 1.3997952 | N20: =IF(ISBLANK(VLOOKUP($C20,'2Q26'!$B$14:$T$3000,N$5,FALSE)),"",VLOOKUP($C20,'2Q26'!$B$14:$T$3000,N$5,FALSE)) | O20: =IF(AND(I20<K20,J20<L20,K20<L20),1,IF(AND(I20>K20,J20>L20,K20>L20),-1,0)) -> 0 | P20: =IF(ISBLANK(VLOOKUP($C20,'2Q26'!$B$14:$T$3000,P$5,FALSE)),"",VLOOKUP($C20,'2Q26'!$B$14:$T$3000,P$5,FALSE)) | Q20: =IF(O20=1,"Surprise",IF(O20=-1,"Shock","")) | R20: =IF(N20="","",IF((N20-L20)/ABS(L20)>$R$9,"Surprise",IF((N20-L20)/ABS(L20)<$R$9*-1,"Shock",""))) | S20: =VLOOKUP($C20,'2Q26'!$B$14:$T$3000,S$5,FALSE) -> 2.4 | T20: =VLOOKUP($C20,'2Q26'!$B$14:$T$3000,T$5,FALSE) -> 2.9 | X20: =X19+1 -> 23 | Y20: A000270 | Z20: 기아차
