Workbook

Sheet 프로브카드
L1: 티에스이
L2: 9030820000
F3: 년월 | G3: 금액(달러) | H3: 금액(원화) | I3: 중량(Kg)
A4: 분기(일평균) | B4: QoQ | C4: 일평균수출 | D4: mom | E4: yoy | J4: 금액(달러)/중량 | K4: 분기 달러매출 | L4: 원화매출
C5: =G5/20 -> 772983.1 | F5: 2022년01월 | G5: 15459662 | I5: 145381.8 | J5: =G5/I5 -> 106.33836
C6: =G6/18 -> 993310.33 | D6: =C6/C5-1 -> 0.28503499 | F6: 2022년02월 | G6: 17879586 | I6: 148945.68 | J6: =G6/I6 -> 120.04098
A7: =C5+C6+C7 -> 3229867.2 | C7: =G7/22 -> 1463573.8 | D7: =C7/C6-1 -> 0.47343053 | F7: 2022년03월 | G7: 32198623 | I7: 128150.94 | J7: =G7/I7 -> 251.25546 | K7: =G5+G6+G7 -> 65537871 | L7: =H5+H6+H7 -> 0
C8: =G8/21 -> 861460.48 | D8: =C8/C7-1 -> -0.41139935 | F8: 2022년04월 | G8: 18090670 | I8: 185780.16 | J8: =G8/I8 -> 97.37676
C9: =G9/21 -> 1459603.1 | D9: =C9/C8-1 -> 0.69433559 | F9: 2022년05월 | G9: 30651666 | I9: 190502.87 | J9: =G9/I9 -> 160.89871
A10: =C8+C9+C10 -> 3049689 | B10: =A10/A7-1 -> -0.05578502 | C10: =G10/21 -> 728625.38 | D10: =C10/C9-1 -> -0.50080583 | F10: 2022년06월 | G10: 15301133 | I10: 77939.4 | J10: =G10/I10 -> 196.3209 | K10: =G8+G9+G10 -> 64043469 | L10: =H8+H9+H10 -> 0
C11: =G11/21 -> 775320.9 | D11: =C11/C10-1 -> 0.06408715 | F11: 2022년07월 | G11: 16281739 | I11: 72951.28 | J11: =G11/I11 -> 223.18647
C12: =G12/22 -> 938008.82 | D12: =C12/C11-1 -> 0.209833 | F12: 2022년08월 | G12: 20636194 | I12: 153497.55 | J12: =G12/I12 -> 134.43989
A13: =C11+C12+C13 -> 2629080.9 | B13: =A13/A10-1 -> -0.13791835 | C13: =G13/20 -> 915751.2 | D13: =C13/C12-1 -> -0.023728581 | F13: 2022년09월 | G13: 18315024 | I13: 130047.55 | J13: =G13/I13 -> 140.83329 | K13: =G11+G12+G13 -> 55232957 | L13: =H11+H12+H13 -> 0
C14: =G14/20 -> 733047 | D14: =C14/C13-1 -> -0.19951292 | F14: 2022년10월 | G14: 14660940 | I14: 71214.93 | J14: =G14/I14 -> 205.86891
C15: =G15/22 -> 551276.41 | D15: =C15/C14-1 -> -0.24796581 | F15: 2022년11월 | G15: 12128081 | I15: 51016.06 | J15: =G15/I15 -> 237.73065
A16: =C14+C15+C16 -> 2065064.3 | B16: =A16/A13-1 -> -0.21452997 | C16: =G16/22 -> 780740.86 | D16: =C16/C15-1 -> 0.41624211 | F16: 2022년12월 | G16: 17176299 | I16: 68132.86 | J16: =G16/I16 -> 252.10007 | K16: =G14+G15+G16 -> 43965320 | L16: =H14+H15+H16 -> 0
C17: =G17/20 -> 888301.55 | D17: =C17/C16-1 -> 0.13776746 | E17: =C17/C5-1 -> 0.14918625 | F17: 2023년01월 | G17: 17766031 | H17: 22373854615 | I17: 135812.03 | J17: =G17/I17 -> 130.81338
C18: =G18/20 -> 1902925.8 | D18: =C18/C17-1 -> 1.1422069 | E18: =C18/C6-1 -> 0.91574142 | F18: 2023년02월 | G18: 38058515 | H18: 48290640364 | I18: 117761.09 | J18: =G18/I18 -> 323.18413
A19: =SUM(C17:C19) -> 2791227.3 | B19: =A19/A16-1 -> 0.35164185

Sheet 알루미늄파우치
L1: 율촌화학
L2: 7616999010
F3: 년월 | G3: 금액(달러) | H3: 금액(원화) | I3: 중량(Kg)
A4: 분기(일평균) | B4: QoQ | C4: 일평균수출 | D4: mom | E4: yoy | J4: 금액(달러)/중량 | K4: 분기 달러매출 | L4: 원화매출
C5: =G5/20 -> 8627.35 | F5: 2022년01월 | G5: 172547 | H5: 203054816 | I5: 11507 | J5: =G5/I5 -> 14.99496
C6: =G6/18 -> 3873.3889 | D6: =C6/C5-1 -> -0.55103376 | F6: 2022년02월 | G6: 69721 | H6: 82773087 | I6: 6702.21 | J6: =G6/I6 -> 10.402688
A7: =C5+C6+C7 -> 14799.875 | C7: =G7/22 -> 2299.1364 | D7: =C7/C6-1 -> -0.4064277 | F7: 2022년03월 | G7: 50581 | H7: 61161042 | I7: 5228.07 | J7: =G7/I7 -> 9.6748896 | K7: =G5+G6+G7 -> 292849 | L7: =H5+H6+H7 -> 346988945
C8: =G8/21 -> 759.80952 | D8: =C8/C7-1 -> -0.66952394 | F8: 2022년04월 | G8: 15956 | H8: 19278682 | I8: 2034.78 | J8: =G8/I8 -> 7.841634
C9: =G9/21 -> 1518.1905 | D9: =C9/C8-1 -> 0.99811983 | F9: 2022년05월 | G9: 31882 | H9: 39725269 | I9: 2424.04 | J9: =G9/I9 -> 13.152423
A10: =C8+C9+C10 -> 5854.7143 | B10: =A10/A7-1 -> -0.60440786 | C10: =G10/21 -> 3576.7143 | D10: =C10/C9-1 -> 1.3559062 | F10: 2022년06월 | G10: 75111 | H10: 94844664 | I10: 4049.29 | J10: =G10/I10 -> 18.549178 | K10: =G8+G9+G10 -> 122949 | L10: =H8+H9+H10 -> 153848615
C11: =G11/21 -> 5011.1905 | D11: =C11/C10-1 -> 0.40105976 | F11: 2022년07월 | G11: 105235 | H11: 135550036 | I11: 6730.04 | J11: =G11/I11 -> 15.636608
C12: =G12/22 -> 4945.0909 | D12: =C12/C11-1 -> -0.013190392 | F12: 2022년08월 | G12: 108792 | H12: 141121252 | I12: 5957.6 | J12: =G12/I12 -> 18.261045
A13: =C11+C12+C13 -> 14508.481 | B13: =A13/A10-1 -> 1.4780853 | C13: =G13/20 -> 4552.2 | D13: =C13/C12-1 -> -0.079450695 | F13: 2022년09월 | G13: 91044 | H13: 122878256 | I13: 8585.65 | J13: =G13/I13 -> 10.604206 | K13: =G11+G12+G13 -> 305071 | L13: =H11+H12+H13 -> 399549544
C14: =G14/20 -> 2691.6 | D14: =C14/C13-1 -> -0.40872545 | F14: 2022년10월 | G14: 53832 | H14: 76842099 | I14: 3929.56 | J14: =G14/I14 -> 13.699244
C15: =G15/22 -> 2924.8636 | D15: =C15/C14-1 -> 0.086663559 | F15: 2022년11월 | G15: 64347 | H15: 89105037 | I15: 4729.87 | J15: =G15/I15 -> 13.604391
A16: =C14+C15+C16 -> 9677.6909 | B16: =A16/A13-1 -> -0.33296321 | C16: =G16/22 -> 4061.2273 | D16: =C16/C15-1 -> 0.3885185 | F16: 2022년12월 | G16: 89347 | H16: 116490213 | I16: 4967.58 | J16: =G16/I16 -> 17.986021 | K16: =G14+G15+G16 -> 207526 | L16: =H14+H15+H16 -> 282437349
C17: =G17/20 -> 4795.15 | D17: =C17/C16-1 -> 0.18071452 | E17: =C17/C5-1 -> -0.44419202 | F17: 2023년01월 | G17: 95903 | H17: 120650813 | I17: 15431.85 | J17: =G17/I17 -> 6.2146146
C18: =G18/8 -> 5448.5 | D18: =C18/C17-1 -> 0.13625225 | E18: =C18/C6-1 -> 0.40664936 | F18: 2023년02월 | G18: 43588 | H18: 53542958 | I18: 1611.39 | J18: =G18/I18 -> 27.049938

Sheet 두산(합)
A1: 두산 | P1: 두산
P2: 741021 | Q2: 증평, 김천, 익산, 김제
G3: 년월 | H3: 금액(달러) | I3: 중량 | P3: * 잠정치가 아니라 확정치만 볼수 있음
A4: 분기(일평균) | B4: QoQ | D4: 일평균수출 | E4: mom | F4: yoy | J4: 금액(달러)/중량 | L4: QoQ | M4: yoy | N4: 단가 | O4: QoQ | P4: 메디톡스는 다른 수출코드에 수출이 없더라
D5: =H5/20 -> 922835.4 | G5: 2022년01월 | H5: ='두산(증평)'!H5+'두산(김천)'!H5+'두산(익산)'!H5+'두산(김제)'!H5 -> 18456708 | I5: ='두산(증평)'!I5+'두산(김천)'!I5+'두산(익산)'!I5+'두산(김제)'!I5 -> 285117.53 | J5: =H5/I5 -> 64.733684
D6: =H6/18 -> 1120955.7 | E6: =D6/D5-1 -> 0.21468652 | G6: 2022년02월 | H6: ='두산(증평)'!H6+'두산(김천)'!H6+'두산(익산)'!H6+'두산(김제)'!H6 -> 20177203 | I6: ='두산(증평)'!I6+'두산(김천)'!I6+'두산(익산)'!I6+'두산(김제)'!I6 -> 259908.2 | J6: =H6/I6 -> 77.632037
A7: =AVERAGE(D5:D7) -> 1018739.1 | D7: =H7/22 -> 1012426.3 | E7: =D7/D6-1 -> -0.096818677 | G7: 2022년03월 | H7: ='두산(증평)'!H7+'두산(김천)'!H7+'두산(익산)'!H7+'두산(김제)'!H7 -> 22273378 | I7: ='두산(증평)'!I7+'두산(김천)'!I7+'두산(익산)'!I7+'두산(김제)'!I7 -> 311646.17 | J7: =H7/I7 -> 71.470084 | K7: =H7+H6+H5 -> 60907289 | N7: =AVERAGE(J5:J7) -> 71.278602
D8: =H8/21 -> 1094393.1 | E8: =D8/D7-1 -> 0.080960829 | G8: 2022년04월 | H8: ='두산(증평)'!H8+'두산(김천)'!H8+'두산(익산)'!H8+'두산(김제)'!H8 -> 22982256 | I8: ='두산(증평)'!I8+'두산(김천)'!I8+'두산(익산)'!I8+'두산(김제)'!I8 -> 309136 | J8: =H8/I8 -> 74.343512
D9: =H9/21 -> 1095136.2 | E9: =D9/D8-1 -> 0.0006790021 | G9: 2022년05월 | H9: ='두산(증평)'!H9+'두산(김천)'!H9+'두산(익산)'!H9+'두산(김제)'!H9 -> 22997861 | I9: ='두산(증평)'!I9+'두산(김천)'!I9+'두산(익산)'!I9+'두산(김제)'!I9 -> 291297.28 | J9: =H9/I9 -> 78.949797
A10: =AVERAGE(D8:D10) -> 1119472 | B10: =A10/A7-1 -> 0.09887996 | D10: =H10/21 -> 1168886.7 | E10: =D10/D9-1 -> 0.067343611 | G10: 2022년06월 | H10: ='두산(증평)'!H10+'두산(김천)'!H10+'두산(익산)'!H10+'두산(김제)'!H10 -> 24546620 | I10: ='두산(증평)'!I10+'두산(김천)'!I10+'두산(익산)'!I10+'두산(김제)'!I10 -> 320078.04 | J10: =H10/I10 -> 76.689485 | K10: =H10+H9+H8 -> 70526737 | L10: =K10/K7-1 -> 0.15793591 | N10: =AVERAGE(J8:J10) -> 76.660931 | O10: =N10/N7-1 -> 0.075511156
D11: =H11/21 -> 1215086 | E11: =D11/D10-1 -> 0.03952426 | G11: 2022년07월 | H11: ='두산(증평)'!H11+'두산(김천)'!H11+'두산(익산)'!H11+'두산(김제)'!H11 -> 25516807 | I11: ='두산(증평)'!I11+'두산(김천)'!I11+'두산(익산)'!I11+'두산(김제)'!I11 -> 297441.27 | J11: =H11/I11 -> 85.787715
D12: =H12/22 -> 1202341.5 | E12: =D12/D11-1 -> -0.010488597 | G12: 2022년08월 | H12: ='두산(증평)'!H12+'두산(김천)'!H12+'두산(익산)'!H12+'두산(김제)'!H12 -> 26451513 | I12: ='두산(증평)'!I12+'두산(김천)'!I12+'두산(익산)'!I12+'두산(김제)'!I12 -> 321863.17 | J12: =H12/I12 -> 82.182478
A13: =AVERAGE(D11:D13) -> 1194464.3 | B13: =A13/A10-1 -> 0.066988946 | D13: =H13/20 -> 1165965.2 | E13: =D13/D12-1 -> -0.030254508 | G13: 2022년09월 | H13: ='두산(증평)'!H13+'두산(김천)'!H13+'두산(익산)'!H13+'두산(김제)'!H13 -> 23319305 | I13: ='두산(증평)'!I13+'두산(김천)'!I13+'두산(익산)'!I13+'두산(김제)'!I13 -> 269401.64 | J13: =H13/I13 -> 86.559625 | K13: =H13+H12+H11 -> 75287625 | L13: =K13/K10-1 -> 0.067504725 | N13: =AVERAGE(J11:J13) -> 84.843273 | O13: =N13/N10-1 -> 0.10673418
D14: =H14/20 -> 810047.35 | E14: =D14/D13-1 -> -0.30525601 | G14: 2022년10월 | H14: ='두산(증평)'!H14+'두산(김천)'!H14+'두산(익산)'!H14+'두산(김제)'!H14 -> 16200947 | I14: ='두산(증평)'!I14+'두산(김천)'!I14+'두산(익산)'!I14+'두산(김제)'!I14 -> 189593.73 | J14: =H14/I14 -> 85.450859
D15: =H15/22 -> 664734.32 | E15: =D15/D14-1 -> -0.17938832 | G15: 2022년11월 | H15: ='두산(증평)'!H15+'두산(김천)'!H15+'두산(익산)'!H15+'두산(김제)'!H15 -> 14624155 | I15: ='두산(증평)'!I15+'두산(김천)'!I15+'두산(익산)'!I15+'두산(김제)'!I15 -> 213056.34 | J15: =H15/I15 -> 68.639849
A16: =AVERAGE(D14:D16) -> 752300.71 | B16: =A16/A13-1 -> -0.3701773 | D16: =H16/22 -> 782120.45 | E16: =D16/D15-1 -> 0.17659106 | G16: 2022년12월 | H16: ='두산(증평)'!H16+'두산(김천)'!H16+'두산(익산)'!H16+'두산(김제)'!H16 -> 17206650 | I16: ='두산(증평)'!I16+'두산(김천)'!I16+'두산(익산)'!I16+'두산(김제)'!I16 -> 207229.41 | J16: =H16/I16 -> 83.031892 | K16: =H16+H15+H14 -> 48031752 | L16: =K16/K13-1 -> -0.36202328 | N16: =AVERAGE(J14:J16) -> 79.040867 | O16: =N16/N13-1 -> -0.068389706
D17: =H17/20 -> 699994.25 | E17: =D17/D16-1 -> -0.10500455 | F17: =D17/D5-1 -> -0.24147443 | G17: 2023년 1월 | H17: ='두산(증평)'!H17+'두산(김천)'!H17+'두산(익산)'!H17+'두산(김제)'!H17 -> 13999885 | I17: ='두산(증평)'!I17+'두산(김천)'!I17+'두산(익산)'!I17+'두산(김제)'!I17 -> 178221.49 | J17: =H17/I17 -> 78.553293
D18: =H18/20 -> 492841.1 | E18: =D18/D17-1 -> -0.2959355 | F18: =D18/D6-1 -> -0.56033848 | G18: 2023년 2월 | H18: ='두산(증평)'!H18+'두산(김천)'!H18+'두산(익산)'!H18+'두산(김제)'!H18 -> 9856822 | I18: ='두산(증평)'!I18+'두산(김천)'!I18+'두산(익산)'!I18+'두산(김제)'!I18 -> 147023.43 | J18: =H18/I18 -> 67.042525
A19: =AVERAGE(D17:D19) -> 633505.03 | B19: =A19/A16-1 -> -0.15790984 | C19: =A19/A7-1 -> -0.37814794 | D19: =H19/22 -> 707679.73 | E19: =D19/D18-1 -> 0.43591865 | F19: =D19/D7-1 -> -0.30100616 | G19: 2023년 3월 | H19: ='두산(증평)'!H19+'두산(김천)'!H19+'두산(익산)'!H19+'두산(김제)'!H19 -> 15568954 | I19: ='두산(증평)'!I19+'두산(김천)'!I19+'두산(익산)'!I19+'두산(김제)'!I19 -> 182859.75 | J19: =H19/I19 -> 85.141503 | K19: =H19+H18+H17 -> 39425661 | L19: =K19/K16-1 -> -0.17917504 | M19: =K19/K7-1 -> -0.35269388 | N19: =AVERAGE(J17:J19) -> 76.912441 | O19: =N19/N16-1 -> -0.02692817
D20: =H20/20 -> 989416.7 | E20: =D20/D19-1 -> 0.39811367 | F20: =D20/D8-1 -> -0.095922058 | G20: 2023년 4월 | H20: ='두산(증평)'!H20+'두산(김천)'!H20+'두산(익산)'!H20+'두산(김제)'!H20 -> 19788334 | I20: ='두산(증평)'!I20+'두산(김천)'!I20+'두산(익산)'!I20+'두산(김제)'!I20 -> 206251.94 | J20: =H20/I20 -> 95.942535
D21: =H21/21 -> 975864 | E21: =D21/D20-1 -> -0.013697667 | F21: =D21/D9-1 -> -0.10891087 | G21: 2023년 5월 | H21: ='두산(증평)'!H21+'두산(김천)'!H21+'두산(익산)'!H21+'두산(김제)'!H21 -> 20493144 | I21: ='두산(증평)'!I21+'두산(김천)'!I21+'두산(익산)'!I21+'두산(김제)'!I21 -> 219725.37 | J21: =H21/I21 -> 93.267082
A22: =AVERAGE(D20:D22) -> 936536.55 | B22: =A22/A19-1 -> 0.47834115 | C22: =A22/A10-1 -> -0.16341227 | D22: =H22/21 -> 844328.95 | E22: =D22/D21-1 -> -0.1347883 | F22: =D22/D10-1 -> -0.27766397 | G22: 2023년 6월 | H22: ='두산(증평)'!H22+'두산(김천)'!H22+'두산(익산)'!H22+'두산(김제)'!H22 -> 17730908 | I22: ='두산(증평)'!I22+'두산(김천)'!I22+'두산(익산)'!I22+'두산(김제)'!I22 -> 198443.57 | J22: =H22/I22 -> 89.349874 | K22: =H22+H21+H20 -> 58012386 | L22: =K22/K19-1 -> 0.47143724 | M22: =K22/K10-1 -> -0.17744123 | N22: =AVERAGE(J20:J22) -> 92.853164 | O22: =N22/N19-1 -> 0.20725806
D23: =H23/21 -> 1110506.4 | E23: =D23/D22-1 -> 0.31525329 | F23: =D23/D11-1 -> -0.086067665 | G23: 2023년 7월 | H23: ='두산(증평)'!H23+'두산(김천)'!H23+'두산(익산)'!H23+'두산(김제)'!H23 -> 23320635 | I23: ='두산(증평)'!I23+'두산(김천)'!I23+'두산(익산)'!I23+'두산(김제)'!I23 -> 273278.29 | J23: =H23/I23 -> 85.336581
D24: =H24/22 -> 1125545.1 | E24: =D24/D23-1 -> 0.013542166 | F24: =D24/D12-1 -> -0.063872377 | G24: 2023년 8월 | H24: ='두산(증평)'!H24+'두산(김천)'!H24+'두산(익산)'!H24+'두산(김제)'!H24 -> 24761992 | I24: ='두산(증평)'!I24+'두산(김천)'!I24+'두산(익산)'!I24+'두산(김제)'!I24 -> 265989.41 | J24: =H24/I24 -> 93.093902
A25: =AVERAGE(D23:D25) -> 1108661.2 | B25: =A25/A22-1 -> 0.18378849 | C25: =A25/A13-1 -> -0.071833941 | D25: =H25/19 -> 1089932.1 | E25: =D25/D24-1 -> -0.031640703 | F25: =D25/D13-1 -> -0.065210518 | G25: 2023년 9월 | H25: ='두산(증평)'!H25+'두산(김천)'!H25+'두산(익산)'!H25+'두산(김제)'!H25 -> 20708709 | I25: ='두산(증평)'!I25+'두산(김천)'!I25+'두산(익산)'!I25+'두산(김제)'!I25 -> 273551.22 | J25: =H25/I25 -> 75.703223 | K25: =H25+H24+H23 -> 68791336 | L25: =K25/K22-1 -> 0.18580429 | M25: =K25/K13-1 -> -0.086286279 | N25: =AVERAGE(J23:J25) -> 84.711235 | O25: =N25/N22-1 -> -0.087686062
D26: =H26/19 -> 1199293.9 | E26: =D26/D25-1 -> 0.10033827 | F26: =D26/D14-1 -> 0.48052326 | G26: 2023년 10월 | H26: ='두산(증평)'!H26+'두산(김천)'!H26+'두산(익산)'!H26+'두산(김제)'!H26 -> 22786585 | I26: ='두산(증평)'!I26+'두산(김천)'!I26+'두산(익산)'!I26+'두산(김제)'!I26 -> 288972.49 | J26: =H26/I26 -> 78.853821
D27: =H27/22 -> 1018373.1 | E27: =D27/D26-1 -> -0.1508561 | F27: =D27/D15-1 -> 0.53200024 | G27: 2023년 11월 | H27: ='두산(증평)'!H27+'두산(김천)'!H27+'두산(익산)'!H27+'두산(김제)'!H27 -> 22404209 | I27: ='두산(증평)'!I27+'두산(김천)'!I27+'두산(익산)'!I27+'두산(김제)'!I27 -> 273452.72 | J27: =H27/I27 -> 81.930833
A28: =AVERAGE(D26:D28) -> 1107659.6 | B28: =A28/A25-1 -> -0.00090346491 | C28: =A28/A16-1 -> 0.47236277 | D28: =H28/19 -> 1105311.6 | E28: =D28/D27-1 -> 0.085369929 | F28: =D28/D16-1 -> 0.41322423 | G28: 2023년 12월 | H28: ='두산(증평)'!H28+'두산(김천)'!H28+'두산(익산)'!H28+'두산(김제)'!H28 -> 21000920 | I28: ='두산(증평)'!I28+'두산(김천)'!I28+'두산(익산)'!I28+'두산(김제)'!I28 -> 283296.23 | J28: =H28/I28 -> 74.130602 | K28: =H28+H27+H26 -> 66191714 | L28: =K28/K25-1 -> -0.037789962 | M28: =K28/K16-1 -> 0.37808244 | N28: =AVERAGE(J26:J28) -> 78.305085 | O28: =N28/N25-1 -> -0.075623384
D29: =H29/22 -> 977993.18 | E29: =D29/D28-1 -> -0.11518779 | F29: =D29/D17-1 -> 0.39714459 | G29: 2024년 1월 | H29: ='두산(증평)'!H29+'두산(김천)'!H29+'두산(익산)'!H29+'두산(김제)'!H29 -> 21515850 | I29: ='두산(증평)'!I29+'두산(김천)'!I29+'두산(익산)'!I29+'두산(김제)'!I29 -> 247929.82 | J29: =H29/I29 -> 86.782018
D30: =H30/19 -> 849739.26 | E30: =D30/D29-1 -> -0.13113989 | F30: =D30/D18-1 -> 0.72416477 | G30: 2024년 2월 | H30: ='두산(증평)'!H30+'두산(김천)'!H30+'두산(익산)'!H30+'두산(김제)'!H30 -> 16145046 | I30: ='두산(증평)'!I30+'두산(김천)'!I30+'두산(익산)'!I30+'두산(김제)'!I30 -> 180270.41 | J30: =H30/I30 -> 89.560156
A31: =AVERAGE(D29:D31) -> 920540.21 | B31: =A31/A28-1 -> -0.16893218 | C31: =A31/A19-1 -> 0.45309063 | D31: =H31/20 -> 933888.2 | E31: =D31/D30-1 -> 0.099029126 | F31: =D31/D19-1 -> 0.31964809 | G31: 2024년 3월 | H31: ='두산(증평)'!H31+'두산(김천)'!H31+'두산(익산)'!H31+'두산(김제)'!H31 -> 18677764 | I31: ='두산(증평)'!I31+'두산(김천)'!I31+'두산(익산)'!I31+'두산(김제)'!I31 -> 245247.74 | J31: =H31/I31 -> 76.158761 | K31: =H31+H30+H29 -> 56338660 | L31: =K31/K28-1 -> -0.14885631 | M31: =K31/K19-1 -> 0.42898454 | N31: =AVERAGE(J29:J31) -> 84.166978 | O31: =N31/N28-1 -> 0.074859672
D32: =H32/21 -> 883705.71 | E32: =D32/D31-1 -> -0.053735004 | F32: =D32/D20-1 -> -0.10684172 | G32: 2024년 4월 | H32: ='두산(증평)'!H32+'두산(김천)'!H32+'두산(익산)'!H32+'두산(김제)'!H32 -> 18557820 | I32: ='두산(증평)'!I32+'두산(김천)'!I32+'두산(익산)'!I32+'두산(김제)'!I32 -> 274358.95 | J32: =H32/I32 -> 67.640658
D33: =H33/21 -> 847120.62 | E33: =D33/D32-1 -> -0.041399636 | F33: =D33/D21-1 -> -0.13192759 | G33: 2024년 5월 | H33: ='두산(증평)'!H33+'두산(김천)'!H33+'두산(익산)'!H33+'두산(김제)'!H33 -> 17789533 | I33: ='두산(증평)'!I33+'두산(김천)'!I33+'두산(익산)'!I33+'두산(김제)'!I33 -> 253195.92 | J33: =H33/I33 -> 70.259951
A34: =AVERAGE(D32:D34) -> 881515.18 | B34: =A34/A31-1 -> -0.042393622 | C34: =A34/A22-1 -> -0.058749837 | D34: =H34/19 -> 913719.21 | E34: =D34/D33-1 -> 0.078617602 | F34: =D34/D22-1 -> 0.082183914 | G34: 2024년 6월 | H34: ='두산(증평)'!H34+'두산(김천)'!H34+'두산(익산)'!H34+'두산(김제)'!H34 -> 17360665 | I34: ='두산(증평)'!I34+'두산(김천)'!I34+'두산(익산)'!I34+'두산(김제)'!I34 -> 232578.6 | J34: =H34/I34 -> 74.644292 | K34: =H34+H33+H32 -> 53708018 | L34: =K34/K31-1 -> -0.046693372 | M34: =K34/K22-1 -> -0.074197396 | N34: =AVERAGE(J32:J34) -> 70.848301 | O34: =N34/N31-1 -> -0.15824113
D35: =H35/23 -> 1084057.4 | E35: =D35/D34-1 -> 0.18642294 | F35: =D35/D23-1 -> -0.023817056 | G35: 2024년 7월 | H35: ='두산(증평)'!H35+'두산(김천)'!H35+'두산(익산)'!H35+'두산(김제)'!H35 -> 24933321 | I35: ='두산(증평)'!I35+'두산(김천)'!I35+'두산(익산)'!I35+'두산(김제)'!I35 -> 302837.93 | J35: =H35/I35 -> 82.332226
D36: =H36/21 -> 868967.67 | E36: =D36/D35-1 -> -0.19841178 | F36: =D36/D24-1 -> -0.22795837 | G36: 2024년 8월 | H36: ='두산(증평)'!H36+'두산(김천)'!H36+'두산(익산)'!H36+'두산(김제)'!H36 -> 18248321 | I36: ='두산(증평)'!I36+'두산(김천)'!I36+'두산(익산)'!I36+'두산(김제)'!I36 -> 252602.69 | J36: =H36/I36 -> 72.241198
A37: =AVERAGE(D35:D37) -> 980169.37 | B37: =A37/A34-1 -> 0.11191434 | C37: =A37/A25-1 -> -0.11589819 | D37: =H37/18 -> 987483 | E37: =D37/D36-1 -> 0.13638636 | F37: =D37/D25-1 -> -0.093995816 | G37: 2024년 9월 | H37: ='두산(증평)'!H37+'두산(김천)'!H37+'두산(익산)'!H37+'두산(김제)'!H37 -> 17774694 | I37: ='두산(증평)'!I37+'두산(김천)'!I37+'두산(익산)'!I37+'두산(김제)'!I37 -> 248304.22 | J37: =H37/I37 -> 71.584341 | K37: =H37+H36+H35 -> 60956336 | L37: =K37/K34-1 -> 0.13495784 | M37: =K37/K25-1 -> -0.11389516 | N37: =AVERAGE(J35:J37) -> 75.385922 | O37: =N37/N34-1 -> 0.064047002
D38: =H38/20 -> 1017089.6 | E38: =D38/D37-1 -> 0.029981833 | F38: =D38/D26-1 -> -0.15192639 | G38: 2024년 10월 | H38: ='두산(증평)'!H38+'두산(김천)'!H38+'두산(익산)'!H38+'두산(김제)'!H38 -> 20341791 | I38: ='두산(증평)'!I38+'두산(김천)'!I38+'두산(익산)'!I38+'두산(김제)'!I38 -> 291022.03 | J38: =H38/I38 -> 69.89777
D39: =H39/21 -> 1231371.1 | E39: =D39/D38-1 -> 0.21068115 | F39: =D39/D27-1 -> 0.20915517 | G39: 2024년 11월 | H39: ='두산(증평)'!H39+'두산(김천)'!H39+'두산(익산)'!H39+'두산(김제)'!H39 -> 25858794 | I39: ='두산(증평)'!I39+'두산(김천)'!I39+'두산(익산)'!I39+'두산(김제)'!I39 -> 330861.09 | J39: =H39/I39 -> 78.156044
A40: =AVERAGE(D38:D40) -> 1307404.5 | B40: =A40/A37-1 -> 0.33385575 | C40: =A40/A28-1 -> 0.18033067 | D40: =H40/21 -> 1673753 | E40: =D40/D39-1 -> 0.35925952 | F40: =D40/D28-1 -> 0.51428157 | G40: 2024년 12월 | H40: ='두산(증평)'!H40+'두산(김천)'!H40+'두산(익산)'!H40+'두산(김제)'!H40 -> 35148812 | I40: ='두산(증평)'!I40+'두산(김천)'!I40+'두산(익산)'!I40+'두산(김제)'!I40 -> 413255.29 | J40: =H40/I40 -> 85.053508 | K40: =H40+H39+H38 -> 81349397 | L40: =K40/K37-1 -> 0.33455195 | M40: =K40/K28-1 -> 0.22899668 | N40: =AVERAGE(J38:J40) -> 77.702441 | O40: =N40/N37-1 -> 0.030728799
...

Sheet 두산(증평)
A1: 두산 | P1: 두산
P2: 741021 | Q2: 증평, 김천, 익산, 김제
G3: 년월 | H3: 금액(달러) | I3: 중량 | P3: * 잠정치가 아니라 확정치만 볼수 있음
A4: 분기(일평균) | B4: QoQ | D4: 일평균수출 | E4: mom | F4: yoy | J4: 금액(달러)/중량 | L4: QoQ | M4: yoy | N4: 단가 | O4: QoQ | P4: 메디톡스는 다른 수출코드에 수출이 없더라
D5: =H5/20 -> 608744.75 | G5: 2022년01월 | H5: 12174895 | I5: 184252 | J5: =H5/I5 -> 66.07741
D6: =H6/18 -> 835815.11 | E6: =D6/D5-1 -> 0.37301408 | G6: 2022년02월 | H6: 15044672 | I6: 173663 | J6: =H6/I6 -> 86.631418
A7: =AVERAGE(D5:D7) -> 717614.64 | D7: =H7/22 -> 708284.05 | E7: =D7/D6-1 -> -0.15258287 | G7: 2022년03월 | H7: 15582249 | I7: 221099 | J7: =H7/I7 -> 70.476343 | K7: =H7+H6+H5 -> 42801816 | N7: =AVERAGE(J5:J7) -> 74.395057
D8: =H8/21 -> 712302.29 | E8: =D8/D7-1 -> 0.0056732045 | G8: 2022년04월 | H8: 14958348 | I8: 192341 | J8: =H8/I8 -> 77.76994
D9: =H9/21 -> 816812.29 | E9: =D9/D8-1 -> 0.14672142 | G9: 2022년05월 | H9: 17153058 | I9: 208386 | J9: =H9/I9 -> 82.313869
A10: =AVERAGE(D8:D10) -> 820408.37 | B10: =A10/A7-1 -> 0.14324364 | D10: =H10/21 -> 932110.52 | E10: =D10/D9-1 -> 0.14115635 | G10: 2022년06월 | H10: 19574321 | I10: 253961 | J10: =H10/I10 -> 77.07609 | K10: =H10+H9+H8 -> 51685727 | L10: =K10/K7-1 -> 0.20755921 | N10: =AVERAGE(J8:J10) -> 79.0533 | O10: =N10/N7-1 -> 0.062614948
D11: =H11/21 -> 931909.57 | E11: =D11/D10-1 -> -0.00021558858 | G11: 2022년07월 | H11: 19570101 | I11: 214562.3 | J11: =H11/I11 -> 91.209411
D12: =H12/22 -> 986340.27 | E12: =D12/D11-1 -> 0.058407707 | G12: 2022년08월 | H12: 21699486 | I12: 256425.8 | J12: =H12/I12 -> 84.622866
A13: =AVERAGE(D11:D13) -> 938765.81 | B13: =A13/A10-1 -> 0.14426651 | D13: =H13/20 -> 898047.6 | E13: =D13/D12-1 -> -0.089515429 | G13: 2022년09월 | H13: 17960952 | I13: 185286 | J13: =H13/I13 -> 96.936369 | K13: =H13+H12+H11 -> 59230539 | L13: =K13/K10-1 -> 0.14597477 | N13: =AVERAGE(J11:J13) -> 90.922882 | O13: =N13/N10-1 -> 0.15014657
D14: =H14/20 -> 621054.7 | E14: =D14/D13-1 -> -0.308439 | G14: 2022년10월 | H14: 12421094 | I14: 120467 | J14: =H14/I14 -> 103.10786
D15: =H15/22 -> 528380.86 | E15: =D15/D14-1 -> -0.14922009 | G15: 2022년11월 | H15: 11624379 | I15: 147274.4 | J15: =H15/I15 -> 78.930072
A16: =AVERAGE(D14:D16) -> 607334.26 | B16: =A16/A13-1 -> -0.3530503 | D16: =H16/22 -> 672567.23 | E16: =D16/D15-1 -> 0.27288339 | G16: 2022년12월 | H16: 14796479 | I16: 159683.6 | J16: =H16/I16 -> 92.661231 | K16: =H16+H15+H14 -> 38841952 | L16: =K16/K13-1 -> -0.34422424 | N16: =AVERAGE(J14:J16) -> 91.566386 | O16: =N16/N13-1 -> 0.0070774757
D17: =H17/20 -> 554906.55 | E17: =D17/D16-1 -> -0.17494263 | F17: =D17/D5-1 -> -0.088441338 | G17: 2023년 1월 | H17: 11098131 | I17: 123133.07 | J17: =H17/I17 -> 90.131197
D18: =H18/20 -> 288857.2 | E18: =D18/D17-1 -> -0.47944893 | F18: =D18/D6-1 -> -0.6544006 | G18: 2023년 2월 | H18: 5777144 | I18: 79600.32 | J18: =H18/I18 -> 72.576894
A19: =AVERAGE(D17:D19) -> 446413.77 | B19: =A19/A16-1 -> -0.264962 | C19: =A19/A7-1 -> -0.37791993 | D19: =H19/22 -> 495477.55 | E19: =D19/D18-1 -> 0.71530274 | F19: =D19/D7-1 -> -0.30045361 | G19: 2023년 3월 | H19: 10900506 | I19: 127218.88 | J19: =H19/I19 -> 85.683084 | K19: =H19+H18+H17 -> 27775781 | L19: =K19/K16-1 -> -0.28490255 | M19: =K19/K7-1 -> -0.35106069 | N19: =AVERAGE(J17:J19) -> 82.797058 | O19: =N19/N16-1 -> -0.095770163
D20: =H20/20 -> 735703.75 | E20: =D20/D19-1 -> 0.48483772 | F20: =D20/D8-1 -> 0.032853277 | G20: 2023년 4월 | H20: 14714075 | I20: 148593.9 | J20: =H20/I20 -> 99.022066
D21: =H21/21 -> 653024.52 | E21: =D21/D20-1 -> -0.11238114 | F21: =D21/D9-1 -> -0.20052069 | G21: 2023년 5월 | H21: 13713515 | I21: 142808.16 | J21: =H21/I21 -> 96.027531
A22: =AVERAGE(D20:D22) -> 648397.25 | B22: =A22/A19-1 -> 0.45245801 | C22: =A22/A10-1 -> -0.20966524 | D22: =H22/21 -> 556463.48 | E22: =D22/D21-1 -> -0.14786741 | F22: =D22/D10-1 -> -0.40300698 | G22: 2023년 6월 | H22: 11685733 | I22: 129568.8 | J22: =H22/I22 -> 90.189405 | K22: =H22+H21+H20 -> 40113323 | L22: =K22/K19-1 -> 0.44418344 | M22: =K22/K10-1 -> -0.22389941 | N22: =AVERAGE(J20:J22) -> 95.079667 | O22: =N22/N19-1 -> 0.14834596
D23: =H23/21 -> 760673.86 | E23: =D23/D22-1 -> 0.36697895 | F23: =D23/D11-1 -> -0.18374714 | G23: 2023년 7월 | H23: 15974151 | I23: 188623.7 | J23: =H23/I23 -> 84.687932
D24: =H24/22 -> 788231.05 | E24: =D24/D23-1 -> 0.036227337 | F24: =D24/D12-1 -> -0.20085282 | G24: 2023년 8월 | H24: 17341083 | I24: 171491.7 | J24: =H24/I24 -> 101.11908
A25: =AVERAGE(D23:D25) -> 756282 | B25: =A25/A22-1 -> 0.16638681 | C25: =A25/A13-1 -> -0.19438694 | D25: =H25/19 -> 719941.11 | E25: =D25/D24-1 -> -0.086636958 | F25: =D25/D13-1 -> -0.19832634 | G25: 2023년 9월 | H25: 13678881 | I25: 156002.57 | J25: =H25/I25 -> 87.68369 | K25: =H25+H24+H23 -> 46994115 | L25: =K25/K22-1 -> 0.17153383 | M25: =K25/K13-1 -> -0.20658978 | N25: =AVERAGE(J23:J25) -> 91.163567 | O25: =N25/N22-1 -> -0.041187566
D26: =H26/19 -> 792430.05 | E26: =D26/D25-1 -> 0.10068733 | F26: =D26/D14-1 -> 0.27594245 | G26: 2023년 10월 | H26: 15056171 | I26: 179728.95 | J26: =H26/I26 -> 83.77154
D27: =H27/22 -> 702365.36 | E27: =D27/D26-1 -> -0.11365633 | F27: =D27/D15-1 -> 0.32927858 | G27: 2023년 11월 | H27: 15452038 | I27: 179496.5 | J27: =H27/I27 -> 86.085456
A28: =AVERAGE(D26:D28) -> 740843.58 | B28: =A28/A25-1 -> -0.020413583 | C28: =A28/A16-1 -> 0.21982839 | D28: =H28/19 -> 727735.32 | E28: =D28/D27-1 -> 0.036120734 | F28: =D28/D16-1 -> 0.082026133 | G28: 2023년 12월 | H28: 13826971 | I28: 186680.01 | J28: =H28/I28 -> 74.067764 | K28: =H28+H27+H26 -> 44335180 | L28: =K28/K25-1 -> -0.05658017 | M28: =K28/K16-1 -> 0.14142513 | N28: =AVERAGE(J26:J28) -> 81.308254 | O28: =N28/N25-1 -> -0.10810584
D29: =H29/22 -> 617347.55 | E29: =D29/D28-1 -> -0.1516867 | F29: =D29/D17-1 -> 0.11252524 | G29: 2024년 1월 | H29: 13581646 | I29: 157350.7 | J29: =H29/I29 -> 86.314494
D30: =H30/19 -> 523755.42 | E30: =D30/D29-1 -> -0.15160362 | F30: =D30/D18-1 -> 0.81319843 | G30: 2024년 2월 | H30: 9951353 | I30: 112009.78 | J30: =H30/I30 -> 88.843608
A31: =AVERAGE(D29:D31) -> 575732.81 | B31: =A31/A28-1 -> -0.2228686 | C31: =A31/A19-1 -> 0.28968426 | D31: =H31/20 -> 586095.45 | E31: =D31/D30-1 -> 0.11902508 | F31: =D31/D19-1 -> 0.18289003 | G31: 2024년 3월 | H31: 11721909 | I31: 153309.15 | J31: =H31/I31 -> 76.459292 | K31: =H31+H30+H29 -> 35254908 | L31: =K31/K28-1 -> -0.20480963 | M31: =K31/K19-1 -> 0.26926793 | N31: =AVERAGE(J29:J31) -> 83.872464 | O31: =N31/N28-1 -> 0.031536908
D32: =H32/21 -> 527690.24 | E32: =D32/D31-1 -> -0.099651365 | F32: =D32/D20-1 -> -0.28274086 | G32: 2024년 4월 | H32: 11081495 | I32: 179360.66 | J32: =H32/I32 -> 61.783309
D33: =H33/21 -> 551130 | E33: =D33/D32-1 -> 0.044419548 | F33: =D33/D21-1 -> -0.15603476 | G33: 2024년 5월 | H33: 11573730 | I33: 177309.9 | J33: =H33/I33 -> 65.27402
A34: =AVERAGE(D32:D34) -> 532154.83 | B34: =A34/A31-1 -> -0.075691313 | C34: =A34/A22-1 -> -0.17927654 | D34: =H34/19 -> 517644.26 | E34: =D34/D33-1 -> -0.060758327 | F34: =D34/D22-1 -> -0.069760577 | G34: 2024년 6월 | H34: 9835241 | I34: 137161.5 | J34: =H34/I34 -> 71.705551 | K34: =H34+H33+H32 -> 32490466 | L34: =K34/K31-1 -> -0.078412969 | M34: =K34/K22-1 -> -0.19003305 | N34: =AVERAGE(J32:J34) -> 66.254293 | O34: =N34/N31-1 -> -0.21005906
D35: =H35/23 -> 762113.52 | E35: =D35/D34-1 -> 0.47227271 | F35: =D35/D23-1 -> 0.0018926174 | G35: 2024년 7월 | H35: 17528611 | I35: 218487.4 | J35: =H35/I35 -> 80.227102
D36: =H36/21 -> 544925.24 | E36: =D36/D35-1 -> -0.28498154 | F36: =D36/D24-1 -> -0.30867321 | G36: 2024년 8월 | H36: 11443430 | I36: 157849.56 | J36: =H36/I36 -> 72.495799
A37: =AVERAGE(D35:D37) -> 653019.7 | B37: =A37/A34-1 -> 0.22712349 | C37: =A37/A25-1 -> -0.13653942 | D37: =H37/18 -> 652020.33 | E37: =D37/D36-1 -> 0.19653172 | F37: =D37/D25-1 -> -0.094342122 | G37: 2024년 9월 | H37: 11736366 | I37: 173496.48 | J37: =H37/I37 -> 67.646133 | K37: =H37+H36+H35 -> 40708407 | L37: =K37/K34-1 -> 0.25293392 | M37: =K37/K25-1 -> -0.13375522 | N37: =AVERAGE(J35:J37) -> 73.456345 | O37: =N37/N34-1 -> 0.10870317
D38: =H38/20 -> 682366.6 | E38: =D38/D37-1 -> 0.046541902 | F38: =D38/D26-1 -> -0.13889359 | G38: 2024년 10월 | H38: 13647332 | I38: 208517.1 | J38: =H38/I38 -> 65.449462
D39: =H39/21 -> 951699.29 | E39: =D39/D38-1 -> 0.39470379 | F39: =D39/D27-1 -> 0.35499177 | G39: 2024년 11월 | H39: 19985685 | I39: 261560.27 | J39: =H39/I39 -> 76.409483
A40: =AVERAGE(D38:D40) -> 1003833.6 | B40: =A40/A37-1 -> 0.53721802 | C40: =A40/A28-1 -> 0.35498731 | D40: =H40/21 -> 1377435 | E40: =D40/D39-1 -> 0.44734274 | F40: =D40/D28-1 -> 0.89276928 | G40: 2024년 12월 | H40: 28926136 | I40: 340609 | J40: =H40/I40 -> 84.924755 | K40: =H40+H39+H38 -> 62559153 | L40: =K40/K37-1 -> 0.53676249 | M40: =K40/K28-1 -> 0.41104994 | N40: =AVERAGE(J38:J40) -> 75.594567 | O40: =N40/N37-1 -> 0.029108743
...

Sheet 두산(김천)
A1: 두산 | P1: 두산
P2: 741021 | Q2: 증평, 김천, 익산, 김제
G3: 년월 | H3: 금액(달러) | I3: 중량 | P3: * 잠정치가 아니라 확정치만 볼수 있음
A4: 분기(일평균) | B4: QoQ | D4: 일평균수출 | E4: mom | F4: yoy | J4: 금액(달러)/중량 | L4: QoQ | M4: yoy | N4: 단가 | O4: QoQ
D5: =H5/20 -> 232266.85 | G5: 2022년01월 | H5: 4645337 | I5: 74082.1 | J5: =H5/I5 -> 62.705255
D6: =H6/18 -> 233087.5 | E6: =D6/D5-1 -> 0.0035332205 | G6: 2022년02월 | H6: 4195575 | I6: 73029.8 | J6: =H6/I6 -> 57.450178
A7: =AVERAGE(D5:D7) -> 242314.13 | D7: =H7/22 -> 261588.05 | E7: =D7/D6-1 -> 0.12227402 | G7: 2022년03월 | H7: 5754937 | I7: 77897.3 | J7: =H7/I7 -> 73.878517 | K7: =H7+H6+H5 -> 14595849 | N7: =AVERAGE(J5:J7) -> 64.677983
D8: =H8/21 -> 266911.14 | E8: =D8/D7-1 -> 0.020349162 | G8: 2022년04월 | H8: 5605134 | I8: 77337.2 | J8: =H8/I8 -> 72.476557
D9: =H9/21 -> 203832.14 | E9: =D9/D8-1 -> -0.23632959 | G9: 2022년05월 | H9: 4280475 | I9: 57482.3 | J9: =H9/I9 -> 74.465966
A10: =AVERAGE(D8:D10) -> 224040.79 | B10: =A10/A7-1 -> -0.075411772 | D10: =H10/21 -> 201379.1 | E10: =D10/D9-1 -> -0.012034646 | G10: 2022년06월 | H10: 4228961 | I10: 55095.9 | J10: =H10/I10 -> 76.756365 | K10: =H10+H9+H8 -> 14114570 | L10: =K10/K7-1 -> -0.03297369 | N10: =AVERAGE(J8:J10) -> 74.566296 | O10: =N10/N7-1 -> 0.1528853
D11: =H11/21 -> 206340.67 | E11: =D11/D10-1 -> 0.024637967 | G11: 2022년07월 | H11: 4333154 | I11: 59529.1 | J11: =H11/I11 -> 72.790518
D12: =H12/22 -> 188165.27 | E12: =D12/D11-1 -> -0.088084401 | G12: 2022년08월 | H12: 4139636 | I12: 53798.3 | J12: =H12/I12 -> 76.947338
A13: =AVERAGE(D11:D13) -> 200772.13 | B13: =A13/A10-1 -> -0.10385905 | D13: =H13/20 -> 207810.45 | E13: =D13/D12-1 -> 0.10440384 | G13: 2022년09월 | H13: 4156209 | I13: 59759.3 | J13: =H13/I13 -> 69.549158 | K13: =H13+H12+H11 -> 12628999 | L13: =K13/K10-1 -> -0.10525089 | N13: =AVERAGE(J11:J13) -> 73.095671 | O13: =N13/N10-1 -> -0.019722378
D14: =H14/20 -> 165763.65 | E14: =D14/D13-1 -> -0.20233246 | G14: 2022년10월 | H14: 3315273 | I14: 60128.5 | J14: =H14/I14 -> 55.136466
D15: =H15/22 -> 101313.95 | E15: =D15/D14-1 -> -0.38880476 | G15: 2022년11월 | H15: 2228907 | I15: 53075.3 | J15: =H15/I15 -> 41.995184
A16: =AVERAGE(D14:D16) -> 118536.22 | B16: =A16/A13-1 -> -0.40959825 | D16: =H16/22 -> 88531.045 | E16: =D16/D15-1 -> -0.12617126 | G16: 2022년12월 | H16: 1947683 | I16: 38819.4 | J16: =H16/I16 -> 50.172929 | K16: =H16+H15+H14 -> 7491863 | L16: =K16/K13-1 -> -0.40677302 | N16: =AVERAGE(J14:J16) -> 49.101526 | O16: =N16/N13-1 -> -0.32825671
D17: =H17/20 -> 107186 | E17: =D17/D16-1 -> 0.21071653 | F17: =D17/D5-1 -> -0.53852218 | G17: 2023년 1월 | H17: 2143720 | I17: 42020.87 | J17: =H17/I17 -> 51.015602
D18: =H18/20 -> 151549.85 | E18: =D18/D17-1 -> 0.41389594 | F18: =D18/D6-1 -> -0.34981563 | G18: 2023년 2월 | H18: 3030997 | I18: 49608.68 | J18: =H18/I18 -> 61.098118
A19: =AVERAGE(D17:D19) -> 133709.62 | B19: =A19/A16-1 -> 0.12800645 | C19: =A19/A7-1 -> -0.4481972 | D19: =H19/22 -> 142393 | E19: =D19/D18-1 -> -0.060421373 | F19: =D19/D7-1 -> -0.45565938 | G19: 2023년 3월 | H19: 3132646 | I19: 34139.58 | J19: =H19/I19 -> 91.759945 | K19: =H19+H18+H17 -> 8307363 | L19: =K19/K16-1 -> 0.10885143 | M19: =K19/K7-1 -> -0.43084071 | N19: =AVERAGE(J17:J19) -> 67.957889 | O19: =N19/N16-1 -> 0.38402803
D20: =H20/20 -> 170206.15 | E20: =D20/D19-1 -> 0.19532667 | F20: =D20/D8-1 -> -0.36231156 | G20: 2023년 4월 | H20: 3404123 | I20: 38106.96 | J20: =H20/I20 -> 89.330742
D21: =H21/21 -> 210504.38 | E21: =D21/D20-1 -> 0.23676131 | F21: =D21/D9-1 -> 0.032733984 | G21: 2023년 5월 | H21: 4420592 | I21: 45619.2 | J21: =H21/I21 -> 96.902006
A22: =AVERAGE(D20:D22) -> 201189.8 | B22: =A22/A19-1 -> 0.50467708 | C22: =A22/A10-1 -> -0.10199481 | D22: =H22/21 -> 222858.86 | E22: =D22/D21-1 -> 0.058689877 | F22: =D22/D10-1 -> 0.10666332 | G22: 2023년 6월 | H22: 4680036 | I22: 49492.63 | J22: =H22/I22 -> 94.560261 | K22: =H22+H21+H20 -> 12504751 | L22: =K22/K19-1 -> 0.50526118 | M22: =K22/K10-1 -> -0.1140537 | N22: =AVERAGE(J20:J22) -> 93.59767 | O22: =N22/N19-1 -> 0.37728925
D23: =H23/21 -> 268097.9 | E23: =D23/D22-1 -> 0.20299417 | F23: =D23/D11-1 -> 0.29929746 | G23: 2023년 7월 | H23: 5630056 | I23: 66234.5 | J23: =H23/I23 -> 85.001865
D24: =H24/22 -> 243150.41 | E24: =D24/D23-1 -> -0.093053676 | F24: =D24/D12-1 -> 0.29221724 | G24: 2023년 8월 | H24: 5349309 | I24: 68745.06 | J24: =H24/I24 -> 77.813722
A25: =AVERAGE(D23:D25) -> 266420.89 | B25: =A25/A22-1 -> 0.32422667 | C25: =A25/A13-1 -> 0.32698146 | D25: =H25/19 -> 288014.37 | E25: =D25/D24-1 -> 0.18451114 | F25: =D25/D13-1 -> 0.38594747 | G25: 2023년 9월 | H25: 5472273 | I25: 94896.33 | J25: =H25/I25 -> 57.665802 | K25: =H25+H24+H23 -> 16451638 | L25: =K25/K22-1 -> 0.31563099 | M25: =K25/K13-1 -> 0.30268741 | N25: =AVERAGE(J23:J25) -> 73.493796 | O25: =N25/N22-1 -> -0.21479032
D26: =H26/19 -> 340627.42 | E26: =D26/D25-1 -> 0.1826751 | F26: =D26/D14-1 -> 1.0548982 | G26: 2023년 10월 | H26: 6471921 | I26: 91401.29 | J26: =H26/I26 -> 70.807764
D27: =H27/22 -> 276817.27 | E27: =D27/D26-1 -> -0.18733121 | F27: =D27/D15-1 -> 1.7322719 | G27: 2023년 11월 | H27: 6089980 | I27: 81141.71 | J27: =H27/I27 -> 75.053631
A28: =AVERAGE(D26:D28) -> 316811.25 | B28: =A28/A25-1 -> 0.18913815 | C28: =A28/A16-1 -> 1.6726958 | D28: =H28/19 -> 332989.05 | E28: =D28/D27-1 -> 0.20292007 | F28: =D28/D16-1 -> 2.7612687 | G28: 2023년 12월 | H28: 6326792 | I28: 84958.18 | J28: =H28/I28 -> 74.469486 | K28: =H28+H27+H26 -> 18888693 | L28: =K28/K25-1 -> 0.14813449 | M28: =K28/K16-1 -> 1.5212278 | N28: =AVERAGE(J26:J28) -> 73.443627 | O28: =N28/N25-1 -> -0.00068262986
D29: =H29/22 -> 321638.45 | E29: =D29/D28-1 -> -0.034087001 | F29: =D29/D17-1 -> 2.0007506 | G29: 2024년 1월 | H29: 7076046 | I29: 75470.14 | J29: =H29/I29 -> 93.759545
D30: =H30/19 -> 301276.32 | E30: =D30/D29-1 -> -0.063307538 | F30: =D30/D18-1 -> 0.98796842 | G30: 2024년 2월 | H30: 5724250 | I30: 62181.84 | J30: =H30/I30 -> 92.05662
A31: =AVERAGE(D29:D31) -> 300031.44 | B31: =A31/A28-1 -> -0.052964687 | C31: =A31/A19-1 -> 1.2439032 | D31: =H31/20 -> 277179.55 | E31: =D31/D30-1 -> -0.079982277 | F31: =D31/D19-1 -> 0.94658129 | G31: 2024년 3월 | H31: 5543591 | I31: 72686.46 | J31: =H31/I31 -> 76.267175 | K31: =H31+H30+H29 -> 18343887 | L31: =K31/K28-1 -> -0.02884297 | M31: =K31/K19-1 -> 1.208148 | N31: =AVERAGE(J29:J31) -> 87.361113 | O31: =N31/N28-1 -> 0.18949889
D32: =H32/21 -> 282141.14 | E32: =D32/D31-1 -> 0.017900285 | F32: =D32/D20-1 -> 0.65764364 | G32: 2024년 4월 | H32: 5924964 | I32: 76747.8 | J32: =H32/I32 -> 77.200441
D33: =H33/21 -> 229982.24 | E33: =D33/D32-1 -> -0.18486813 | F33: =D33/D21-1 -> 0.092529462 | G33: 2024년 5월 | H33: 4829627 | I33: 59707.55 | J33: =H33/I33 -> 80.888045
A34: =AVERAGE(D32:D34) -> 261413.64 | B34: =A34/A31-1 -> -0.12871253 | C34: =A34/A22-1 -> 0.29933844 | D34: =H34/19 -> 272117.53 | E34: =D34/D33-1 -> 0.18321105 | F34: =D34/D22-1 -> 0.22103079 | G34: 2024년 6월 | H34: 5170233 | I34: 66963.21 | J34: =H34/I34 -> 77.210053 | K34: =H34+H33+H32 -> 15924824 | L34: =K34/K31-1 -> -0.13187298 | M34: =K34/K22-1 -> 0.27350189 | N34: =AVERAGE(J32:J34) -> 78.432846 | O34: =N34/N31-1 -> -0.10219956
D35: =H35/23 -> 259542.74 | E35: =D35/D34-1 -> -0.046210868 | F35: =D35/D23-1 -> -0.031910602 | G35: 2024년 7월 | H35: 5969483 | I35: 66961.31 | J35: =H35/I35 -> 89.148241
D36: =H36/21 -> 275197.95 | E36: =D36/D35-1 -> 0.06031844 | F36: =D36/D24-1 -> 0.13180131 | G36: 2024년 8월 | H36: 5779157 | I36: 80836.36 | J36: =H36/I36 -> 71.492049
A37: =AVERAGE(D35:D37) -> 271217.64 | B37: =A37/A34-1 -> 0.03750379 | C37: =A37/A25-1 -> 0.018004383 | D37: =H37/18 -> 278912.22 | E37: =D37/D36-1 -> 0.01349672 | F37: =D37/D25-1 -> -0.031603098 | G37: 2024년 9월 | H37: 5020420 | I37: 63222.8 | J37: =H37/I37 -> 79.408378 | K37: =H37+H36+H35 -> 16769060 | L37: =K37/K34-1 -> 0.053013836 | M37: =K37/K25-1 -> 0.019294249 | N37: =AVERAGE(J35:J37) -> 80.016223 | O37: =N37/N34-1 -> 0.020187667
D38: =H38/20 -> 279558.65 | E38: =D38/D37-1 -> 0.0023176746 | F38: =D38/D26-1 -> -0.17928319 | G38: 2024년 10월 | H38: 5591173 | I38: 64337 | J38: =H38/I38 -> 86.904472
D39: =H39/21 -> 179248.76 | E39: =D39/D38-1 -> -0.35881518 | F39: =D39/D27-1 -> -0.3524654 | G39: 2024년 11월 | H39: 3764224 | I39: 43177.5 | J39: =H39/I39 -> 87.180221
A40: =AVERAGE(D38:D40) -> 227954.45 | B40: =A40/A37-1 -> -0.15951464 | C40: =A40/A28-1 -> -0.28047235 | D40: =H40/21 -> 225055.95 | E40: =D40/D39-1 -> 0.25555094 | F40: =D40/D28-1 -> -0.32413408 | G40: 2024년 12월 | H40: 4726175 | I40: 54092 | J40: =H40/I40 -> 87.372902 | K40: =H40+H39+H38 -> 14081572 | L40: =K40/K37-1 -> -0.16026468 | M40: =K40/K28-1 -> -0.25449728 | N40: =AVERAGE(J38:J40) -> 87.152532 | O40: =N40/N37-1 -> 0.089185776
...

Sheet 두산(익산)
A1: 두산 | P1: 두산
P2: 741021 | Q2: 증평, 김천, 익산, 김제
G3: 년월 | H3: 금액(달러) | I3: 중량 | P3: * 잠정치가 아니라 확정치만 볼수 있음
A4: 분기(일평균) | B4: QoQ | D4: 일평균수출 | E4: mom | F4: yoy | J4: 금액(달러)/중량 | L4: QoQ | M4: yoy | N4: 단가 | O4: QoQ | P4: 메디톡스는 다른 수출코드에 수출이 없더라
D5: =H5/20 -> 81823.8 | G5: 2022년01월 | H5: 1636476 | I5: 26783.43 | J5: =H5/I5 -> 61.100315
D6: =H6/18 -> 52053.111 | E6: =D6/D5-1 -> -0.36383899 | G6: 2022년02월 | H6: 936956 | I6: 13215.4 | J6: =H6/I6 -> 70.8988
A7: =AVERAGE(D5:D7) -> 58810.364 | D7: =H7/22 -> 42554.182 | E7: =D7/D6-1 -> -0.18248533 | G7: 2022년03월 | H7: 936192 | I7: 12649.87 | J7: =H7/I7 -> 74.008033 | K7: =H7+H6+H5 -> 3509624 | N7: =AVERAGE(J5:J7) -> 68.669049
D8: =H8/21 -> 115179.71 | E8: =D8/D7-1 -> 1.7066603 | G8: 2022년04월 | H8: 2418774 | I8: 39457.8 | J8: =H8/I8 -> 61.300275
D9: =H9/21 -> 74491.81 | E9: =D9/D8-1 -> -0.35325582 | G9: 2022년05월 | H9: 1564328 | I9: 25428.98 | J9: =H9/I9 -> 61.517528
A10: =AVERAGE(D8:D10) -> 75022.857 | B10: =A10/A7-1 -> 0.27567408 | D10: =H10/21 -> 35397.048 | E10: =D10/D9-1 -> -0.5248196 | G10: 2022년06월 | H10: 743338 | I10: 11021.14 | J10: =H10/I10 -> 67.446562 | K10: =H10+H9+H8 -> 4726440 | L10: =K10/K7-1 -> 0.34670837 | N10: =AVERAGE(J8:J10) -> 63.421455 | O10: =N10/N7-1 -> -0.076418622
D11: =H11/21 -> 76835.81 | E11: =D11/D10-1 -> 1.1706841 | G11: 2022년07월 | H11: 1613552 | I11: 23349.87 | J11: =H11/I11 -> 69.103254
D12: =H12/22 -> 27835.955 | E12: =D12/D11-1 -> -0.63772159 | G12: 2022년08월 | H12: 612391 | I12: 11639.07 | J12: =H12/I12 -> 52.615114
A13: =AVERAGE(D11:D13) -> 54926.321 | B13: =A13/A10-1 -> -0.26787217 | D13: =H13/20 -> 60107.2 | E13: =D13/D12-1 -> 1.1593368 | G13: 2022년09월 | H13: 1202144 | I13: 24356.34 | J13: =H13/I13 -> 49.356513 | K13: =H13+H12+H11 -> 3428087 | L13: =K13/K10-1 -> -0.27469999 | N13: =AVERAGE(J11:J13) -> 57.02496 | O13: =N13/N10-1 -> -0.10085695
D14: =H14/20 -> 23229 | E14: =D14/D13-1 -> -0.61354047 | G14: 2022년10월 | H14: 464580 | I14: 8998.23 | J14: =H14/I14 -> 51.630154
D15: =H15/22 -> 35039.5 | E15: =D15/D14-1 -> 0.50843773 | G15: 2022년11월 | H15: 770869 | I15: 12706.64 | J15: =H15/I15 -> 60.666628
A16: =AVERAGE(D14:D16) -> 26430.227 | B16: =A16/A13-1 -> -0.5188058 | D16: =H16/22 -> 21022.182 | E16: =D16/D15-1 -> -0.40004333 | G16: 2022년12월 | H16: 462488 | I16: 8726.41 | J16: =H16/I16 -> 52.998656 | K16: =H16+H15+H14 -> 1697937 | L16: =K16/K13-1 -> -0.50469839 | N16: =AVERAGE(J14:J16) -> 55.098479 | O16: =N16/N13-1 -> -0.033783121
D17: =H17/20 -> 37901.7 | E17: =D17/D16-1 -> 0.80293845 | F17: =D17/D5-1 -> -0.53678881 | G17: 2023년 1월 | H17: 758034 | I17: 13067.55 | J17: =H17/I17 -> 58.008885
D18: =H18/20 -> 52434.05 | E18: =D18/D17-1 -> 0.38342212 | F18: =D18/D6-1 -> 0.0073182732 | G18: 2023년 2월 | H18: 1048681 | I18: 17814.43 | J18: =H18/I18 -> 58.866941
A19: =AVERAGE(D17:D19) -> 53381.644 | B19: =A19/A16-1 -> 1.0197194 | C19: =A19/A7-1 -> -0.092308906 | D19: =H19/22 -> 69809.182 | E19: =D19/D18-1 -> 0.33137116 | F19: =D19/D7-1 -> 0.64047759 | G19: 2023년 3월 | H19: 1535802 | I19: 21501.29 | J19: =H19/I19 -> 71.428365 | K19: =H19+H18+H17 -> 3342517 | L19: =K19/K16-1 -> 0.96857539 | M19: =K19/K7-1 -> -0.047613932 | N19: =AVERAGE(J17:J19) -> 62.768064 | O19: =N19/N16-1 -> 0.13919775
D20: =H20/20 -> 83506.8 | E20: =D20/D19-1 -> 0.19621514 | F20: =D20/D8-1 -> -0.27498691 | G20: 2023년 4월 | H20: 1670136 | I20: 19551.08 | J20: =H20/I20 -> 85.424232
D21: =H21/21 -> 112335.1 | E21: =D21/D20-1 -> 0.34522093 | F21: =D21/D9-1 -> 0.50801942 | G21: 2023년 5월 | H21: 2359037 | I21: 31298.01 | J21: =H21/I21 -> 75.373386
A22: =AVERAGE(D20:D22) -> 86949.505 | B22: =A22/A19-1 -> 0.62882778 | C22: =A22/A10-1 -> 0.15897352 | D22: =H22/21 -> 65006.619 | E22: =D22/D21-1 -> -0.42131514 | F22: =D22/D10-1 -> 0.83649834 | G22: 2023년 6월 | H22: 1365139 | I22: 19382.14 | J22: =H22/I22 -> 70.432831 | K22: =H22+H21+H20 -> 5394312 | L22: =K22/K19-1 -> 0.61384729 | M22: =K22/K10-1 -> 0.14130551 | N22: =AVERAGE(J20:J22) -> 77.076817 | O22: =N22/N19-1 -> 0.22796231
D23: =H23/21 -> 81734.667 | E23: =D23/D22-1 -> 0.25732837 | F23: =D23/D11-1 -> 0.063757474 | G23: 2023년 7월 | H23: 1716428 | I23: 18420.09 | J23: =H23/I23 -> 93.182389
D24: =H24/22 -> 94163.636 | E24: =D24/D23-1 -> 0.15206485 | F24: =D24/D12-1 -> 2.3828061 | G24: 2023년 8월 | H24: 2071600 | I24: 25752.65 | J24: =H24/I24 -> 80.442207
A25: =AVERAGE(D23:D25) -> 85958.294 | B25: =A25/A22-1 -> -0.011399844 | C25: =A25/A13-1 -> 0.56497453 | D25: =H25/19 -> 81976.579 | E25: =D25/D24-1 -> -0.12942424 | F25: =D25/D13-1 -> 0.36383959 | G25: 2023년 9월 | H25: 1557555 | I25: 22652.32 | J25: =H25/I25 -> 68.759182 | K25: =H25+H24+H23 -> 5345583 | L25: =K25/K22-1 -> -0.0090334041 | M25: =K25/K13-1 -> 0.5593487 | N25: =AVERAGE(J23:J25) -> 80.794593 | O25: =N25/N22-1 -> 0.048234688
D26: =H26/19 -> 66236.474 | E26: =D26/D25-1 -> -0.19200734 | F26: =D26/D14-1 -> 1.8514561 | G26: 2023년 10월 | H26: 1258493 | I26: 17842.25 | J26: =H26/I26 -> 70.534434
D27: =H27/22 -> 39190.5 | E27: =D27/D26-1 -> -0.40832448 | F27: =D27/D15-1 -> 0.1184663 | G27: 2023년 11월 | H27: 862191 | I27: 12814.51 | J27: =H27/I27 -> 67.282401
A28: =AVERAGE(D26:D28) -> 50004.728 | B28: =A28/A25-1 -> -0.41826756 | C28: =A28/A16-1 -> 0.89195225 | D28: =H28/19 -> 44587.211 | E28: =D28/D27-1 -> 0.13770456 | F28: =D28/D16-1 -> 1.1209602 | G28: 2023년 12월 | H28: 847157 | I28: 11658.04 | J28: =H28/I28 -> 72.667189 | K28: =H28+H27+H26 -> 2967841 | L28: =K28/K25-1 -> -0.44480499 | M28: =K28/K16-1 -> 0.74790996 | N28: =AVERAGE(J26:J28) -> 70.161341 | O28: =N28/N25-1 -> -0.13160845
D29: =H29/22 -> 39007.182 | E29: =D29/D28-1 -> -0.12514864 | F29: =D29/D17-1 -> 0.029167077 | G29: 2024년 1월 | H29: 858158 | I29: 15108.98 | J29: =H29/I29 -> 56.797878
D30: =H30/19 -> 24707.526 | E30: =D30/D29-1 -> -0.36659033 | F30: =D30/D18-1 -> -0.52878852 | G30: 2024년 2월 | H30: 469443 | I30: 6078.79 | J30: =H30/I30 -> 77.226389
A31: =AVERAGE(D29:D31) -> 44775.969 | B31: =A31/A28-1 -> -0.10456529 | C31: =A31/A19-1 -> -0.16121037 | D31: =H31/20 -> 70613.2 | E31: =D31/D30-1 -> 1.8579632 | F31: =D31/D19-1 -> 0.01151737 | G31: 2024년 3월 | H31: 1412264 | I31: 19252.13 | J31: =H31/I31 -> 73.356247 | K31: =H31+H30+H29 -> 2739865 | L31: =K31/K28-1 -> -0.076815436 | M31: =K31/K19-1 -> -0.18029886 | N31: =AVERAGE(J29:J31) -> 69.126838 | O31: =N31/N28-1 -> -0.014744637
D32: =H32/21 -> 73874.333 | E32: =D32/D31-1 -> 0.046183055 | F32: =D32/D20-1 -> -0.11534949 | G32: 2024년 4월 | H32: 1551361 | I32: 18250.49 | J32: =H32/I32 -> 85.0038
D33: =H33/21 -> 66008.381 | E33: =D33/D32-1 -> -0.10647747 | F33: =D33/D21-1 -> -0.41239752 | G33: 2024년 5월 | H33: 1386176 | I33: 16178.47 | J33: =H33/I33 -> 85.68029
A34: =AVERAGE(D32:D34) -> 87946.712 | B34: =A34/A31-1 -> 0.96414981 | C34: =A34/A22-1 -> 0.011468806 | D34: =H34/19 -> 123957.42 | E34: =D34/D33-1 -> 0.87790428 | F34: =D34/D22-1 -> 0.90684307 | G34: 2024년 6월 | H34: 2355191 | I34: 28453.89 | J34: =H34/I34 -> 82.772197 | K34: =H34+H33+H32 -> 5292728 | L34: =K34/K31-1 -> 0.93174773 | M34: =K34/K22-1 -> -0.018831688 | N34: =AVERAGE(J32:J34) -> 84.485429 | O34: =N34/N31-1 -> 0.22217986
D35: =H35/23 -> 62401.174 | E35: =D35/D34-1 -> -0.49659187 | F35: =D35/D23-1 -> -0.23653969 | G35: 2024년 7월 | H35: 1435227 | I35: 17389.22 | J35: =H35/I35 -> 82.535444
D36: =H36/21 -> 48749.238 | E36: =D36/D35-1 -> -0.21877691 | F36: =D36/D24-1 -> -0.48229232 | G36: 2024년 8월 | H36: 1023734 | I36: 13916.77 | J36: =H36/I36 -> 73.561178
A37: =AVERAGE(D35:D37) -> 55864.23 | B37: =A37/A34-1 -> -0.36479456 | C37: =A37/A25-1 -> -0.35010076 | D37: =H37/18 -> 56442.278 | E37: =D37/D36-1 -> 0.15780841 | F37: =D37/D25-1 -> -0.31148288 | G37: 2024년 9월 | H37: 1015961 | I37: 11568.55 | J37: =H37/I37 -> 87.820946 | K37: =H37+H36+H35 -> 3474922 | L37: =K37/K34-1 -> -0.34345351 | M37: =K37/K25-1 -> -0.34994518 | N37: =AVERAGE(J35:J37) -> 81.305856 | O37: =N37/N34-1 -> -0.037634572
D38: =H38/20 -> 54987 | E38: =D38/D37-1 -> -0.02578347 | F38: =D38/D26-1 -> -0.16983805 | G38: 2024년 10월 | H38: 1099740 | I38: 18141.23 | J38: =H38/I38 -> 60.621027
D39: =H39/21 -> 100347.86 | E39: =D39/D38-1 -> 0.82493784 | F39: =D39/D27-1 -> 1.5605148 | G39: 2024년 11월 | H39: 2107305 | I39: 26110.72 | J39: =H39/I39 -> 80.706507
A40: =AVERAGE(D38:D40) -> 75508.143 | B40: =A40/A37-1 -> 0.35163669 | C40: =A40/A28-1 -> 0.51002007 | D40: =H40/21 -> 71189.571 | E40: =D40/D39-1 -> -0.29057208 | F40: =D40/D28-1 -> 0.59663658 | G40: 2024년 12월 | H40: 1494981 | I40: 18535.4 | J40: =H40/I40 -> 80.655448 | K40: =H40+H39+H38 -> 4702026 | L40: =K40/K37-1 -> 0.35313138 | M40: =K40/K28-1 -> 0.58432544 | N40: =AVERAGE(J38:J40) -> 73.994328 | O40: =N40/N37-1 -> -0.089926223
...

Sheet 두산(김제)
A1: 두산 | P1: 두산
P2: 741021 | Q2: 증평, 김천, 익산, 김제
G3: 년월 | H3: 금액(달러) | I3: 중량 | P3: * 잠정치가 아니라 확정치만 볼수 있음
A4: 분기(일평균) | B4: QoQ | D4: 일평균수출 | E4: mom | F4: yoy | J4: 금액(달러)/중량 | L4: QoQ | M4: yoy | N4: 단가 | O4: QoQ
D5: =H5/20 -> 0 | G5: 2022년01월 | J5: =H5/I5 -> #DIV/0!
D6: =H6/18 -> 0 | E6: =D6/D5-1 -> #DIV/0! | G6: 2022년02월 | J6: =H6/I6 -> #DIV/0!
A7: =AVERAGE(D5:D7) -> 0 | D7: =H7/22 -> 0 | E7: =D7/D6-1 -> #DIV/0! | G7: 2022년03월 | J7: =H7/I7 -> #DIV/0! | K7: =H7+H6+H5 -> 0 | N7: =AVERAGE(J5:J7) -> #DIV/0!
D8: =H8/21 -> 0 | E8: =D8/D7-1 -> #DIV/0! | G8: 2022년04월 | J8: =H8/I8 -> #DIV/0!
D9: =H9/21 -> 0 | E9: =D9/D8-1 -> #DIV/0! | G9: 2022년05월 | J9: =H9/I9 -> #DIV/0!
A10: =AVERAGE(D8:D10) -> 0 | B10: =A10/A7-1 -> #DIV/0! | D10: =H10/21 -> 0 | E10: =D10/D9-1 -> #DIV/0! | G10: 2022년06월 | J10: =H10/I10 -> #DIV/0! | K10: =H10+H9+H8 -> 0 | L10: =K10/K7-1 -> #DIV/0! | N10: =AVERAGE(J8:J10) -> #DIV/0! | O10: =N10/N7-1 -> #DIV/0!
D11: =H11/21 -> 0 | E11: =D11/D10-1 -> #DIV/0! | G11: 2022년07월 | J11: =H11/I11 -> #DIV/0!
D12: =H12/22 -> 0 | E12: =D12/D11-1 -> #DIV/0! | G12: 2022년08월 | J12: =H12/I12 -> #DIV/0!
A13: =AVERAGE(D11:D13) -> 0 | B13: =A13/A10-1 -> #DIV/0! | D13: =H13/20 -> 0 | E13: =D13/D12-1 -> #DIV/0! | G13: 2022년09월 | J13: =H13/I13 -> #DIV/0! | K13: =H13+H12+H11 -> 0 | L13: =K13/K10-1 -> #DIV/0! | N13: =AVERAGE(J11:J13) -> #DIV/0! | O13: =N13/N10-1 -> #DIV/0!
D14: =H14/20 -> 0 | E14: =D14/D13-1 -> #DIV/0! | G14: 2022년10월 | J14: =H14/I14 -> #DIV/0!
D15: =H15/22 -> 0 | E15: =D15/D14-1 -> #DIV/0! | G15: 2022년11월 | J15: =H15/I15 -> #DIV/0!
A16: =AVERAGE(D14:D16) -> 0 | B16: =A16/A13-1 -> #DIV/0! | D16: =H16/22 -> 0 | E16: =D16/D15-1 -> #DIV/0! | G16: 2022년12월 | J16: =H16/I16 -> #DIV/0! | K16: =H16+H15+H14 -> 0 | L16: =K16/K13-1 -> #DIV/0! | N16: =AVERAGE(J14:J16) -> #DIV/0! | O16: =N16/N13-1 -> #DIV/0!
D17: =H17/20 -> 0 | E17: =D17/D16-1 -> #DIV/0! | F17: =D17/D5-1 -> #DIV/0! | G17: 2023년 1월 | J17: =H17/I17 -> #DIV/0!
D18: =H18/20 -> 0 | E18: =D18/D17-1 -> #DIV/0! | F18: =D18/D6-1 -> #DIV/0! | G18: 2023년 2월 | J18: =H18/I18 -> #DIV/0!
A19: =AVERAGE(D17:D19) -> 0 | B19: =A19/A16-1 -> #DIV/0! | C19: =A19/A7-1 -> #DIV/0! | D19: =H19/22 -> 0 | E19: =D19/D18-1 -> #DIV/0! | F19: =D19/D7-1 -> #DIV/0! | G19: 2023년 3월 | J19: =H19/I19 -> #DIV/0! | K19: =H19+H18+H17 -> 0 | L19: =K19/K16-1 -> #DIV/0! | M19: =K19/K7-1 -> #DIV/0! | N19: =AVERAGE(J17:J19) -> #DIV/0! | O19: =N19/N16-1 -> #DIV/0!
D20: =H20/20 -> 0 | E20: =D20/D19-1 -> #DIV/0! | F20: =D20/D8-1 -> #DIV/0! | G20: 2023년 4월 | J20: =H20/I20 -> #DIV/0!
D21: =H21/21 -> 0 | E21: =D21/D20-1 -> #DIV/0! | F21: =D21/D9-1 -> #DIV/0! | G21: 2023년 5월 | J21: =H21/I21 -> #DIV/0!
A22: =AVERAGE(D20:D22) -> 0 | B22: =A22/A19-1 -> #DIV/0! | C22: =A22/A10-1 -> #DIV/0! | D22: =H22/21 -> 0 | E22: =D22/D21-1 -> #DIV/0! | F22: =D22/D10-1 -> #DIV/0! | G22: 2023년 6월 | J22: =H22/I22 -> #DIV/0! | K22: =H22+H21+H20 -> 0 | L22: =K22/K19-1 -> #DIV/0! | M22: =K22/K10-1 -> #DIV/0! | N22: =AVERAGE(J20:J22) -> #DIV/0! | O22: =N22/N19-1 -> #DIV/0!
D23: =H23/21 -> 0 | E23: =D23/D22-1 -> #DIV/0! | F23: =D23/D11-1 -> #DIV/0! | G23: 2023년 7월 | J23: =H23/I23 -> #DIV/0!
D24: =H24/22 -> 0 | E24: =D24/D23-1 -> #DIV/0! | F24: =D24/D12-1 -> #DIV/0! | G24: 2023년 8월 | J24: =H24/I24 -> #DIV/0!
A25: =AVERAGE(D23:D25) -> 0 | B25: =A25/A22-1 -> #DIV/0! | C25: =A25/A13-1 -> #DIV/0! | D25: =H25/19 -> 0 | E25: =D25/D24-1 -> #DIV/0! | F25: =D25/D13-1 -> #DIV/0! | G25: 2023년 9월 | J25: =H25/I25 -> #DIV/0! | K25: =H25+H24+H23 -> 0 | L25: =K25/K22-1 -> #DIV/0! | M25: =K25/K13-1 -> #DIV/0! | N25: =AVERAGE(J23:J25) -> #DIV/0! | O25: =N25/N22-1 -> #DIV/0!
D26: =H26/19 -> 0 | E26: =D26/D25-1 -> #DIV/0! | F26: =D26/D14-1 -> #DIV/0! | G26: 2023년 10월 | J26: =H26/I26 -> #DIV/0!
D27: =H27/22 -> 0 | E27: =D27/D26-1 -> #DIV/0! | F27: =D27/D15-1 -> #DIV/0! | G27: 2023년 11월 | J27: =H27/I27 -> #DIV/0!
A28: =AVERAGE(D26:D28) -> 0 | B28: =A28/A25-1 -> #DIV/0! | C28: =A28/A16-1 -> #DIV/0! | D28: =H28/19 -> 0 | E28: =D28/D27-1 -> #DIV/0! | F28: =D28/D16-1 -> #DIV/0! | G28: 2023년 12월 | J28: =H28/I28 -> #DIV/0! | K28: =H28+H27+H26 -> 0 | L28: =K28/K25-1 -> #DIV/0! | M28: =K28/K16-1 -> #DIV/0! | N28: =AVERAGE(J26:J28) -> #DIV/0! | O28: =N28/N25-1 -> #DIV/0!
D29: =H29/22 -> 0 | E29: =D29/D28-1 -> #DIV/0! | F29: =D29/D17-1 -> #DIV/0! | G29: 2024년 1월 | H29: 0 | I29: 0 | J29: =H29/I29 -> #DIV/0!
D30: =H30/19 -> 0 | E30: =D30/D29-1 -> #DIV/0! | F30: =D30/D18-1 -> #DIV/0! | G30: 2024년 2월 | H30: 0 | I30: 0 | J30: =H30/I30 -> #DIV/0!
A31: =AVERAGE(D29:D31) -> 0 | B31: =A31/A28-1 -> #DIV/0! | C31: =A31/A19-1 -> #DIV/0! | D31: =H31/20 -> 0 | E31: =D31/D30-1 -> #DIV/0! | F31: =D31/D19-1 -> #DIV/0! | G31: 2024년 3월 | H31: 0 | I31: 0 | J31: =H31/I31 -> #DIV/0! | K31: =H31+H30+H29 -> 0 | L31: =K31/K28-1 -> #DIV/0! | M31: =K31/K19-1 -> #DIV/0! | N31: =AVERAGE(J29:J31) -> #DIV/0! | O31: =N31/N28-1 -> #DIV/0!
D32: =H32/21 -> 0 | E32: =D32/D31-1 -> #DIV/0! | F32: =D32/D20-1 -> #DIV/0! | G32: 2024년 4월 | H32: 0 | I32: 0 | J32: =H32/I32 -> #DIV/0!
D33: =H33/21 -> 0 | E33: =D33/D32-1 -> #DIV/0! | F33: =D33/D21-1 -> #DIV/0! | G33: 2024년 5월 | H33: 0 | I33: 0 | J33: =H33/I33 -> #DIV/0!
A34: =AVERAGE(D32:D34) -> 0 | B34: =A34/A31-1 -> #DIV/0! | C34: =A34/A22-1 -> #DIV/0! | D34: =H34/19 -> 0 | E34: =D34/D33-1 -> #DIV/0! | F34: =D34/D22-1 -> #DIV/0! | G34: 2024년 6월 | H34: 0 | I34: 0 | J34: =H34/I34 -> #DIV/0! | K34: =H34+H33+H32 -> 0 | L34: =K34/K31-1 -> #DIV/0! | M34: =K34/K22-1 -> #DIV/0! | N34: =AVERAGE(J32:J34) -> #DIV/0! | O34: =N34/N31-1 -> #DIV/0!
D35: =H35/23 -> 0 | E35: =D35/D34-1 -> #DIV/0! | F35: =D35/D23-1 -> #DIV/0! | G35: 2024년 7월 | H35: 0 | I35: 0 | J35: =H35/I35 -> #DIV/0!
D36: =H36/21 -> 95.238095 | E36: =D36/D35-1 -> #DIV/0! | F36: =D36/D24-1 -> #DIV/0! | G36: 2024년 8월 | H36: 2000 | I36: 0 | J36: =H36/I36 -> #DIV/0!
A37: =AVERAGE(D35:D37) -> 67.801587 | B37: =A37/A34-1 -> #DIV/0! | C37: =A37/A25-1 -> #DIV/0! | D37: =H37/18 -> 108.16667 | E37: =D37/D36-1 -> 0.13575 | F37: =D37/D25-1 -> #DIV/0! | G37: 2024년 9월 | H37: 1947 | I37: 16.39 | J37: =H37/I37 -> 118.79195 | K37: =H37+H36+H35 -> 3947 | L37: =K37/K34-1 -> #DIV/0! | M37: =K37/K25-1 -> #DIV/0! | N37: =AVERAGE(J35:J37) -> #DIV/0! | O37: =N37/N34-1 -> #DIV/0!
D38: =H38/20 -> 177.3 | E38: =D38/D37-1 -> 0.63913713 | F38: =D38/D26-1 -> #DIV/0! | G38: 2024년 10월 | H38: 3546 | I38: 26.7 | J38: =H38/I38 -> 132.80899
D39: =H39/21 -> 75.238095 | E39: =D39/D38-1 -> -0.57564526 | F39: =D39/D27-1 -> #DIV/0! | G39: 2024년 11월 | H39: 1580 | I39: 12.6 | J39: =H39/I39 -> 125.39683
A40: =AVERAGE(D38:D40) -> 108.30635 | B40: =A40/A37-1 -> 0.59740138 | C40: =A40/A28-1 -> #DIV/0! | D40: =H40/21 -> 72.380952 | E40: =D40/D39-1 -> -0.037974684 | F40: =D40/D28-1 -> #DIV/0! | G40: 2024년 12월 | H40: 1520 | I40: 18.89 | J40: =H40/I40 -> 80.465855 | K40: =H40+H39+H38 -> 6646 | L40: =K40/K37-1 -> 0.68381049 | M40: =K40/K28-1 -> #DIV/0! | N40: =AVERAGE(J38:J40) -> 112.89056 | O40: =N40/N37-1 -> #DIV/0!
...

Sheet DB하이텍
A1: =P1 -> DB하이텍 | P1: DB하이텍
P2: 854231 + 부천
G3: 년월 | H3: 금액(달러) | I3: 중량 | P3: * 잠정치가 아니라 확정치만 볼수 있음
A4: 분기(일평균) | B4: QoQ | D4: 일평균수출 | E4: mom | F4: yoy | J4: 금액(달러)/중량 | L4: QoQ | M4: yoy | N4: 단가 | O4: QoQ
D5: =H5/20 -> 3718403.6 | G5: 2022년01월 | H5: 74368072 | I5: 14670.54 | J5: =H5/I5 -> 5069.2116
D6: =H6/18 -> 4961602.7 | E6: =D6/D5-1 -> 0.33433677 | G6: 2022년02월 | H6: 89308848 | I6: 16152.57 | J6: =H6/I6 -> 5529.0798
A7: =AVERAGE(D5:D7) -> 4264287.1 | D7: =H7/22 -> 4112855 | E7: =D7/D6-1 -> -0.17106322 | G7: 2022년03월 | H7: 90482809 | I7: 15385.58 | J7: =H7/I7 -> 5881.0138 | K7: =H7+H6+H5 -> 254159729 | N7: =AVERAGE(J5:J7) -> 5493.1017
D8: =H8/21 -> 3740616.7 | E8: =D8/D7-1 -> -0.090506046 | G8: 2022년04월 | H8: 78552951 | I8: 12525.32 | J8: =H8/I8 -> 6271.5325
D9: =H9/21 -> 4461629.5 | E9: =D9/D8-1 -> 0.19275239 | G9: 2022년05월 | H9: 93694220 | I9: 15888.95 | J9: =H9/I9 -> 5896.8163
A10: =AVERAGE(D8:D10) -> 3902021.4 | B10: =A10/A7-1 -> -0.084953394 | D10: =H10/21 -> 3503818 | E10: =D10/D9-1 -> -0.21467751 | G10: 2022년06월 | H10: 73580178 | I10: 8003.77 | J10: =H10/I10 -> 9193.19 | K10: =H10+H9+H8 -> 245827349 | L10: =K10/K7-1 -> -0.032784029 | N10: =AVERAGE(J8:J10) -> 7120.5129 | O10: =N10/N7-1 -> 0.29626452
D11: =H11/21 -> 3709810.8 | E11: =D11/D10-1 -> 0.058790942 | G11: 2022년07월 | H11: 77906026 | I11: 8053.17 | J11: =H11/I11 -> 9673.9577
D12: =H12/22 -> 4101174 | E12: =D12/D11-1 -> 0.10549414 | G12: 2022년08월 | H12: 90225829 | I12: 9641.43 | J12: =H12/I12 -> 9358.1376
A13: =AVERAGE(D11:D13) -> 4045311.3 | B13: =A13/A10-1 -> 0.036721968 | D13: =H13/20 -> 4324949.2 | E13: =D13/D12-1 -> 0.054563669 | G13: 2022년09월 | H13: 86498983 | I13: 11838.27 | J13: =H13/I13 -> 7306.725 | K13: =H13+H12+H11 -> 254630838 | L13: =K13/K10-1 -> 0.035811674 | N13: =AVERAGE(J11:J13) -> 8779.6068 | O13: =N13/N10-1 -> 0.23300201
D14: =H14/20 -> 4353565 | E14: =D14/D13-1 -> 0.0066164709 | G14: 2022년10월 | H14: 87071301 | I14: 10929.85 | J14: =H14/I14 -> 7966.3766
D15: =H15/22 -> 3565429.5 | E15: =D15/D14-1 -> -0.18103223 | G15: 2022년11월 | H15: 78439448 | I15: 11398.07 | J15: =H15/I15 -> 6881.8184
A16: =AVERAGE(D14:D16) -> 3779309.9 | B16: =A16/A13-1 -> -0.065755481 | D16: =H16/22 -> 3418935.3 | E16: =D16/D15-1 -> -0.041087388 | G16: 2022년12월 | H16: 75216576 | I16: 16585.34 | J16: =H16/I16 -> 4535.1242 | K16: =H16+H15+H14 -> 240727325 | L16: =K16/K13-1 -> -0.054602628 | N16: =AVERAGE(J14:J16) -> 6461.1064 | O16: =N16/N13-1 -> -0.26407793
D17: =H17/20 -> 3752751.5 | E17: =D17/D16-1 -> 0.097637466 | F17: =D17/D5-1 -> 0.0092372571 | G17: 2023년 1월 | H17: 75055029 | I17: 13925.93 | J17: =H17/I17 -> 5389.5883
D18: =H18/20 -> 3340490.1 | E18: =D18/D17-1 -> -0.10985576 | F18: =D18/D6-1 -> -0.32673164 | G18: 2023년 2월 | H18: 66809802 | I18: 13073.39 | J18: =H18/I18 -> 5110.3656
A19: =AVERAGE(D17:D19) -> 3300759.5 | B19: =A19/A16-1 -> -0.12662377 | C19: =A19/A7-1 -> -0.2259528 | D19: =H19/22 -> 2809036.8 | E19: =D19/D18-1 -> -0.1590944 | F19: =D19/D7-1 -> -0.31701048 | G19: 2023년 3월 | H19: 61798810 | I19: 15931.54 | J19: =H19/I19 -> 3879.023 | K19: =H19+H18+H17 -> 203663641 | L19: =K19/K16-1 -> -0.15396542 | M19: =K19/K7-1 -> -0.19867856 | N19: =AVERAGE(J17:J19) -> 4792.9923 | O19: =N19/N16-1 -> -0.25817778
D20: =H20/20 -> 2835489.3 | E20: =D20/D19-1 -> 0.0094169224 | F20: =D20/D8-1 -> -0.24197278 | G20: 2023년 4월 | H20: 56709786 | I20: 15541.08 | J20: =H20/I20 -> 3649.0248
D21: =H21/21 -> 2540003.6 | E21: =D21/D20-1 -> -0.10420977 | F21: =D21/D9-1 -> -0.43070046 | G21: 2023년 5월 | H21: 53340076 | I21: 4251.78 | J21: =H21/I21 -> 12545.352
A22: =AVERAGE(D20:D22) -> 2545569.4 | B22: =A22/A19-1 -> -0.22879282 | C22: =A22/A10-1 -> -0.34762803 | D22: =H22/21 -> 2261215.3 | E22: =D22/D21-1 -> -0.10975903 | F22: =D22/D10-1 -> -0.35464248 | G22: 2023년 6월 | H22: 47485521 | I22: 3799.45 | J22: =H22/I22 -> 12497.999 | K22: =H22+H21+H20 -> 157535383 | L22: =K22/K19-1 -> -0.22649236 | M22: =K22/K10-1 -> -0.3591625 | N22: =AVERAGE(J20:J22) -> 9564.1251 | O22: =N22/N19-1 -> 0.99543929
D23: =H23/21 -> 2181742.4 | E23: =D23/D22-1 -> -0.035146103 | F23: =D23/D11-1 -> -0.41189928 | G23: 2023년 7월 | H23: 45816590 | I23: 4078.35 | J23: =H23/I23 -> 11234.1
D24: =H24/22 -> 1954245.9 | E24: =D24/D23-1 -> -0.10427286 | F24: =D24/D12-1 -> -0.52349112 | G24: 2023년 8월 | H24: 42993409 | I24: 3853.65 | J24: =H24/I24 -> 11156.542
A25: =AVERAGE(D23:D25) -> 2127146.7 | B25: =A25/A22-1 -> -0.16437295 | C25: =A25/A13-1 -> -0.47416985 | D25: =H25/19 -> 2245451.7 | E25: =D25/D24-1 -> 0.14901189 | F25: =D25/D13-1 -> -0.4808143 | G25: 2023년 9월 | H25: 42663583 | I25: 4269.38 | J25: =H25/I25 -> 9992.9224 | K25: =H25+H24+H23 -> 131473582 | L25: =K25/K22-1 -> -0.16543459 | M25: =K25/K13-1 -> -0.48366984 | N25: =AVERAGE(J23:J25) -> 10794.521 | O25: =N25/N22-1 -> 0.12864703
D26: =H26/19 -> 2501104.2 | E26: =D26/D25-1 -> 0.11385347 | F26: =D26/D14-1 -> -0.42550434 | G26: 2023년 10월 | H26: 47520980 | I26: 5109.14 | J26: =H26/I26 -> 9301.1701
D27: =H27/22 -> 2156322.6 | E27: =D27/D26-1 -> -0.13785174 | F27: =D27/D15-1 -> -0.39521377 | G27: 2023년 11월 | H27: 47439098 | I27: 4945.83 | J27: =H27/I27 -> 9591.7365
A28: =AVERAGE(D26:D28) -> 2318327.3 | B28: =A28/A25-1 -> 0.089876559 | C28: =A28/A16-1 -> -0.38657392 | D28: =H28/19 -> 2297555 | E28: =D28/D27-1 -> 0.065496861 | F28: =D28/D16-1 -> -0.32799108 | G28: 2023년 12월 | H28: 43653545 | I28: 4198.96 | J28: =H28/I28 -> 10396.276 | K28: =H28+H27+H26 -> 138613623 | L28: =K28/K25-1 -> 0.0543078 | M28: =K28/K16-1 -> -0.42418825 | N28: =AVERAGE(J26:J28) -> 9763.0607 | O28: =N28/N25-1 -> -0.095554095
D29: =H29/22 -> 2300226.2 | E29: =D29/D28-1 -> 0.0011626391 | F29: =D29/D17-1 -> -0.38705607 | G29: 2024년 1월 | H29: 50604977 | I29: 5587.69 | J29: =H29/I29 -> 9056.5112
D30: =H30/19 -> 2060832.9 | E30: =D30/D29-1 -> -0.10407382 | F30: =D30/D18-1 -> -0.38307469 | G30: 2024년 2월 | H30: 39155825 | I30: 4027.8 | J30: =H30/I30 -> 9721.3926
A31: =AVERAGE(D29:D31) -> 2187063.8 | B31: =A31/A28-1 -> -0.056619907 | C31: =A31/A19-1 -> -0.33740588 | D31: =H31/20 -> 2200132.3 | E31: =D31/D30-1 -> 0.067593741 | F31: =D31/D19-1 -> -0.2167663 | G31: 2024년 3월 | H31: 44002646 | I31: 4106.75 | J31: =H31/I31 -> 10714.713 | K31: =H31+H30+H29 -> 133763448 | L31: =K31/K28-1 -> -0.034990608 | M31: =K31/K19-1 -> -0.3432139 | N31: =AVERAGE(J29:J31) -> 9830.8721 | O31: =N31/N28-1 -> 0.0069457156
D32: =H32/21 -> 2033824.8 | E32: =D32/D31-1 -> -0.075589768 | F32: =D32/D20-1 -> -0.28272527 | G32: 2024년 4월 | H32: 42710321 | I32: 4051.08 | J32: =H32/I32 -> 10542.947
D33: =H33/21 -> 2261047.3 | E33: =D33/D32-1 -> 0.11172175 | F33: =D33/D21-1 -> -0.10982517 | G33: 2024년 5월 | H33: 47481993 | I33: 4832.35 | J33: =H33/I33 -> 9825.8597
A34: =AVERAGE(D32:D34) -> 2124993.5 | B34: =A34/A31-1 -> -0.028380662 | C34: =A34/A22-1 -> -0.1652188 | D34: =H34/19 -> 2080108.4 | E34: =D34/D33-1 -> -0.080024384 | F34: =D34/D22-1 -> -0.080092735 | G34: 2024년 6월 | H34: 39522059 | I34: 4102.32 | J34: =H34/I34 -> 9634.0751 | K34: =H34+H33+H32 -> 129714373 | L34: =K34/K31-1 -> -0.030270414 | M34: =K34/K22-1 -> -0.17660166 | N34: =AVERAGE(J32:J34) -> 10000.961 | O34: =N34/N31-1 -> 0.017301457
D35: =H35/23 -> 2074581.3 | E35: =D35/D34-1 -> -0.0026571039 | F35: =D35/D23-1 -> -0.0491172 | G35: 2024년 7월 | H35: 47715370 | I35: 4958 | J35: =H35/I35 -> 9623.9149
D36: =H36/21 -> 2116291.1 | E36: =D36/D35-1 -> 0.020105184 | F36: =D36/D24-1 -> 0.082919597 | G36: 2024년 8월 | H36: 44442114 | I36: 4352.55 | J36: =H36/I36 -> 10210.592
A37: =AVERAGE(D35:D37) -> 2132703.4 | B37: =A37/A34-1 -> 0.0036282264 | C37: =A37/A25-1 -> 0.0026123186 | D37: =H37/18 -> 2207237.9 | E37: =D37/D36-1 -> 0.042974591 | F37: =D37/D25-1 -> -0.017018334 | G37: 2024년 9월 | H37: 39730282 | I37: 4147.21 | J37: =H37/I37 -> 9580.0025 | K37: =H37+H36+H35 -> 131887766 | L37: =K37/K34-1 -> 0.016755221 | M37: =K37/K25-1 -> 0.0031503211 | N37: =AVERAGE(J35:J37) -> 9804.8366 | O37: =N37/N34-1 -> -0.019610511
D38: =H38/20 -> 2310470.9 | E38: =D38/D37-1 -> 0.046770202 | F38: =D38/D26-1 -> -0.076219679 | G38: 2024년 10월 | H38: 46209417 | I38: 4839.6 | J38: =H38/I38 -> 9548.1893
D39: =H39/21 -> 2020946.1 | E39: =D39/D38-1 -> -0.12530985 | F39: =D39/D27-1 -> -0.062781209 | G39: 2024년 11월 | H39: 42439868 | I39: 4367.5 | J39: =H39/I39 -> 9717.1993
A40: =AVERAGE(D38:D40) -> 2072241.2 | B40: =A40/A37-1 -> -0.028350061 | C40: =A40/A28-1 -> -0.10614813 | D40: =H40/21 -> 1885306.6 | E40: =D40/D39-1 -> -0.067116844 | F40: =D40/D28-1 -> -0.17942919 | G40: 2024년 12월 | H40: 39591438 | I40: 4031.34 | J40: =H40/I40 -> 9820.9126 | K40: =H40+H39+H38 -> 128240723 | L40: =K40/K37-1 -> -0.027652625 | M40: =K40/K28-1 -> -0.074833193 | N40: =AVERAGE(J38:J40) -> 9695.4338 | O40: =N40/N37-1 -> -0.011158047
...

Sheet 제주반도체(칩)
A1: =P1 -> 제주반도체 | P1: 제주반도체
P2: 8542391000 | Q2: 제주
G3: 년월 | H3: 금액(달러) | I3: 중량 | P3: * 잠정치가 아니라 확정치만 볼수 있음
A4: 분기(일평균) | B4: QoQ | D4: 일평균수출 | E4: mom | F4: yoy | J4: 금액(달러)/중량 | L4: QoQ | M4: yoy | N4: 단가 | O4: QoQ
D5: =H5/20 -> 418146.45 | G5: 2022년01월 | H5: 8362929 | I5: 1014.19 | J5: =H5/I5 -> 8245.9194
