Workbook

Sheet 종가
A1: DATE | B1: 코스피 | C1: =일간종가DB!C9 -> SK하이닉스 | D1: =일간종가DB!D9 -> 삼성전자 | E1: =일간종가DB!E9 -> 삼성전기 | F1: =일간종가DB!F9 -> SK스퀘어 | G1: =일간종가DB!G9 -> 삼성물산 | H1: =일간종가DB!H9 -> LG전자 | I1: =일간종가DB!I9 -> LG이노텍 | J1: =일간종가DB!J9 -> 현대차 | ... EV1: =일간종가DB!EV9 -> 아이에스동서
A2: =일간종가DB!A15 -> 45819 | B2: =일간종가DB!B15 -> 2907.04 | C2: =일간종가DB!C15 -> 240000 | D2: =일간종가DB!D15 -> 59900 | E2: =일간종가DB!E15 -> 132400 | F2: =일간종가DB!F15 -> 138400 | G2: =일간종가DB!G15 -> 173200 | H2: =일간종가DB!H15 -> 74600 | ... EV2: =일간종가DB!EV15 -> 24400
A3: =일간종가DB!A16 -> 45820 | B3: =일간종가DB!B16 -> 2920.03 | C3: =일간종가DB!C16 -> 235500 | D3: =일간종가DB!D16 -> 59500 | E3: =일간종가DB!E16 -> 131400 | F3: =일간종가DB!F16 -> 140600 | G3: =일간종가DB!G16 -> 168100 | H3: =일간종가DB!H16 -> 75200 | ... EV3: =일간종가DB!EV16 -> 23800
A4: =일간종가DB!A17 -> 45821 | B4: =일간종가DB!B17 -> 2894.62 | C4: =일간종가DB!C17 -> 235500 | D4: =일간종가DB!D17 -> 58300 | E4: =일간종가DB!E17 -> 127400 | F4: =일간종가DB!F17 -> 138800 | G4: =일간종가DB!G17 -> 165900 | H4: =일간종가DB!H17 -> 72200 | ... EV4: =일간종가DB!EV17 -> 23250
A5: =일간종가DB!A18 -> 45824 | B5: =일간종가DB!B18 -> 2946.66 | C5: =일간종가DB!C18 -> 248000 | D5: =일간종가DB!D18 -> 57200 | E5: =일간종가DB!E18 -> 126900 | F5: =일간종가DB!F18 -> 149900 | G5: =일간종가DB!G18 -> 172200 | H5: =일간종가DB!H18 -> 72000 | ... EV5: =일간종가DB!EV18 -> 23000
A6: =일간종가DB!A19 -> 45825 | B6: =일간종가DB!B19 -> 2950.3 | C6: =일간종가DB!C19 -> 249000 | D6: =일간종가DB!D19 -> 58100 | E6: =일간종가DB!E19 -> 130700 | F6: =일간종가DB!F19 -> 153400 | G6: =일간종가DB!G19 -> 172400 | H6: =일간종가DB!H19 -> 72200 | ... EV6: =일간종가DB!EV19 -> 22550
A7: =일간종가DB!A20 -> 45826 | B7: =일간종가DB!B20 -> 2972.19 | C7: =일간종가DB!C20 -> 246500 | D7: =일간종가DB!D20 -> 59800 | E7: =일간종가DB!E20 -> 133000 | F7: =일간종가DB!F20 -> 148400 | G7: =일간종가DB!G20 -> 164800 | H7: =일간종가DB!H20 -> 73800 | ... EV7: =일간종가DB!EV20 -> 22150
A8: =일간종가DB!A21 -> 45827 | B8: =일간종가DB!B21 -> 2977.74 | C8: =일간종가DB!C21 -> 246000 | D8: =일간종가DB!D21 -> 59200 | E8: =일간종가DB!E21 -> 130300 | F8: =일간종가DB!F21 -> 148400 | G8: =일간종가DB!G21 -> 165300 | H8: =일간종가DB!H21 -> 73100 | ... EV8: =일간종가DB!EV21 -> 22000
A9: =일간종가DB!A22 -> 45828 | B9: =일간종가DB!B22 -> 3021.84 | C9: =일간종가DB!C22 -> 257000 | D9: =일간종가DB!D22 -> 59500 | E9: =일간종가DB!E22 -> 133300 | F9: =일간종가DB!F22 -> 155500 | G9: =일간종가DB!G22 -> 161900 | H9: =일간종가DB!H22 -> 74000 | ... EV9: =일간종가DB!EV22 -> 21850
A10: =일간종가DB!A23 -> 45831 | B10: =일간종가DB!B23 -> 3014.47 | C10: =일간종가DB!C23 -> 259500 | D10: =일간종가DB!D23 -> 58000 | E10: =일간종가DB!E23 -> 130300 | F10: =일간종가DB!F23 -> 163700 | G10: =일간종가DB!G23 -> 161600 | H10: =일간종가DB!H23 -> 74700 | ... EV10: =일간종가DB!EV23 -> 21650
A11: =일간종가DB!A24 -> 45832 | B11: =일간종가DB!B24 -> 3103.64 | C11: =일간종가DB!C24 -> 278500 | D11: =일간종가DB!D24 -> 60500 | E11: =일간종가DB!E24 -> 136700 | F11: =일간종가DB!F24 -> 181000 | G11: =일간종가DB!G24 -> 162500 | H11: =일간종가DB!H24 -> 76200 | ... EV11: =일간종가DB!EV24 -> 22300
A12: =일간종가DB!A25 -> 45833 | B12: =일간종가DB!B25 -> 3108.25 | C12: =일간종가DB!C25 -> 286000 | D12: =일간종가DB!D25 -> 61300 | E12: =일간종가DB!E25 -> 139100 | F12: =일간종가DB!F25 -> 192200 | G12: =일간종가DB!G25 -> 165100 | H12: =일간종가DB!H25 -> 76100 | ... EV12: =일간종가DB!EV25 -> 22200
A13: =일간종가DB!A26 -> 45834 | B13: =일간종가DB!B26 -> 3079.56 | C13: =일간종가DB!C26 -> 293000 | D13: =일간종가DB!D26 -> 60200 | E13: =일간종가DB!E26 -> 138900 | F13: =일간종가DB!F26 -> 187400 | G13: =일간종가DB!G26 -> 160600 | H13: =일간종가DB!H26 -> 74700 | ... EV13: =일간종가DB!EV26 -> 21900
... A253: =일간종가DB!A266 -> 46195 | B253: =일간종가DB!B266 -> 9114.55 | C253: =일간종가DB!C266 -> 2919000 | D253: =일간종가DB!D266 -> 353500 | E253: =일간종가DB!E266 -> 2228000 | F253: =일간종가DB!F266 -> 1970000 | G253: =일간종가DB!G266 -> 520000 | H253: =일간종가DB!H266 -> 227500 | ... EV253: =일간종가DB!EV266 -> 24250

Sheet 변동성
A1: DATE | B1: 코스피 | C1: =주간종가DB!C9 -> SK하이닉스 | D1: =주간종가DB!D9 -> 삼성전자 | E1: =주간종가DB!E9 -> NAVER | F1: =주간종가DB!F9 -> KB금융 | G1: =주간종가DB!G9 -> 알테오젠 | H1: =주간종가DB!H9 -> 두산에너빌리티 | I1: =주간종가DB!I9 -> LS ELECTRIC | J1: =주간종가DB!J9 -> 두산 | ... EV1: =주간종가DB!EV9 -> 파크시스템스
A2: =주간종가!A5 -> 46195 | B2: =(주간고가!B5-주간저가!B5)/주간종가!B5 -> 0.038654679 | C2: =(주간고가!C5-주간저가!C5)/주간종가!C5 -> 0.074340528 | D2: =(주간고가!D5-주간저가!D5)/주간종가!D5 -> 0.059405941 | E2: =(주간고가!E5-주간저가!E5)/주간종가!E5 -> 0.60810811 | F2: =(주간고가!F5-주간저가!F5)/주간종가!F5 -> 1.1910828 | G2: =(주간고가!G5-주간저가!G5)/주간종가!G5 -> 0.13552068 | H2: =(주간고가!H5-주간저가!H5)/주간종가!H5 -> 0.21762208 | I2: =(주간고가!I5-주간저가!I5)/주간종가!I5 -> 0.27346939 | ... EV2: =(주간고가!EV5-주간저가!EV5)/주간종가!EV5 -> 0.0096525097

Sheet 주간종가
A1: DATE | B1: 코스피 | C1: =주간종가DB!C9 -> SK하이닉스 | D1: =주간종가DB!D9 -> 삼성전자 | E1: =주간종가DB!E9 -> NAVER | F1: =주간종가DB!F9 -> KB금융 | G1: =주간종가DB!G9 -> 알테오젠 | H1: =주간종가DB!H9 -> 두산에너빌리티 | I1: =주간종가DB!I9 -> LS ELECTRIC | J1: =주간종가DB!J9 -> 두산 | ... EV1: =주간종가DB!EV9 -> 파크시스템스
A2: =주간종가DB!A15 -> 46178 | B2: =주간종가DB!B15 -> 8160.59 | C2: =주간종가DB!C15 -> 2070000 | D2: =주간종가DB!D15 -> 329000 | E2: =주간종가DB!E15 -> 255500 | F2: =주간종가DB!F15 -> 171600 | G2: =주간종가DB!G15 -> 332500 | H2: =주간종가DB!H15 -> 95600 | ... EV2: =주간종가DB!EV15 -> 284000
A3: =주간종가DB!A16 -> 46185 | B3: =주간종가DB!B16 -> 8123.62 | C3: =주간종가DB!C16 -> 2150000 | D3: =주간종가DB!D16 -> 322500 | E3: =주간종가DB!E16 -> 247000 | F3: =주간종가DB!F16 -> 161200 | G3: =주간종가DB!G16 -> 337000 | H3: =주간종가DB!H16 -> 93100 | ... EV3: =주간종가DB!EV16 -> 339500
A4: =주간종가DB!A17 -> 46192 | B4: =주간종가DB!B17 -> 9052.42 | C4: =주간종가DB!C17 -> 2764000 | D4: =주간종가DB!D17 -> 354000 | E4: =주간종가DB!E17 -> 229500 | F4: =주간종가DB!F17 -> 158300 | G4: =주간종가DB!G17 -> 353500 | H4: =주간종가DB!H17 -> 97900 | ... EV4: =주간종가DB!EV17 -> 255500
A5: =주간종가DB!A18 -> 46195 | B5: =주간종가DB!B18 -> 9114.55 | C5: =주간종가DB!C18 -> 2919000 | D5: =주간종가DB!D18 -> 353500 | E5: =주간종가DB!E18 -> 222000 | F5: =주간종가DB!F18 -> 157000 | G5: =주간종가DB!G18 -> 350500 | H5: =주간종가DB!H18 -> 94200 | ... EV5: =주간종가DB!EV18 -> 259000

Sheet 주간시가
A1: DATE | B1: 코스피 | C1: =일간종가DB!C9 -> SK하이닉스 | D1: =일간종가DB!D9 -> 삼성전자 | E1: =일간종가DB!E9 -> 삼성전기 | F1: =일간종가DB!F9 -> SK스퀘어 | G1: =일간종가DB!G9 -> 삼성물산 | H1: =일간종가DB!H9 -> LG전자 | I1: =일간종가DB!I9 -> LG이노텍 | J1: =일간종가DB!J9 -> 현대차 | ... EV1: =일간종가DB!EV9 -> 아이에스동서
A2: =주간종가DB!A15 -> 46178 | B2: =주간시가DB!B15 -> 8485.67 | C2: =주간시가DB!C15 -> 28000 | D2: =주간시가DB!D15 -> 107500 | E2: =주간시가DB!E15 -> 52000 | F2: =주간시가DB!F15 -> 31750 | G2: =주간시가DB!G15 -> 174100 | H2: =주간시가DB!H15 -> 179500 | I2: =주간시가DB!I15 -> 61900 | ... EV2: =주간시가DB!EV15 -> 126300
A3: =주간종가DB!A16 -> 46185 | B3: =주간시가DB!B16 -> 8048.09 | C3: =주간시가DB!C16 -> 24900 | D3: =주간시가DB!D16 -> 95700 | E3: =주간시가DB!E16 -> 44800 | F3: =주간시가DB!F16 -> 30200 | G3: =주간시가DB!G16 -> 140000 | H3: =주간시가DB!H16 -> 135000 | I3: =주간시가DB!I16 -> 44400 | ... EV3: =주간시가DB!EV16 -> 101300
A4: =주간종가DB!A17 -> 46192 | B4: =주간시가DB!B17 -> 8526.12 | C4: =주간시가DB!C17 -> 33000 | D4: =주간시가DB!D17 -> 120800 | E4: =주간시가DB!E17 -> 52500 | F4: =주간시가DB!F17 -> 33150 | G4: =주간시가DB!G17 -> 152800 | H4: =주간시가DB!H17 -> 117500 | I4: =주간시가DB!I17 -> 42000 | ... EV4: =주간시가DB!EV17 -> 117000
A5: =주간종가DB!A18 -> 46195 | B5: =주간시가DB!B18 -> 8954.43 | C5: =주간시가DB!C18 -> 28950 | D5: =주간시가DB!D18 -> 101400 | E5: =주간시가DB!E18 -> 39450 | F5: =주간시가DB!F18 -> 30500 | G5: =주간시가DB!G18 -> 141300 | H5: =주간시가DB!H18 -> 131900 | I5: =주간시가DB!I18 -> 36650 | ... EV5: =주간시가DB!EV18 -> 125100

Sheet 주간고가
A1: DATE | B1: 코스피 | C1: =일간종가DB!C9 -> SK하이닉스 | D1: =일간종가DB!D9 -> 삼성전자 | E1: =일간종가DB!E9 -> 삼성전기 | F1: =일간종가DB!F9 -> SK스퀘어 | G1: =일간종가DB!G9 -> 삼성물산 | H1: =일간종가DB!H9 -> LG전자 | I1: =일간종가DB!I9 -> LG이노텍 | J1: =일간종가DB!J9 -> 현대차 | ... EV1: =일간종가DB!EV9 -> 아이에스동서
A2: =주간종가DB!A15 -> 46178 | B2: =주간고가DB!B15 -> 8933.62 | C2: =주간고가DB!C15 -> 2407000 | D2: =주간고가DB!D15 -> 370000 | E2: =주간고가DB!E15 -> 2086000 | F2: =주간고가DB!F15 -> 1392000 | G2: =주간고가DB!G15 -> 565000 | H2: =주간고가DB!H15 -> 438000 | I2: =주간고가DB!I15 -> 1788000 | ... EV2: =주간고가DB!EV15 -> 28800
A3: =주간종가DB!A16 -> 46185 | B3: =주간고가DB!B16 -> 8434.4 | C3: =주간고가DB!C16 -> 2304000 | D3: =주간고가DB!D16 -> 339000 | E3: =주간고가DB!E16 -> 1991000 | F3: =주간고가DB!F16 -> 1422000 | G3: =주간고가DB!G16 -> 460500 | H3: =주간고가DB!H16 -> 292500 | I3: =주간고가DB!I16 -> 1192000 | ... EV3: =주간고가DB!EV16 -> 26200
A4: =주간종가DB!A17 -> 46192 | B4: =주간고가DB!B17 -> 9385.59 | C4: =주간고가DB!C17 -> 2891000 | D4: =주간고가DB!D17 -> 374500 | E4: =주간고가DB!E17 -> 2417000 | F4: =주간고가DB!F17 -> 1891000 | G4: =주간고가DB!G17 -> 559000 | H4: =주간고가DB!H17 -> 262000 | I4: =주간고가DB!I17 -> 1320000 | ... EV4: =주간고가DB!EV17 -> 26500
A5: =주간종가DB!A18 -> 46195 | B5: =주간고가DB!B18 -> 9253 | C5: =주간고가DB!C18 -> 2945000 | D5: =주간고가DB!D18 -> 363000 | E5: =주간고가DB!E18 -> 2320000 | F5: =주간고가DB!F18 -> 1987000 | G5: =주간고가DB!G18 -> 541000 | H5: =주간고가DB!H18 -> 241500 | I5: =주간고가DB!I18 -> 1182000 | ... EV5: =주간고가DB!EV18 -> 25350

Sheet 주간저가
A1: DATE | B1: 코스피 | C1: =일간종가DB!C9 -> SK하이닉스 | D1: =일간종가DB!D9 -> 삼성전자 | E1: =일간종가DB!E9 -> 삼성전기 | F1: =일간종가DB!F9 -> SK스퀘어 | G1: =일간종가DB!G9 -> 삼성물산 | H1: =일간종가DB!H9 -> LG전자 | I1: =일간종가DB!I9 -> LG이노텍 | J1: =일간종가DB!J9 -> 현대차 | ... EV1: =일간종가DB!EV9 -> 아이에스동서
A2: =주간종가DB!A15 -> 46178 | B2: =주간저가DB!B15 -> 8038.1 | C2: =주간저가DB!C15 -> 2070000 | D2: =주간저가DB!D15 -> 319500 | E2: =주간저가DB!E15 -> 1615000 | F2: =주간저가DB!F15 -> 1210000 | G2: =주간저가DB!G15 -> 438000 | H2: =주간저가DB!H15 -> 294500 | I2: =주간저가DB!I15 -> 1074000 | ... EV2: =주간저가DB!EV15 -> 25350
A3: =주간종가DB!A16 -> 46185 | B3: =주간저가DB!B16 -> 7394.46 | C3: =주간저가DB!C16 -> 1855000 | D3: =주간저가DB!D16 -> 287500 | E3: =주간저가DB!E16 -> 1552000 | F3: =주간저가DB!F16 -> 1075000 | G3: =주간저가DB!G16 -> 384000 | H3: =주간저가DB!H16 -> 207500 | I3: =주간저가DB!I16 -> 976000 | ... EV3: =주간저가DB!EV16 -> 23300
A4: =주간종가DB!A17 -> 46192 | B4: =주간저가DB!B17 -> 8450.24 | C4: =주간저가DB!C17 -> 2265000 | D4: =주간저가DB!D17 -> 331500 | E4: =주간저가DB!E17 -> 1835000 | F4: =주간저가DB!F17 -> 1355000 | G4: =주간저가DB!G17 -> 461000 | H4: =주간저가DB!H17 -> 205500 | I4: =주간저가DB!I17 -> 1090000 | ... EV4: =주간저가DB!EV17 -> 22600
A5: =주간종가DB!A18 -> 46195 | B5: =주간저가DB!B18 -> 8900.68 | C5: =주간저가DB!C18 -> 2728000 | D5: =주간저가DB!D18 -> 342000 | E5: =주간저가DB!E18 -> 2185000 | F5: =주간저가DB!F18 -> 1800000 | G5: =주간저가DB!G18 -> 493500 | H5: =주간저가DB!H18 -> 221000 | I5: =주간저가DB!I18 -> 1115000 | ... EV5: =주간저가DB!EV18 -> 22850

Sheet 일간종가DB
A1: Refresh | B1: Last Update : 2026-06-22 19:09:43
A2: 0
A3: Time Series (Company)
A4: Frequency | B4: D | C4: Ascending | D4: 0
A5: Period(From) | B5: 20250611 | C5: Korean | D5: 0
A6: Period(To) | B6: 20260622 | D6: 0
A8: Code | B8: IKS001 | C8: A000660 | D8: A005930 | E8: A009150 | F8: A402340 | G8: A028260 | H8: A066570 | I8: A011070 | J8: A005380 | K8: A042700 | L8: A240810 | M8: A032830 | N8: A000990 | O8: A298040 | P8: A006400 | Q8: A034730 | R8: A010120 | S8: A012450 | T8: A440110 | U8: A089970 | V8: A222800 | W8: A003550 | X8: A067310 | Y8: A003230 | Z8: A420770 | AA8: A084370 | AB8: A347850 | AC8: A080220 | AD8: A028050 | AE8: A095610 | AF8: A319660 | AG8: A267260 | AH8: A000720 | AI8: A278470 | AJ8: A074600 | AK8: A105560 | AL8: A196170 | AM8: A036930 | AN8: A353200 | AO8: A010060 | AP8: A086790 | AQ8: A095340 | AR8: A454910 | AS8: A329180 | AT8: A281820 | AU8: A039030 | AV8: A006260 | AW8: A131290 | AX8: A138930 | AY8: A290550 | AZ8: A352820 | BA8: A161890 | BB8: A079550 | BC8: A403870 | BD8: A047810 | BE8: A055550 | BF8: A012330 | BG8: A047050 | BH8: A141080 | BI8: A178320 | BJ8: A036570 | BK8: A003490 | BL8: A259960 | BM8: A035420 | BN8: A373220 | BO8: A032640 | BP8: A000150 | BQ8: A030200 | BR8: A207940 | BS8: A290650 | BT8: A042660 | BU8: A005290 | BV8: A009540 | BW8: A483650 | BX8: A062040 | BY8: A120110 | BZ8: A001040 | CA8: A195870 | CB8: A015760 | CC8: A004170 | CD8: A000810 | CE8: A112610 | CF8: A023530 | CG8: A018260 | CH8: A131970 | CI8: A009830 | CJ8: A356860 | CK8: A267270 | CL8: A068270 | CM8: A226950 | CN8: A000270 | CO8: A035900 | CP8: A375500 | CQ8: A021240 | CR8: A064290 | CS8: A064350 | CT8: A034020 | CU8: A443060 | CV8: A016360 | CW8: A000100 | CX8: A071050 | CY8: A336260 | CZ8: A108490 | DA8: A138040 | DB8: A082740 | DC8: A032350 | DD8: A175330 | DE8: A257720 | DF8: A030000 | DG8: A006800 | DH8: A058470 | DI8: A323280 | DJ8: A214450 | DK8: A064760 | DL8: A122640 | DM8: A383220 | DN8: A145020 | DO8: A170920 | DP8: A051910 | DQ8: A005940 | DR8: A111770 | DS8: A183300 | DT8: A039490 | DU8: A078930 | DV8: A005850 | DW8: A357780 | DX8: A001820 | DY8: A006360 | DZ8: A204320 | EA8: A009970 | EB8: A277810 | EC8: A005490 | ED8: A033780 | EE8: A003670 | EF8: A077360 | EG8: A007660 | EH8: A007070 | EI8: A047040 | EJ8: A237690 | EK8: A002380 | EL8: A017670 | EM8: A139130 | EN8: A316140 | EO8: A087010 | EP8: A475830 | EQ8: A034220 | ER8: A247540 | ES8: A322000 | ET8: A028300 | EU8: A011200 | EV8: A010780
A9: Name | B9: 코스피 | C9: SK하이닉스 | D9: 삼성전자 | E9: 삼성전기 | F9: SK스퀘어 | G9: 삼성물산 | H9: LG전자 | I9: LG이노텍 | J9: 현대차 | K9: 한미반도체 | L9: 원익IPS | M9: 삼성생명 | N9: DB하이텍 | O9: 효성중공업 | P9: 삼성SDI | Q9: SK | R9: LS ELECTRIC | S9: 한화에어로스페이스 | T9: 파두 | U9: 브이엠 | V9: 심텍 | W9: LG | X9: 하나마이크론 | Y9: 삼양식품 | Z9: 기가비스 | AA9: 유진테크 | AB9: 디앤디파마텍 | AC9: 제주반도체 | AD9: 삼성E&A | AE9: 테스 | AF9: 피에스케이 | AG9: HD현대일렉트릭 | AH9: 현대건설 | AI9: 에이피알 | AJ9: 원익QnC | AK9: KB금융 | AL9: 알테오젠 | AM9: 주성엔지니어링 | AN9: 대덕전자 | AO9: OCI홀딩스 | AP9: 하나금융지주 | AQ9: ISC | AR9: 두산로보틱스 | AS9: HD현대중공업 | AT9: 케이씨텍 | AU9: 이오테크닉스 | AV9: LS | AW9: 티에스이 | AX9: BNK금융지주 | AY9: 디케이티 | AZ9: 하이브 | BA9: 한국콜마 | BB9: LIG디펜스앤에어로스페이스 | BC9: HPSP | BD9: 한국항공우주 | BE9: 신한지주 | BF9: 현대모비스 | BG9: 포스코인터내셔널 | BH9: 리가켐바이오 | BI9: 서진시스템 | BJ9: NC | BK9: 대한항공 | BL9: 크래프톤 | BM9: NAVER | BN9: LG에너지솔루션 | BO9: LG유플러스 | BP9: 두산 | BQ9: KT | BR9: 삼성바이오로직스 | BS9: 엘앤씨바이오 | BT9: 한화오션 | BU9: 동진쎄미켐 | BV9: HD한국조선해양 | BW9: 달바글로벌 | BX9: 산일전기 | BY9: 코오롱인더 | BZ9: CJ | CA9: 해성디에스 | CB9: 한국전력 | CC9: 신세계 | CD9: 삼성화재 | CE9: 씨에스윈드 | CF9: 롯데쇼핑 | CG9: 삼성에스디에스 | CH9: 두산테스나 | CI9: 한화솔루션 | CJ9: 티엘비 | CK9: HD건설기계 | CL9: 셀트리온 | CM9: 올릭스 | CN9: 기아 | CO9: JYP Ent. | CP9: DL이앤씨 | CQ9: 코웨이 | CR9: 인텍플러스 | CS9: 현대로템 | CT9: 두산에너빌리티 | CU9: HD현대마린솔루션 | CV9: 삼성증권 | CW9: 유한양행 | CX9: 한국금융지주 | CY9: 두산퓨얼셀 | CZ9: 로보티즈 | DA9: 메리츠금융지주 | DB9: 한화엔진 | DC9: 롯데관광개발 | DD9: JB금융지주 | DE9: 실리콘투 | DF9: 제일기획 | DG9: 미래에셋증권 | DH9: 리노공업 | DI9: 태성 | DJ9: 파마리서치 | DK9: 티씨케이 | DL9: 예스티 | DM9: F&F | DN9: 휴젤 | DO9: 엘티씨 | DP9: LG화학 | DQ9: NH투자증권 | DR9: 영원무역 | DS9: 코미코 | DT9: 키움증권 | DU9: GS | DV9: 에스엘 | DW9: 솔브레인 | DX9: 삼화콘덴서 | DY9: GS건설 | DZ9: HL만도 | EA9: 영원무역홀딩스 | EB9: 레인보우로보틱스 | EC9: POSCO홀딩스 | ED9: KT&G | EE9: 포스코퓨처엠 | EF9: 덕산하이메탈 | EG9: 이수페타시스 | EH9: GS리테일 | EI9: 대우건설 | EJ9: 에스티팜 | EK9: KCC | EL9: SK텔레콤 | EM9: iM금융지주 | EN9: 우리금융지주 | EO9: 펩트론 | EP9: 오름테라퓨틱 | EQ9: LG디스플레이 | ER9: 에코프로비엠 | ES9: HD현대에너지솔루션 | ET9: HLB | EU9: HMM | EV9: 아이에스동서
A10: Item Code | B10: S100100 | C10: S100300 | D10: S100300 | E10: S100300 | F10: S100300 | G10: S100300 | H10: S100300 | I10: S100300 | J10: S100300 | K10: S100300 | L10: S100300 | M10: S100300 | N10: S100300 | O10: S100300 | P10: S100300 | Q10: S100300 | R10: S100300 | S10: S100300 | T10: S100300 | U10: S100300 | V10: S100300 | W10: S100300 | X10: S100300 | Y10: S100300 | Z10: S100300 | AA10: S100300 | AB10: S100300 | AC10: S100300 | AD10: S100300 | AE10: S100300 | AF10: S100300 | AG10: S100300 | AH10: S100300 | AI10: S100300 | AJ10: S100300 | AK10: S100300 | AL10: S100300 | AM10: S100300 | AN10: S100300 | AO10: S100300 | AP10: S100300 | AQ10: S100300 | AR10: S100300 | AS10: S100300 | AT10: S100300 | AU10: S100300 | AV10: S100300 | AW10: S100300 | AX10: S100300 | AY10: S100300 | AZ10: S100300 | BA10: S100300 | BB10: S100300 | BC10: S100300 | BD10: S100300 | BE10: S100300 | BF10: S100300 | BG10: S100300 | BH10: S100300 | BI10: S100300 | BJ10: S100300 | BK10: S100300 | BL10: S100300 | BM10: S100300 | BN10: S100300 | BO10: S100300 | BP10: S100300 | BQ10: S100300 | BR10: S100300 | BS10: S100300 | BT10: S100300 | BU10: S100300 | BV10: S100300 | BW10: S100300 | BX10: S100300 | BY10: S100300 | BZ10: S100300 | CA10: S100300 | CB10: S100300 | CC10: S100300 | CD10: S100300 | CE10: S100300 | CF10: S100300 | CG10: S100300 | CH10: S100300 | CI10: S100300 | CJ10: S100300 | CK10: S100300 | CL10: S100300 | CM10: S100300 | CN10: S100300 | CO10: S100300 | CP10: S100300 | CQ10: S100300 | CR10: S100300 | CS10: S100300 | CT10: S100300 | CU10: S100300 | CV10: S100300 | CW10: S100300 | CX10: S100300 | CY10: S100300 | CZ10: S100300 | DA10: S100300 | DB10: S100300 | DC10: S100300 | DD10: S100300 | DE10: S100300 | DF10: S100300 | DG10: S100300 | DH10: S100300 | DI10: S100300 | DJ10: S100300 | DK10: S100300 | DL10: S100300 | DM10: S100300 | DN10: S100300 | DO10: S100300 | DP10: S100300 | DQ10: S100300 | DR10: S100300 | DS10: S100300 | DT10: S100300 | DU10: S100300 | DV10: S100300 | DW10: S100300 | DX10: S100300 | DY10: S100300 | DZ10: S100300 | EA10: S100300 | EB10: S100300 | EC10: S100300 | ED10: S100300 | EE10: S100300 | EF10: S100300 | EG10: S100300 | EH10: S100300 | EI10: S100300 | EJ10: S100300 | EK10: S100300 | EL10: S100300 | EM10: S100300 | EN10: S100300 | EO10: S100300 | EP10: S100300 | EQ10: S100300 | ER10: S100300 | ES10: S100300 | ET10: S100300 | EU10: S100300 | EV10: S100300
A11: Unit | B11: Local/Shares | C11: Local/Shares | D11: Local/Shares | E11: Local/Shares | F11: Local/Shares | G11: Local/Shares | H11: Local/Shares | I11: Local/Shares | J11: Local/Shares | K11: Local/Shares | L11: Local/Shares | M11: Local/Shares | N11: Local/Shares | O11: Local/Shares | P11: Local/Shares | Q11: Local/Shares | R11: Local/Shares | S11: Local/Shares | T11: Local/Shares | U11: Local/Shares | V11: Local/Shares | W11: Local/Shares | X11: Local/Shares | Y11: Local/Shares | Z11: Local/Shares | AA11: Local/Shares | AB11: Local/Shares | AC11: Local/Shares | AD11: Local/Shares | AE11: Local/Shares | AF11: Local/Shares | AG11: Local/Shares | AH11: Local/Shares | AI11: Local/Shares | AJ11: Local/Shares | AK11: Local/Shares | AL11: Local/Shares | AM11: Local/Shares | AN11: Local/Shares | AO11: Local/Shares | AP11: Local/Shares | AQ11: Local/Shares | AR11: Local/Shares | AS11: Local/Shares | AT11: Local/Shares | AU11: Local/Shares | AV11: Local/Shares | AW11: Local/Shares | AX11: Local/Shares | AY11: Local/Shares | AZ11: Local/Shares | BA11: Local/Shares | BB11: Local/Shares | BC11: Local/Shares | BD11: Local/Shares | BE11: Local/Shares | BF11: Local/Shares | BG11: Local/Shares | BH11: Local/Shares | BI11: Local/Shares | BJ11: Local/Shares | BK11: Local/Shares | BL11: Local/Shares | BM11: Local/Shares | BN11: Local/Shares | BO11: Local/Shares | BP11: Local/Shares | BQ11: Local/Shares | BR11: Local/Shares | BS11: Local/Shares | BT11: Local/Shares | BU11: Local/Shares | BV11: Local/Shares | BW11: Local/Shares | BX11: Local/Shares | BY11: Local/Shares | BZ11: Local/Shares | CA11: Local/Shares | CB11: Local/Shares | CC11: Local/Shares | CD11: Local/Shares | CE11: Local/Shares | CF11: Local/Shares | CG11: Local/Shares | CH11: Local/Shares | CI11: Local/Shares | CJ11: Local/Shares | CK11: Local/Shares | CL11: Local/Shares | CM11: Local/Shares | CN11: Local/Shares | CO11: Local/Shares | CP11: Local/Shares | CQ11: Local/Shares | CR11: Local/Shares | CS11: Local/Shares | CT11: Local/Shares | CU11: Local/Shares | CV11: Local/Shares | CW11: Local/Shares | CX11: Local/Shares | CY11: Local/Shares | CZ11: Local/Shares | DA11: Local/Shares | DB11: Local/Shares | DC11: Local/Shares | DD11: Local/Shares | DE11: Local/Shares | DF11: Local/Shares | DG11: Local/Shares | DH11: Local/Shares | DI11: Local/Shares | DJ11: Local/Shares | DK11: Local/Shares | DL11: Local/Shares | DM11: Local/Shares | DN11: Local/Shares | DO11: Local/Shares | DP11: Local/Shares | DQ11: Local/Shares | DR11: Local/Shares | DS11: Local/Shares | DT11: Local/Shares | DU11: Local/Shares | DV11: Local/Shares | DW11: Local/Shares | DX11: Local/Shares | DY11: Local/Shares | DZ11: Local/Shares | EA11: Local/Shares | EB11: Local/Shares | EC11: Local/Shares | ED11: Local/Shares | EE11: Local/Shares | EF11: Local/Shares | EG11: Local/Shares | EH11: Local/Shares | EI11: Local/Shares | EJ11: Local/Shares | EK11: Local/Shares | EL11: Local/Shares | EM11: Local/Shares | EN11: Local/Shares | EO11: Local/Shares | EP11: Local/Shares | EQ11: Local/Shares | ER11: Local/Shares | ES11: Local/Shares | ET11: Local/Shares | EU11: Local/Shares | EV11: Local/Shares
A12: Base Date
A14: D A T E | B14: 종가 | C14: 수정주가 | D14: 수정주가 | E14: 수정주가 | F14: 수정주가 | G14: 수정주가 | H14: 수정주가 | I14: 수정주가 | J14: 수정주가 | K14: 수정주가 | L14: 수정주가 | M14: 수정주가 | N14: 수정주가 | O14: 수정주가 | P14: 수정주가 | Q14: 수정주가 | R14: 수정주가 | S14: 수정주가 | T14: 수정주가 | U14: 수정주가 | V14: 수정주가 | W14: 수정주가 | X14: 수정주가 | Y14: 수정주가 | Z14: 수정주가 | AA14: 수정주가 | AB14: 수정주가 | AC14: 수정주가 | AD14: 수정주가 | AE14: 수정주가 | AF14: 수정주가 | AG14: 수정주가 | AH14: 수정주가 | AI14: 수정주가 | AJ14: 수정주가 | AK14: 수정주가 | AL14: 수정주가 | AM14: 수정주가 | AN14: 수정주가 | AO14: 수정주가 | AP14: 수정주가 | AQ14: 수정주가 | AR14: 수정주가 | AS14: 수정주가 | AT14: 수정주가 | AU14: 수정주가 | AV14: 수정주가 | AW14: 수정주가 | AX14: 수정주가 | AY14: 수정주가 | AZ14: 수정주가 | BA14: 수정주가 | BB14: 수정주가 | BC14: 수정주가 | BD14: 수정주가 | BE14: 수정주가 | BF14: 수정주가 | BG14: 수정주가 | BH14: 수정주가 | BI14: 수정주가 | BJ14: 수정주가 | BK14: 수정주가 | BL14: 수정주가 | BM14: 수정주가 | BN14: 수정주가 | BO14: 수정주가 | BP14: 수정주가 | BQ14: 수정주가 | BR14: 수정주가 | BS14: 수정주가 | BT14: 수정주가 | BU14: 수정주가 | BV14: 수정주가 | BW14: 수정주가 | BX14: 수정주가 | BY14: 수정주가 | BZ14: 수정주가 | CA14: 수정주가 | CB14: 수정주가 | CC14: 수정주가 | CD14: 수정주가 | CE14: 수정주가 | CF14: 수정주가 | CG14: 수정주가 | CH14: 수정주가 | CI14: 수정주가 | CJ14: 수정주가 | CK14: 수정주가 | CL14: 수정주가 | CM14: 수정주가 | CN14: 수정주가 | CO14: 수정주가 | CP14: 수정주가 | CQ14: 수정주가 | CR14: 수정주가 | CS14: 수정주가 | CT14: 수정주가 | CU14: 수정주가 | CV14: 수정주가 | CW14: 수정주가 | CX14: 수정주가 | CY14: 수정주가 | CZ14: 수정주가 | DA14: 수정주가 | DB14: 수정주가 | DC14: 수정주가 | DD14: 수정주가 | DE14: 수정주가 | DF14: 수정주가 | DG14: 수정주가 | DH14: 수정주가 | DI14: 수정주가 | DJ14: 수정주가 | DK14: 수정주가 | DL14: 수정주가 | DM14: 수정주가 | DN14: 수정주가 | DO14: 수정주가 | DP14: 수정주가 | DQ14: 수정주가 | DR14: 수정주가 | DS14: 수정주가 | DT14: 수정주가 | DU14: 수정주가 | DV14: 수정주가 | DW14: 수정주가 | DX14: 수정주가 | DY14: 수정주가 | DZ14: 수정주가 | EA14: 수정주가 | EB14: 수정주가 | EC14: 수정주가 | ED14: 수정주가 | EE14: 수정주가 | EF14: 수정주가 | EG14: 수정주가 | EH14: 수정주가 | EI14: 수정주가 | EJ14: 수정주가 | EK14: 수정주가 | EL14: 수정주가 | EM14: 수정주가 | EN14: 수정주가 | EO14: 수정주가 | EP14: 수정주가 | EQ14: 수정주가 | ER14: 수정주가 | ES14: 수정주가 | ET14: 수정주가 | EU14: 수정주가 | EV14: 수정주가
A15: 45819 | B15: 2907.04 | C15: 240000 | D15: 59900 | E15: 132400 | F15: 138400 | G15: 173200 | H15: 74600 | I15: 149900 | J15: 201000 | K15: 85800 | L15: 26500 | M15: 122500 | N15: 45850 | O15: 679000 | P15: 172900 | Q15: 194700 | R15: 51900 | S15: 905000 | T15: 11160 | U15: 12780 | V15: 23300 | W15: 75200 | X15: 11920 | Y15: 1197000 | Z15: 28350 | AA15: 37200 | AB15: 24374 | AC15: 13950 | AD15: 23200 | AE15: 24700 | AF15: 19910 | AG15: 418500 | AH15: 72100 | AI15: 136000 | AJ15: 18200 | AK15: 107200 | AL15: 408000 | AM15: 32250 | AN15: 16330 | AO15: 80400 | AP15: 77800 | AQ15: 56700 | AR15: 51500 | AS15: 418000 | AT15: 27500 | AU15: 148100 | AV15: 179900 | AW15: 41950 | AX15: 11710 | AY15: 6800 | AZ15: 300500 | BA15: 92100 | BB15: 451500 | BC15: 27700 | BD15: 87900 | BE15: 59800 | BF15: 288500 | BG15: 51400 | BH15: 118000 | BI15: 21800 | BJ15: 177900 | BK15: 22850 | BL15: 372500 | BM15: 201000 | BN15: 292500 | BO15: 13120 | BP15: 585000 | BQ15: 51600 | BR15: 1535029 | BS15: 29000 | BT15: 79400 | BU15: 30800 | BV15: 336500 | BW15: 147500 | BX15: 69400 | BY15: 33600 | BZ15: 156800 | CA15: 23650 | CB15: 28100 | CC15: 176000 | CD15: 440000 | CE15: 51300 | CF15: 76900 | CG15: 137800 | CH15: 29050 | CI15: 36079 | CJ15: 18290 | CK15: 71800 | CL15: 154604 | CM15: 46750 | CN15: 96900 | CO15: 78100 | CP15: 50500 | CQ15: 94800 | CR15: 9480 | CS15: 170900 | CT15: 51100 | CU15: 198600 | CV15: 64700 | CW15: 107200 | CX15: 123000 | CY15: 19230 | CZ15: 58235 | DA15: 112800 | DB15: 28150 | DC15: 13020 | DD15: 19390 | DE15: 61800 | DF15: 19000 | DG15: 19356 | DH15: 49650 | DI15: 24850 | DJ15: 521000 | DK15: 101900 | DL15: 15390 | DM15: 77800 | DN15: 370000 | DO15: 10300 | DP15: 208500 | DQ15: 18220 | DR15: 60800 | DS15: 36161 | DT15: 190000 | DU15: 47150 | DV15: 32400 | DW15: 171900 | DX15: 26450 | DY15: 24150 | DZ15: 34650 | EA15: 128400 | EB15: 285000 | EC15: 266500 | ED15: 121600 | EE15: 120195 | EF15: 4315 | EG15: 44800 | EH15: 17080 | EI15: 4440 | EJ15: 83700 | EK15: 327500 | EL15: 53700 | EM15: 11520 | EN15: 20450 | EO15: 191800 | EP15: 18340 | EQ15: 8880 | ER15: 94900 | ES15: 50900 | ET15: 53200 | EU15: 22500 | EV15: 24400
A16: 45820 | B16: 2920.03 | C16: 235500 | D16: 59500 | E16: 131400 | F16: 140600 | G16: 168100 | H16: 75200 | I16: 150000 | J16: 201500 | K16: 88000 | L16: 25950 | M16: 122600 | N16: 45150 | O16: 677000 | P16: 174800 | Q16: 192500 | R16: 52500 | S16: 953000 | T16: 11000 | U16: 12900 | V16: 23500 | W16: 75600 | X16: 11700 | Y16: 1192000 | Z16: 28350 | AA16: 36750 | AB16: 24600 | AC16: 13750 | AD16: 23400 | AE16: 24400 | AF16: 19820 | AG16: 434000 | AH16: 76200 | AI16: 135100 | AJ16: 17980 | AK16: 105900 | AL16: 410500 | AM16: 32000 | AN16: 16220 | AO16: 79100 | AP16: 77200 | AQ16: 55100 | AR16: 52200 | AS16: 419500 | AT16: 27200 | AU16: 148400 | AV16: 175100 | AW16: 40650 | AX16: 11820 | AY16: 6790 | AZ16: 302000 | BA16: 90500 | BB16: 460000 | BC16: 28500 | BD16: 90500 | BE16: 58600 | BF16: 284500 | BG16: 51700 | BH16: 117400 | BI16: 20800 | BJ16: 176600 | BK16: 22300 | BL16: 382000 | BM16: 198900 | BN16: 304000 | BO16: 13270 | BP16: 593000 | BQ16: 51800 | BR16: 1514425 | BS16: 30450 | BT16: 84000 | BU16: 30750 | BV16: 340500 | BW16: 164600 | BX16: 70600 | BY16: 34300 | BZ16: 150800 | CA16: 23950 | CB16: 28450 | CC16: 177600 | CD16: 439000 | CE16: 51300 | CF16: 76500 | CG16: 138600 | CH16: 28700 | CI16: 34240 | CJ16: 19674 | CK16: 71400 | CL16: 156224 | CM16: 47000 | CN16: 98400 | CO16: 77400 | CP16: 50200 | CQ16: 93800 | CR16: 9280 | CS16: 179700 | CT16: 54600 | CU16: 197100 | CV16: 63800 | CW16: 108400 | CX16: 122100 | CY16: 19280 | CZ16: 58722 | DA16: 112200 | DB16: 29050 | DC16: 13420 | DD16: 20900 | DE16: 55400 | DF16: 20000 | DG16: 19167 | DH16: 49000 | DI16: 27450 | DJ16: 523000 | DK16: 98800 | DL16: 15840 | DM16: 77600 | DN16: 376500 | DO16: 10080 | DP16: 210500 | DQ16: 18160 | DR16: 60800 | DS16: 34939 | DT16: 197000 | DU16: 46850 | DV16: 32600 | DW16: 169400 | DX16: 26900 | DY16: 23650 | DZ16: 34800 | EA16: 133500 | EB16: 289000 | EC16: 265500 | ED16: 122200 | EE16: 128337 | EF16: 4255 | EG16: 43500 | EH16: 17170 | EI16: 4515 | EJ16: 83000 | EK16: 322500 | EL16: 54100 | EM16: 11490 | EN16: 20550 | EO16: 192600 | EP16: 17970 | EQ16: 9050 | ER16: 97500 | ES16: 49700 | ET16: 53400 | EU16: 23000 | EV16: 23800
A17: 45821 | B17: 2894.62 | C17: 235500 | D17: 58300 | E17: 127400 | F17: 138800 | G17: 165900 | H17: 72200 | I17: 144300 | J17: 199000 | K17: 86800 | L17: 25100 | M17: 124800 | N17: 44050 | O17: 680000 | P17: 172100 | Q17: 190600 | R17: 51600 | S17: 945000 | T17: 10670 | U17: 12330 | V17: 24000 | W17: 74800 | X17: 11540 | Y17: 1196000 | Z17: 27700 | AA17: 35750 | AB17: 24450 | AC17: 13270 | AD17: 23100 | AE17: 24400 | AF17: 19300 | AG17: 430000 | AH17: 73600 | AI17: 131000 | AJ17: 17400 | AK17: 106000 | AL17: 385500 | AM17: 31050 | AN17: 15590 | AO17: 77500 | AP17: 78500 | AQ17: 53000 | AR17: 50700 | AS17: 427500 | AT17: 26200 | AU17: 145400 | AV17: 172900 | AW17: 39900 | AX17: 11900 | AY17: 6590 | AZ17: 296000 | BA17: 88300 | BB17: 526000 | BC17: 27650 | BD17: 97700 | BE17: 59000 | BF17: 282000 | BG17: 50100 | BH17: 108900 | BI17: 20550 | BJ17: 176500 | BK17: 21450 | BL17: 366500 | BM17: 200500 | BN17: 296000 | BO17: 13120 | BP17: 569000 | BQ17: 51600 | BR17: 1499707 | BS17: 30400 | BT17: 84700 | BU17: 29800 | BV17: 350500 | BW17: 165300 | BX17: 69400 | BY17: 33100 | BZ17: 146000 | CA17: 23800 | CB17: 27450 | CC17: 171500 | CD17: 436500 | CE17: 48850 | CF17: 74100 | CG17: 137200 | CH17: 28050 | CI17: 33391 | CJ17: 19248 | CK17: 69300 | CL17: 153269 | CM17: 43550 | CN17: 97200 | CO17: 76000 | CP17: 48100 | CQ17: 93700 | CR17: 8810 | CS17: 186800 | CT17: 54600 | CU17: 199800 | CV17: 64500 | CW17: 106500 | CX17: 120600 | CY17: 18550 | CZ17: 53755 | DA17: 110100 | DB17: 29350 | DC17: 13400 | DD17: 20000 | DE17: 54100 | DF17: 19800 | DG17: 18978 | DH17: 47850 | DI17: 28000 | DJ17: 433500 | DK17: 99900 | DL17: 16230 | DM17: 74600 | DN17: 356000 | DO17: 9910 | DP17: 208500 | DQ17: 18260 | DR17: 59300 | DS17: 33768 | DT17: 195000 | DU17: 47450 | DV17: 31050 | DW17: 167000 | DX17: 25750 | DY17: 23000 | DZ17: 33100 | EA17: 131700 | EB17: 277000 | EC17: 264000 | ED17: 123200 | EE17: 123200 | EF17: 4135 | EG17: 44300 | EH17: 16290 | EI17: 4345 | EJ17: 81200 | EK17: 315000 | EL17: 54600 | EM17: 11540 | EN17: 20550 | EO17: 186200 | EP17: 17820 | EQ17: 8840 | ER17: 92000 | ES17: 48200 | ET17: 52700 | EU17: 24200 | EV17: 23250
A18: 45824 | B18: 2946.66 | C18: 248000 | D18: 57200 | E18: 126900 | F18: 149900 | G18: 172200 | H18: 72000 | I18: 143400 | J18: 201500 | K18: 87500 | L18: 25050 | M18: 127900 | N18: 43950 | O18: 771000 | P18: 168900 | Q18: 201000 | R18: 57200 | S18: 970000 | T18: 10540 | U18: 12140 | V18: 23700 | W18: 75600 | X18: 11430 | Y18: 1279000 | Z18: 27200 | AA18: 35500 | AB18: 31782 | AC18: 13170 | AD18: 23550 | AE18: 24100 | AF18: 19450 | AG18: 456500 | AH18: 79100 | AI18: 132600 | AJ18: 17330 | AK18: 107800 | AL18: 405500 | AM18: 31200 | AN18: 15590 | AO18: 78700 | AP18: 79700 | AQ18: 53000 | AR18: 50900 | AS18: 449000 | AT18: 26200 | AU18: 147200 | AV18: 183800 | AW18: 39350 | AX18: 12080 | AY18: 6450 | AZ18: 299000 | BA18: 89600 | BB18: 554000 | BC18: 28200 | BD18: 98800 | BE18: 60600 | BF18: 285500 | BG18: 54600 | BH18: 114500 | BI18: 20350 | BJ18: 170900 | BK18: 21350 | BL18: 370500 | BM18: 209500 | BN18: 293000 | BO18: 13170 | BP18: 599000 | BQ18: 53100 | BR18: 1493820 | BS18: 29950 | BT18: 85300 | BU18: 29850 | BV18: 367500 | BW18: 162600 | BX18: 75400 | BY18: 33700 | BZ18: 153000 | CA18: 23700 | CB18: 27550 | CC18: 170600 | CD18: 444500 | CE18: 50500 | CF18: 73400 | CG18: 166900 | CH18: 27650 | CI18: 34381 | CJ18: 20101 | CK18: 71400 | CL18: 154222 | CM18: 45600 | CN18: 97500 | CO18: 76100 | CP18: 51800 | CQ18: 94500 | CR18: 8580 | CS18: 198600 | CT18: 59600 | CU18: 201500 | CV18: 67000 | CW18: 106300 | CX18: 125800 | CY18: 19190 | CZ18: 54145 | DA18: 109700 | DB18: 30200 | DC18: 14380 | DD18: 21000 | DE18: 54600 | DF18: 20300 | DG18: 19784 | DH18: 48200 | DI18: 28100 | DJ18: 458000 | DK18: 101100 | DL18: 18170 | DM18: 75900 | DN18: 367500 | DO18: 9960 | DP18: 205500 | DQ18: 18870 | DR18: 60300 | DS18: 34634 | DT18: 212500 | DU18: 48000 | DV18: 31250 | DW18: 166200 | DX18: 25750 | DY18: 23800 | DZ18: 33050 | EA18: 136700 | EB18: 276500 | EC18: 259000 | ED18: 123000 | EE18: 118500 | EF18: 4160 | EG18: 44300 | EH18: 16310 | EI18: 4610 | EJ18: 79900 | EK18: 318500 | EL18: 55200 | EM18: 11820 | EN18: 20900 | EO18: 187500 | EP18: 18260 | EQ18: 8790 | ER18: 90000 | ES18: 49950 | ET18: 51000 | EU18: 24300 | EV18: 23000
A19: 45825 | B19: 2950.3 | C19: 249000 | D19: 58100 | E19: 130700 | F19: 153400 | G19: 172400 | H19: 72200 | I19: 143800 | J19: 205000 | K19: 87000 | L19: 25850 | M19: 126800 | N19: 44250 | O19: 766000 | P19: 169300 | Q19: 198500 | R19: 56200 | S19: 954000 | T19: 10630 | U19: 12700 | V19: 23900 | W19: 75000 | X19: 11670 | Y19: 1288000 | Z19: 27400 | AA19: 36350 | AB19: 34059 | AC19: 13380 | AD19: 23250 | AE19: 25500 | AF19: 19680 | AG19: 470500 | AH19: 78000 | AI19: 131200 | AJ19: 17670 | AK19: 107100 | AL19: 397500 | AM19: 31800 | AN19: 15700 | AO19: 74800 | AP19: 79500 | AQ19: 53200 | AR19: 50900 | AS19: 436500 | AT19: 26500 | AU19: 153300 | AV19: 178400 | AW19: 39350 | AX19: 11920 | AY19: 6500 | AZ19: 298500 | BA19: 88000 | BB19: 561000 | BC19: 28200 | BD19: 96500 | BE19: 60300 | BF19: 286000 | BG19: 50300 | BH19: 111200 | BI19: 20500 | BJ19: 171900 | BK19: 21500 | BL19: 367500 | BM19: 206500 | BN19: 294000 | BO19: 13030 | BP19: 612000 | BQ19: 53000 | BR19: 1486461 | BS19: 29750 | BT19: 92000 | BU19: 30900 | BV19: 365000 | BW19: 157400 | BX19: 73200 | BY19: 33350 | BZ19: 147900 | CA19: 26350 | CB19: 28250 | CC19: 172700 | CD19: 444500 | CE19: 49700 | CF19: 73000 | CG19: 158200 | CH19: 28250 | CI19: 31269 | CJ19: 20243 | CK19: 75900 | CL19: 154222 | CM19: 46750 | CN19: 99600 | CO19: 75300 | CP19: 52800 | CQ19: 97300 | CR19: 8680 | CS19: 198000 | CT19: 59400 | CU19: 205500 | CV19: 66100 | CW19: 104700 | CX19: 127400 | CY19: 18950 | CZ19: 54339 | DA19: 108300 | DB19: 29550 | DC19: 14690 | DD19: 21900 | DE19: 55300 | DF19: 20700 | DG19: 20013 | DH19: 48400 | DI19: 29350 | DJ19: 420000 | DK19: 99000 | DL19: 18350 | DM19: 76100 | DN19: 359500 | DO19: 10110 | DP19: 207000 | DQ19: 18630 | DR19: 60100 | DS19: 35805 | DT19: 210000 | DU19: 47500 | DV19: 31500 | DW19: 167800 | DX19: 26600 | DY19: 23200 | DZ19: 33550 | EA19: 132800 | EB19: 270500 | EC19: 257500 | ED19: 123700 | EE19: 120200 | EF19: 4180 | EG19: 45850 | EH19: 16270 | EI19: 4530 | EJ19: 79100 | EK19: 317000 | EL19: 55300 | EM19: 11710 | EN19: 20900 | EO19: 189200 | EP19: 19100 | EQ19: 8940 | ER19: 89500 | ES19: 48050 | ET19: 50900 | EU19: 23000 | EV19: 22550
A20: 45826 | B20: 2972.19 | C20: 246500 | D20: 59800 | E20: 133000 | F20: 148400 | G20: 164800 | H20: 73800 | I20: 153400 | J20: 206000 | K20: 87500 | L20: 25950 | M20: 123600 | N20: 47250 | O20: 804000 | P20: 169200 | Q20: 196100 | R20: 56000 | S20: 927000 | T20: 10860 | U20: 12410 | V20: 23300 | W20: 76000 | X20: 11750 | Y20: 1272000 | Z20: 27700 | AA20: 37500 | AB20: 33108 | AC20: 13680 | AD20: 22900 | AE20: 25300 | AF20: 19900 | AG20: 467000 | AH20: 76700 | AI20: 133600 | AJ20: 17890 | AK20: 107000 | AL20: 395000 | AM20: 31750 | AN20: 15810 | AO20: 72100 | AP20: 78900 | AQ20: 53200 | AR20: 51400 | AS20: 428500 | AT20: 26500 | AU20: 156100 | AV20: 176200 | AW20: 39700 | AX20: 11770 | AY20: 6600 | AZ20: 304000 | BA20: 89800 | BB20: 563000 | BC20: 28500 | BD20: 96900 | BE20: 59200 | BF20: 299500 | BG20: 49550 | BH20: 106000 | BI20: 20400 | BJ20: 186900 | BK20: 21350 | BL20: 382500 | BM20: 243500 | BN20: 292000 | BO20: 13230 | BP20: 607000 | BQ20: 52400 | BR20: 1477631 | BS20: 29650 | BT20: 92400 | BU20: 31400 | BV20: 368500 | BW20: 175000 | BX20: 79100 | BY20: 33600 | BZ20: 148500 | CA20: 26050 | CB20: 28900 | CC20: 184300 | CD20: 422500 | CE20: 46800 | CF20: 74400 | CG20: 161100 | CH20: 28600 | CI20: 30231 | CJ20: 20433 | CK20: 75300 | CL20: 154699 | CM20: 43250 | CN20: 98900 | CO20: 75700 | CP20: 52300 | CQ20: 95700 | CR20: 9170 | CS20: 196500 | CT20: 61000 | CU20: 203500 | CV20: 67100 | CW20: 103700 | CX20: 126800 | CY20: 18690 | CZ20: 55021 | DA20: 107700 | DB20: 30750 | DC20: 15400 | DD20: 21100 | DE20: 56700 | DF20: 20300 | DG20: 20063 | DH20: 50200 | DI20: 29150 | DJ20: 432000 | DK20: 100900 | DL20: 17820 | DM20: 77600 | DN20: 384000 | DO20: 10130 | DP20: 207500 | DQ20: 19450 | DR20: 57300 | DS20: 36263 | DT20: 209500 | DU20: 46700 | DV20: 31500 | DW20: 170800 | DX20: 26900 | DY20: 22600 | DZ20: 33350 | EA20: 130800 | EB20: 272000 | EC20: 259000 | ED20: 126500 | EE20: 120800 | EF20: 4235 | EG20: 45300 | EH20: 16440 | EI20: 4455 | EJ20: 78000 | EK20: 313000 | EL20: 55300 | EM20: 11600 | EN20: 20900 | EO20: 185000 | EP20: 18260 | EQ20: 9210 | ER20: 90400 | ES20: 45450 | ET20: 50300 | EU20: 22950 | EV20: 22150
A21: 45827 | B21: 2977.74 | C21: 246000 | D21: 59200 | E21: 130300 | F21: 148400 | G21: 165300 | H21: 73100 | I21: 148000 | J21: 207000 | K21: 92500 | L21: 25700 | M21: 124500 | N21: 46900 | O21: 844000 | P21: 168200 | Q21: 192600 | R21: 55500 | S21: 934000 | T21: 11630 | U21: 12000 | V21: 23300 | W21: 75300 | X21: 11900 | Y21: 1281000 | Z21: 27950 | AA21: 37400 | AB21: 35661 | AC21: 13600 | AD21: 22650 | AE21: 25800 | AF21: 19510 | AG21: 473000 | AH21: 78400 | AI21: 137000 | AJ21: 17790 | AK21: 106700 | AL21: 387000 | AM21: 31650 | AN21: 17050 | AO21: 71800 | AP21: 78700 | AQ21: 53500 | AR21: 51200 | AS21: 430500 | AT21: 26700 | AU21: 153600 | AV21: 179100 | AW21: 39150 | AX21: 11790 | AY21: 6630 | AZ21: 300000 | BA21: 88000 | BB21: 593000 | BC21: 28200 | BD21: 97300 | BE21: 59400 | BF21: 293000 | BG21: 49350 | BH21: 107100 | BI21: 20350 | BJ21: 190500 | BK21: 21400 | BL21: 360500 | BM21: 252000 | BN21: 291000 | BO21: 13280 | BP21: 610000 | BQ21: 51900 | BR21: 1470272 | BS21: 28100 | BT21: 89200 | BU21: 30900 | BV21: 379000 | BW21: 175000 | BX21: 84700 | BY21: 34000 | BZ21: 162900 | CA21: 25750 | CB21: 28300 | CC21: 184700 | CD21: 428000 | CE21: 46850 | CF21: 74300 | CG21: 168400 | CH21: 28400 | CI21: 30184 | CJ21: 20765 | CK21: 76800 | CL21: 152697 | CM21: 41000 | CN21: 98200 | CO21: 75600 | CP21: 48800 | CQ21: 95000 | CR21: 9230 | CS21: 212000 | CT21: 61000 | CU21: 207000 | CV21: 67300 | CW21: 101100 | CX21: 127300 | CY21: 19400 | CZ21: 55313 | DA21: 106400 | DB21: 29900 | DC21: 16830 | DD21: 21350 | DE21: 55600 | DF21: 20500 | DG21: 19854 | DH21: 50600 | DI21: 29650 | DJ21: 452000 | DK21: 100200 | DL21: 17490 | DM21: 80900 | DN21: 372000 | DO21: 9990 | DP21: 206000 | DQ21: 19200 | DR21: 59000 | DS21: 35194 | DT21: 205500 | DU21: 46400 | DV21: 32150 | DW21: 169300 | DX21: 26900 | DY21: 22200 | DZ21: 33550 | EA21: 131600 | EB21: 273000 | EC21: 260000 | ED21: 125600 | EE21: 125800 | EF21: 4210 | EG21: 47150 | EH21: 16500 | EI21: 4395 | EJ21: 77300 | EK21: 312000 | EL21: 55300 | EM21: 11710 | EN21: 20850 | EO21: 199700 | EP21: 18070 | EQ21: 9190 | ER21: 90900 | ES21: 45000 | ET21: 53200 | EU21: 22750 | EV21: 22000
A22: 45828 | B22: 3021.84 | C22: 257000 | D22: 59500 | E22: 133300 | F22: 155500 | G22: 161900 | H22: 74000 | I22: 149700 | J22: 210000 | K22: 93000 | L22: 26050 | M22: 127200 | N22: 47050 | O22: 827000 | P22: 176300 | Q22: 196700 | R22: 55100 | S22: 938000 | T22: 11520 | U22: 12130 | V22: 24500 | W22: 77500 | X22: 11860 | Y22: 1307000 | Z22: 28200 | AA22: 38600 | AB22: 35611 | AC22: 13690 | AD22: 22400 | AE22: 26050 | AF22: 19760 | AG22: 470000 | AH22: 75300 | AI22: 139800 | AJ22: 18130 | AK22: 106500 | AL22: 390000 | AM22: 31500 | AN22: 16940 | AO22: 72300 | AP22: 80000 | AQ22: 53400 | AR22: 52500 | AS22: 443000 | AT22: 26400 | AU22: 159800 | AV22: 177000 | AW22: 39750 | AX22: 11790 | AY22: 6690 | AZ22: 307000 | BA22: 90300 | BB22: 609000 | BC22: 28150 | BD22: 94900 | BE22: 59300 | BF22: 291500 | BG22: 49100 | BH22: 107400 | BI22: 21150 | BJ22: 190400 | BK22: 21550 | BL22: 358000 | BM22: 269500 | BN22: 305000 | BO22: 13220 | BP22: 605000 | BQ22: 51800 | BR22: 1495292 | BS22: 29200 | BT22: 88600 | BU22: 30950 | BV22: 375500 | BW22: 172500 | BX22: 82000 | BY22: 34050 | BZ22: 158900 | CA22: 25900 | CB22: 29100 | CC22: 187300 | CD22: 428500 | CE22: 48100 | CF22: 75000 | CG22: 172000 | CH22: 28650 | CI22: 30325 | CJ22: 21191 | CK22: 75900 | CL22: 154604 | CM22: 40850 | CN22: 98700 | CO22: 76000 | CP22: 46400 | CQ22: 97800 | CR22: 9260 | CS22: 212000 | CT22: 60200 | CU22: 207500 | CV22: 67700 | CW22: 104200 | CX22: 131900 | CY22: 23450 | CZ22: 61351 | DA22: 106400 | DB22: 29750 | DC22: 17070 | DD22: 21100 | DE22: 57100 | DF22: 20300 | DG22: 19446 | DH22: 51600 | DI22: 29350 | DJ22: 457000 | DK22: 101800 | DL22: 17220 | DM22: 79300 | DN22: 368500 | DO22: 10020 | DP22: 211500 | DQ22: 19170 | DR22: 59900 | DS22: 35347 | DT22: 213500 | DU22: 46400 | DV22: 32150 | DW22: 183900 | DX22: 26600 | DY22: 21850 | DZ22: 33650 | EA22: 132000 | EB22: 290000 | EC22: 262500 | ED22: 125500 | EE22: 129200 | EF22: 4275 | EG22: 46450 | EH22: 16990 | EI22: 4255 | EJ22: 80800 | EK22: 314000 | EL22: 56300 | EM22: 11780 | EN22: 21350 | EO22: 199500 | EP22: 18050 | EQ22: 9220 | ER22: 102000 | ES22: 45300 | ET22: 53500 | EU22: 23000 | EV22: 21850
A23: 45831 | B23: 3014.47 | C23: 259500 | D23: 58000 | E23: 130300 | F23: 163700 | G23: 161600 | H23: 74700 | I23: 146000 | J23: 201500 | K23: 90400 | L23: 25600 | M23: 124400 | N23: 46350 | O23: 827000 | P23: 169300 | Q23: 195800 | R23: 53800 | S23: 919000 | T23: 11000 | U23: 11800 | V23: 23350 | W23: 81800 | X23: 11500 | Y23: 1328000 | Z23: 26850 | AA23: 37550 | AB23: 33684 | AC23: 13330 | AD23: 22600 | AE23: 25450 | AF23: 18950 | AG23: 474000 | AH23: 75500 | AI23: 141200 | AJ23: 17650 | AK23: 107600 | AL23: 380000 | AM23: 30250 | AN23: 16540 | AO23: 72100 | AP23: 79800 | AQ23: 51300 | AR23: 59100 | AS23: 433500 | AT23: 25600 | AU23: 152700 | AV23: 182400 | AW23: 38150 | AX23: 12040 | AY23: 6460 | AZ23: 303000 | BA23: 88700 | BB23: 630000 | BC23: 27600 | BD23: 95000 | BE23: 60100 | BF23: 280500 | BG23: 49300 | BH23: 104200 | BI23: 21350 | BJ23: 194200 | BK23: 21500 | BL23: 350500 | BM23: 290000 | BN23: 294000 | BO23: 13440 | BP23: 624000 | BQ23: 51000 | BR23: 1459970 | BS23: 29000 | BT23: 86300 | BU23: 29800 | BV23: 375500 | BW23: 183200 | BX23: 84100 | BY23: 33350 | BZ23: 157100 | CA23: 26000 | CB23: 28250 | CC23: 185100 | CD23: 425500 | CE23: 47250 | CF23: 74000 | CG23: 191800 | CH23: 27500 | CI23: 29948 | CJ23: 21049 | CK23: 74800 | CL23: 151553 | CM23: 38950 | CN23: 95900 | CO23: 75000 | CP23: 46300 | CQ23: 94900 | CR23: 9010 | CS23: 214000 | CT23: 68600 | CU23: 208500 | CV23: 71500 | CW23: 101100 | CX23: 132000 | CY23: 23950 | CZ23: 79756 | DA23: 112400 | DB23: 29250 | DC23: 16600 | DD23: 21000 | DE23: 57600 | DF23: 20350 | DG23: 21457 | DH23: 50400 | DI23: 27800 | DJ23: 490000 | DK23: 99500 | DL23: 17280 | DM23: 78000 | DN23: 362000 | DO23: 9860 | DP23: 202500 | DQ23: 19420 | DR23: 60000 | DS23: 34277 | DT23: 220000 | DU23: 46050 | DV23: 31450 | DW23: 176100 | DX23: 26350 | DY23: 21450 | DZ23: 32650 | EA23: 130100 | EB23: 305500 | EC23: 253500 | ED23: 123700 | EE23: 125800 | EF23: 4145 | EG23: 45600 | EH23: 16960 | EI23: 4165 | EJ23: 78300 | EK23: 304500 | EL23: 56100 | EM23: 11900 | EN23: 21350 | EO23: 190700 | EP23: 17180 | EQ23: 9010 | ER23: 99200 | ES23: 45300 | ET23: 51300 | EU23: 23550 | EV23: 21650
A24: 45832 | B24: 3103.64 | C24: 278500 | D24: 60500 | E24: 136700 | F24: 181000 | G24: 162500 | H24: 76200 | I24: 151700 | J24: 206000 | K24: 92800 | L24: 26300 | M24: 128500 | N24: 47000 | O24: 826000 | P24: 176800 | Q24: 199200 | R24: 62200 | S24: 895000 | T24: 11290 | U24: 12420 | V24: 24050 | W24: 84900 | X24: 12250 | Y24: 1296000 | Z24: 27300 | AA24: 39100 | AB24: 32182 | AC24: 15050 | AD24: 23250 | AE24: 25650 | AF24: 19650 | AG24: 482000 | AH24: 76300 | AI24: 141200 | AJ24: 18450 | AK24: 112300 | AL24: 390000 | AM24: 31550 | AN24: 17680 | AO24: 73100 | AP24: 82300 | AQ24: 53400 | AR24: 66000 | AS24: 463500 | AT24: 26900 | AU24: 157700 | AV24: 184800 | AW24: 39500 | AX24: 12150 | AY24: 6600 | AZ24: 312500 | BA24: 89800 | BB24: 554000 | BC24: 27800 | BD24: 91100 | BE24: 61000 | BF24: 285000 | BG24: 49300 | BH24: 107400 | BI24: 21800 | BJ24: 194100 | BK24: 23450 | BL24: 361500 | BM24: 290500 | BN24: 300500 | BO24: 13750 | BP24: 670000 | BQ24: 52100 | BR24: 1477631 | BS24: 28900 | BT24: 87400 | BU24: 32100 | BV24: 392000 | BW24: 190200 | BX24: 85800 | BY24: 39150 | BZ24: 160500 | CA24: 26350 | CB24: 34100 | CC24: 185000 | CD24: 444000 | CE24: 47900 | CF24: 75000 | CG24: 193500 | CH24: 29350 | CI24: 30467 | CJ24: 21381 | CK24: 80200 | CL24: 153650 | CM24: 40150 | CN24: 96900 | CO24: 76000 | CP24: 48400 | CQ24: 97300 | CR24: 9200 | CS24: 200000 | CT24: 68900 | CU24: 209500 | CV24: 75800 | CW24: 102700 | CX24: 148400 | CY24: 24000 | CZ24: 73719 | DA24: 114100 | DB24: 29850 | DC24: 16450 | DD24: 21350 | DE24: 57800 | DF24: 20450 | DG24: 22453 | DH24: 51000 | DI24: 27050 | DJ24: 475000 | DK24: 102000 | DL24: 16910 | DM24: 78300 | DN24: 368000 | DO24: 10440 | DP24: 211000 | DQ24: 20600 | DR24: 60500 | DS24: 36671 | DT24: 236500 | DU24: 46850 | DV24: 32350 | DW24: 179900 | DX24: 27450 | DY24: 21950 | DZ24: 33750 | EA24: 131200 | EB24: 315000 | EC24: 263000 | ED24: 124600 | EE24: 129200 | EF24: 4250 | EG24: 49150 | EH24: 17040 | EI24: 4240 | EJ24: 79100 | EK24: 308000 | EL24: 56800 | EM24: 12130 | EN24: 22200 | EO24: 205000 | EP24: 17660 | EQ24: 9430 | ER24: 105200 | ES24: 45600 | ET24: 49550 | EU24: 22800 | EV24: 22300
A25: 45833 | B25: 3108.25 | C25: 286000 | D25: 61300 | E25: 139100 | F25: 192200 | G25: 165100 | H25: 76100 | I25: 153700 | J25: 217000 | K25: 97500 | L25: 27300 | M25: 129000 | N25: 46950 | O25: 856000 | P25: 175400 | Q25: 202500 | R25: 59100 | S25: 856000 | T25: 12000 | U25: 12450 | V25: 24100 | W25: 84000 | X25: 12670 | Y25: 1299000 | Z25: 27900 | AA25: 39700 | AB25: 31782 | AC25: 17970 | AD25: 23000 | AE25: 26150 | AF25: 19630 | AG25: 497000 | AH25: 81100 | AI25: 151600 | AJ25: 18810 | AK25: 109500 | AL25: 390000 | AM25: 32100 | AN25: 17710 | AO25: 73500 | AP25: 83200 | AQ25: 62000 | AR25: 67600 | AS25: 437000 | AT25: 27350 | AU25: 168900 | AV25: 181500 | AW25: 40450 | AX25: 12710 | AY25: 6740 | AZ25: 310500 | BA25: 89700 | BB25: 527000 | BC25: 28750 | BD25: 89900 | BE25: 60600 | BF25: 297500 | BG25: 49250 | BH25: 108900 | BI25: 21650 | BJ25: 192800 | BK25: 23900 | BL25: 357000 | BM25: 283500 | BN25: 298000 | BO25: 13790 | BP25: 667000 | BQ25: 52400 | BR25: 1477631 | BS25: 27700 | BT25: 82500 | BU25: 33750 | BV25: 364000 | BW25: 187000 | BX25: 86600 | BY25: 39400 | BZ25: 160600 | CA25: 27350 | CB25: 37850 | CC25: 183500 | CD25: 440500 | CE25: 47800 | CF25: 75800 | CG25: 180100 | CH25: 29350 | CI25: 30750 | CJ25: 21381 | CK25: 77500 | CL25: 152983 | CM25: 39300 | CN25: 101100 | CO25: 74200 | CP25: 55400 | CQ25: 95600 | CR25: 9350 | CS25: 191800 | CT25: 65800 | CU25: 202000 | CV25: 77200 | CW25: 102000 | CX25: 146300 | CY25: 23500 | CZ25: 69823 | DA25: 114300 | DB25: 27950 | DC25: 16780 | DD25: 21100 | DE25: 56200 | DF25: 20300 | DG25: 23349 | DH25: 51900 | DI25: 26200 | DJ25: 480500 | DK25: 106800 | DL25: 16870 | DM25: 77800 | DN25: 378000 | DO25: 11320 | DP25: 212500 | DQ25: 20700 | DR25: 61800 | DS25: 36875 | DT25: 236500 | DU25: 46750 | DV25: 33400 | DW25: 182000 | DX25: 27400 | DY25: 22400 | DZ25: 33900 | EA25: 133000 | EB25: 296500 | EC25: 269500 | ED25: 125300 | EE25: 130000 | EF25: 4310 | EG25: 48850 | EH25: 16810 | EI25: 4360 | EJ25: 79200 | EK25: 311000 | EL25: 57100 | EM25: 12580 | EN25: 22500 | EO25: 203500 | EP25: 18090 | EQ25: 9340 | ER25: 105400 | ES25: 46050 | ET25: 49650 | EU25: 22850 | EV25: 22200
A26: 45834 | B26: 3079.56 | C26: 293000 | D26: 60200 | E26: 138900 | F26: 187400 | G26: 160600 | H26: 74700 | I26: 152000 | J26: 209500 | K26: 103700 | L26: 26800 | M26: 125500 | N26: 46250 | O26: 863000 | P26: 174600 | Q26: 203500 | R26: 56800 | S26: 878000 | T26: 12470 | U26: 12510 | V26: 23400 | W26: 81400 | X26: 12440 | Y26: 1319000 | Z26: 27150 | AA26: 39650 | AB26: 31382 | AC26: 16500 | AD26: 22650 | AE26: 25900 | AF26: 19500 | AG26: 484000 | AH26: 78900 | AI26: 149300 | AJ26: 18450 | AK26: 109900 | AL26: 385000 | AM26: 32700 | AN26: 17830 | AO26: 73500 | AP26: 83500 | AQ26: 62000 | AR26: 62100 | AS26: 423500 | AT26: 27250 | AU26: 171400 | AV26: 185000 | AW26: 40550 | AX26: 12400 | AY26: 6590 | AZ26: 306000 | BA26: 88400 | BB26: 524000 | BC26: 29250 | BD26: 94700 | BE26: 59700 | BF26: 294500 | BG26: 48900 | BH26: 110800 | BI26: 22100 | BJ26: 188200 | BK26: 24000 | BL26: 358500 | BM26: 261000 | BN26: 297000 | BO26: 14300 | BP26: 659000 | BQ26: 52400 | BR26: 1470272 | BS26: 26800 | BT26: 80300 | BU26: 33300 | BV26: 362500 | BW26: 185000 | BX26: 81800 | BY26: 42900 | BZ26: 158500 | CA26: 29050 | CB26: 40600 | CC26: 182700 | CD26: 441500 | CE26: 47500 | CF26: 76000 | CG26: 174900 | CH26: 28100 | CI26: 30467 | CJ26: 21428 | CK26: 76300 | CL26: 152697 | CM26: 37800 | CN26: 99100 | CO26: 73200 | CP26: 58200 | CQ26: 97400 | CR26: 9300 | CS26: 196700 | CT26: 64700 | CU26: 200500 | CV26: 75700 | CW26: 102000 | CX26: 142300 | CY26: 23050 | CZ26: 68752 | DA26: 113900 | DB26: 27500 | DC26: 16890 | DD26: 20600 | DE26: 56600 | DF26: 20050 | DG26: 21756 | DH26: 50400 | DI26: 25050 | DJ26: 499500 | DK26: 105800 | DL26: 16430 | DM26: 80000 | DN26: 377500 | DO26: 12250 | DP26: 216000 | DQ26: 20400 | DR26: 62900 | DS26: 38250 | DT26: 234500 | DU26: 46200 | DV26: 32250 | DW26: 179300 | DX26: 26750 | DY26: 21650 | DZ26: 33700 | EA26: 130900 | EB26: 284000 | EC26: 267500 | ED26: 124800 | EE26: 128900 | EF26: 4260 | EG26: 50500 | EH26: 16670 | EI26: 4340 | EJ26: 77700 | EK26: 310500 | EL26: 56700 | EM26: 12420 | EN26: 22550 | EO26: 207000 | EP26: 19500 | EQ26: 9300 | ER26: 105600 | ES26: 45050 | ET26: 47900 | EU26: 23100 | EV26: 21900
... A266: 46195 | B266: 9114.55 | C266: 2919000 | D266: 353500 | E266: 2228000 | F266: 1970000 | G266: 520000 | H266: 227500 | I266: 1130000 | J266: 581000 | K266: 301500 | L266: 172500 | M266: 450500 | N266: 174000 | O266: 3834000 | P266: 533000 | Q266: 730000 | R266: 245000 | S266: 1125000 | T266: 115900 | U266: 102800 | V266: 134000 | W266: 109900 | X266: 56800 | Y266: 1070000 | Z266: 159200 | AA266: 187300 | AB266: 107500 | AC266: 134000 | AD266: 49900 | AE266: 183400 | AF266: 180200 | AG266: 1033000 | AH266: 127800 | AI266: 373000 | AJ266: 39050 | AK266: 157000 | AL266: 350500 | AM266: 197900 | AN266: 155000 | AO266: 247000 | AP266: 119700 | AQ266: 198200 | AR266: 100400 | AS266: 636000 | AT266: 94000 | AU266: 518000 | AV266: 394000 | AW266: 259500 | AX266: 16950 | AY266: 22750 | AZ266: 213000 | BA266: 85800 | BB266: 848000 | BC266: 60000 | BD266: 148600 | BE266: 97500 | BF266: 569000 | BG266: 53200 | BH266: 133900 | BI266: 66400 | BJ266: 260500 | BK266: 27050 | BL266: 225000 | BM266: 222000 | BN266: 385500 | BO266: 14480 | BP266: 1631000 | BQ266: 52300 | BR266: 1295000 | BS266: 88000 | BT266: 116500 | BU266: 63800 | BV266: 397500 | BW266: 200500 | BX266: 229500 | BY266: 64500 | BZ266: 168600 | CA266: 85900 | CB266: 38000 | CC266: 720000 | CD266: 685000 | CE266: 43450 | CF266: 177200 | CG266: 208500 | CH266: 142700 | CI266: 37850 | CJ266: 85500 | CK266: 132500 | CL266: 168500 | CM266: 130700 | CN266: 151400 | CO266: 54800 | CP266: 74000 | CQ266: 86000 | CR266: 45300 | CS266: 203500 | CT266: 94200 | CU266: 209500 | CV266: 114000 | CW266: 73400 | CX266: 221000 | CY266: 62800 | CZ266: 289000 | DA266: 105700 | DB266: 56100 | DC266: 16160 | DD266: 25200 | DE266: 34700 | DF266: 18650 | DG266: 46100 | DH266: 92400 | DI266: 53200 | DJ266: 293500 | DK266: 267500 | DL266: 38500 | DM266: 75300 | DN266: 253000 | DO266: 56000 | DP266: 323000 | DQ266: 30800 | DR266: 72500 | DS266: 109300 | DT266: 337000 | DU266: 67600 | DV266: 63500 | DW266: 385000 | DX266: 167000 | DY266: 27150 | DZ266: 56900 | EA266: 166700 | EB266: 573000 | EC266: 346500 | ED266: 174900 | EE266: 192000 | EF266: 13490 | EG266: 117900 | EH266: 22100 | EI266: 21800 | EJ266: 118500 | EK266: 517000 | EL266: 94200 | EM266: 16480 | EN266: 29850 | EO266: 205000 | EP266: 60300 | EQ266: 12930 | ER266: 166700 | ES266: 137000 | ET266: 50800 | EU266: 19550 | EV266: 24250

Sheet 주간시가DB
A1: Refresh | B1: Last Update : 2026-06-22 19:10:14
A2: 0
A3: Time Series (Company)
A4: Frequency | B4: W | C4: Ascending | D4: 0
A5: Period(From) | B5: 20260605 | C5: Korean | D5: 0
A6: Period(To) | B6: =일간종가DB!B6 -> 20260622 | D6: 0
A8: Code | B8: IKS001 | C8: A039440 | D8: A388210 | E8: A001430 | F8: A017960 | G8: A322000 | H8: A226950 | I8: A397030 | J8: A089970 | K8: A036620 | L8: A041510 | M8: A285130 | N8: A138610 | O8: A108490 | P8: A466100 | Q8: A077970 | R8: A006650 | S8: A214320 | T8: A042520 | U8: A100090 | V8: A237690 | W8: A347850 | X8: A267270 | Y8: A417200 | Z8: A099320 | AA8: A139480 | AB8: A483650 | AC8: A484590 | AD8: A032350 | AE8: A352820 | AF8: A125490 | AG8: A004170 | AH8: A011210 | AI8: A035510 | AJ8: A481070 | AK8: A272210 | AL8: A494120 | AM8: A189300 | AN8: A009420 | AO8: A204320 | AP8: A194370 | AQ8: A439260 | AR8: A053030 | AS8: A001120 | AT8: A000720 | AU8: A247540 | AV8: A300720 | AW8: A298380 | AX8: A010950 | AY8: A003670 | AZ8: A217590 | BA8: A034230 | BB8: A298020 | BC8: A010060 | BD8: A475150 | BE8: A079900 | BF8: A006280 | BG8: A044490 | BH8: A047810 | BI8: A499790 | BJ8: A141080 | BK8: A484870 | BL8: A196170 | BM8: A089890 | BN8: A066970 | BO8: A069260 | BP8: A287840 | BQ8: A257720 | BR8: A009830 | BS8: A079550 | BT8: A278470 | BU8: A192820 | BV8: A023530 | BW8: A062040 | BX8: A123410 | BY8: A128940 | BZ8: A042670 | CA8: A017800 | CB8: A348210 | CC8: A488280 | CD8: A0126Z0 | CE8: A006730 | CF8: A419530 | CG8: A083650 | CH8: A005300 | CI8: A380550 | CJ8: A102710 | CK8: A078930 | CL8: A295310 | CM8: A011070 | CN8: A069960 | CO8: A006360 | CP8: A001040 | CQ8: A002020 | CR8: A462350 | CS8: A033500 | CT8: A031440 | CU8: A161580 | CV8: A241710 | CW8: A031430 | CX8: A071320 | CY8: A093050 | CZ8: A042370 | DA8: A450080 | DB8: A336570 | DC8: A207940 | DD8: A011790 | DE8: A030200 | DF8: A105630 | DG8: A003380 | DH8: A394800 | DI8: A375500 | DJ8: A001800 | DK8: A004360 | DL8: A249420 | DM8: A012330 | DN8: A474650 | DO8: A122870 | DP8: A006260 | DQ8: A035900 | DR8: A082920 | DS8: A347700 | DT8: A015760 | DU8: A281740 | DV8: A468530 | DW8: A009180 | DX8: A120110 | DY8: A005940 | DZ8: A098070 | EA8: A000120 | EB8: A033790 | EC8: A222800 | ED8: A004020 | EE8: A229640 | EF8: A195940 | EG8: A089030 | EH8: A100790 | EI8: A140410 | EJ8: A328130 | EK8: A010130 | EL8: A039200 | EM8: A090430 | EN8: A131290 | EO8: A105840 | EP8: A078520 | EQ8: A071970 | ER8: A030190 | ES8: A005490 | ET8: A138930 | EU8: A072990 | EV8: A042660
A9: Name | B9: 코스피 | C9: 에스티아이 | D9: 씨엠티엑스 | E9: 세아베스틸지주 | F9: 한국카본 | G9: HD현대에너지솔루션 | H9: 올릭스 | I9: 에이프릴바이오 | J9: 브이엠 | K9: 감성코퍼레이션 | L9: 에스엠 | M9: SK케미칼 | N9: 나이벡 | O9: 로보티즈 | P9: 클로봇 | Q9: STX엔진 | R9: 대한유화 | S9: 이노션 | T9: 한스바이오메드 | U9: SK오션플랜트 | V9: 에스티팜 | W9: 디앤디파마텍 | X9: HD건설기계 | Y9: LS머트리얼즈 | Z9: 쎄트렉아이 | AA9: 이마트 | AB9: 달바글로벌 | AC9: 삼양컴텍 | AD9: 롯데관광개발 | AE9: 하이브 | AF9: 한라캐스트 | AG9: 신세계 | AH9: 현대위아 | AI9: 신세계 I&C | AJ9: 에이유브랜즈 | AK9: 한화시스템 | AL9: 큐리오시스 | AM9: 인텔리안테크 | AN9: 한올바이오파마 | AO9: HL만도 | AP9: 제이에스코퍼레이션 | AQ9: 대한조선 | AR9: 바이넥스 | AS9: LX인터내셔널 | AT9: 현대건설 | AU9: 에코프로비엠 | AV9: 한일시멘트 | AW9: 에이비엘바이오 | AX9: S-Oil | AY9: 포스코퓨처엠 | AZ9: 티엠씨 | BA9: 파라다이스 | BB9: 효성티앤씨 | BC9: OCI홀딩스 | BD9: SK이터닉스 | BE9: 전진건설로봇 | BF9: 녹십자 | BG9: 태웅 | BH9: 한국항공우주 | BI9: GS피앤엘 | BJ9: 리가켐바이오 | BK9: 엠앤씨솔루션 | BL9: 알테오젠 | BM9: 코세스 | BN9: 엘앤에프 | BO9: TKG휴켐스 | BP9: 인투셀 | BQ9: 실리콘투 | BR9: 한화솔루션 | BS9: LIG디펜스앤에어로스페이스 | BT9: 에이피알 | BU9: 코스맥스 | BV9: 롯데쇼핑 | BW9: 산일전기 | BX9: 코리아에프티 | BY9: 한미약품 | BZ9: HD현대인프라코어 | CA9: 현대엘리베이터 | CB9: 넥스틴 | CC9: 에스투더블유 | CD9: 삼성에피스홀딩스 | CE9: 서부T&D | CF9: SAMG엔터 | CG9: 비에이치아이 | CH9: 롯데칠성 | CI9: 뉴로핏 | CJ9: 이엔에프테크놀로지 | CK9: GS | CL9: 에이치브이엠 | CM9: LG이노텍 | CN9: 현대백화점 | CO9: GS건설 | CP9: CJ | CQ9: 코오롱 | CR9: 이노스페이스 | CS9: 동성화인텍 | CT9: 신세계푸드 | CU9: 필옵틱스 | CV9: 코스메카코리아 | CW9: 신세계인터내셔날 | CX9: 지역난방공사 | CY9: LF | CZ9: 비츠로테크 | DA9: 에코프로머티 | DB9: 원텍 | DC9: 삼성바이오로직스 | DD9: SKC | DE9: KT | DF9: 한세실업 | DG9: 하림지주 | DH9: 쓰리빌리언 | DI9: DL이앤씨 | DJ9: 오리온홀딩스 | DK9: 세방 | DL9: 일동제약 | DM9: 현대모비스 | DN9: 링크솔루션 | DO9: 와이지엔터테인먼트 | DP9: LS | DQ9: JYP Ent. | DR9: 비츠로셀 | DS9: 스피어 | DT9: 한국전력 | DU9: 레이크머티리얼즈 | DV9: 프로티나 | DW9: 한솔로지스틱스 | DX9: 코오롱인더 | DY9: NH투자증권 | DZ9: 한텍 | EA9: CJ대한통운 | EB9: 피노 | EC9: 심텍 | ED9: 현대제철 | EE9: LS에코에너지 | EF9: HK이노엔 | EG9: 테크윙 | EH9: 미래에셋벤처투자 | EI9: 메지온 | EJ9: 루닛 | EK9: 고려아연 | EL9: 오스코텍 | EM9: 아모레퍼시픽 | EN9: 티에스이 | EO9: 우진 | EP9: 에이블씨엔씨 | EQ9: HD현대마린엔진 | ER9: NICE평가정보 | ES9: POSCO홀딩스 | ET9: BNK금융지주 | EU9: 에이치시티 | EV9: 한화오션
A10: Item Code | B10: S200710 | C10: S200710 | D10: S200710 | E10: S200710 | F10: S200710 | G10: S200710 | H10: S200710 | I10: S200710 | J10: S200710 | K10: S200710 | L10: S200710 | M10: S200710 | N10: S200710 | O10: S200710 | P10: S200710 | Q10: S200710 | R10: S200710 | S10: S200710 | T10: S200710 | U10: S200710 | V10: S200710 | W10: S200710 | X10: S200710 | Y10: S200710 | Z10: S200710 | AA10: S200710 | AB10: S200710 | AC10: S200710 | AD10: S200710 | AE10: S200710 | AF10: S200710 | AG10: S200710 | AH10: S200710 | AI10: S200710 | AJ10: S200710 | AK10: S200710 | AL10: S200710 | AM10: S200710 | AN10: S200710 | AO10: S200710 | AP10: S200710 | AQ10: S200710 | AR10: S200710 | AS10: S200710 | AT10: S200710 | AU10: S200710 | AV10: S200710 | AW10: S200710 | AX10: S200710 | AY10: S200710 | AZ10: S200710 | BA10: S200710 | BB10: S200710 | BC10: S200710 | BD10: S200710 | BE10: S200710 | BF10: S200710 | BG10: S200710 | BH10: S200710 | BI10: S200710 | BJ10: S200710 | BK10: S200710 | BL10: S200710 | BM10: S200710 | BN10: S200710 | BO10: S200710 | BP10: S200710 | BQ10: S200710 | BR10: S200710 | BS10: S200710 | BT10: S200710 | BU10: S200710 | BV10: S200710 | BW10: S200710 | BX10: S200710 | BY10: S200710 | BZ10: S200710 | CA10: S200710 | CB10: S200710 | CC10: S200710 | CD10: S200710 | CE10: S200710 | CF10: S200710 | CG10: S200710 | CH10: S200710 | CI10: S200710 | CJ10: S200710 | CK10: S200710 | CL10: S200710 | CM10: S200710 | CN10: S200710 | CO10: S200710 | CP10: S200710 | CQ10: S200710 | CR10: S200710 | CS10: S200710 | CT10: S200710 | CU10: S200710 | CV10: S200710 | CW10: S200710 | CX10: S200710 | CY10: S200710 | CZ10: S200710 | DA10: S200710 | DB10: S200710 | DC10: S200710 | DD10: S200710 | DE10: S200710 | DF10: S200710 | DG10: S200710 | DH10: S200710 | DI10: S200710 | DJ10: S200710 | DK10: S200710 | DL10: S200710 | DM10: S200710 | DN10: S200710 | DO10: S200710 | DP10: S200710 | DQ10: S200710 | DR10: S200710 | DS10: S200710 | DT10: S200710 | DU10: S200710 | DV10: S200710 | DW10: S200710 | DX10: S200710 | DY10: S200710 | DZ10: S200710 | EA10: S200710 | EB10: S200710 | EC10: S200710 | ED10: S200710 | EE10: S200710 | EF10: S200710 | EG10: S200710 | EH10: S200710 | EI10: S200710 | EJ10: S200710 | EK10: S200710 | EL10: S200710 | EM10: S200710 | EN10: S200710 | EO10: S200710 | EP10: S200710 | EQ10: S200710 | ER10: S200710 | ES10: S200710 | ET10: S200710 | EU10: S200710 | EV10: S200710
