Workbook

Sheet 반도체 수출 판가 증가율
A1: Refresh | B1: Last Update : 2026-05-21 08:15:52 | L1: 수출데이터는 한달에 3번 매월 1일, 11일, 21일 발표합니다.
A2: 0 | L2: 확정수출데이터는 매월 15일에 발표하고 전월 확정을 발표합니다.
A3: Time Series (Company)
A4: Frequency | B4: M | C4: Ascending | D4: 0 | L4: 수출데이터는 변동성 모멘텀, 상대강도 등 강한 섹터에서 수출데이터
A5: Period(From) | B5: 20070131 | C5: Korean | D5: 0 | L5: 발표를 위주로 살피는게 중요하고, 약한 섹터에서는 수출데이터가 크게
A6: Period(To) | B6: CPD [20260521] | L6: 급변하지 않는 이상 시장의 관심이 약합니다.
A8: Code | B8: A005930 | L8: rs 및 변동성 모멘텀 + 기관 유동성 + 주요 거래대금 을 기둥으로 하고
A9: Name | B9: 삼성전자 | L9: 거기에 조금더 확률을 높이기 위해 수출데이터를 보는 방법을 선호합니다.
A10: Item Code | B10: S300910 | L10: 수출데이터를 주력 지표로 보고 있진 않습니다.
A11: Unit | B11: Local/Shares
A12: Base Date
A14: D A T E | B14: 월간수정주가 | C14: 디램판가 | D14: 디램판가 yoy | E14: 디램수출 yoy
A15: 39113 | B15: 11580 | C15: 2282.1671 | E15: 673429633 | G15: 22 | H15: =E15/G15 -> 30610438
A16: 39141 | B16: 11340 | C16: 2080.0801 | E16: 521299068 | G16: 20 | H16: =E16/G16 -> 26064953
A17: 39171 | B17: 11260 | C17: 1436.0643 | E17: 545020575 | G17: 21 | H17: =E17/G17 -> 25953361
A18: 39202 | B18: 11480 | C18: 1253.1916 | E18: 517709975 | G18: 21 | H18: =E18/G18 -> 24652856
A19: 39233 | B19: 10700 | C19: 1256.475 | E19: 411857936 | G19: 23 | H19: =E19/G19 -> 17906867
A20: 39262 | B20: 11320 | C20: 1340.1394 | E20: 464977996 | G20: 20 | H20: =E20/G20 -> 23248900
A21: 39294 | B21: 12280 | C21: 1321.8147 | E21: 468238435 | G21: 22 | H21: =E21/G21 -> 21283565
A22: 39325 | B22: 11820 | C22: 1391.3241 | E22: 524072000 | G22: 22 | H22: =E22/G22 -> 23821455
A23: 39353 | B23: 11500 | C23: 1447.5453 | E23: 472642496 | G23: 20 | H23: =E23/G23 -> 23632125
A24: 39386 | B24: 11000 | C24: 1291.1539 | E24: 449158887 | G24: 21 | H24: =E24/G24 -> 21388518
A25: 39416 | B25: 11300 | C25: 1428.4301 | E25: 429390223 | G25: 22 | H25: =E25/G25 -> 19517737
A26: 39444 | B26: 11120 | C26: 1094.2401 | E26: 377614611 | G26: 19 | H26: =E26/G26 -> 19874453
A27: 39478 | B27: 11900 | C27: 1031.8422 | D27: =C27/C15-1 -> -0.54786739 | E27: 388308216 | F27: =E27/E15-1 -> -0.4233871 | G27: 22 | H27: =E27/G27 -> 17650373 | I27: =H27/H15-1 -> -0.4233871
A28: 39507 | B28: 11200 | C28: 1138.3693 | D28: =C28/C16-1 -> -0.45272813 | E28: 404505084 | F28: =E28/E16-1 -> -0.22404411 | G28: 21 | H28: =E28/G28 -> 19262147 | I28: =H28/H16-1 -> -0.26099439
A29: 39538 | B29: 12460 | C29: 1315.5591 | D29: =C29/C17-1 -> -0.083913504 | E29: 476066897 | F29: =E29/E17-1 -> -0.12651573 | G29: 21 | H29: =E29/G29 -> 22669852 | I29: =H29/H17-1 -> -0.12651573
A30: 39568 | B30: 14220 | C30: 1254.1787 | D30: =C30/C18-1 -> 0.00078771604 | E30: 425342672 | F30: =E30/E18-1 -> -0.17841515 | G30: 22 | H30: =E30/G30 -> 19333758 | I30: =H30/H18-1 -> -0.21575992
A31: 39598 | B31: 14820 | C31: 1336.0881 | D31: =C31/C19-1 -> 0.06336222 | E31: 457504077 | F31: =E31/E19-1 -> 0.11082982 | G31: 21 | H31: =E31/G31 -> 21785908 | I31: =H31/H19-1 -> 0.21662314
A32: 39629 | B32: 12500 | C32: 1405.2222 | D32: =C32/C20-1 -> 0.048564178 | E32: 478735318 | F32: =E32/E20-1 -> 0.029587039 | G32: 20 | H32: =E32/G32 -> 23936766 | I32: =H32/H20-1 -> 0.029587039
A33: 39660 | B33: 11280 | C33: 1427.831 | D33: =C33/C21-1 -> 0.080205128 | E33: 547325021 | F33: =E33/E21-1 -> 0.16890238 | G33: 23 | H33: =E33/G33 -> 23796740 | I33: =H33/H21-1 -> 0.11808054
A34: 39689 | B34: 10320 | C34: 1260.4473 | D34: =C34/C22-1 -> -0.094066394 | E34: 568252609 | F34: =E34/E22-1 -> 0.084302556 | G34: 20 | H34: =E34/G34 -> 28412630 | I34: =H34/H22-1 -> 0.19273281
A35: 39721 | B35: 10780 | C35: 1092.0841 | D35: =C35/C23-1 -> -0.24556133 | E35: 481671245 | F35: =E35/E23-1 -> 0.019102703 | G35: 22 | H35: =E35/G35 -> 21894148 | I35: =H35/H23-1 -> -0.073542998
A36: 39752 | B36: 10700 | C36: 850.73945 | D36: =C36/C24-1 -> -0.34110146 | E36: 368762884 | F36: =E36/E24-1 -> -0.17899235 | G36: 21 | H36: =E36/G36 -> 17560137 | I36: =H36/H24-1 -> -0.17899235
A37: 39780 | B37: 9720 | C37: 776.73353 | D37: =C37/C25-1 -> -0.45623272 | E37: 317521445 | F37: =E37/E25-1 -> -0.2605294 | G37: 20 | H37: =E37/G37 -> 15876072 | I37: =H37/H25-1 -> -0.18658234
A38: 39812 | B38: 9020 | C38: 791.41504 | D38: =C38/C26-1 -> -0.27674465 | E38: 273625655 | F38: =E38/E26-1 -> -0.27538383 | G38: 21 | H38: =E38/G38 -> 13029793 | I38: =H38/H26-1 -> -0.34439489
... A206: 44924 | B206: 55300 | C206: 7376.2759 | D206: =C206/C194-1 -> -0.57859318 | E206: 1419716100 | F206: =E206/E194-1 -> -0.40540574 | G206: 21 | H206: =E206/G206 -> 67605529 | I206: =H206/H194-1 -> -0.37709173
A207: 44957 | B207: 61000 | C207: 7561.4765 | D207: =C207/C195-1 -> -0.5070312 | E207: 889144043 | F207: =E207/E195-1 -> -0.66010395 | G207: 22 | H207: =디램!F17 -> 44457202 | I207: =H207/H195-1 -> -0.66010395
A208: 44985 | B208: 60600 | C208: 8346.8842 | D208: =C208/C196-1 -> -0.47462971 | E208: 947429033 | F208: =E208/E196-1 -> -0.43123683 | G208: 20 | H208: =디램!F18 -> 47371452 | I208: =H208/H196-1 -> -0.43123683
A209: 45016 | B209: 64000 | C209: 8549.7291 | D209: =C209/C197-1 -> -0.43703771 | E209: 1134771349 | F209: =E209/E197-1 -> -0.53912742 | G209: 22 | H209: =디램!F19 -> 51580516 | I209: =H209/H197-1 -> -0.53912742
...

Sheet 총수출
L1: 삼성전자, 하이닉스
L2: 8542321010
P3: 년월 | Q3: 금액(달러) | R3: 금액(원화) | S3: 중량(Kg)
A4: 년월 | B4: 분기(일평균합) | C4: 분기(평균) | D4: QoQ | E4: YoY | F4: 일평균수출 | G4: MoM | H4: YoY | I4: 금액(달러)/중량 | J4: 판가 yoy | K4: 분기 달러매출 | L4: QoQ | M4: YoY | N4: 판가 | O4: QoQ | T4: 금액(달러)/중량 | U4: 일평균수출중량
A5: 2022년01월 | F5: =Q5/20 -> 2772768.8 | I5: =T5 -> #DIV/0! | P5: 2022년01월 | Q5: 55455376 | T5: =Q5/S5 -> #DIV/0! | U5: =S5/20 -> 0
A6: 2022년02월 | F6: =Q6/18 -> 3008657.5 | G6: =F6/F5-1 -> 0.085073339 | I6: =T6 -> #DIV/0! | P6: 2022년02월 | Q6: 54155835 | T6: =Q6/S6 -> #DIV/0! | U6: =S6/18 -> 0
A7: 2022년03월 | B7: =F5+F6+F7 -> 8680827.9 | C7: =AVERAGE(F5:F7) -> 2893609.3 | F7: =Q7/22 -> 2899401.6 | G7: =F7/F6-1 -> -0.036313841 | I7: =T7 -> #DIV/0! | K7: =Q5+Q6+Q7 -> 173398046 | N7: =AVERAGE(T5:T7) -> #DIV/0! | P7: 2022년03월 | Q7: 63786835 | T7: =Q7/S7 -> #DIV/0! | U7: =S7/22 -> 0
A8: 2022년04월 | F8: =Q8/21 -> 2754419.8 | G8: =F8/F7-1 -> -0.050004036 | I8: =T8 -> #DIV/0! | P8: 2022년04월 | Q8: 57842816 | T8: =Q8/S8 -> #DIV/0! | U8: =S8/21 -> 0
A9: 2022년05월 | F9: =Q9/21 -> 2932920.3 | G9: =F9/F8-1 -> 0.064805109 | I9: =T9 -> #DIV/0! | P9: 2022년05월 | Q9: 61591326 | T9: =Q9/S9 -> #DIV/0! | U9: =S9/21 -> 0 | AC9: 2500
A10: 2022년06월 | B10: =F8+F9+F10 -> 8434003.6 | C10: =AVERAGE(F8:F10) -> 2811334.5 | D10: =C10/C7-1 -> -0.028433264 | F10: =Q10/21 -> 2746663.5 | G10: =F10/F9-1 -> -0.063505566 | I10: =T10 -> #DIV/0! | K10: =Q8+Q9+Q10 -> 177114076 | L10: =K10/K7-1 -> 0.021430634 | N10: =AVERAGE(T8:T10) -> #DIV/0! | O10: =N10/N7-1 -> #DIV/0! | P10: 2022년06월 | Q10: 57679934 | T10: =Q10/S10 -> #DIV/0! | U10: =S10/21 -> 0 | AC10: 4545
A11: 2022년07월 | F11: =Q11/21 -> 2868655.9 | G11: =F11/F10-1 -> 0.044414753 | I11: =T11 -> #DIV/0! | P11: 2022년07월 | Q11: 60241774 | T11: =Q11/S11 -> #DIV/0! | U11: =S11/21 -> 0 | AC11: =AC9*AC10 -> 11362500
A12: 2022년08월 | F12: =Q12/22 -> 2572997.7 | G12: =F12/F11-1 -> -0.10306505 | I12: =T12 -> #DIV/0! | P12: 2022년08월 | Q12: 56605950 | T12: =Q12/S12 -> #DIV/0! | U12: =S12/22 -> 0
A13: 2022년09월 | B13: =F11+F12+F13 -> 8300468.6 | C13: =AVERAGE(F11:F13) -> 2766822.9 | D13: =C13/C10-1 -> -0.01583293 | F13: =Q13/20 -> 2858815 | G13: =F13/F12-1 -> 0.11108338 | I13: =T13 -> #DIV/0! | K13: =Q11+Q12+Q13 -> 174024024 | L13: =K13/K10-1 -> -0.017446677 | N13: =AVERAGE(T11:T13) -> #DIV/0! | O13: =N13/N10-1 -> #DIV/0! | P13: 2022년09월 | Q13: 57176300 | T13: =Q13/S13 -> #DIV/0! | U13: =S13/20 -> 0
A14: 2022년10월 | F14: =Q14/20 -> 2621404.6 | G14: =F14/F13-1 -> -0.083045038 | I14: =T14 -> #DIV/0! | P14: 2022년10월 | Q14: 52428092 | T14: =Q14/S14 -> #DIV/0! | U14: =S14/20 -> 0
A15: 2022년11월 | F15: =Q15/22 -> 2353266.1 | G15: =F15/F14-1 -> -0.10228809 | I15: =T15 -> #DIV/0! | P15: 2022년11월 | Q15: 51771855 | T15: =Q15/S15 -> #DIV/0! | U15: =S15/22 -> 0
A16: 2022년12월 | B16: =F14+F15+F16 -> 7467791.9 | C16: =AVERAGE(F14:F16) -> 2489264 | D16: =C16/C13-1 -> -0.10031683 | F16: =Q16/22 -> 2493121.2 | G16: =F16/F15-1 -> 0.059430187 | I16: =T16 -> #DIV/0! | K16: =Q14+Q15+Q16 -> 159048613 | L16: =K16/K13-1 -> -0.086053699 | N16: =AVERAGE(T14:T16) -> #DIV/0! | O16: =N16/N13-1 -> #DIV/0! | P16: 2022년12월 | Q16: 54848666 | T16: =Q16/S16 -> #DIV/0! | U16: =S16/22 -> 0
A17: 2023년01월 | F17: =Q17/20 -> 2316957.2 | G17: =F17/F16-1 -> -0.070659996 | H17: =F17/F5-1 -> -0.16438859 | I17: =T17 -> #DIV/0! | J17: =I17/I5-1 -> #DIV/0! | P17: 2023년01월 | Q17: 46339145 | T17: =Q17/S17 -> #DIV/0! | U17: =S17/20 -> 0
A18: 2023년02월 | F18: =Q18/20 -> 2499729.6 | G18: =F18/F17-1 -> 0.078884667 | H18: =F18/F6-1 -> -0.16915447 | I18: =T18 -> #DIV/0! | J18: =I18/I6-1 -> #DIV/0! | P18: 2023년02월 | Q18: 49994593 | T18: =Q18/S18 -> #DIV/0! | U18: =S18/20 -> 0
A19: 2023년03월 | B19: =SUM(F17:F19) -> 7311345.3 | C19: =AVERAGE(F17:F19) -> 2437115.1 | D19: =C19/C16-1 -> -0.02094952 | E19: =C19/C7-1 -> -0.15775945 | F19: =Q19/22 -> 2494658.4 | G19: =F19/F18-1 -> -0.0020287339 | H19: =F19/F7-1 -> -0.13959544 | I19: =T19 -> #DIV/0! | J19: =I19/I7-1 -> #DIV/0! | K19: =Q17+Q18+Q19 -> 151216222 | L19: =K19/K16-1 -> -0.049245264 | M19: =U19/U7-1 -> #DIV/0! | N19: =AVERAGE(T17:T19) -> #DIV/0! | O19: =N19/N16-1 -> #DIV/0! | P19: 2023년03월 | Q19: 54882484 | T19: =Q19/S19 -> #DIV/0! | U19: =S19/22 -> 0
A20: 2023년04월 | F20: =Q20/20 -> 2471544 | G20: =F20/F19-1 -> -0.0092655628 | H20: =F20/F8-1 -> -0.10269889 | I20: =T20 -> #DIV/0! | J20: =I20/I8-1 -> #DIV/0! | P20: 2023년04월 | Q20: 49430879 | T20: =Q20/S20 -> #DIV/0! | U20: =S20/20 -> 0
A21: 2023년05월 | F21: =Q21/21 -> 2478771.2 | G21: =F21/F20-1 -> 0.0029241804 | H21: =F21/F9-1 -> -0.15484536 | I21: =T21 -> #DIV/0! | J21: =I21/I9-1 -> #DIV/0! | P21: 2023년05월 | Q21: 52054195 | T21: =Q21/S21 -> #DIV/0! | U21: =S21/21 -> 0
A22: 2023년06월 | B22: =SUM(F20:F22) -> 7535922.5 | C22: =AVERAGE(F20:F22) -> 2511974.2 | D22: =C22/C19-1 -> 0.030716264 | E22: =C22/C10-1 -> -0.10648337 | F22: =Q22/21 -> 2585607.3 | G22: =F22/F21-1 -> 0.043100446 | H22: =F22/F10-1 -> -0.05863703 | I22: =T22 -> #DIV/0! | J22: =I22/I10-1 -> #DIV/0! | K22: =Q20+Q21+Q22 -> 155782828 | L22: =K22/K19-1 -> 0.030199181 | M22: =U22/U10-1 -> #DIV/0! | N22: =AVERAGE(T20:T22) -> #DIV/0! | O22: =N22/N19-1 -> #DIV/0! | P22: 2023년06월 | Q22: 54297754 | T22: =Q22/S22 -> #DIV/0! | U22: =S22/22 -> 0
A23: 2023년07월 | F23: =Q23/21 -> 2402751.2 | G23: =F23/F22-1 -> -0.070720752 | H23: =F23/F11-1 -> -0.16241218 | I23: =T23 -> #DIV/0! | J23: =I23/I11-1 -> #DIV/0! | P23: 2023년07월 | Q23: 50457776 | T23: =Q23/S23 -> #DIV/0! | U23: =S23/21 -> 0
A24: 2023년08월 | F24: =Q24/22 -> 2363367 | G24: =F24/F23-1 -> -0.016391309 | H24: =F24/F12-1 -> -0.081473343 | I24: =T24 -> #DIV/0! | J24: =I24/I12-1 -> #DIV/0! | P24: 2023년08월 | Q24: 51994074 | T24: =Q24/S24 -> #DIV/0! | U24: =S24/22 -> 0
A25: 2023년09월 | B25: =SUM(F23:F25) -> 7642470.4 | C25: =AVERAGE(F23:F25) -> 2547490.1 | D25: =C25/C22-1 -> 0.01413867 | E25: =C25/C13-1 -> -0.07927242 | F25: =Q25/19 -> 2876352.2 | G25: =F25/F24-1 -> 0.21705692 | H25: =F25/F13-1 -> 0.0061344151 | I25: =T25 -> #DIV/0! | J25: =I25/I13-1 -> #DIV/0! | K25: =Q23+Q24+Q25 -> 157102541 | L25: =K25/K22-1 -> 0.0084714921 | M25: =U25/U13-1 -> #DIV/0! | N25: =AVERAGE(T23:T25) -> #DIV/0! | O25: =N25/N22-1 -> #DIV/0! | P25: 2023년09월 | Q25: 54650691 | T25: =Q25/S25 -> #DIV/0! | U25: =S25/22 -> 0
A26: 2023년10월 | F26: =Q26/19 -> 2894207.9 | G26: =F26/F25-1 -> 0.0062077715 | H26: =F26/F14-1 -> 0.1040676 | I26: =T26 -> #DIV/0! | J26: =I26/I14-1 -> #DIV/0! | P26: 2023년10월 | Q26: 54989950 | T26: =Q26/S26 -> #DIV/0! | U26: =S26/19 -> 0
A27: 2023년11월 | F27: =Q27/22 -> 2525504.1 | G27: =F27/F26-1 -> -0.12739368 | H27: =F27/F15-1 -> 0.073191022 | I27: =T27 -> #DIV/0! | J27: =I27/I15-1 -> #DIV/0! | P27: 2023년11월 | Q27: 55561090 | T27: =Q27/S27 -> #DIV/0! | U27: =S27/22 -> 0
A28: 2023년12월 | B28: =SUM(F26:F28) -> 8449880 | C28: =AVERAGE(F26:F28) -> 2816626.7 | D28: =C28/C25-1 -> 0.10564773 | E28: =C28/C16-1 -> 0.13150984 | F28: =Q28/19 -> 3030168.1 | G28: =F28/F27-1 -> 0.19982702 | H28: =F28/F16-1 -> 0.21541146 | I28: =T28 -> #DIV/0! | J28: =I28/I16-1 -> #DIV/0! | K28: =Q26+Q27+Q28 -> 168124233 | L28: =K28/K25-1 -> 0.070156039 | M28: =U28/U16-1 -> #DIV/0! | N28: =AVERAGE(T26:T28) -> #DIV/0! | O28: =N28/N25-1 -> #DIV/0! | P28: 2023년12월 | Q28: 57573193 | T28: =Q28/S28 -> #DIV/0! | U28: =S28/19 -> 0
A29: 2024년01월 | F29: =Q29/22 -> 2486810.1 | G29: =F29/F28-1 -> -0.1793161 | H29: =F29/F17-1 -> 0.073308597 | I29: =T29 -> #DIV/0! | J29: =I29/I17-1 -> #DIV/0! | P29: 2024년01월 | Q29: 54709823 | T29: =Q29/S29 -> #DIV/0! | U29: =S29/22 -> 0
A30: 2024년02월 | F30: =Q30/19 -> 2740862.6 | G30: =F30/F29-1 -> 0.10215999 | H30: =F30/F18-1 -> 0.096463624 | I30: =T30 -> #DIV/0! | J30: =I30/I18-1 -> #DIV/0! | P30: 2024년02월 | Q30: 52076390 | T30: =Q30/S30 -> #DIV/0! | U30: =S30/19 -> 0
A31: 2024년03월 | B31: =SUM(F29:F31) -> 8053588.2 | C31: =AVERAGE(F29:F31) -> 2684529.4 | D31: =C31/C28-1 -> -0.046899106 | E31: =C31/C19-1 -> 0.10151934 | F31: =Q31/20 -> 2825915.5 | G31: =F31/F30-1 -> 0.031031405 | H31: =F31/F19-1 -> 0.13278655 | I31: =T31 -> #DIV/0! | J31: =I31/I19-1 -> #DIV/0! | K31: =Q29+Q30+Q31 -> 163304522 | L31: =K31/K28-1 -> -0.028667557 | M31: =U31/U19-1 -> #DIV/0! | N31: =AVERAGE(T29:T31) -> #DIV/0! | O31: =N31/N28-1 -> #DIV/0! | P31: 2024년03월 | Q31: 56518309 | T31: =Q31/S31 -> #DIV/0! | U31: =S31/20 -> 0
A32: 2024년04월 | F32: =Q32/21 -> 2673728.5 | G32: =F32/F31-1 -> -0.053854027 | H32: =F32/F20-1 -> 0.081804968 | I32: =T32 -> #DIV/0! | J32: =I32/I20-1 -> #DIV/0! | P32: 2024년04월 | Q32: 56148299 | T32: =Q32/S32 -> #DIV/0! | U32: =S32/21 -> 0
A33: 2024년05월 | F33: =Q33/21 -> 2762883.7 | G33: =F33/F32-1 -> 0.033344875 | H33: =F33/F21-1 -> 0.11461827 | I33: =T33 -> #DIV/0! | J33: =I33/I21-1 -> #DIV/0! | P33: 2024년05월 | Q33: 58020557 | T33: =Q33/S33 -> #DIV/0! | U33: =S33/21 -> 0
A34: 2024년06월 | B34: =SUM(F32:F34) -> 8454592.9 | C34: =AVERAGE(F32:F34) -> 2818197.6 | D34: =C34/C31-1 -> 0.049792055 | E34: =C34/C22-1 -> 0.12190551 | F34: =Q34/19 -> 3017980.7 | G34: =F34/F33-1 -> 0.092330008 | H34: =F34/F22-1 -> 0.16722315 | I34: =T34 -> #DIV/0! | J34: =I34/I22-1 -> #DIV/0! | K34: =Q32+Q33+Q34 -> 171510490 | L34: =K34/K31-1 -> 0.050249484 | M34: =U34/U22-1 -> #DIV/0! | N34: =AVERAGE(T32:T34) -> #DIV/0! | O34: =N34/N31-1 -> #DIV/0! | P34: 2024년06월 | Q34: 57341634 | T34: =Q34/S34 -> #DIV/0! | U34: =S34/19 -> 0
A35: 2024년07월 | F35: =Q35/23 -> 2498208.2 | G35: =F35/F34-1 -> -0.17222528 | H35: =F35/F23-1 -> 0.039728181 | I35: =T35 -> #DIV/0! | J35: =I35/I23-1 -> #DIV/0! | P35: 2024년07월 | Q35: 57458788 | T35: =Q35/S35 -> #DIV/0! | U35: =S35/23 -> 0
A36: 2024년08월 | F36: =Q36/21 -> 2744901.1 | G36: =F36/F35-1 -> 0.098747963 | H36: =F36/F24-1 -> 0.16143669 | I36: =T36 -> #DIV/0! | J36: =I36/I24-1 -> #DIV/0! | P36: 2024년08월 | Q36: 57642924 | T36: =Q36/S36 -> #DIV/0! | U36: =S36/21 -> 0
A37: 2024년09월 | B37: =SUM(F35:F37) -> 8495592.3 | C37: =AVERAGE(F35:F37) -> 2831864.1 | D37: =C37/C34-1 -> 0.0048493563 | E37: =C37/C25-1 -> 0.11162907 | F37: =Q37/18 -> 3252482.9 | G37: =F37/F36-1 -> 0.18491806 | H37: =F37/F25-1 -> 0.1307666 | I37: =T37 -> #DIV/0! | J37: =I37/I25-1 -> #DIV/0! | K37: =Q35+Q36+Q37 -> 173646405 | L37: =K37/K34-1 -> 0.012453553 | M37: =U37/U25-1 -> #DIV/0! | N37: =AVERAGE(T35:T37) -> #DIV/0! | O37: =N37/N34-1 -> #DIV/0! | P37: 2024년09월 | Q37: 58544693 | T37: =Q37/S37 -> #DIV/0! | U37: =S37/18 -> 0
A38: 2024년10월 | F38: =Q38/20 -> 2875009.6 | G38: =F38/F37-1 -> -0.11605698 | H38: =F38/F26-1 -> -0.0066333503 | I38: =T38 -> #DIV/0! | J38: =I38/I26-1 -> #DIV/0! | P38: 2024년10월 | Q38: 57500192 | T38: =Q38/S38 -> #DIV/0! | U38: =S38/20 -> 0
A39: 2024년11월 | F39: =Q39/21 -> 2680410.9 | G39: =F39/F38-1 -> -0.067686277 | H39: =F39/F27-1 -> 0.061336988 | I39: =T39 -> #DIV/0! | J39: =I39/I27-1 -> #DIV/0! | P39: 2024년11월 | Q39: 56288629 | T39: =Q39/S39 -> #DIV/0! | U39: =S39/21 -> 0
A40: 2024년12월 | B40: =SUM(F38:F40) -> 8477289.6 | C40: =AVERAGE(F38:F40) -> 2825763.2 | D40: =C40/C37-1 -> -0.002154377 | E40: =C40/C28-1 -> 0.0032437755 | F40: =Q40/21 -> 2921869 | G40: =F40/F39-1 -> 0.09008251 | H40: =F40/F28-1 -> -0.035740264 | I40: =T40 -> #DIV/0! | J40: =I40/I28-1 -> #DIV/0! | K40: =Q38+Q39+Q40 -> 175148071 | L40: =K40/K37-1 -> 0.0086478381 | M40: =U40/U28-1 -> #DIV/0! | N40: =AVERAGE(T38:T40) -> #DIV/0! | O40: =N40/N37-1 -> #DIV/0! | P40: 2024년12월 | Q40: 61359250 | T40: =Q40/S40 -> #DIV/0! | U40: =S40/21 -> 0
...

Sheet 디램
L1: 삼성전자, 하이닉스
L2: 8542321010
P3: 년월 | Q3: 금액(달러) | R3: 금액(원화) | S3: 중량(Kg)
A4: 년월 | B4: 분기(일평균합) | C4: 분기(평균) | D4: QoQ | E4: YoY | F4: 일평균수출 | G4: MoM | H4: YoY | I4: 금액(달러)/중량 | J4: 판가 yoy | K4: 분기 달러매출 | L4: QoQ | M4: YoY | N4: 판가 | O4: QoQ | T4: 금액(달러)/중량 | U4: 일평균수출중량
A5: 2022년01월 | F5: =Q5/20 -> 1.1292405e+08 | I5: =T5 -> 15338.651 | P5: 2022년01월 | Q5: 2258480961 | R5: 2665462773215 | S5: 147241.17 | T5: =Q5/S5 -> 15338.651 | U5: =S5/20 -> 7362.0585
A6: 2022년02월 | F6: =Q6/18 -> 1.2024532e+08 | G6: =F6/F5-1 -> 0.064833604 | I6: =T6 -> 15887.621 | P6: 2022년02월 | Q6: 2164415779 | R6: 2571067122269 | S6: 136232.84 | T6: =Q6/S6 -> 15887.621 | U6: =S6/18 -> 7568.4911
A7: 2022년03월 | B7: =F5+F6+F7 -> 3.4508862e+08 | C7: =AVERAGE(F5:F7) -> 1.1502954e+08 | F7: =Q7/22 -> 1.1191925e+08 | G7: =F7/F6-1 -> -0.069242332 | I7: =T7 -> 15187.037 | K7: =Q5+Q6+Q7 -> 6885120341 | N7: =AVERAGE(T5:T7) -> 15471.103 | P7: 2022년03월 | Q7: 2462223601 | R7: 2965368123176 | S7: 162126.66 | T7: =Q7/S7 -> 15187.037 | U7: =S7/22 -> 7369.3936
A8: 2022년04월 | F8: =Q8/21 -> 1.0399463e+08 | G8: =F8/F7-1 -> -0.070806591 | I8: =T8 -> 16152.593 | P8: 2022년04월 | Q8: 2183887307 | R8: 2646416027355 | S8: 135203.51 | T8: =Q8/S8 -> 16152.593 | U8: =S8/21 -> 6438.2624
A9: 2022년05월 | F9: =Q9/21 -> 1.1761733e+08 | G9: =F9/F8-1 -> 0.13099424 | I9: =T9 -> 21394.35 | P9: 2022년05월 | Q9: 2469963975 | R9: 3103714973420 | S9: 115449.36 | T9: =Q9/S9 -> 21394.35 | U9: =S9/21 -> 5497.5886 | AC9: 2500
A10: 2022년06월 | B10: =F8+F9+F10 -> 3.401678e+08 | C10: =AVERAGE(F8:F10) -> 1.1338927e+08 | D10: =C10/C7-1 -> -0.014259588 | F10: =Q10/21 -> 1.1855584e+08 | G10: =F10/F9-1 -> 0.0079793018 | I10: =T10 -> 16953.913 | K10: =Q8+Q9+Q10 -> 7143523845 | L10: =K10/K7-1 -> 0.037530717 | N10: =AVERAGE(T8:T10) -> 18166.952 | O10: =N10/N7-1 -> 0.17425057 | P10: 2022년06월 | Q10: 2489672563 | R10: 3129635500938 | S10: 146849.44 | T10: =Q10/S10 -> 16953.913 | U10: =S10/21 -> 6992.8305 | AC10: 4545
A11: 2022년07월 | F11: =Q11/21 -> 1.1277957e+08 | G11: =F11/F10-1 -> -0.04872187 | I11: =T11 -> 12524.079 | P11: 2022년07월 | Q11: 2368371059 | R11: 3056790027285 | S11: 189105.41 | T11: =Q11/S11 -> 12524.079 | U11: =S11/21 -> 9005.0195 | AC11: =AC9*AC10 -> 11362500
A12: 2022년08월 | F12: =Q12/22 -> 91056608 | G12: =F12/F11-1 -> -0.19261436 | I12: =T12 -> 15154.651 | P12: 2022년08월 | Q12: 2003245387 | R12: 2602739850591 | S12: 132186.84 | T12: =Q12/S12 -> 15154.651 | U12: =S12/22 -> 6008.4927
A13: 2022년09월 | B13: =F11+F12+F13 -> 2.9499991e+08 | C13: =AVERAGE(F11:F13) -> 98333304 | D13: =C13/C10-1 -> -0.1327812 | F13: =Q13/20 -> 91163729 | G13: =F13/F12-1 -> 0.0011764143 | I13: =T13 -> 13845.394 | K13: =Q11+Q12+Q13 -> 6194891022 | L13: =K13/K10-1 -> -0.1327962 | N13: =AVERAGE(T11:T13) -> 13841.374 | O13: =N13/N10-1 -> -0.23810144 | P13: 2022년09월 | Q13: 1823274576 | R13: 2485923751874 | S13: 131688.17 | T13: =Q13/S13 -> 13845.394 | U13: =S13/20 -> 6584.4085
A14: 2022년10월 | F14: =Q14/20 -> 78270684 | G14: =F14/F13-1 -> -0.14142735 | I14: =T14 -> 8934.4073 | P14: 2022년10월 | Q14: 1565413680 | R14: 2231131827519 | S14: 175211.81 | T14: =Q14/S14 -> 8934.4073 | U14: =S14/20 -> 8760.5905
A15: 2022년11월 | F15: =Q15/22 -> 63759188 | G15: =F15/F14-1 -> -0.18540142 | I15: =T15 -> 8595.1092 | P15: 2022년11월 | Q15: 1402702132 | R15: 1938324728325 | S15: 163197.71 | T15: =Q15/S15 -> 8595.1092 | U15: =S15/22 -> 7418.0777
A16: 2022년12월 | B16: =F14+F15+F16 -> 2.0656242e+08 | C16: =AVERAGE(F14:F16) -> 68854141 | D16: =C16/C13-1 -> -0.29978819 | F16: =Q16/22 -> 64532550 | G16: =F16/F15-1 -> 0.012129423 | I16: =T16 -> 7376.2763 | K16: =Q14+Q15+Q16 -> 4387831912 | L16: =K16/K13-1 -> -0.29170152 | N16: =AVERAGE(T14:T16) -> 8301.9309 | O16: =N16/N13-1 -> -0.40020906 | P16: 2022년12월 | Q16: 1419716100 | R16: 1858865689714 | S16: 192470.57 | T16: =Q16/S16 -> 7376.2763 | U16: =S16/22 -> 8748.6623
A17: 2023년01월 | F17: =Q17/20 -> 44457202 | G17: =F17/F16-1 -> -0.31108871 | H17: =F17/F5-1 -> -0.60630882 | I17: =T17 -> 7561.4772 | J17: =I17/I5-1 -> -0.50703116 | P17: 2023년01월 | Q17: 889144043 | R17: 1117828908030 | S17: 117588.67 | T17: =Q17/S17 -> 7561.4772 | U17: =S17/20 -> 5879.4335
A18: 2023년02월 | F18: =Q18/20 -> 47371452 | G18: =F18/F17-1 -> 0.065551797 | H18: =F18/F6-1 -> -0.60604329 | I18: =T18 -> 8346.8849 | J18: =I18/I6-1 -> -0.47462967 | P18: 2023년02월 | Q18: 947429033 | R18: 1188739027335 | S18: 113506.9 | T18: =Q18/S18 -> 8346.8849 | U18: =S18/20 -> 5675.345
A19: 2023년03월 | B19: =SUM(F17:F19) -> 1.4340917e+08 | C19: =AVERAGE(F17:F19) -> 47803057 | D19: =C19/C16-1 -> -0.30573447 | E19: =C19/C7-1 -> -0.584428 | F19: =Q19/22 -> 51580516 | G19: =F19/F18-1 -> 0.088852338 | H19: =F19/F7-1 -> -0.53912742 | I19: =T19 -> 8549.7298 | J19: =I19/I7-1 -> -0.43703767 | K19: =Q17+Q18+Q19 -> 2971344425 | L19: =K19/K16-1 -> -0.32282173 | M19: =U19/U7-1 -> -0.18134383 | N19: =AVERAGE(T17:T19) -> 8152.6973 | O19: =N19/N16-1 -> -0.017975774 | P19: 2023년03월 | Q19: 1134771349 | R19: 1483284305311 | S19: 132725.99 | T19: =Q19/S19 -> 8549.7298 | U19: =S19/22 -> 6032.9995
A20: 2023년04월 | F20: =Q20/20 -> 58175934 | G20: =F20/F19-1 -> 0.12786647 | H20: =F20/F8-1 -> -0.44058715 | I20: =T20 -> 7959.5594 | J20: =I20/I8-1 -> -0.50722715 | P20: 2023년04월 | Q20: 1163518682 | R20: 1526855493802 | S20: 146178.78 | T20: =Q20/S20 -> 7959.5594 | U20: =S20/20 -> 7308.939
A21: 2023년05월 | F21: =Q21/21 -> 56809753 | G21: =F21/F20-1 -> -0.02348362 | H21: =F21/F9-1 -> -0.51699506 | I21: =T21 -> 7567.6282 | J21: =I21/I9-1 -> -0.64627912 | P21: 2023년05월 | Q21: 1193004804 | R21: 1588176470577 | S21: 157645.8 | T21: =Q21/S21 -> 7567.6282 | U21: =S21/21 -> 7506.9429
A22: 2023년06월 | B22: =SUM(F20:F22) -> 1.7042584e+08 | C22: =AVERAGE(F20:F22) -> 56808614 | D22: =C22/C19-1 -> 0.18838874 | E22: =C22/C10-1 -> -0.49899478 | F22: =Q22/21 -> 55440156 | G22: =F22/F21-1 -> -0.024108472 | H22: =F22/F10-1 -> -0.53237092 | I22: =T22 -> 7708.7108 | J22: =I22/I10-1 -> -0.54531376 | K22: =Q20+Q21+Q22 -> 3520766767 | L22: =K22/K19-1 -> 0.18490699 | M22: =U22/U10-1 -> -0.018283015 | N22: =AVERAGE(T20:T22) -> 7745.2995 | O22: =N22/N19-1 -> -0.049970923 | P22: 2023년06월 | Q22: 1164243281 | R22: 1515127865190 | S22: 151029.57 | T22: =Q22/S22 -> 7708.7108 | U22: =S22/22 -> 6864.9805
A23: 2023년07월 | F23: =Q23/21 -> 54389114 | G23: =F23/F22-1 -> -0.018958137 | H23: =F23/F11-1 -> -0.51773967 | I23: =T23 -> 10863.607 | J23: =I23/I11-1 -> -0.13258235 | P23: 2023년07월 | Q23: 1142171397 | R23: 1474669212488 | S23: 105137.4 | T23: =Q23/S23 -> 10863.607 | U23: =S23/21 -> 5006.5429
A24: 2023년08월 | F24: =Q24/22 -> 58446524 | G24: =F24/F23-1 -> 0.074599672 | H24: =F24/F12-1 -> -0.35812979 | I24: =T24 -> 9972.0066 | J24: =I24/I12-1 -> -0.34198374 | P24: 2023년08월 | Q24: 1285823533 | R24: 1684356368072 | S24: 128943.31 | T24: =Q24/S24 -> 9972.0066 | U24: =S24/22 -> 5861.0595
A25: 2023년09월 | B25: =SUM(F23:F25) -> 1.7501998e+08 | C25: =AVERAGE(F23:F25) -> 58339993 | D25: =C25/C22-1 -> 0.026956804 | E25: =C25/C13-1 -> -0.40671176 | F25: =Q25/19 -> 62184341 | G25: =F25/F24-1 -> 0.063952756 | H25: =F25/F13-1 -> -0.31788288 | I25: =T25 -> 8914.2132 | J25: =I25/I13-1 -> -0.35616038 | K25: =Q23+Q24+Q25 -> 3609497400 | L25: =K25/K22-1 -> 0.025202076 | M25: =U25/U13-1 -> -0.085018799 | N25: =AVERAGE(T23:T25) -> 9916.6089 | O25: =N25/N22-1 -> 0.28033899 | P25: 2023년09월 | Q25: 1181502470 | R25: 1568248010360 | S25: 132541.42 | T25: =Q25/S25 -> 8914.2132 | U25: =S25/22 -> 6024.61
A26: 2023년10월 | F26: =Q26/19 -> 60038106 | G26: =F26/F25-1 -> -0.03451406 | H26: =F26/F14-1 -> -0.23294261 | I26: =T26 -> 10150.539 | J26: =I26/I14-1 -> 0.13611773 | P26: 2023년10월 | Q26: 1140724023 | R26: 1537956473286 | S26: 112380.64 | T26: =Q26/S26 -> 10150.539 | U26: =S26/19 -> 5914.7705
A27: 2023년11월 | F27: =Q27/22 -> 60981302 | G27: =F27/F26-1 -> 0.015709943 | H27: =F27/F15-1 -> -0.043568405 | I27: =T27 -> 10382.542 | J27: =I27/I15-1 -> 0.20795935 | P27: 2023년11월 | Q27: 1341588637 | R27: 1773992637174 | S27: 129215.81 | T27: =Q27/S27 -> 10382.542 | U27: =S27/22 -> 5873.4459
A28: 2023년12월 | B28: =SUM(F26:F28) -> 1.9747518e+08 | C28: =AVERAGE(F26:F28) -> 65825059 | D28: =C28/C25-1 -> 0.12830077 | E28: =C28/C16-1 -> -0.043992727 | F28: =Q28/19 -> 76455769 | G28: =F28/F27-1 -> 0.25375758 | H28: =F28/F16-1 -> 0.18476287 | I28: =T28 -> 9082.5496 | J28: =I28/I16-1 -> 0.23131906 | K28: =Q26+Q27+Q28 -> 3934972279 | L28: =K28/K25-1 -> 0.0901718 | M28: =U28/U16-1 -> -0.03781001 | N28: =AVERAGE(T26:T28) -> 9871.8769 | O28: =N28/N25-1 -> -0.0045108191 | P28: 2023년12월 | Q28: 1452659619 | R28: 1893512536683 | S28: 159939.63 | T28: =Q28/S28 -> 9082.5496 | U28: =S28/19 -> 8417.8753
A29: 2024년01월 | F29: =Q29/22 -> 63964054 | G29: =F29/F28-1 -> -0.16338487 | H29: =F29/F17-1 -> 0.43877821 | I29: =T29 -> 10919.484 | J29: =I29/I17-1 -> 0.44409401 | P29: 2024년01월 | Q29: 1407209178 | R29: 1850754511236 | S29: 128871.4 | T29: =Q29/S29 -> 10919.484 | U29: =S29/22 -> 5857.7909
A30: 2024년02월 | F30: =Q30/19 -> 78497995 | G30: =F30/F29-1 -> 0.22722045 | H30: =F30/F18-1 -> 0.65707387 | I30: =T30 -> 12842.64 | J30: =I30/I18-1 -> 0.53861473 | P30: 2024년02월 | Q30: 1491461901 | R30: 1987222371583 | S30: 116133.59 | T30: =Q30/S30 -> 12842.64 | U30: =S30/19 -> 6112.2942
A31: 2024년03월 | B31: =SUM(F29:F31) -> 2.2391169e+08 | C31: =AVERAGE(F29:F31) -> 74637229 | D31: =C31/C28-1 -> 0.13387257 | E31: =C31/C19-1 -> 0.56134847 | F31: =Q31/20 -> 81449639 | G31: =F31/F30-1 -> 0.037601529 | H31: =F31/F19-1 -> 0.57907764 | I31: =T31 -> 14434.331 | J31: =I31/I19-1 -> 0.68827922 | K31: =Q29+Q30+Q31 -> 4527663868 | L31: =K31/K28-1 -> 0.15062154 | M31: =U31/U19-1 -> -0.064682177 | N31: =AVERAGE(T29:T31) -> 12732.152 | O31: =N31/N28-1 -> 0.28973972 | P31: 2024년03월 | Q31: 1628992789 | R31: 2164824160043 | S31: 112855.44 | T31: =Q31/S31 -> 14434.331 | U31: =S31/20 -> 5642.772
A32: 2024년04월 | F32: =Q32/21 -> 75942074 | G32: =F32/F31-1 -> -0.067619271 | H32: =F32/F20-1 -> 0.30538642 | I32: =T32 -> 14997.59 | J32: =I32/I20-1 -> 0.88422362 | P32: 2024년04월 | Q32: 1594783559 | R32: 2170380602179 | S32: 106335.99 | T32: =Q32/S32 -> 14997.59 | U32: =S32/21 -> 5063.6186
A33: 2024년05월 | F33: =Q33/21 -> 84148819 | G33: =F33/F32-1 -> 0.10806585 | H33: =F33/F21-1 -> 0.48123897 | I33: =T33 -> 15458.351 | J33: =I33/I21-1 -> 1.0426942 | P33: 2024년05월 | Q33: 1767125202 | R33: 2417076226000 | S33: 114315.25 | T33: =Q33/S33 -> 15458.351 | U33: =S33/21 -> 5443.5833
A34: 2024년06월 | B34: =SUM(F32:F34) -> 2.6005291e+08 | C34: =AVERAGE(F32:F34) -> 86684304 | D34: =C34/C31-1 -> 0.16140839 | E34: =C34/C22-1 -> 0.5259007 | F34: =Q34/19 -> 99962020 | G34: =F34/F33-1 -> 0.18791946 | H34: =F34/F22-1 -> 0.80306165 | I34: =T34 -> 16238.924 | J34: =I34/I22-1 -> 1.106568 | K34: =Q32+Q33+Q34 -> 5261187137 | L34: =K34/K31-1 -> 0.16200921 | M34: =U34/U22-1 -> -0.10331795 | N34: =AVERAGE(T32:T34) -> 15564.955 | O34: =N34/N31-1 -> 0.22249208 | P34: 2024년06월 | Q34: 1899278376 | R34: 2611161209928 | S34: 116958.39 | T34: =Q34/S34 -> 16238.924 | U34: =S34/19 -> 6155.7047
A35: 2024년07월 | F35: =Q35/23 -> 86358077 | G35: =F35/F34-1 -> -0.13609111 | H35: =F35/F23-1 -> 0.58778238 | I35: =T35 -> 18838.406 | J35: =I35/I23-1 -> 0.73408386 | P35: 2024년07월 | Q35: 1986235775 | R35: 2749024686511 | S35: 105435.45 | T35: =Q35/S35 -> 18838.406 | U35: =S35/23 -> 4584.15
A36: 2024년08월 | F36: =Q36/21 -> 87614070 | G36: =F36/F35-1 -> 0.014544007 | H36: =F36/F24-1 -> 0.49904671 | I36: =T36 -> 18781.805 | J36: =I36/I24-1 -> 0.88345291 | P36: 2024년08월 | Q36: 1839895463 | R36: 2512659063317 | S36: 97961.59 | T36: =Q36/S36 -> 18781.805 | U36: =S36/21 -> 4664.8376
A37: 2024년09월 | B37: =SUM(F35:F37) -> 2.7887674e+08 | C37: =AVERAGE(F35:F37) -> 92958914 | D37: =C37/C34-1 -> 0.072384615 | E37: =C37/C25-1 -> 0.59339948 | F37: =Q37/18 -> 1.049046e+08 | G37: =F37/F36-1 -> 0.19734875 | H37: =F37/F25-1 -> 0.68699379 | I37: =T37 -> 15556.183 | J37: =I37/I25-1 -> 0.74509881 | K37: =Q35+Q36+Q37 -> 5714413973 | L37: =K37/K34-1 -> 0.086145355 | M37: =U37/U25-1 -> 0.11934133 | N37: =AVERAGE(T35:T37) -> 17725.464 | O37: =N37/N34-1 -> 0.13880604 | P37: 2024년09월 | Q37: 1888282735 | R37: 2520248718703 | S37: 121384.71 | T37: =Q37/S37 -> 15556.183 | U37: =S37/18 -> 6743.595
A38: 2024년10월 | F38: =Q38/20 -> 95601691 | G38: =F38/F37-1 -> -0.088679678 | H38: =F38/F26-1 -> 0.59235019 | I38: =T38 -> 20008.644 | J38: =I38/I26-1 -> 0.97119036 | P38: 2024년10월 | Q38: 1912033811 | R38: 2569694800717 | S38: 95560.39 | T38: =Q38/S38 -> 20008.644 | U38: =S38/20 -> 4778.0195
A39: 2024년11월 | F39: =Q39/21 -> 86907992 | G39: =F39/F38-1 -> -0.09093666 | H39: =F39/F27-1 -> 0.42515804 | I39: =T39 -> 17065.913 | J39: =I39/I27-1 -> 0.64371234 | P39: 2024년11월 | Q39: 1825067835 | R39: 2535842880820 | S39: 106942.29 | T39: =Q39/S39 -> 17065.913 | U39: =S39/21 -> 5092.49
A40: 2024년12월 | B40: =SUM(F38:F40) -> 2.8234132e+08 | C40: =AVERAGE(F38:F40) -> 94113773 | D40: =C40/C37-1 -> 0.012423321 | E40: =C40/C28-1 -> 0.42975599 | F40: =Q40/21 -> 99831636 | G40: =F40/F39-1 -> 0.14870489 | H40: =F40/F28-1 -> 0.30574365 | I40: =T40 -> 15464.043 | J40: =I40/I28-1 -> 0.70261038 | K40: =Q38+Q39+Q40 -> 5833565998 | L40: =K40/K37-1 -> 0.020851136 | M40: =U40/U28-1 -> -0.23309309 | N40: =AVERAGE(T38:T40) -> 17512.867 | O40: =N40/N37-1 -> -0.011993913 | P40: 2024년12월 | Q40: 2096464352 | R40: 2981748925522 | S40: 135570.26 | T40: =Q40/S40 -> 15464.043 | U40: =S40/21 -> 6455.7267
...

Sheet 낸드
L1: 삼성전자, 하이닉스
L2: 8542321030
P3: 년월 | Q3: 금액(달러) | R3: 금액(원화) | S3: 중량(Kg)
A4: 년월 | B4: 분기(일평균합) | C4: 분기(평균) | D4: QoQ | E4: YoY | F4: 일평균수출 | G4: MoM | H4: YoY | I4: 금액(달러)/중량 | J4: 판가 yoy | K4: 분기 달러매출 | L4: QoQ | M4: YoY | N4: 판가 | O4: QoQ | T4: 금액(달러)/중량 | U4: 일평균수출중량
A5: 2022년01월 | F5: =Q5/20 -> 26112557 | I5: =T5 -> 10911.979 | P5: 2022년01월 | Q5: 522251145 | S5: 47860.35 | T5: =Q5/S5 -> 10911.979 | U5: =S5/20 -> 2393.0175
A6: 2022년02월 | F6: =Q6/18 -> 34954581 | G6: =F6/F5-1 -> 0.33861193 | I6: =T6 -> 13784.046 | P6: 2022년02월 | Q6: 629182451 | S6: 45645.7 | T6: =Q6/S6 -> 13784.046 | U6: =S6/20 -> 2282.285
A7: 2022년03월 | B7: =F5+F6+F7 -> 94981519 | C7: =AVERAGE(F5:F7) -> 31660506 | F7: =Q7/22 -> 33914381 | G7: =F7/F6-1 -> -0.029758599 | I7: =T7 -> 14076.693 | K7: =Q5+Q6+Q7 -> 1897549984 | L7: =R5+R6+R7 -> 0 | M7: =S5+S6+S7 -> 146509.72 | N7: =AVERAGE(T5:T7) -> 12924.24 | P7: 2022년03월 | Q7: 746116388 | S7: 53003.67 | T7: =Q7/S7 -> 14076.693 | U7: =S7/20 -> 2650.1835
A8: 2022년04월 | F8: =Q8/21 -> 35334201 | G8: =F8/F7-1 -> 0.041864836 | I8: =T8 -> 13884.885 | P8: 2022년04월 | Q8: 742018227 | S8: 53440.72 | T8: =Q8/S8 -> 13884.885 | U8: =S8/20 -> 2672.036
A9: 2022년05월 | F9: =Q9/21 -> 38254286 | G9: =F9/F8-1 -> 0.082641872 | I9: =T9 -> 13605.341 | P9: 2022년05월 | Q9: 803340002 | S9: 59045.93 | T9: =Q9/S9 -> 13605.341 | U9: =S9/20 -> 2952.2965
A10: 2022년06월 | B10: =F8+F9+F10 -> 1.1103998e+08 | C10: =AVERAGE(F8:F10) -> 37013328 | D10: =C10/C7-1 -> 0.16906936 | F10: =Q10/21 -> 37451496 | G10: =F10/F9-1 -> -0.020985608 | I10: =T10 -> 16589.513 | K10: =Q8+Q9+Q10 -> 2331839653 | L10: =K10/K7-1 -> 0.22886863 | M10: =S8+S9+S10 -> 159895 | N10: =AVERAGE(T8:T10) -> 14693.246 | O10: =N10/N7-1 -> 0.13687509 | P10: 2022년06월 | Q10: 786481424 | S10: 47408.35 | T10: =Q10/S10 -> 16589.513 | U10: =S10/20 -> 2370.4175
A11: 2022년07월 | F11: =Q11/21 -> 35150713 | G11: =F11/F10-1 -> -0.061433693 | I11: =T11 -> 18335.972 | P11: 2022년07월 | Q11: 738164966 | S11: 40257.75 | T11: =Q11/S11 -> 18335.972 | U11: =S11/20 -> 2012.8875
A12: 2022년08월 | F12: =Q12/22 -> 28114984 | G12: =F12/F11-1 -> -0.20015892 | I12: =T12 -> 15769.786 | P12: 2022년08월 | Q12: 618529649 | S12: 39222.45 | T12: =Q12/S12 -> 15769.786 | U12: =S12/20 -> 1961.1225
A13: 2022년09월 | B13: =F11+F12+F13 -> 96922398 | C13: =AVERAGE(F11:F13) -> 32307466 | D13: =C13/C10-1 -> -0.12713966 | F13: =Q13/20 -> 33656701 | G13: =F13/F12-1 -> 0.19710903 | I13: =T13 -> 11345.553 | K13: =Q11+Q12+Q13 -> 2029828641 | L13: =K13/K10-1 -> -0.1295162 | M13: =S11+S12+S13 -> 138810.41 | N13: =AVERAGE(T11:T13) -> 15150.437 | O13: =N13/N10-1 -> 0.031115715 | P13: 2022년09월 | Q13: 673134026 | S13: 59330.21 | T13: =Q13/S13 -> 11345.553 | U13: =S13/20 -> 2966.5105
A14: 2022년10월 | F14: =Q14/20 -> 28343188 | G14: =F14/F13-1 -> -0.15787385 | I14: =T14 -> 8066.6423 | P14: 2022년10월 | Q14: 566863763 | S14: 70272.58 | T14: =Q14/S14 -> 8066.6423 | U14: =S14/20 -> 3513.629
A15: 2022년11월 | F15: =Q15/22 -> 23496355 | G15: =F15/F14-1 -> -0.17100523 | I15: =T15 -> 10803.899 | P15: 2022년11월 | Q15: 516919802 | S15: 47845.67 | T15: =Q15/S15 -> 10803.899 | U15: =S15/20 -> 2392.2835
A16: 2022년12월 | B16: =F14+F15+F16 -> 67595069 | C16: =AVERAGE(F14:F16) -> 22531690 | D16: =C16/C13-1 -> -0.30258567 | F16: =Q16/22 -> 15755526 | G16: =F16/F15-1 -> -0.32944805 | I16: =T16 -> 8633.1071 | K16: =Q14+Q15+Q16 -> 1430405147 | L16: =K16/K13-1 -> -0.29530744 | N16: =AVERAGE(T14:T16) -> 9167.8829 | O16: =N16/N13-1 -> -0.39487666 | P16: 2022년12월 | Q16: 346621582 | S16: 40150.27 | T16: =Q16/S16 -> 8633.1071 | U16: =S16/20 -> 2007.5135
A17: 2023년01월 | F17: =Q17/20 -> 18210581 | G17: =F17/F16-1 -> 0.1558218 | H17: =F17/F5-1 -> -0.30261212 | I17: =T17 -> 13356.109 | J17: =I17/I5-1 -> 0.22398596 | P17: 2023년01월 | Q17: 364211620 | R17: 457909426432 | S17: 27269.29 | T17: =Q17/S17 -> 13356.109 | U17: =S17/20 -> 1363.4645
A18: 2023년02월 | F18: =Q18/20 -> 24603075 | G18: =F18/F17-1 -> 0.35103184 | H18: =F18/F6-1 -> -0.29614161 | I18: =T18 -> 10150.162 | J18: =I18/I6-1 -> -0.26362971 | P18: 2023년02월 | Q18: 492061495 | R18: 620274925462 | S18: 48478.19 | T18: =Q18/S18 -> 10150.162 | U18: =S18/20 -> 2423.9095
A19: 2023년03월 | B19: =SUM(F17:F19) -> 71788388 | C19: =AVERAGE(F17:F19) -> 23929463 | D19: =C19/C16-1 -> 0.062035864 | E19: =C19/C7-1 -> -0.24418573 | F19: =Q19/22 -> 28974732 | G19: =F19/F18-1 -> 0.17768744 | H19: =F19/F7-1 -> -0.14565058 | I19: =T19 -> 6987.2494 | J19: =I19/I7-1 -> -0.50362991 | K19: =Q17+Q18+Q19 -> 1493717220 | L19: =K19/K16-1 -> 0.044261637 | M19: =U19/U7-1 -> 0.7211944 | N19: =AVERAGE(T17:T19) -> 10164.507 | O19: =N19/N16-1 -> 0.10870821 | P19: 2023년03월 | Q19: 637444105 | R19: 833612611570 | S19: 91229.62 | T19: =Q19/S19 -> 6987.2494 | U19: =S19/20 -> 4561.481
A20: 2023년04월 | F20: =Q20/20 -> 17624314 | G20: =F20/F19-1 -> -0.39173505 | H20: =F20/F8-1 -> -0.50121092 | I20: =T20 -> 9581.6756 | J20: =I20/I8-1 -> -0.30992039 | P20: 2023년04월 | Q20: 352486276 | R20: 462395140391 | S20: 36787.54 | T20: =Q20/S20 -> 9581.6756 | U20: =S20/20 -> 1839.377
A21: 2023년05월 | F21: =Q21/21 -> 17641094 | G21: =F21/F20-1 -> 0.00095212137 | H21: =F21/F9-1 -> -0.53884659 | I21: =T21 -> 9576.0124 | J21: =I21/I9-1 -> -0.29615784 | P21: 2023년05월 | Q21: 370462980 | R21: 493315759699 | S21: 38686.56 | T21: =Q21/S21 -> 9576.0124 | U21: =S21/20 -> 1934.328
A22: 2023년06월 | B22: =SUM(F20:F22) -> 57610047 | C22: =AVERAGE(F20:F22) -> 19203349 | D22: =C22/C19-1 -> -0.19750187 | E22: =C22/C10-1 -> -0.48117745 | F22: =Q22/21 -> 22344639 | G22: =F22/F21-1 -> 0.26662432 | H22: =F22/F10-1 -> -0.40337126 | I22: =T22 -> 6414.351 | J22: =I22/I10-1 -> -0.61334904 | K22: =Q20+Q21+Q22 -> 1192186675 | L22: =K22/K19-1 -> -0.20186588 | M22: =U22/U10-1 -> 0.54306805 | N22: =AVERAGE(T20:T22) -> 8524.013 | O22: =N22/N19-1 -> -0.16139435 | P22: 2023년06월 | Q22: 469237419 | R22: 610745873085 | S22: 73154.31 | T22: =Q22/S22 -> 6414.351 | U22: =S22/20 -> 3657.7155
A23: 2023년07월 | F23: =Q23/21 -> 16908303 | G23: =F23/F22-1 -> -0.24329486 | H23: =F23/F11-1 -> -0.51897695 | I23: =T23 -> 8282.01 | J23: =I23/I11-1 -> -0.548319 | P23: 2023년07월 | Q23: 355074367 | R23: 458165493536 | S23: 42872.97 | T23: =Q23/S23 -> 8282.01 | U23: =S23/21 -> 2041.57
A24: 2023년08월 | F24: =Q24/22 -> 25600321 | G24: =F24/F23-1 -> 0.51406801 | H24: =F24/F12-1 -> -0.089442092 | I24: =T24 -> 9513.8787 | J24: =I24/I12-1 -> -0.39670211 | P24: 2023년08월 | Q24: 563207063 | R24: 738732840823 | S24: 59198.47 | T24: =Q24/S24 -> 9513.8787 | U24: =S24/22 -> 2690.8395
A25: 2023년09월 | B25: =SUM(F23:F25) -> 79932748 | C25: =AVERAGE(F23:F25) -> 26644249 | D25: =C25/C22-1 -> 0.3874793 | E25: =C25/C13-1 -> -0.17529127 | F25: =Q25/19 -> 37424124 | G25: =F25/F24-1 -> 0.4618615 | H25: =F25/F13-1 -> 0.11193677 | I25: =T25 -> 8637.9827 | J25: =I25/I13-1 -> -0.23864593 | K25: =Q23+Q24+Q25 -> 1629339781 | L25: =K25/K22-1 -> 0.36668176 | M25: =U25/U13-1 -> 0.38744899 | N25: =AVERAGE(T23:T25) -> 8811.2905 | O25: =N25/N22-1 -> 0.033702137 | P25: 2023년09월 | Q25: 711058351 | R25: 943805086160 | S25: 82317.64 | T25: =Q25/S25 -> 8637.9827 | U25: =S25/20 -> 4115.882
A26: 2023년10월 | F26: =Q26/19 -> 29654344 | G26: =F26/F25-1 -> -0.20761422 | H26: =F26/F14-1 -> 0.046259986 | I26: =T26 -> 10309.483 | J26: =I26/I14-1 -> 0.27803896 | P26: 2023년10월 | Q26: 563432529 | R26: 759063439626 | S26: 54651.87 | T26: =Q26/S26 -> 10309.483 | U26: =S26/19 -> 2876.4142
A27: 2023년11월 | F27: =Q27/22 -> 26223986 | G27: =F27/F26-1 -> -0.11567808 | H27: =F27/F15-1 -> 0.11608743 | I27: =T27 -> 10992.765 | J27: =I27/I15-1 -> 0.017481273 | P27: 2023년11월 | Q27: 576927692 | R27: 761642990862 | S27: 52482.49 | T27: =Q27/S27 -> 10992.765 | U27: =S27/22 -> 2385.5677
A28: 2023년12월 | B28: =SUM(F26:F28) -> 88693264 | C28: =AVERAGE(F26:F28) -> 29564421 | D28: =C28/C25-1 -> 0.10959858 | E28: =C28/C16-1 -> 0.31212624 | F28: =Q28/19 -> 32814934 | G28: =F28/F27-1 -> 0.25133282 | H28: =F28/F16-1 -> 1.0827571 | I28: =T28 -> 9093.0202 | J28: =I28/I16-1 -> 0.053273181 | K28: =Q26+Q27+Q28 -> 1763843974 | L28: =K28/K25-1 -> 0.082551347 | M28: =U28/U16-1 -> 0.79764905 | N28: =AVERAGE(T26:T28) -> 10131.756 | O28: =N28/N25-1 -> 0.14986065 | P28: 2023년12월 | Q28: 623483753 | R28: 813384975117 | S28: 68567.29 | T28: =Q28/S28 -> 9093.0202 | U28: =S28/19 -> 3608.8047
A29: 2024년01월 | F29: =Q29/22 -> 38979936 | G29: =F29/F28-1 -> 0.18787182 | H29: =F29/F17-1 -> 1.1405103 | I29: =T29 -> 13527.072 | J29: =I29/I17-1 -> 0.012800312 | P29: 2024년01월 | Q29: 857558588 | R29: 1129047268119 | S29: 63395.73 | T29: =Q29/S29 -> 13527.072 | U29: =S29/22 -> 2881.6241
A30: 2024년02월 | F30: =Q30/19 -> 46795713 | G30: =F30/F29-1 -> 0.20050771 | H30: =F30/F18-1 -> 0.90202704 | I30: =T30 -> 15856.204 | J30: =I30/I18-1 -> 0.5621626 | P30: 2024년02월 | Q30: 889118556 | R30: 1184914481031 | S30: 56073.86 | T30: =Q30/S30 -> 15856.204 | U30: =S30/19 -> 2951.2558
A31: 2024년03월 | B31: =SUM(F29:F31) -> 1.2662541e+08 | C31: =AVERAGE(F29:F31) -> 42208471 | D31: =C31/C28-1 -> 0.42767791 | E31: =C31/C19-1 -> 0.76387043 | F31: =Q31/20 -> 40849765 | G31: =F31/F30-1 -> -0.12706182 | H31: =F31/F19-1 -> 0.40984099 | I31: =T31 -> 14855.551 | J31: =I31/I19-1 -> 1.1260943 | K31: =Q29+Q30+Q31 -> 2563672440 | L31: =K31/K28-1 -> 0.45345761 | M31: =U31/U19-1 -> -0.39716991 | N31: =AVERAGE(T29:T31) -> 14746.276 | O31: =N31/N28-1 -> 0.45545109 | P31: 2024년03월 | Q31: 816995296 | R31: 1086063333108 | S31: 54995.96 | T31: =Q31/S31 -> 14855.551 | U31: =S31/20 -> 2749.798
A32: 2024년04월 | F32: =Q32/21 -> 29303940 | G32: =F32/F31-1 -> -0.28264115 | H32: =F32/F20-1 -> 0.66269964 | I32: =T32 -> 14448.304 | J32: =I32/I20-1 -> 0.50790995 | P32: 2024년04월 | Q32: 615382745 | R32: 838301417681 | S32: 42592.04 | T32: =Q32/S32 -> 14448.304 | U32: =S32/14 -> 3042.2886
A33: 2024년05월 | F33: =Q33/21 -> 32649250 | G33: =F33/F32-1 -> 0.11415903 | H33: =F33/F21-1 -> 0.85074969 | I33: =T33 -> 16364.293 | J33: =I33/I21-1 -> 0.70888382 | P33: 2024년05월 | Q33: 685634245 | R33: 938113887023 | S33: 41898.19 | T33: =Q33/S33 -> 16364.293 | U33: =S33/21 -> 1995.1519
A34: 2024년06월 | B34: =SUM(F32:F34) -> 97630421 | C34: =AVERAGE(F32:F34) -> 32543474 | D34: =C34/C31-1 -> -0.22898242 | E34: =C34/C22-1 -> 0.69467698 | F34: =Q34/19 -> 35677231 | G34: =F34/F33-1 -> 0.092742736 | H34: =F34/F22-1 -> 0.59667966 | I34: =T34 -> 14906.319 | J34: =I34/I22-1 -> 1.3239013 | K34: =Q32+Q33+Q34 -> 1978884370 | L34: =K34/K31-1 -> -0.22810561 | M34: =U34/U22-1 -> -0.34564894 | N34: =AVERAGE(T32:T34) -> 15239.639 | O34: =N34/N31-1 -> 0.033456782 | P34: 2024년06월 | Q34: 677867380 | R34: 931543953192 | S34: 45475.17 | T34: =Q34/S34 -> 14906.319 | U34: =S34/19 -> 2393.43
A35: 2024년07월 | F35: =Q35/23 -> 23310713 | G35: =F35/F34-1 -> -0.34662212 | H35: =F35/F23-1 -> 0.37865479 | I35: =T35 -> 13980.299 | J35: =I35/I23-1 -> 0.68803207 | P35: 2024년07월 | Q35: 536146405 | R35: 742153879668 | S35: 38350.14 | T35: =Q35/S35 -> 13980.299 | U35: =S35/23 -> 1667.3974
A36: 2024년08월 | F36: =Q36/21 -> 18476769 | G36: =F36/F35-1 -> -0.20737006 | H36: =F36/F24-1 -> -0.27826026 | I36: =T36 -> 12797.703 | J36: =I36/I24-1 -> 0.34516147 | P36: 2024년08월 | Q36: 388012152 | R36: 528336419639 | S36: 30318.89 | T36: =Q36/S36 -> 12797.703 | U36: =S36/21 -> 1443.7567
A37: 2024년09월 | B37: =SUM(F35:F37) -> 76611893 | C37: =AVERAGE(F35:F37) -> 25537298 | D37: =C37/C34-1 -> -0.21528666 | E37: =C37/C25-1 -> -0.041545609 | F37: =Q37/18 -> 34824411 | G37: =F37/F36-1 -> 0.88476733 | H37: =F37/F25-1 -> -0.069466232 | I37: =T37 -> 15422.433 | J37: =I37/I25-1 -> 0.7854207 | K37: =Q35+Q36+Q37 -> 1550997953 | L37: =K37/K34-1 -> -0.21622608 | M37: =U37/U25-1 -> -0.45138463 | N37: =AVERAGE(T35:T37) -> 14066.812 | O37: =N37/N34-1 -> -0.076958974 | P37: 2024년09월 | Q37: 626839396 | R37: 836739797672 | S37: 40644.65 | T37: =Q37/S37 -> 15422.433 | U37: =S37/18 -> 2258.0361
A38: 2024년10월 | F38: =Q38/20 -> 22021239 | G38: =F38/F37-1 -> -0.36764935 | H38: =F38/F26-1 -> -0.25740259 | I38: =T38 -> 13510.53 | J38: =I38/I26-1 -> 0.3104954 | P38: 2024년10월 | Q38: 440424775 | R38: 592246813792 | S38: 32598.63 | T38: =Q38/S38 -> 13510.53 | U38: =S38/20 -> 1629.9315
A39: 2024년11월 | F39: =Q39/21 -> 22806292 | G39: =F39/F38-1 -> 0.035649812 | H39: =F39/F27-1 -> -0.13032703 | I39: =T39 -> 10441.394 | J39: =I39/I27-1 -> -0.050157643 | P39: 2024년11월 | Q39: 478932127 | R39: 665428575403 | S39: 45868.6 | T39: =Q39/S39 -> 10441.394 | U39: =S39/14 -> 3276.3286
A40: 2024년12월 | B40: =SUM(F38:F40) -> 74018253 | C40: =AVERAGE(F38:F40) -> 24672751 | D40: =C40/C37-1 -> -0.033854281 | E40: =C40/C28-1 -> -0.16545801 | F40: =Q40/21 -> 29190722 | G40: =F40/F39-1 -> 0.27994163 | H40: =F40/F28-1 -> -0.11044399 | I40: =T40 -> 14528.647 | J40: =I40/I28-1 -> 0.59778013 | K40: =Q38+Q39+Q40 -> 1532362069 | L40: =K40/K37-1 -> -0.012015415 | M40: =U40/U28-1 -> -0.44325505 | N40: =AVERAGE(T38:T40) -> 12826.857 | O40: =N40/N37-1 -> -0.088147516 | P40: 2024년12월 | Q40: 613005167 | R40: 874744044813 | S40: 42192.86 | T40: =Q40/S40 -> 14528.647 | U40: =S40/21 -> 2009.1838
...

Sheet HBM
L1: 삼성전자, 하이닉스
L2: 8542323000
P3: 년월 | Q3: 금액(달러) | R3: 금액(원화) | S3: 중량(Kg)
A4: 년월 | B4: 분기(일평균합) | C4: 분기(평균) | D4: QoQ | E4: YoY | F4: 일평균수출 | G4: MoM | H4: YoY | I4: 금액(달러)/중량 | J4: 판가 yoy | K4: 분기 달러매출 | L4: QoQ | M4: YoY | N4: 판가 | O4: QoQ | T4: 금액(달러)/중량
A5: 2022년01월 | F5: =Q5/20 -> 1.2064243e+08 | I5: =T5 -> 31446.577 | P5: 2022년01월 | Q5: 2412848672 | R5: 2848238592761 | S5: 76728.5 | T5: =Q5/S5 -> 31446.577
A6: 2022년02월 | F6: =Q6/18 -> 1.1724991e+08 | G6: =F6/F5-1 -> -0.028120483 | I6: =T6 -> 28452.854 | P6: 2022년02월 | Q6: 2110498381 | R6: 2507495787262 | S6: 74175.28 | T6: =Q6/S6 -> 28452.854
A7: 2022년03월 | B7: =F5+F6+F7 -> 3.7646104e+08 | C7: =AVERAGE(F5:F7) -> 1.2548701e+08 | F7: =Q7/22 -> 1.385687e+08 | G7: =F7/F6-1 -> 0.18182351 | I7: =T7 -> 28733.446 | K7: =Q5+Q6+Q7 -> 7571858458 | N7: =AVERAGE(T5:T7) -> 29544.292 | P7: 2022년03월 | Q7: 3048511405 | R7: 3675609941057 | S7: 106096.27 | T7: =Q7/S7 -> 28733.446
A8: 2022년04월 | F8: =Q8/21 -> 94205287 | G8: =F8/F7-1 -> -0.32015465 | I8: =T8 -> 28092.884 | P8: 2022년04월 | Q8: 1978311024 | R8: 2402550303120 | S8: 70420.36 | T8: =Q8/S8 -> 28092.884
A9: 2022년05월 | F9: =Q9/21 -> 1.1455237e+08 | G9: =F9/F8-1 -> 0.21598669 | I9: =T9 -> 27518.815 | P9: 2022년05월 | Q9: 2405599871 | R9: 3027407363396 | S9: 87416.55 | T9: =Q9/S9 -> 27518.815 | AC9: 2500
A10: 2022년06월 | B10: =F8+F9+F10 -> 3.2804393e+08 | C10: =AVERAGE(F8:F10) -> 1.0934798e+08 | D10: =C10/C7-1 -> -0.12861123 | F10: =Q10/21 -> 1.1928626e+08 | G10: =F10/F9-1 -> 0.041325107 | I10: =T10 -> 22879.877 | K10: =Q8+Q9+Q10 -> 6888922437 | L10: =K10/K7-1 -> -0.090193976 | N10: =AVERAGE(T8:T10) -> 26163.859 | O10: =N10/N7-1 -> -0.11441917 | P10: 2022년06월 | Q10: 2505011542 | R10: 3168883237563 | S10: 109485.36 | T10: =Q10/S10 -> 22879.877 | AC10: 4545
A11: 2022년07월 | F11: =Q11/21 -> 86944386 | G11: =F11/F10-1 -> -0.27112826 | I11: =T11 -> 24016.314 | P11: 2022년07월 | Q11: 1825832115 | R11: 2362830964842 | S11: 76024.66 | T11: =Q11/S11 -> 24016.314 | AC11: =AC9*AC10 -> 11362500
A12: 2022년08월 | F12: =Q12/22 -> 94352260 | G12: =F12/F11-1 -> 0.085202437 | I12: =T12 -> 26153.454 | P12: 2022년08월 | Q12: 2075749720 | R12: 2700316213060 | S12: 79368.09 | T12: =Q12/S12 -> 26153.454
A13: 2022년09월 | B13: =F11+F12+F13 -> 3.0458249e+08 | C13: =AVERAGE(F11:F13) -> 1.015275e+08 | D13: =C13/C10-1 -> -0.071519195 | F13: =Q13/20 -> 1.2328584e+08 | G13: =F13/F12-1 -> 0.30665489 | I13: =T13 -> 22268.224 | K13: =Q11+Q12+Q13 -> 6367298666 | L13: =K13/K10-1 -> -0.075719211 | N13: =AVERAGE(T11:T13) -> 24145.998 | O13: =N13/N10-1 -> -0.077123987 | P13: 2022년09월 | Q13: 2465716831 | R13: 3374471593153 | S13: 110728.04 | T13: =Q13/S13 -> 22268.224
A14: 2022년10월 | F14: =Q14/20 -> 82270275 | G14: =F14/F13-1 -> -0.33268676 | I14: =T14 -> 23214.33 | P14: 2022년10월 | Q14: 1645405495 | R14: 2347512725855 | S14: 70878.87 | T14: =Q14/S14 -> 23214.33
A15: 2022년11월 | F15: =Q15/22 -> 61227410 | G15: =F15/F14-1 -> -0.25577725 | I15: =T15 -> 18944.993 | P15: 2022년11월 | Q15: 1347003024 | R15: 1852368936099 | S15: 71100.74 | T15: =Q15/S15 -> 18944.993
A16: 2022년12월 | B16: =F14+F15+F16 -> 2.1102256e+08 | C16: =AVERAGE(F14:F16) -> 70340854 | D16: =C16/C13-1 -> -0.30717435 | F16: =Q16/22 -> 67524876 | G16: =F16/F15-1 -> 0.1028537 | I16: =T16 -> 17738.196 | K16: =Q14+Q15+Q16 -> 4477955793 | L16: =K16/K13-1 -> -0.29672597 | N16: =AVERAGE(T14:T16) -> 19965.84 | O16: =N16/N13-1 -> -0.17312012 | P16: 2022년12월 | Q16: 1485547274 | R16: 1942406237917 | S16: 83748.5 | T16: =Q16/S16 -> 17738.196
A17: 2023년01월 | F17: =Q17/20 -> 55570314 | G17: =F17/F16-1 -> -0.17703938 | H17: =F17/F5-1 -> -0.53938003 | I17: =T17 -> 19115.621 | J17: =I17/I5-1 -> -0.39212396 | P17: 2023년01월 | Q17: 1111406272 | R17: 1394645194991 | S17: 58141.26 | T17: =Q17/S17 -> 19115.621
A18: 2023년02월 | F18: =Q18/20 -> 53172544 | G18: =F18/F17-1 -> -0.043148399 | H18: =F18/F6-1 -> -0.54650248 | I18: =T18 -> 15176.898 | J18: =I18/I6-1 -> -0.46659487 | P18: 2023년02월 | Q18: 1063450871 | R18: 1336072931904 | S18: 70070.37 | T18: =Q18/S18 -> 15176.898
A19: 2023년03월 | B19: =SUM(F17:F19) -> 1.821737e+08 | C19: =AVERAGE(F17:F19) -> 60724565 | D19: =C19/C16-1 -> -0.13670986 | E19: =C19/C7-1 -> -0.51608885 | F19: =Q19/22 -> 73430839 | G19: =F19/F18-1 -> 0.38099166 | H19: =F19/F7-1 -> -0.47007629 | I19: =T19 -> 14440.15 | J19: =I19/I7-1 -> -0.49744455 | K19: =Q17+Q18+Q19 -> 3790335606 | L19: =K19/K16-1 -> -0.15355672 | M19: =U19/U7-1 -> #DIV/0! | N19: =AVERAGE(T17:T19) -> 16244.223 | O19: =N19/N16-1 -> -0.18639921 | P19: 2023년03월 | Q19: 1615478463 | R19: 2109620267886 | S19: 111874.08 | T19: =Q19/S19 -> 14440.15
A20: 2023년04월 | F20: =Q20/20 -> 49145162 | G20: =F20/F19-1 -> -0.33072858 | H20: =F20/F8-1 -> -0.47831843 | I20: =T20 -> 12824.233 | J20: =I20/I8-1 -> -0.54350599 | P20: 2023년04월 | Q20: 982903236 | R20: 1289895158494 | S20: 76644.21 | T20: =Q20/S20 -> 12824.233
A21: 2023년05월 | F21: =Q21/21 -> 60593007 | G21: =F21/F20-1 -> 0.23293941 | H21: =F21/F9-1 -> -0.47104539 | I21: =T21 -> 14539.023 | J21: =I21/I9-1 -> -0.47166972 | P21: 2023년05월 | Q21: 1272453143 | R21: 1692196854931 | S21: 87519.85 | T21: =Q21/S21 -> 14539.023
A22: 2023년06월 | B22: =SUM(F20:F22) -> 2.117687e+08 | C22: =AVERAGE(F20:F22) -> 70589567 | D22: =C22/C19-1 -> 0.16245487 | E22: =C22/C10-1 -> -0.35445017 | F22: =Q22/21 -> 1.0203053e+08 | G22: =F22/F21-1 -> 0.68386646 | H22: =F22/F10-1 -> -0.14465816 | I22: =T22 -> 14988.141 | J22: =I22/I10-1 -> -0.3449204 | K22: =Q20+Q21+Q22 -> 4397997554 | L22: =K22/K19-1 -> 0.16031877 | M22: =U22/U10-1 -> #DIV/0! | N22: =AVERAGE(T20:T22) -> 14117.132 | O22: =N22/N19-1 -> -0.13094443 | P22: 2023년06월 | Q22: 2142641175 | R22: 2773357497612 | S22: 142955.77 | T22: =Q22/S22 -> 14988.141
A23: 2023년07월 | F23: =Q23/21 -> 67934697 | G23: =F23/F22-1 -> -0.33417286 | H23: =F23/F11-1 -> -0.21864194 | I23: =T23 -> 13608.504 | J23: =I23/I11-1 -> -0.43336416 | P23: 2023년07월 | Q23: 1426628646 | R23: 1834784992970 | S23: 104833.61 | T23: =Q23/S23 -> 13608.504
A24: 2023년08월 | F24: =Q24/22 -> 75905846 | G24: =F24/F23-1 -> 0.11733545 | H24: =F24/F12-1 -> -0.1955058 | I24: =T24 -> 15377.134 | J24: =I24/I12-1 -> -0.41204195 | P24: 2023년08월 | Q24: 1669928603 | R24: 2196209451688 | S24: 108598.17 | T24: =Q24/S24 -> 15377.134
A25: 2023년09월 | B25: =SUM(F23:F25) -> 2.5300665e+08 | C25: =AVERAGE(F23:F25) -> 84335550 | D25: =C25/C22-1 -> 0.19473109 | E25: =C25/C13-1 -> -0.1693329 | F25: =Q25/19 -> 1.0916611e+08 | G25: =F25/F24-1 -> 0.43817788 | H25: =F25/F13-1 -> -0.11452843 | I25: =T25 -> 15900.095 | J25: =I25/I13-1 -> -0.28597385 | K25: =Q23+Q24+Q25 -> 5170713296 | L25: =K25/K22-1 -> 0.17569717 | M25: =U25/U13-1 -> #DIV/0! | N25: =AVERAGE(T23:T25) -> 14961.911 | O25: =N25/N22-1 -> 0.059840661 | P25: 2023년09월 | Q25: 2074156047 | R25: 2753212041729 | S25: 130449.29 | T25: =Q25/S25 -> 15900.095
A26: 2023년10월 | F26: =Q26/19 -> 97127795 | G26: =F26/F25-1 -> -0.11027519 | H26: =F26/F14-1 -> 0.18059403 | I26: =T26 -> 18932.41 | J26: =I26/I14-1 -> -0.18445161 | P26: 2023년10월 | Q26: 1845428103 | R26: 2490302612845 | S26: 97474.55 | T26: =Q26/S26 -> 18932.41
A27: 2023년11월 | F27: =Q27/22 -> 91596765 | G27: =F27/F26-1 -> -0.056945898 | H27: =F27/F15-1 -> 0.49600914 | I27: =T27 -> 18917.419 | J27: =I27/I15-1 -> -0.0014554959 | P27: 2023년11월 | Q27: 2015128839 | R27: 2649551051947 | S27: 106522.4 | T27: =Q27/S27 -> 18917.419
A28: 2023년12월 | B28: =SUM(F26:F28) -> 3.2154194e+08 | C28: =AVERAGE(F26:F28) -> 1.0718065e+08 | D28: =C28/C25-1 -> 0.27088335 | E28: =C28/C16-1 -> 0.52373253 | F28: =Q28/19 -> 1.3281738e+08 | G28: =F28/F27-1 -> 0.45002261 | H28: =F28/F16-1 -> 0.96694001 | I28: =T28 -> 21224.716 | J28: =I28/I16-1 -> 0.19655441 | K28: =Q26+Q27+Q28 -> 6384087177 | L28: =K28/K25-1 -> 0.23466277 | M28: =U28/U16-1 -> #DIV/0! | N28: =AVERAGE(T26:T28) -> 19691.515 | O28: =N28/N25-1 -> 0.31610961 | P28: 2023년12월 | Q28: 2523530235 | R28: 3292535123896 | S28: 118895.83 | T28: =Q28/S28 -> 21224.716
A29: 2024년01월 | F29: =Q29/22 -> 89106768 | G29: =F29/F28-1 -> -0.32910311 | H29: =F29/F17-1 -> 0.60349586 | I29: =T29 -> 28286.561 | J29: =I29/I17-1 -> 0.47976156 | P29: 2024년01월 | Q29: 1960348887 | R29: 2593154233547 | S29: 69303.19 | T29: =Q29/S29 -> 28286.561
A30: 2024년02월 | F30: =Q30/19 -> 1.2148634e+08 | G30: =F30/F29-1 -> 0.36337947 | H30: =F30/F18-1 -> 1.2847569 | I30: =T30 -> 28373.821 | J30: =I30/I18-1 -> 0.86954019 | P30: 2024년02월 | Q30: 2308240418 | R30: 3076874251538 | S30: 81351.06 | T30: =Q30/S30 -> 28373.821
A31: 2024년03월 | B31: =SUM(F29:F31) -> 3.4708346e+08 | C31: =AVERAGE(F29:F31) -> 1.1569449e+08 | D31: =C31/C28-1 -> 0.07943448 | E31: =C31/C19-1 -> 0.90523366 | F31: =Q31/20 -> 1.3649035e+08 | G31: =F31/F30-1 -> 0.12350372 | H31: =F31/F19-1 -> 0.85876063 | I31: =T31 -> 31590.174 | J31: =I31/I19-1 -> 1.1876625 | K31: =Q29+Q30+Q31 -> 6998396359 | L31: =K31/K28-1 -> 0.096225062 | M31: =U31/U19-1 -> #DIV/0! | N31: =AVERAGE(T29:T31) -> 29416.852 | O31: =N31/N28-1 -> 0.49388466 | P31: 2024년03월 | Q31: 2729807054 | R31: 3626271521238 | S31: 86413.17 | T31: =Q31/S31 -> 31590.174
A32: 2024년04월 | F32: =Q32/21 -> 102800596 | G32: =F32/F31-1 -> -0.24682885 | H32: =F32/F20-1 -> 1.0917745 | I32: =T32 -> 25866.498 | J32: =I32/I20-1 -> 1.0170015 | P32: 2024년04월 | Q32: 2158812516 | R32: 2945745554926 | S32: 83459.79 | T32: =Q32/S32 -> 25866.498
A33: 2024년05월 | F33: =Q33/21 -> 1.2850841e+08 | G33: =F33/F32-1 -> 0.2500746 | H33: =F33/F21-1 -> 1.1208456 | I33: =T33 -> 33184.21 | J33: =I33/I21-1 -> 1.2824236 | P33: 2024년05월 | Q33: 2698676682 | R33: 3686283280708 | S33: 81324.12 | T33: =Q33/S33 -> 33184.21
A34: 2024년06월 | B34: =SUM(F32:F34) -> 4.2827287e+08 | C34: =AVERAGE(F32:F34) -> 1.4275762e+08 | D34: =C34/C31-1 -> 0.23391899 | E34: =C34/C22-1 -> 1.0223615 | F34: =Q34/19 -> 1.9696386e+08 | G34: =F34/F33-1 -> 0.53269234 | H34: =F34/F22-1 -> 0.9304404 | I34: =T34 -> 27821.874 | J34: =I34/I22-1 -> 0.85625923 | K34: =Q32+Q33+Q34 -> 8599802559 | L34: =K34/K31-1 -> 0.22882474 | M34: =U34/U22-1 -> #DIV/0! | N34: =AVERAGE(T32:T34) -> 28957.528 | O34: =N34/N31-1 -> -0.015614324 | P34: 2024년06월 | Q34: 3742313361 | R34: 5153509421843 | S34: 134509.75 | T34: =Q34/S34 -> 27821.874
A35: 2024년07월 | F35: =Q35/23 -> 1.2955934e+08 | G35: =F35/F34-1 -> -0.3422177 | H35: =F35/F23-1 -> 0.90711589 | I35: =T35 -> 33203.561 | J35: =I35/I23-1 -> 1.4399125 | P35: 2024년07월 | Q35: 2979864837 | R35: 4124348379035 | S35: 89745.34 | T35: =Q35/S35 -> 33203.561
A36: 2024년08월 | F36: =Q36/21 -> 1.5939352e+08 | G36: =F36/F35-1 -> 0.23027421 | H36: =F36/F24-1 -> 1.0998846 | I36: =T36 -> 32350.575 | J36: =I36/I24-1 -> 1.1038104 | P36: 2024년08월 | Q36: 3347263827 | R36: 4562204563504 | S36: 103468.45 | T36: =Q36/S36 -> 32350.575
A37: 2024년09월 | B37: =SUM(F35:F37) -> 5.0020706e+08 | C37: =AVERAGE(F35:F37) -> 1.6673569e+08 | D37: =C37/C34-1 -> 0.16796345 | E37: =C37/C25-1 -> 0.97705104 | F37: =Q37/18 -> 2.1125421e+08 | G37: =F37/F36-1 -> 0.32536261 | H37: =F37/F25-1 -> 0.93516293 | I37: =T37 -> 35133.75 | J37: =I37/I25-1 -> 1.2096567 | K37: =Q35+Q36+Q37 -> 10129704357 | L37: =K37/K34-1 -> 0.17789964 | M37: =U37/U25-1 -> #DIV/0! | N37: =AVERAGE(T35:T37) -> 33562.629 | O37: =N37/N34-1 -> 0.1590295 | P37: 2024년09월 | Q37: 3802575693 | R37: 5073475111461 | S37: 108231.42 | T37: =Q37/S37 -> 35133.75
A38: 2024년10월 | F38: =Q38/20 -> 1.7414141e+08 | G38: =F38/F37-1 -> -0.17567838 | H38: =F38/F26-1 -> 0.79291015 | I38: =T38 -> 52676.081 | J38: =I38/I26-1 -> 1.7823231 | P38: 2024년10월 | Q38: 3482828191 | R38: 4704942187128 | S38: 66117.83 | T38: =Q38/S38 -> 52676.081
A39: 2024년11월 | F39: =Q39/21 -> 1.7084197e+08 | G39: =F39/F38-1 -> -0.018946907 | H39: =F39/F27-1 -> 0.86515285 | I39: =T39 -> 43052.4 | J39: =I39/I27-1 -> 1.2758073 | P39: 2024년11월 | Q39: 3587681336 | R39: 4990791761062 | S39: 83332.9 | T39: =Q39/S39 -> 43052.4
A40: 2024년12월 | B40: =SUM(F38:F40) -> 5.5122727e+08 | C40: =AVERAGE(F38:F40) -> 1.8374242e+08 | D40: =C40/C37-1 -> 0.10199818 | E40: =C40/C28-1 -> 0.71432463 | F40: =Q40/21 -> 2.0624389e+08 | G40: =F40/F39-1 -> 0.2072203 | H40: =F40/F28-1 -> 0.55283812 | I40: =T40 -> 48946.435 | J40: =I40/I28-1 -> 1.3061055 | K40: =Q38+Q39+Q40 -> 11401631269 | L40: =K40/K37-1 -> 0.12556407 | M40: =U40/U28-1 -> #DIV/0! | N40: =AVERAGE(T38:T40) -> 48224.972 | O40: =N40/N37-1 -> 0.43686517 | P40: 2024년12월 | Q40: 4331121742 | R40: 6195829283153 | S40: 88486.97 | T40: =Q40/S40 -> 48946.435
...

Sheet AIR 쿨러
K1: SNT에너지
K2: 841950
P3: 년월 | Q3: 금액(달러) | R3: 금액(원화) | S3: 중량(Kg)
A4: 년월 | B4: 분기(일평균합) | C4: 분기(평균) | D4: QoQ | E4: YoY | F4: 일평균수출 | G4: MoM | H4: YoY | I4: 금액(달러)/중량 | J4: 판가 yoy | K4: 원화매출 | L4: QoQ | M4: YoY | N4: 판가 | O4: QoQ | T4: 금액(달러)/중량 | U4: 분기 달러매출
A5: 2022년01월 | F5: =Q5/20 -> 2021927.4 | I5: =T5 -> 8.5615042 | P5: 2022년01월 | Q5: 40438549 | R5: 47648953741 | S5: 4723299.6 | T5: =Q5/S5 -> 8.5615042
A6: 2022년02월 | F6: =Q6/18 -> 2766094.8 | G6: =F6/F5-1 -> 0.36804848 | I6: =T6 -> 7.3099962 | P6: 2022년02월 | Q6: 49789706 | R6: 59137691192 | S6: 6811180.8 | T6: =Q6/S6 -> 7.3099962
A7: 2022년03월 | B7: =F5+F6+F7 -> 6455871.7 | C7: =AVERAGE(F5:F7) -> 2151957.2 | F7: =Q7/22 -> 1667849.5 | G7: =F7/F6-1 -> -0.3970382 | I7: =T7 -> 11.890854 | K7: =R5+R6+R7 -> 150922885496 | N7: =AVERAGE(T5:T7) -> 9.2541182 | P7: 2022년03월 | Q7: 36692689 | R7: 44136240563 | S7: 3085790.8 | T7: =Q7/S7 -> 11.890854 | U7: =Q5+Q6+Q7 -> 126920944
A8: 2022년04월 | F8: =Q8/21 -> 2419642.1 | G8: =F8/F7-1 -> 0.45075568 | I8: =T8 -> 6.0845223 | P8: 2022년04월 | Q8: 50812485 | R8: 61485693581 | S8: 8351105.1 | T8: =Q8/S8 -> 6.0845223
A9: 2022년05월 | F9: =Q9/21 -> 2457083.3 | G9: =F9/F8-1 -> 0.015473835 | I9: =T9 -> 8.811389 | P9: 2022년05월 | Q9: 51598749 | R9: 64894259336 | S9: 5855915.4 | T9: =Q9/S9 -> 8.811389
A10: 2022년06월 | B10: =F8+F9+F10 -> 6384148 | C10: =AVERAGE(F8:F10) -> 2128049.3 | D10: =C10/C7-1 -> -0.011109837 | F10: =Q10/21 -> 1507422.6 | G10: =F10/F9-1 -> -0.38649918 | I10: =T10 -> 6.4865782 | K10: =R8+R9+R10 -> 166059992361 | L10: =U10/U7-1 -> 0.056304064 | N10: =AVERAGE(T8:T10) -> 7.1274965 | O10: =N10/N7-1 -> -0.22980274 | P10: 2022년06월 | Q10: 31655875 | R10: 39680039444 | S10: 4880211.7 | T10: =Q10/S10 -> 6.4865782 | U10: =Q8+Q9+Q10 -> 134067109
A11: 2022년07월 | F11: =Q11/21 -> 2323299.8 | G11: =F11/F10-1 -> 0.54123985 | I11: =T11 -> 6.5050675 | P11: 2022년07월 | Q11: 48789296 | R11: 63246545076 | S11: 7500198.3 | T11: =Q11/S11 -> 6.5050675
A12: 2022년08월 | F12: =Q12/22 -> 1588061.8 | G12: =F12/F11-1 -> -0.31646281 | I12: =T12 -> 6.5623658 | P12: 2022년08월 | Q12: 34937360 | R12: 45307696939 | S12: 5323897 | T12: =Q12/S12 -> 6.5623658
A13: 2022년09월 | B13: =F11+F12+F13 -> 5332855.6 | C13: =AVERAGE(F11:F13) -> 1777618.5 | D13: =C13/C10-1 -> -0.16467231 | F13: =Q13/20 -> 1421494 | G13: =F13/F12-1 -> -0.10488749 | I13: =T13 -> 8.6246996 | K13: =R11+R12+R13 -> 147508506324 | L13: =U13/U10-1 -> -0.16342989 | N13: =AVERAGE(T11:T13) -> 7.230711 | O13: =N13/N10-1 -> 0.014481164 | P13: 2022년09월 | Q13: 28429880 | R13: 38954264309 | S13: 3296332.8 | T13: =Q13/S13 -> 8.6246996 | U13: =Q11+Q12+Q13 -> 112156536
A14: 2022년10월 | F14: =Q14/20 -> 2271454.8 | G14: =F14/F13-1 -> 0.59793485 | I14: =T14 -> 7.3649078 | P14: 2022년10월 | Q14: 45429096 | R14: 64840062847 | S14: 6168318.4 | T14: =Q14/S14 -> 7.3649078
A15: 2022년11월 | F15: =Q15/22 -> 2545601.7 | G15: =F15/F14-1 -> 0.12069222 | I15: =T15 -> 8.9641789 | P15: 2022년11월 | Q15: 56003238 | R15: 77562878574 | S15: 6247447.6 | T15: =Q15/S15 -> 8.9641789
A16: 2022년12월 | B16: =F14+F15+F16 -> 6744992.3 | C16: =AVERAGE(F14:F16) -> 2248330.8 | D16: =C16/C13-1 -> 0.26479934 | F16: =Q16/22 -> 1927935.7 | G16: =F16/F15-1 -> -0.24264047 | I16: =T16 -> 9.1619374 | K16: =R14+R15+R16 -> 197954265251 | L16: =U16/U13-1 -> 0.28255495 | N16: =AVERAGE(T14:T16) -> 8.497008 | O16: =N16/N13-1 -> 0.1751276 | P16: 2022년12월 | Q16: 42414586 | R16: 55551323830 | S16: 4629434.2 | T16: =Q16/S16 -> 9.1619374 | U16: =Q14+Q15+Q16 -> 143846920
A17: 2023년01월 | F17: =Q17/20 -> 3056027.1 | G17: =F17/F16-1 -> 0.58512917 | H17: =F17/F5-1 -> 0.51144253 | I17: =T17 -> 8.2571742 | J17: =I17/I5-1 -> -0.035546325 | P17: 2023년01월 | Q17: 61120543 | R17: 76737255258 | S17: 7402113.8 | T17: =Q17/S17 -> 8.2571742
A18: 2023년02월 | F18: =Q18/20 -> 3122832.1 | G18: =F18/F17-1 -> 0.021860064 | H18: =F18/F6-1 -> 0.12896786 | I18: =T18 -> 8.1792077 | J18: =I18/I6-1 -> 0.11890725 | P18: 2023년02월 | Q18: 62456642 | R18: 78401354470 | S18: 7636025.9 | T18: =Q18/S18 -> 8.1792077
A19: 2023년03월 | B19: =SUM(F17:F19) -> 7580720.4 | C19: =AVERAGE(F17:F19) -> 2526906.8 | D19: =C19/C16-1 -> 0.1239035 | E19: =C19/C7-1 -> 0.17423653 | F19: =Q19/22 -> 1401861.2 | G19: =F19/F18-1 -> -0.551093 | H19: =F19/F7-1 -> -0.15947981 | I19: =T19 -> 9.5888933 | J19: =I19/I7-1 -> -0.19359088 | K19: =R17+R18+R19 -> 195472631425 | L19: =U19/U16-1 -> 0.073489311 | M19: =U19/U7-1 -> 0.21664814 | N19: =AVERAGE(T17:T19) -> 8.6750918 | O19: =N19/N16-1 -> 0.020958406 | P19: 2023년03월 | Q19: 30840946 | R19: 40334021697 | S19: 3216319.6 | T19: =Q19/S19 -> 9.5888933 | U19: =Q17+Q18+Q19 -> 154418131
A20: 2023년04월 | F20: =Q20/20 -> 3944774 | G20: =F20/F19-1 -> 1.8139548 | H20: =F20/F8-1 -> 0.63031298 | I20: =T20 -> 8.0299577 | J20: =I20/I8-1 -> 0.31973511 | P20: 2023년04월 | Q20: 78895480 | R20: 103443702622 | S20: 9825142.7 | T20: =Q20/S20 -> 8.0299577
